{
    DataVersion: 3465,
    size: [14, 29, 14],
    data: [
        {pos: [5, 0, 8], state: "sullysmod:petrified_log{axis:y}"},
        {pos: [8, 0, 4], state: "sullysmod:amber{is_melted:false}", nbt: {RenderEntity: 0b, StuckEntity: [], id: "sullysmod:amber"}},
        {pos: [4, 1, 5], state: "sullysmod:amber{is_melted:false}", nbt: {RenderEntity: 0b, StuckEntity: [], id: "sullysmod:amber"}},
        {pos: [5, 1, 8], state: "sullysmod:stripped_petrified_log{axis:y}"},
        {pos: [8, 1, 4], state: "sullysmod:stripped_petrified_log{axis:y}"},
        {pos: [8, 1, 6], state: "sullysmod:amber{is_melted:false}", nbt: {RenderEntity: 0b, StuckEntity: [], id: "sullysmod:amber"}},
        {pos: [4, 2, 5], state: "sullysmod:stripped_petrified_log{axis:y}"},
        {pos: [5, 2, 8], state: "sullysmod:stripped_petrified_log{axis:y}"},
        {pos: [6, 2, 2], state: "sullysmod:stripped_petrified_log{axis:y}"},
        {pos: [8, 2, 4], state: "sullysmod:petrified_log{axis:y}"},
        {pos: [8, 2, 6], state: "sullysmod:stripped_petrified_log{axis:y}"},
        {pos: [13, 2, 8], state: "sullysmod:amber{is_melted:false}", nbt: {RenderEntity: 0b, StuckEntity: [], id: "sullysmod:amber"}},
        {pos: [2, 3, 5], state: "minecraft:gravel"},
        {pos: [2, 3, 6], state: "minecraft:gravel"},
        {pos: [2, 3, 7], state: "minecraft:gravel"},
        {pos: [3, 3, 4], state: "minecraft:gravel"},
        {pos: [3, 3, 5], state: "minecraft:gravel"},
        {pos: [3, 3, 6], state: "minecraft:gravel"},
        {pos: [3, 3, 7], state: "minecraft:gravel"},
        {pos: [3, 3, 8], state: "minecraft:gravel"},
        {pos: [3, 3, 9], state: "sullysmod:amber{is_melted:false}", nbt: {RenderEntity: 0b, StuckEntity: [], id: "sullysmod:amber"}},
        {pos: [4, 3, 2], state: "minecraft:gravel"},
        {pos: [4, 3, 3], state: "minecraft:gravel"},
        {pos: [4, 3, 4], state: "minecraft:gravel"},
        {pos: [4, 3, 5], state: "sullysmod:petrified_log{axis:y}"},
        {pos: [4, 3, 6], state: "minecraft:gravel"},
        {pos: [4, 3, 7], state: "minecraft:gravel"},
        {pos: [4, 3, 8], state: "minecraft:gravel"},
        {pos: [4, 3, 9], state: "minecraft:gravel"},
        {pos: [5, 3, 1], state: "minecraft:gravel"},
        {pos: [5, 3, 2], state: "minecraft:gravel"},
        {pos: [5, 3, 3], state: "minecraft:gravel"},
        {pos: [5, 3, 4], state: "minecraft:gravel"},
        {pos: [5, 3, 5], state: "minecraft:gravel"},
        {pos: [5, 3, 6], state: "minecraft:gravel"},
        {pos: [5, 3, 7], state: "minecraft:gravel"},
        {pos: [5, 3, 8], state: "sullysmod:petrified_log{axis:y}"},
        {pos: [5, 3, 9], state: "minecraft:gravel"},
        {pos: [6, 3, 0], state: "sullysmod:amber{is_melted:false}", nbt: {RenderEntity: 0b, StuckEntity: [], id: "sullysmod:amber"}},
        {pos: [6, 3, 1], state: "minecraft:gravel"},
        {pos: [6, 3, 2], state: "sullysmod:stripped_petrified_log{axis:y}"},
        {pos: [6, 3, 3], state: "minecraft:gravel"},
        {pos: [6, 3, 4], state: "minecraft:gravel"},
        {pos: [6, 3, 5], state: "minecraft:gravel"},
        {pos: [6, 3, 6], state: "minecraft:gravel"},
        {pos: [6, 3, 7], state: "minecraft:gravel"},
        {pos: [6, 3, 8], state: "minecraft:gravel"},
        {pos: [6, 3, 9], state: "minecraft:gravel"},
        {pos: [6, 3, 10], state: "minecraft:gravel"},
        {pos: [7, 3, 2], state: "minecraft:gravel"},
        {pos: [7, 3, 3], state: "minecraft:gravel"},
        {pos: [7, 3, 4], state: "minecraft:gravel"},
        {pos: [7, 3, 5], state: "minecraft:gravel"},
        {pos: [7, 3, 6], state: "minecraft:gravel"},
        {pos: [7, 3, 7], state: "minecraft:gravel"},
        {pos: [7, 3, 8], state: "minecraft:gravel"},
        {pos: [7, 3, 9], state: "minecraft:gravel"},
        {pos: [7, 3, 10], state: "minecraft:gravel"},
        {pos: [8, 3, 3], state: "minecraft:gravel"},
        {pos: [8, 3, 4], state: "sullysmod:petrified_log{axis:y}"},
        {pos: [8, 3, 5], state: "minecraft:gravel"},
        {pos: [8, 3, 6], state: "sullysmod:stripped_petrified_log{axis:y}"},
        {pos: [8, 3, 7], state: "minecraft:gravel"},
        {pos: [8, 3, 8], state: "minecraft:gravel"},
        {pos: [8, 3, 9], state: "minecraft:gravel"},
        {pos: [9, 3, 4], state: "minecraft:gravel"},
        {pos: [9, 3, 5], state: "minecraft:gravel"},
        {pos: [9, 3, 6], state: "minecraft:gravel"},
        {pos: [9, 3, 7], state: "minecraft:gravel"},
        {pos: [9, 3, 8], state: "minecraft:gravel"},
        {pos: [10, 3, 5], state: "minecraft:gravel"},
        {pos: [10, 3, 6], state: "minecraft:gravel"},
        {pos: [10, 3, 7], state: "minecraft:gravel"},
        {pos: [13, 3, 8], state: "sullysmod:stripped_petrified_log{axis:y}"},
        {pos: [1, 4, 6], state: "sullysmod:stripped_petrified_log{axis:x}"},
        {pos: [1, 4, 7], state: "minecraft:gravel"},
        {pos: [2, 4, 4], state: "minecraft:gravel"},
        {pos: [2, 4, 5], state: "minecraft:gravel"},
        {pos: [2, 4, 6], state: "sullysmod:stripped_petrified_log{axis:y}"},
        {pos: [2, 4, 7], state: "minecraft:gravel"},
        {pos: [2, 4, 8], state: "minecraft:gravel"},
        {pos: [2, 4, 9], state: "minecraft:gravel"},
        {pos: [3, 4, 2], state: "minecraft:gravel"},
        {pos: [3, 4, 3], state: "minecraft:gravel"},
        {pos: [3, 4, 4], state: "minecraft:gravel"},
        {pos: [3, 4, 5], state: "minecraft:gravel"},
        {pos: [3, 4, 6], state: "minecraft:gravel"},
        {pos: [3, 4, 7], state: "minecraft:gravel"},
        {pos: [3, 4, 8], state: "minecraft:gravel"},
        {pos: [3, 4, 9], state: "sullysmod:stripped_petrified_log{axis:z}"},
        {pos: [3, 4, 10], state: "sullysmod:stripped_petrified_log{axis:z}"},
        {pos: [4, 4, 1], state: "minecraft:gravel"},
        {pos: [4, 4, 2], state: "minecraft:gravel"},
        {pos: [4, 4, 3], state: "minecraft:gravel"},
        {pos: [4, 4, 4], state: "minecraft:gravel"},
        {pos: [4, 4, 5], state: "sullysmod:petrified_log{axis:y}"},
        {pos: [4, 4, 6], state: "minecraft:gravel"},
        {pos: [4, 4, 7], state: "minecraft:gravel"},
        {pos: [4, 4, 8], state: "minecraft:gravel"},
        {pos: [4, 4, 9], state: "minecraft:gravel"},
        {pos: [4, 4, 10], state: "minecraft:gravel"},
        {pos: [5, 4, 1], state: "minecraft:gravel"},
        {pos: [5, 4, 2], state: "minecraft:gravel"},
        {pos: [5, 4, 3], state: "minecraft:gravel"},
        {pos: [5, 4, 4], state: "minecraft:gravel"},
        {pos: [5, 4, 5], state: "minecraft:gravel"},
        {pos: [5, 4, 6], state: "minecraft:gravel"},
        {pos: [5, 4, 7], state: "sullysmod:petrified_log{axis:y}"},
        {pos: [5, 4, 8], state: "minecraft:gravel"},
        {pos: [5, 4, 9], state: "minecraft:gravel"},
        {pos: [5, 4, 10], state: "minecraft:gravel"},
        {pos: [5, 4, 11], state: "minecraft:gravel"},
        {pos: [6, 4, 0], state: "sullysmod:petrified_log{axis:z}"},
        {pos: [6, 4, 1], state: "sullysmod:stripped_petrified_log{axis:z}"},
        {pos: [6, 4, 2], state: "sullysmod:stripped_petrified_log{axis:y}"},
        {pos: [6, 4, 3], state: "minecraft:gravel"},
        {pos: [6, 4, 4], state: "minecraft:gravel"},
        {pos: [6, 4, 5], state: "minecraft:gravel"},
        {pos: [6, 4, 6], state: "minecraft:gravel"},
        {pos: [6, 4, 7], state: "minecraft:gravel"},
        {pos: [6, 4, 8], state: "minecraft:gravel"},
        {pos: [6, 4, 9], state: "minecraft:gravel"},
        {pos: [6, 4, 10], state: "minecraft:gravel"},
        {pos: [6, 4, 11], state: "minecraft:gravel"},
        {pos: [6, 4, 12], state: "sullysmod:amber{is_melted:false}", nbt: {RenderEntity: 0b, StuckEntity: [], id: "sullysmod:amber"}},
        {pos: [7, 4, 1], state: "minecraft:gravel"},
        {pos: [7, 4, 2], state: "minecraft:gravel"},
        {pos: [7, 4, 3], state: "minecraft:gravel"},
        {pos: [7, 4, 4], state: "minecraft:gravel"},
        {pos: [7, 4, 5], state: "minecraft:gravel"},
        {pos: [7, 4, 6], state: "minecraft:gravel"},
        {pos: [7, 4, 7], state: "minecraft:gravel"},
        {pos: [7, 4, 8], state: "sullysmod:petrified_log{axis:y}"},
        {pos: [7, 4, 9], state: "minecraft:gravel"},
        {pos: [7, 4, 10], state: "minecraft:gravel"},
        {pos: [7, 4, 11], state: "minecraft:gravel"},
        {pos: [8, 4, 1], state: "minecraft:gravel"},
        {pos: [8, 4, 2], state: "minecraft:gravel"},
        {pos: [8, 4, 3], state: "minecraft:gravel"},
        {pos: [8, 4, 4], state: "sullysmod:petrified_log{axis:y}"},
        {pos: [8, 4, 5], state: "minecraft:gravel"},
        {pos: [8, 4, 6], state: "sullysmod:petrified_log{axis:y}"},
        {pos: [8, 4, 7], state: "minecraft:gravel"},
        {pos: [8, 4, 8], state: "minecraft:gravel"},
        {pos: [8, 4, 9], state: "sullysmod:amber{is_melted:false}", nbt: {RenderEntity: 0b, StuckEntity: [], id: "sullysmod:amber"}},
        {pos: [8, 4, 10], state: "minecraft:gravel"},
        {pos: [9, 4, 2], state: "minecraft:gravel"},
        {pos: [9, 4, 3], state: "sullysmod:petrified_log{axis:x}"},
        {pos: [9, 4, 4], state: "minecraft:gravel"},
        {pos: [9, 4, 5], state: "minecraft:gravel"},
        {pos: [9, 4, 6], state: "minecraft:gravel"},
        {pos: [9, 4, 7], state: "minecraft:gravel"},
        {pos: [9, 4, 8], state: "minecraft:gravel"},
        {pos: [9, 4, 9], state: "minecraft:gravel"},
        {pos: [9, 4, 10], state: "sullysmod:stripped_petrified_log{axis:z}"},
        {pos: [9, 4, 11], state: "sullysmod:stripped_petrified_log{axis:z}"},
        {pos: [10, 4, 3], state: "sullysmod:stripped_petrified_log{axis:x}"},
        {pos: [10, 4, 4], state: "minecraft:gravel"},
        {pos: [10, 4, 5], state: "minecraft:gravel"},
        {pos: [10, 4, 6], state: "minecraft:gravel"},
        {pos: [10, 4, 7], state: "sullysmod:petrified_log{axis:x}"},
        {pos: [10, 4, 8], state: "minecraft:gravel"},
        {pos: [10, 4, 9], state: "minecraft:gravel"},
        {pos: [11, 4, 1], state: "sullysmod:petrified_log{axis:z}"},
        {pos: [11, 4, 2], state: "sullysmod:petrified_log{axis:z}"},
        {pos: [11, 4, 3], state: "sullysmod:petrified_log{axis:x}"},
        {pos: [11, 4, 6], state: "minecraft:gravel"},
        {pos: [11, 4, 7], state: "sullysmod:stripped_petrified_log{axis:x}"},
        {pos: [11, 4, 8], state: "minecraft:gravel"},
        {pos: [12, 4, 7], state: "sullysmod:petrified_log{axis:x}"},
        {pos: [12, 4, 8], state: "sullysmod:petrified_log{axis:z}"},
        {pos: [13, 4, 8], state: "sullysmod:stripped_petrified_log{axis:x}"},
        {pos: [0, 5, 6], state: "minecraft:gravel"},
        {pos: [0, 5, 7], state: "minecraft:gravel"},
        {pos: [0, 5, 8], state: "sullysmod:stripped_petrified_log{axis:x}"},
        {pos: [1, 5, 4], state: "minecraft:gravel"},
        {pos: [1, 5, 5], state: "minecraft:gravel"},
        {pos: [1, 5, 6], state: "minecraft:gravel"},
        {pos: [1, 5, 7], state: "minecraft:gravel"},
        {pos: [1, 5, 8], state: "sullysmod:stripped_petrified_log{axis:x}"},
        {pos: [1, 5, 9], state: "minecraft:gravel"},
        {pos: [2, 5, 3], state: "minecraft:gravel"},
        {pos: [2, 5, 4], state: "minecraft:gravel"},
        {pos: [2, 5, 5], state: "minecraft:gravel"},
        {pos: [2, 5, 6], state: "sullysmod:stripped_petrified_log{axis:y}"},
        {pos: [2, 5, 7], state: "minecraft:gravel"},
        {pos: [2, 5, 8], state: "sullysmod:petrified_log{axis:x}"},
        {pos: [2, 5, 9], state: "minecraft:gravel"},
        {pos: [2, 5, 10], state: "minecraft:gravel"},
        {pos: [3, 5, 1], state: "sullysmod:stripped_petrified_log{axis:z}"},
        {pos: [3, 5, 2], state: "sullysmod:stripped_petrified_log{axis:z}"},
        {pos: [3, 5, 3], state: "sullysmod:petrified_log{axis:z}"},
        {pos: [3, 5, 4], state: "minecraft:gravel"},
        {pos: [3, 5, 5], state: "minecraft:gravel"},
        {pos: [3, 5, 6], state: "sullysmod:stripped_petrified_log{axis:y}"},
        {pos: [3, 5, 7], state: "minecraft:gravel"},
        {pos: [3, 5, 8], state: "sullysmod:stripped_petrified_log{axis:y}"},
        {pos: [3, 5, 9], state: "sullysmod:petrified_log{axis:y}"},
        {pos: [3, 5, 10], state: "minecraft:gravel"},
        {pos: [3, 5, 11], state: "minecraft:gravel"},
        {pos: [4, 5, 0], state: "minecraft:gravel"},
        {pos: [4, 5, 1], state: "minecraft:gravel"},
        {pos: [4, 5, 2], state: "minecraft:gravel"},
        {pos: [4, 5, 3], state: "sullysmod:petrified_log{axis:y}"},
        {pos: [4, 5, 4], state: "minecraft:gravel"},
        {pos: [4, 5, 5], state: "sullysmod:petrified_log{axis:y}"},
        {pos: [4, 5, 6], state: "sullysmod:amber{is_melted:false}", nbt: {RenderEntity: 0b, StuckEntity: [], id: "sullysmod:amber"}},
        {pos: [4, 5, 7], state: "minecraft:gravel"},
        {pos: [4, 5, 8], state: "minecraft:gravel"},
        {pos: [4, 5, 9], state: "sullysmod:petrified_log{axis:y}"},
        {pos: [4, 5, 10], state: "minecraft:gravel"},
        {pos: [4, 5, 11], state: "minecraft:gravel"},
        {pos: [5, 5, 0], state: "minecraft:gravel"},
        {pos: [5, 5, 1], state: "minecraft:gravel"},
        {pos: [5, 5, 2], state: "minecraft:gravel"},
        {pos: [5, 5, 3], state: "minecraft:gravel"},
        {pos: [5, 5, 4], state: "minecraft:gravel"},
        {pos: [5, 5, 5], state: "sullysmod:petrified_log{axis:y}"},
        {pos: [5, 5, 6], state: "minecraft:gravel"},
        {pos: [5, 5, 7], state: "sullysmod:petrified_log{axis:y}"},
        {pos: [5, 5, 8], state: "minecraft:gravel"},
        {pos: [5, 5, 9], state: "minecraft:gravel"},
        {pos: [5, 5, 10], state: "sullysmod:petrified_log{axis:y}"},
        {pos: [5, 5, 11], state: "minecraft:gravel"},
        {pos: [5, 5, 12], state: "minecraft:gravel"},
        {pos: [6, 5, 0], state: "minecraft:gravel"},
        {pos: [6, 5, 1], state: "minecraft:gravel"},
        {pos: [6, 5, 2], state: "sullysmod:stripped_petrified_log{axis:y}"},
        {pos: [6, 5, 3], state: "sullysmod:amber{is_melted:false}", nbt: {RenderEntity: 0b, StuckEntity: [], id: "sullysmod:amber"}},
        {pos: [6, 5, 4], state: "minecraft:gravel"},
        {pos: [6, 5, 5], state: "minecraft:gravel"},
        {pos: [6, 5, 6], state: "minecraft:gravel"},
        {pos: [6, 5, 7], state: "minecraft:gravel"},
        {pos: [6, 5, 8], state: "sullysmod:amber{is_melted:false}", nbt: {RenderEntity: 0b, StuckEntity: [], id: "sullysmod:amber"}},
        {pos: [6, 5, 9], state: "minecraft:gravel"},
        {pos: [6, 5, 10], state: "sullysmod:petrified_log{axis:z}"},
        {pos: [6, 5, 11], state: "sullysmod:petrified_log{axis:z}"},
        {pos: [6, 5, 12], state: "sullysmod:petrified_log{axis:z}"},
        {pos: [7, 5, 1], state: "minecraft:gravel"},
        {pos: [7, 5, 2], state: "minecraft:gravel"},
        {pos: [7, 5, 3], state: "minecraft:gravel"},
        {pos: [7, 5, 4], state: "minecraft:gravel"},
        {pos: [7, 5, 5], state: "sullysmod:petrified_log{axis:y}"},
        {pos: [7, 5, 6], state: "sullysmod:amber{is_melted:false}", nbt: {RenderEntity: 0b, StuckEntity: [], id: "sullysmod:amber"}},
        {pos: [7, 5, 7], state: "minecraft:gravel"},
        {pos: [7, 5, 8], state: "sullysmod:petrified_log{axis:y}"},
        {pos: [7, 5, 9], state: "minecraft:gravel"},
        {pos: [7, 5, 10], state: "minecraft:gravel"},
        {pos: [7, 5, 11], state: "minecraft:gravel"},
        {pos: [8, 5, 1], state: "minecraft:gravel"},
        {pos: [8, 5, 2], state: "sullysmod:petrified_log{axis:z}"},
        {pos: [8, 5, 3], state: "sullysmod:petrified_log{axis:y}"},
        {pos: [8, 5, 4], state: "sullysmod:petrified_log{axis:y}"},
        {pos: [8, 5, 5], state: "minecraft:gravel"},
        {pos: [8, 5, 6], state: "sullysmod:stripped_petrified_log{axis:y}"},
        {pos: [8, 5, 7], state: "minecraft:gravel"},
        {pos: [8, 5, 8], state: "minecraft:gravel"},
        {pos: [8, 5, 9], state: "sullysmod:stripped_petrified_log{axis:y}"},
        {pos: [8, 5, 10], state: "sullysmod:stripped_petrified_log{axis:y}"},
        {pos: [8, 5, 11], state: "minecraft:gravel"},
        {pos: [9, 5, 1], state: "minecraft:gravel"},
        {pos: [9, 5, 2], state: "minecraft:gravel"},
        {pos: [9, 5, 3], state: "sullysmod:petrified_log{axis:y}"},
        {pos: [9, 5, 4], state: "minecraft:gravel"},
        {pos: [9, 5, 5], state: "minecraft:gravel"},
        {pos: [9, 5, 6], state: "minecraft:gravel"},
        {pos: [9, 5, 7], state: "sullysmod:petrified_log{axis:y}"},
        {pos: [9, 5, 8], state: "sullysmod:petrified_log{axis:y}"},
        {pos: [9, 5, 9], state: "sullysmod:petrified_log{axis:y}"},
        {pos: [9, 5, 10], state: "minecraft:gravel"},
        {pos: [10, 5, 2], state: "minecraft:gravel"},
        {pos: [10, 5, 3], state: "minecraft:gravel"},
        {pos: [10, 5, 4], state: "minecraft:gravel"},
        {pos: [10, 5, 5], state: "sullysmod:petrified_log{axis:y}"},
        {pos: [10, 5, 6], state: "minecraft:gravel"},
        {pos: [10, 5, 7], state: "minecraft:suspicious_gravel{dusted:0}", nbt: {id: "minecraft:brushable_block", item: {Count: 0b, id: "minecraft:air"}}},
        {pos: [10, 5, 8], state: "sullysmod:petrified_log{axis:y}"},
        {pos: [10, 5, 9], state: "minecraft:gravel"},
        {pos: [10, 5, 10], state: "minecraft:gravel"},
        {pos: [11, 5, 1], state: "sullysmod:petrified_log{axis:y}"},
        {pos: [11, 5, 2], state: "minecraft:gravel"},
        {pos: [11, 5, 5], state: "sullysmod:stripped_petrified_log{axis:x}"},
        {pos: [11, 5, 6], state: "minecraft:gravel"},
        {pos: [11, 5, 7], state: "minecraft:gravel"},
        {pos: [11, 5, 8], state: "minecraft:gravel"},
        {pos: [12, 5, 5], state: "sullysmod:stripped_petrified_log{axis:x}"},
        {pos: [12, 5, 6], state: "minecraft:gravel"},
        {pos: [12, 5, 7], state: "minecraft:gravel"},
        {pos: [0, 6, 5], state: "minecraft:gravel"},
        {pos: [0, 6, 6], state: "minecraft:gravel"},
        {pos: [0, 6, 7], state: "minecraft:gravel"},
        {pos: [1, 6, 4], state: "sullysmod:stripped_petrified_log{axis:x}"},
        {pos: [1, 6, 5], state: "minecraft:gravel"},
        {pos: [1, 6, 6], state: "minecraft:gravel"},
        {pos: [1, 6, 7], state: "minecraft:gravel"},
        {pos: [1, 6, 8], state: "minecraft:gravel"},
        {pos: [1, 6, 9], state: "minecraft:gravel"},
        {pos: [2, 6, 2], state: "minecraft:gravel"},
        {pos: [2, 6, 3], state: "minecraft:gravel"},
        {pos: [2, 6, 4], state: "sullysmod:petrified_log{axis:x}"},
        {pos: [2, 6, 5], state: "minecraft:gravel"},
        {pos: [2, 6, 6], state: "minecraft:gravel"},
        {pos: [2, 6, 7], state: "minecraft:gravel"},
        {pos: [2, 6, 8], state: "minecraft:gravel"},
        {pos: [2, 6, 9], state: "minecraft:gravel"},
        {pos: [2, 6, 10], state: "minecraft:gravel"},
        {pos: [3, 6, 1], state: "sullysmod:stripped_petrified_log{axis:y}"},
        {pos: [3, 6, 2], state: "minecraft:suspicious_gravel{dusted:0}", nbt: {id: "minecraft:brushable_block", item: {Count: 0b, id: "minecraft:air"}}},
        {pos: [3, 6, 3], state: "minecraft:gravel"},
        {pos: [3, 6, 4], state: "sullysmod:petrified_log{axis:y}"},
        {pos: [3, 6, 5], state: "minecraft:gravel"},
        {pos: [3, 6, 6], state: "sullysmod:petrified_log{axis:y}"},
        {pos: [3, 6, 7], state: "sullysmod:petrified_log{axis:y}"},
        {pos: [3, 6, 8], state: "sullysmod:stripped_petrified_log{axis:y}"},
        {pos: [3, 6, 9], state: "minecraft:gravel"},
        {pos: [3, 6, 10], state: "minecraft:gravel"},
        {pos: [3, 6, 11], state: "minecraft:gravel"},
        {pos: [4, 6, 0], state: "minecraft:gravel"},
        {pos: [4, 6, 1], state: "minecraft:gravel"},
        {pos: [4, 6, 2], state: "minecraft:gravel"},
        {pos: [4, 6, 3], state: "sullysmod:petrified_log{axis:y}"},
        {pos: [4, 6, 4], state: "sullysmod:petrified_log{axis:y}"},
        {pos: [4, 6, 5], state: "sullysmod:rough_amber{is_melted:false}"},
        {pos: [4, 6, 6], state: "sullysmod:rough_amber{is_melted:false}"},
        {pos: [4, 6, 7], state: "sullysmod:petrified_log{axis:y}"},
        {pos: [4, 6, 8], state: "sullysmod:petrified_log{axis:y}"},
        {pos: [4, 6, 9], state: "minecraft:gravel"},
        {pos: [4, 6, 10], state: "minecraft:gravel"},
        {pos: [4, 6, 11], state: "minecraft:gravel"},
        {pos: [4, 6, 12], state: "minecraft:gravel"},
        {pos: [5, 6, 0], state: "minecraft:gravel"},
        {pos: [5, 6, 1], state: "minecraft:gravel"},
        {pos: [5, 6, 2], state: "minecraft:gravel"},
        {pos: [5, 6, 3], state: "minecraft:gravel"},
        {pos: [5, 6, 4], state: "sullysmod:petrified_log{axis:y}"},
        {pos: [5, 6, 5], state: "sullysmod:petrified_log{axis:y}"},
        {pos: [5, 6, 6], state: "sullysmod:petrified_log{axis:y}"},
        {pos: [5, 6, 7], state: "sullysmod:petrified_log{axis:y}"},
        {pos: [5, 6, 8], state: "minecraft:gravel"},
        {pos: [5, 6, 9], state: "sullysmod:petrified_log{axis:y}"},
        {pos: [5, 6, 10], state: "sullysmod:petrified_log{axis:y}"},
        {pos: [5, 6, 11], state: "minecraft:gravel"},
        {pos: [5, 6, 12], state: "minecraft:gravel"},
        {pos: [6, 6, 0], state: "minecraft:gravel"},
        {pos: [6, 6, 1], state: "minecraft:gravel"},
        {pos: [6, 6, 2], state: "minecraft:gravel"},
        {pos: [6, 6, 3], state: "sullysmod:petrified_log{axis:y}"},
        {pos: [6, 6, 4], state: "minecraft:gravel"},
        {pos: [6, 6, 5], state: "sullysmod:petrified_log{axis:y}"},
        {pos: [6, 6, 6], state: "sullysmod:petrified_log{axis:y}"},
        {pos: [6, 6, 7], state: "sullysmod:amber{is_melted:false}", nbt: {RenderEntity: 0b, StuckEntity: [], id: "sullysmod:amber"}},
        {pos: [6, 6, 8], state: "sullysmod:amber{is_melted:false}", nbt: {RenderEntity: 0b, StuckEntity: [], id: "sullysmod:amber"}},
        {pos: [6, 6, 9], state: "sullysmod:petrified_log{axis:y}"},
        {pos: [6, 6, 10], state: "minecraft:gravel"},
        {pos: [6, 6, 11], state: "minecraft:gravel"},
        {pos: [6, 6, 12], state: "minecraft:gravel"},
        {pos: [7, 6, 0], state: "minecraft:gravel"},
        {pos: [7, 6, 1], state: "minecraft:gravel"},
        {pos: [7, 6, 2], state: "minecraft:gravel"},
        {pos: [7, 6, 3], state: "sullysmod:stripped_petrified_log{axis:y}"},
        {pos: [7, 6, 4], state: "sullysmod:petrified_log{axis:y}"},
        {pos: [7, 6, 5], state: "sullysmod:petrified_log{axis:y}"},
        {pos: [7, 6, 6], state: "sullysmod:rough_amber{is_melted:false}"},
        {pos: [7, 6, 7], state: "sullysmod:petrified_log{axis:y}"},
        {pos: [7, 6, 8], state: "sullysmod:amber{is_melted:false}", nbt: {RenderEntity: 0b, StuckEntity: [], id: "sullysmod:amber"}},
        {pos: [7, 6, 9], state: "minecraft:gravel"},
        {pos: [7, 6, 10], state: "minecraft:gravel"},
        {pos: [7, 6, 11], state: "minecraft:gravel"},
        {pos: [7, 6, 12], state: "minecraft:gravel"},
        {pos: [8, 6, 1], state: "minecraft:gravel"},
        {pos: [8, 6, 2], state: "minecraft:gravel"},
        {pos: [8, 6, 3], state: "sullysmod:petrified_log{axis:y}"},
        {pos: [8, 6, 4], state: "sullysmod:petrified_log{axis:y}"},
        {pos: [8, 6, 5], state: "minecraft:gravel"},
        {pos: [8, 6, 6], state: "sullysmod:petrified_log{axis:y}"},
        {pos: [8, 6, 7], state: "sullysmod:petrified_log{axis:y}"},
        {pos: [8, 6, 8], state: "sullysmod:petrified_log{axis:y}"},
        {pos: [8, 6, 9], state: "sullysmod:petrified_log{axis:y}"},
        {pos: [8, 6, 10], state: "minecraft:gravel"},
        {pos: [8, 6, 11], state: "minecraft:gravel"},
        {pos: [9, 6, 2], state: "minecraft:gravel"},
        {pos: [9, 6, 3], state: "minecraft:gravel"},
        {pos: [9, 6, 4], state: "sullysmod:petrified_log{axis:y}"},
        {pos: [9, 6, 5], state: "sullysmod:petrified_log{axis:y}"},
        {pos: [9, 6, 6], state: "sullysmod:petrified_log{axis:y}"},
        {pos: [9, 6, 7], state: "sullysmod:petrified_log{axis:y}"},
        {pos: [9, 6, 8], state: "sullysmod:petrified_log{axis:y}"},
        {pos: [9, 6, 9], state: "minecraft:gravel"},
        {pos: [9, 6, 10], state: "minecraft:gravel"},
        {pos: [9, 6, 11], state: "minecraft:gravel"},
        {pos: [10, 6, 2], state: "minecraft:gravel"},
        {pos: [10, 6, 3], state: "minecraft:gravel"},
        {pos: [10, 6, 4], state: "minecraft:gravel"},
        {pos: [10, 6, 5], state: "sullysmod:petrified_log{axis:y}"},
        {pos: [10, 6, 6], state: "minecraft:gravel"},
        {pos: [10, 6, 7], state: "minecraft:gravel"},
        {pos: [10, 6, 8], state: "sullysmod:stripped_petrified_log{axis:y}"},
        {pos: [10, 6, 9], state: "minecraft:gravel"},
        {pos: [10, 6, 10], state: "minecraft:gravel"},
        {pos: [11, 6, 4], state: "minecraft:gravel"},
        {pos: [11, 6, 5], state: "minecraft:gravel"},
        {pos: [11, 6, 6], state: "minecraft:gravel"},
        {pos: [11, 6, 7], state: "minecraft:gravel"},
        {pos: [11, 6, 8], state: "minecraft:gravel"},
        {pos: [11, 6, 9], state: "minecraft:gravel"},
        {pos: [12, 6, 5], state: "sullysmod:petrified_log{axis:y}"},
        {pos: [12, 6, 6], state: "minecraft:gravel"},
        {pos: [12, 6, 7], state: "minecraft:gravel"},
        {pos: [12, 6, 8], state: "minecraft:gravel"},
        {pos: [0, 7, 6], state: "minecraft:gravel"},
        {pos: [1, 7, 3], state: "minecraft:gravel"},
        {pos: [1, 7, 5], state: "minecraft:gravel"},
        {pos: [1, 7, 6], state: "minecraft:gravel"},
        {pos: [1, 7, 7], state: "minecraft:gravel"},
        {pos: [2, 7, 3], state: "minecraft:gravel"},
        {pos: [2, 7, 4], state: "minecraft:gravel"},
        {pos: [2, 7, 5], state: "minecraft:gravel"},
        {pos: [2, 7, 6], state: "minecraft:gravel"},
        {pos: [2, 7, 7], state: "minecraft:gravel"},
        {pos: [2, 7, 8], state: "minecraft:gravel"},
        {pos: [2, 7, 9], state: "minecraft:gravel"},
        {pos: [3, 7, 1], state: "minecraft:gravel"},
        {pos: [3, 7, 2], state: "minecraft:gravel"},
        {pos: [3, 7, 3], state: "minecraft:gravel"},
        {pos: [3, 7, 4], state: "sullysmod:petrified_log{axis:y}"},
        {pos: [3, 7, 5], state: "sullysmod:petrified_log{axis:y}"},
        {pos: [3, 7, 6], state: "sullysmod:petrified_log{axis:y}"},
        {pos: [3, 7, 7], state: "sullysmod:petrified_log{axis:y}"},
        {pos: [3, 7, 8], state: "minecraft:gravel"},
        {pos: [3, 7, 9], state: "minecraft:gravel"},
        {pos: [3, 7, 10], state: "minecraft:gravel"},
        {pos: [4, 7, 2], state: "minecraft:gravel"},
        {pos: [4, 7, 3], state: "minecraft:gravel"},
        {pos: [4, 7, 4], state: "sullysmod:petrified_log{axis:y}"},
        {pos: [4, 7, 5], state: "sullysmod:petrified_log{axis:y}"},
        {pos: [4, 7, 6], state: "sullysmod:petrified_log{axis:y}"},
        {pos: [4, 7, 7], state: "sullysmod:petrified_log{axis:y}"},
        {pos: [4, 7, 8], state: "sullysmod:petrified_log{axis:y}"},
        {pos: [4, 7, 9], state: "minecraft:gravel"},
        {pos: [4, 7, 10], state: "minecraft:gravel"},
        {pos: [4, 7, 11], state: "minecraft:gravel"},
        {pos: [5, 7, 0], state: "minecraft:gravel"},
        {pos: [5, 7, 1], state: "minecraft:gravel"},
        {pos: [5, 7, 2], state: "minecraft:gravel"},
        {pos: [5, 7, 3], state: "sullysmod:petrified_log{axis:y}"},
        {pos: [5, 7, 4], state: "sullysmod:petrified_log{axis:y}"},
        {pos: [5, 7, 5], state: "sullysmod:stripped_petrified_log{axis:y}"},
        {pos: [5, 7, 6], state: "sullysmod:stripped_petrified_log{axis:y}"},
        {pos: [5, 7, 7], state: "sullysmod:stripped_petrified_log{axis:y}"},
        {pos: [5, 7, 8], state: "sullysmod:petrified_log{axis:y}"},
        {pos: [5, 7, 9], state: "sullysmod:petrified_log{axis:y}"},
        {pos: [5, 7, 10], state: "minecraft:gravel"},
        {pos: [5, 7, 11], state: "minecraft:gravel"},
        {pos: [6, 7, 0], state: "minecraft:gravel"},
        {pos: [6, 7, 1], state: "minecraft:suspicious_gravel{dusted:0}", nbt: {id: "minecraft:brushable_block", item: {Count: 0b, id: "minecraft:air"}}},
        {pos: [6, 7, 2], state: "minecraft:gravel"},
        {pos: [6, 7, 3], state: "sullysmod:petrified_log{axis:y}"},
        {pos: [6, 7, 4], state: "sullysmod:petrified_log{axis:y}"},
        {pos: [6, 7, 5], state: "sullysmod:stripped_petrified_log{axis:y}"},
        {pos: [6, 7, 6], state: "sullysmod:stripped_petrified_log{axis:y}"},
        {pos: [6, 7, 7], state: "sullysmod:stripped_petrified_log{axis:y}"},
        {pos: [6, 7, 8], state: "sullysmod:petrified_log{axis:y}"},
        {pos: [6, 7, 9], state: "sullysmod:petrified_log{axis:y}"},
        {pos: [6, 7, 10], state: "minecraft:gravel"},
        {pos: [6, 7, 11], state: "minecraft:gravel"},
        {pos: [7, 7, 1], state: "minecraft:gravel"},
        {pos: [7, 7, 2], state: "minecraft:gravel"},
        {pos: [7, 7, 3], state: "sullysmod:petrified_log{axis:y}"},
        {pos: [7, 7, 4], state: "sullysmod:petrified_log{axis:y}"},
        {pos: [7, 7, 5], state: "sullysmod:stripped_petrified_log{axis:y}"},
        {pos: [7, 7, 6], state: "sullysmod:stripped_petrified_log{axis:y}"},
        {pos: [7, 7, 7], state: "sullysmod:stripped_petrified_log{axis:y}"},
        {pos: [7, 7, 8], state: "sullysmod:petrified_log{axis:y}"},
        {pos: [7, 7, 9], state: "sullysmod:petrified_log{axis:y}"},
        {pos: [7, 7, 10], state: "minecraft:gravel"},
        {pos: [7, 7, 11], state: "minecraft:gravel"},
        {pos: [8, 7, 2], state: "minecraft:gravel"},
        {pos: [8, 7, 3], state: "sullysmod:petrified_log{axis:y}"},
        {pos: [8, 7, 4], state: "sullysmod:petrified_log{axis:y}"},
        {pos: [8, 7, 5], state: "sullysmod:petrified_log{axis:y}"},
        {pos: [8, 7, 6], state: "sullysmod:petrified_log{axis:y}"},
        {pos: [8, 7, 7], state: "sullysmod:petrified_log{axis:y}"},
        {pos: [8, 7, 8], state: "sullysmod:petrified_log{axis:y}"},
        {pos: [8, 7, 9], state: "sullysmod:petrified_log{axis:y}"},
        {pos: [8, 7, 11], state: "minecraft:gravel"},
        {pos: [9, 7, 2], state: "minecraft:gravel"},
        {pos: [9, 7, 3], state: "minecraft:gravel"},
        {pos: [9, 7, 4], state: "sullysmod:petrified_log{axis:y}"},
        {pos: [9, 7, 5], state: "sullysmod:petrified_log{axis:y}"},
        {pos: [9, 7, 6], state: "sullysmod:petrified_log{axis:y}"},
        {pos: [9, 7, 7], state: "sullysmod:petrified_log{axis:y}"},
        {pos: [9, 7, 8], state: "sullysmod:petrified_log{axis:y}"},
        {pos: [9, 7, 9], state: "minecraft:gravel"},
        {pos: [9, 7, 10], state: "minecraft:gravel"},
        {pos: [10, 7, 3], state: "minecraft:gravel"},
        {pos: [10, 7, 4], state: "minecraft:gravel"},
        {pos: [10, 7, 5], state: "minecraft:gravel"},
        {pos: [10, 7, 6], state: "sullysmod:petrified_log{axis:y}"},
        {pos: [10, 7, 7], state: "minecraft:gravel"},
        {pos: [10, 7, 8], state: "minecraft:gravel"},
        {pos: [10, 7, 9], state: "minecraft:gravel"},
        {pos: [11, 7, 5], state: "minecraft:gravel"},
        {pos: [11, 7, 6], state: "minecraft:gravel"},
        {pos: [11, 7, 7], state: "minecraft:gravel"},
        {pos: [11, 7, 8], state: "minecraft:gravel"},
        {pos: [12, 7, 7], state: "minecraft:gravel"},
        {pos: [12, 7, 8], state: "minecraft:gravel"},
        {pos: [2, 8, 5], state: "sullysmod:petrified_sapling{stage:0}"},
        {pos: [3, 8, 4], state: "sullysmod:petrified_log{axis:y}"},
        {pos: [3, 8, 5], state: "sullysmod:petrified_log{axis:y}"},
        {pos: [3, 8, 6], state: "sullysmod:petrified_log{axis:y}"},
        {pos: [3, 8, 7], state: "sullysmod:petrified_log{axis:y}"},
        {pos: [4, 8, 3], state: "minecraft:gravel"},
        {pos: [4, 8, 4], state: "sullysmod:petrified_log{axis:y}"},
        {pos: [4, 8, 5], state: "sullysmod:petrified_log{axis:y}"},
        {pos: [4, 8, 6], state: "sullysmod:petrified_log{axis:y}"},
        {pos: [4, 8, 7], state: "sullysmod:petrified_log{axis:y}"},
        {pos: [4, 8, 8], state: "sullysmod:petrified_log{axis:y}"},
        {pos: [4, 8, 9], state: "minecraft:gravel"},
        {pos: [5, 8, 3], state: "sullysmod:petrified_log{axis:y}"},
        {pos: [5, 8, 4], state: "sullysmod:petrified_log{axis:y}"},
        {pos: [5, 8, 5], state: "sullysmod:rough_amber{is_melted:false}"},
        {pos: [5, 8, 6], state: "sullysmod:rough_amber{is_melted:false}"},
        {pos: [5, 8, 7], state: "sullysmod:stripped_petrified_log{axis:y}"},
        {pos: [5, 8, 8], state: "sullysmod:petrified_log{axis:y}"},
        {pos: [5, 8, 9], state: "sullysmod:stripped_petrified_log{axis:y}"},
        {pos: [5, 8, 10], state: "minecraft:gravel"},
        {pos: [6, 8, 3], state: "sullysmod:petrified_log{axis:y}"},
        {pos: [6, 8, 4], state: "sullysmod:petrified_log{axis:y}"},
        {pos: [6, 8, 5], state: "sullysmod:rough_amber{is_melted:false}"},
        {pos: [6, 8, 6], state: "sullysmod:rough_amber{is_melted:false}"},
        {pos: [6, 8, 7], state: "sullysmod:stripped_petrified_log{axis:y}"},
        {pos: [6, 8, 8], state: "sullysmod:petrified_log{axis:y}"},
        {pos: [6, 8, 9], state: "sullysmod:petrified_log{axis:y}"},
        {pos: [6, 8, 10], state: "minecraft:gravel"},
        {pos: [7, 8, 3], state: "sullysmod:petrified_log{axis:y}"},
        {pos: [7, 8, 4], state: "sullysmod:petrified_log{axis:y}"},
        {pos: [7, 8, 5], state: "sullysmod:stripped_petrified_log{axis:y}"},
        {pos: [7, 8, 6], state: "sullysmod:stripped_petrified_log{axis:y}"},
        {pos: [7, 8, 7], state: "sullysmod:stripped_petrified_log{axis:y}"},
        {pos: [7, 8, 8], state: "sullysmod:petrified_log{axis:y}"},
        {pos: [7, 8, 9], state: "sullysmod:petrified_log{axis:y}"},
        {pos: [8, 8, 3], state: "sullysmod:petrified_log{axis:y}"},
        {pos: [8, 8, 4], state: "sullysmod:petrified_log{axis:y}"},
        {pos: [8, 8, 5], state: "sullysmod:petrified_log{axis:y}"},
        {pos: [8, 8, 6], state: "sullysmod:petrified_log{axis:y}"},
        {pos: [8, 8, 7], state: "sullysmod:petrified_log{axis:y}"},
        {pos: [8, 8, 8], state: "sullysmod:petrified_log{axis:y}"},
        {pos: [8, 8, 9], state: "sullysmod:petrified_log{axis:y}"},
        {pos: [9, 8, 4], state: "minecraft:gravel"},
        {pos: [9, 8, 5], state: "sullysmod:petrified_log{axis:y}"},
        {pos: [9, 8, 6], state: "sullysmod:petrified_log{axis:y}"},
        {pos: [9, 8, 7], state: "sullysmod:petrified_log{axis:y}"},
        {pos: [9, 8, 8], state: "minecraft:gravel"},
        {pos: [3, 9, 4], state: "minecraft:gravel"},
        {pos: [3, 9, 5], state: "sullysmod:petrified_log{axis:y}"},
        {pos: [3, 9, 6], state: "sullysmod:petrified_log{axis:y}"},
        {pos: [4, 9, 4], state: "sullysmod:petrified_log{axis:y}"},
        {pos: [4, 9, 5], state: "sullysmod:petrified_log{axis:y}"},
        {pos: [4, 9, 6], state: "sullysmod:petrified_log{axis:y}"},
        {pos: [4, 9, 7], state: "sullysmod:petrified_log{axis:y}"},
        {pos: [4, 9, 8], state: "sullysmod:petrified_log{axis:y}"},
        {pos: [5, 9, 3], state: "sullysmod:petrified_log{axis:y}"},
        {pos: [5, 9, 4], state: "sullysmod:petrified_log{axis:y}"},
        {pos: [5, 9, 5], state: "sullysmod:stripped_petrified_log{axis:y}"},
        {pos: [5, 9, 6], state: "sullysmod:rough_amber{is_melted:false}"},
        {pos: [5, 9, 7], state: "sullysmod:stripped_petrified_log{axis:y}"},
        {pos: [5, 9, 8], state: "sullysmod:petrified_log{axis:y}"},
        {pos: [5, 9, 9], state: "minecraft:gravel"},
        {pos: [6, 9, 3], state: "sullysmod:petrified_log{axis:y}"},
        {pos: [6, 9, 4], state: "sullysmod:petrified_log{axis:y}"},
        {pos: [6, 9, 5], state: "sullysmod:stripped_petrified_log{axis:y}"},
        {pos: [6, 9, 6], state: "sullysmod:stripped_petrified_log{axis:y}"},
        {pos: [6, 9, 7], state: "sullysmod:stripped_petrified_log{axis:y}"},
        {pos: [6, 9, 8], state: "sullysmod:petrified_log{axis:y}"},
        {pos: [6, 9, 9], state: "sullysmod:petrified_log{axis:y}"},
        {pos: [7, 9, 3], state: "sullysmod:petrified_log{axis:y}"},
        {pos: [7, 9, 4], state: "sullysmod:petrified_log{axis:y}"},
        {pos: [7, 9, 5], state: "sullysmod:stripped_petrified_log{axis:y}"},
        {pos: [7, 9, 6], state: "sullysmod:stripped_petrified_log{axis:y}"},
        {pos: [7, 9, 7], state: "sullysmod:stripped_petrified_log{axis:y}"},
        {pos: [7, 9, 8], state: "sullysmod:petrified_log{axis:y}"},
        {pos: [7, 9, 9], state: "sullysmod:petrified_log{axis:y}"},
        {pos: [8, 9, 3], state: "sullysmod:petrified_log{axis:y}"},
        {pos: [8, 9, 4], state: "sullysmod:petrified_log{axis:y}"},
        {pos: [8, 9, 5], state: "sullysmod:petrified_log{axis:y}"},
        {pos: [8, 9, 6], state: "sullysmod:petrified_log{axis:y}"},
        {pos: [8, 9, 7], state: "sullysmod:petrified_log{axis:y}"},
        {pos: [8, 9, 8], state: "sullysmod:petrified_log{axis:y}"},
        {pos: [9, 9, 5], state: "minecraft:suspicious_gravel{dusted:0}", nbt: {id: "minecraft:brushable_block", item: {Count: 0b, id: "minecraft:air"}}},
        {pos: [9, 9, 6], state: "sullysmod:petrified_log{axis:y}"},
        {pos: [9, 9, 7], state: "sullysmod:petrified_log{axis:y}"},
        {pos: [3, 10, 5], state: "sullysmod:petrified_log{axis:y}"},
        {pos: [4, 10, 4], state: "sullysmod:petrified_log{axis:y}"},
        {pos: [4, 10, 5], state: "sullysmod:petrified_log{axis:y}"},
        {pos: [4, 10, 6], state: "sullysmod:petrified_log{axis:y}"},
        {pos: [4, 10, 7], state: "sullysmod:petrified_log{axis:y}"},
        {pos: [4, 10, 8], state: "sullysmod:petrified_log{axis:y}"},
        {pos: [5, 10, 3], state: "minecraft:gravel"},
        {pos: [5, 10, 4], state: "sullysmod:petrified_log{axis:y}"},
        {pos: [5, 10, 5], state: "sullysmod:stripped_petrified_log{axis:y}"},
        {pos: [5, 10, 6], state: "sullysmod:stripped_petrified_log{axis:y}"},
        {pos: [5, 10, 7], state: "sullysmod:stripped_petrified_log{axis:y}"},
        {pos: [5, 10, 8], state: "sullysmod:petrified_log{axis:y}"},
        {pos: [5, 10, 9], state: "minecraft:air"},
        {pos: [6, 10, 3], state: "sullysmod:petrified_log{axis:y}"},
        {pos: [6, 10, 4], state: "sullysmod:petrified_log{axis:y}"},
        {pos: [6, 10, 5], state: "sullysmod:stripped_petrified_log{axis:y}"},
        {pos: [6, 10, 6], state: "sullysmod:stripped_petrified_log{axis:y}"},
        {pos: [6, 10, 7], state: "sullysmod:stripped_petrified_log{axis:y}"},
        {pos: [6, 10, 8], state: "sullysmod:amber{is_melted:false}", nbt: {RenderEntity: 0b, StuckEntity: [], id: "sullysmod:amber"}},
        {pos: [6, 10, 9], state: "minecraft:air"},
        {pos: [7, 10, 3], state: "sullysmod:petrified_log{axis:y}"},
        {pos: [7, 10, 4], state: "sullysmod:petrified_log{axis:y}"},
        {pos: [7, 10, 5], state: "sullysmod:stripped_petrified_log{axis:y}"},
        {pos: [7, 10, 6], state: "sullysmod:stripped_petrified_log{axis:y}"},
        {pos: [7, 10, 7], state: "sullysmod:stripped_petrified_log{axis:y}"},
        {pos: [7, 10, 8], state: "sullysmod:petrified_log{axis:y}"},
        {pos: [7, 10, 9], state: "sullysmod:stripped_petrified_log{axis:y}"},
        {pos: [8, 10, 4], state: "sullysmod:petrified_log{axis:y}"},
        {pos: [8, 10, 5], state: "sullysmod:petrified_log{axis:y}"},
        {pos: [8, 10, 6], state: "sullysmod:petrified_log{axis:y}"},
        {pos: [8, 10, 7], state: "sullysmod:petrified_log{axis:y}"},
        {pos: [9, 10, 7], state: "minecraft:gravel"},
        {pos: [4, 11, 4], state: "sullysmod:petrified_log{axis:y}"},
        {pos: [4, 11, 5], state: "sullysmod:petrified_log{axis:y}"},
        {pos: [4, 11, 6], state: "sullysmod:petrified_log{axis:y}"},
        {pos: [4, 11, 7], state: "sullysmod:petrified_log{axis:y}"},
        {pos: [4, 11, 8], state: "minecraft:air"},
        {pos: [5, 11, 4], state: "sullysmod:petrified_log{axis:y}"},
        {pos: [5, 11, 5], state: "sullysmod:stripped_petrified_log{axis:y}"},
        {pos: [5, 11, 6], state: "sullysmod:stripped_petrified_log{axis:y}"},
        {pos: [5, 11, 7], state: "sullysmod:stripped_petrified_log{axis:y}"},
        {pos: [5, 11, 8], state: "sullysmod:petrified_log{axis:y}"},
        {pos: [5, 11, 11], state: "minecraft:air"},
        {pos: [6, 11, 3], state: "sullysmod:petrified_log{axis:y}"},
        {pos: [6, 11, 4], state: "sullysmod:petrified_log{axis:y}"},
        {pos: [6, 11, 5], state: "sullysmod:stripped_petrified_log{axis:y}"},
        {pos: [6, 11, 6], state: "sullysmod:stripped_petrified_log{axis:y}"},
        {pos: [6, 11, 7], state: "sullysmod:stripped_petrified_log{axis:y}"},
        {pos: [6, 11, 8], state: "sullysmod:amber{is_melted:false}", nbt: {RenderEntity: 0b, StuckEntity: [], id: "sullysmod:amber"}},
        {pos: [6, 11, 9], state: "minecraft:air"},
        {pos: [7, 11, 3], state: "minecraft:air"},
        {pos: [7, 11, 4], state: "sullysmod:petrified_log{axis:y}"},
        {pos: [7, 11, 5], state: "sullysmod:stripped_petrified_log{axis:y}"},
        {pos: [7, 11, 6], state: "sullysmod:stripped_petrified_log{axis:y}"},
        {pos: [7, 11, 7], state: "sullysmod:rough_amber{is_melted:false}"},
        {pos: [7, 11, 8], state: "minecraft:air"},
        {pos: [8, 11, 4], state: "sullysmod:stripped_petrified_log{axis:y}"},
        {pos: [8, 11, 5], state: "sullysmod:petrified_log{axis:y}"},
        {pos: [8, 11, 6], state: "sullysmod:petrified_log{axis:y}"},
        {pos: [8, 11, 7], state: "sullysmod:petrified_log{axis:y}"},
        {pos: [9, 11, 7], state: "minecraft:air"},
        {pos: [3, 12, 6], state: "minecraft:air"},
        {pos: [4, 12, 4], state: "sullysmod:stripped_petrified_log{axis:y}"},
        {pos: [4, 12, 5], state: "sullysmod:petrified_log{axis:y}"},
        {pos: [4, 12, 6], state: "sullysmod:petrified_log{axis:y}"},
        {pos: [4, 12, 7], state: "sullysmod:petrified_log{axis:y}"},
        {pos: [4, 12, 8], state: "minecraft:air"},
        {pos: [5, 12, 4], state: "sullysmod:petrified_log{axis:y}"},
        {pos: [5, 12, 5], state: "sullysmod:stripped_petrified_log{axis:y}"},
        {pos: [5, 12, 6], state: "sullysmod:stripped_petrified_log{axis:y}"},
        {pos: [5, 12, 7], state: "sullysmod:stripped_petrified_log{axis:y}"},
        {pos: [5, 12, 8], state: "sullysmod:petrified_log{axis:y}"},
        {pos: [6, 12, 3], state: "minecraft:air"},
        {pos: [6, 12, 4], state: "sullysmod:petrified_log{axis:y}"},
        {pos: [6, 12, 5], state: "sullysmod:stripped_petrified_log{axis:y}"},
        {pos: [6, 12, 6], state: "sullysmod:rough_amber{is_melted:false}"},
        {pos: [6, 12, 7], state: "sullysmod:rough_amber{is_melted:false}"},
        {pos: [6, 12, 8], state: "sullysmod:petrified_log{axis:y}"},
        {pos: [6, 12, 9], state: "minecraft:air"},
        {pos: [7, 12, 4], state: "sullysmod:stripped_petrified_log{axis:y}"},
        {pos: [7, 12, 5], state: "sullysmod:stripped_petrified_log{axis:y}"},
        {pos: [7, 12, 6], state: "sullysmod:stripped_petrified_log{axis:y}"},
        {pos: [7, 12, 7], state: "sullysmod:rough_amber{is_melted:false}"},
        {pos: [7, 12, 8], state: "minecraft:air"},
        {pos: [8, 12, 4], state: "sullysmod:amber{is_melted:false}", nbt: {RenderEntity: 0b, StuckEntity: [], id: "sullysmod:amber"}},
        {pos: [8, 12, 5], state: "sullysmod:petrified_log{axis:y}"},
        {pos: [8, 12, 6], state: "sullysmod:petrified_log{axis:y}"},
        {pos: [8, 12, 7], state: "sullysmod:petrified_log{axis:y}"},
        {pos: [9, 12, 7], state: "sullysmod:petrified_log{axis:x}"},
        {pos: [3, 13, 6], state: "minecraft:air"},
        {pos: [4, 13, 5], state: "sullysmod:petrified_log{axis:y}"},
        {pos: [4, 13, 6], state: "sullysmod:petrified_log{axis:y}"},
        {pos: [4, 13, 7], state: "sullysmod:petrified_log{axis:y}"},
        {pos: [4, 13, 8], state: "minecraft:air"},
        {pos: [5, 13, 4], state: "sullysmod:petrified_log{axis:y}"},
        {pos: [5, 13, 5], state: "sullysmod:stripped_petrified_log{axis:y}"},
        {pos: [5, 13, 6], state: "sullysmod:stripped_petrified_log{axis:y}"},
        {pos: [5, 13, 7], state: "sullysmod:stripped_petrified_log{axis:y}"},
        {pos: [5, 13, 8], state: "sullysmod:petrified_log{axis:y}"},
        {pos: [6, 13, 3], state: "minecraft:air"},
        {pos: [6, 13, 4], state: "sullysmod:petrified_log{axis:y}"},
        {pos: [6, 13, 5], state: "sullysmod:rough_amber{is_melted:false}"},
        {pos: [6, 13, 6], state: "sullysmod:rough_amber{is_melted:false}"},
        {pos: [6, 13, 7], state: "sullysmod:rough_amber{is_melted:false}"},
        {pos: [6, 13, 8], state: "sullysmod:petrified_log{axis:y}"},
        {pos: [6, 13, 9], state: "minecraft:air"},
        {pos: [7, 13, 4], state: "sullysmod:amber{is_melted:false}", nbt: {RenderEntity: 0b, StuckEntity: [], id: "sullysmod:amber"}},
        {pos: [7, 13, 5], state: "sullysmod:rough_amber{is_melted:false}"},
        {pos: [7, 13, 6], state: "sullysmod:stripped_petrified_log{axis:y}"},
        {pos: [7, 13, 7], state: "sullysmod:stripped_petrified_log{axis:y}"},
        {pos: [7, 13, 8], state: "sullysmod:stripped_petrified_log{axis:y}"},
        {pos: [8, 13, 5], state: "sullysmod:petrified_log{axis:y}"},
        {pos: [8, 13, 6], state: "sullysmod:petrified_log{axis:y}"},
        {pos: [8, 13, 7], state: "sullysmod:stripped_petrified_log{axis:y}"},
        {pos: [3, 14, 6], state: "minecraft:air"},
        {pos: [4, 14, 5], state: "sullysmod:petrified_log{axis:y}"},
        {pos: [4, 14, 6], state: "sullysmod:petrified_log{axis:y}"},
        {pos: [4, 14, 7], state: "sullysmod:petrified_log{axis:y}"},
        {pos: [5, 14, 4], state: "sullysmod:amber{is_melted:false}", nbt: {RenderEntity: 0b, StuckEntity: [], id: "sullysmod:amber"}},
        {pos: [5, 14, 5], state: "sullysmod:rough_amber{is_melted:false}"},
        {pos: [5, 14, 6], state: "sullysmod:stripped_petrified_log{axis:y}"},
        {pos: [5, 14, 7], state: "sullysmod:stripped_petrified_log{axis:y}"},
        {pos: [5, 14, 8], state: "sullysmod:petrified_log{axis:y}"},
        {pos: [6, 14, 3], state: "sullysmod:petrified_log{axis:z}"},
        {pos: [6, 14, 4], state: "sullysmod:petrified_log{axis:y}"},
        {pos: [6, 14, 5], state: "sullysmod:rough_amber{is_melted:false}"},
        {pos: [6, 14, 6], state: "sullysmod:stripped_petrified_log{axis:y}"},
        {pos: [6, 14, 7], state: "sullysmod:rough_amber{is_melted:false}"},
        {pos: [6, 14, 8], state: "sullysmod:petrified_log{axis:y}"},
        {pos: [6, 14, 9], state: "minecraft:air"},
        {pos: [7, 14, 4], state: "minecraft:air"},
        {pos: [7, 14, 5], state: "sullysmod:rough_amber{is_melted:false}"},
        {pos: [7, 14, 6], state: "sullysmod:stripped_petrified_log{axis:y}"},
        {pos: [7, 14, 7], state: "sullysmod:stripped_petrified_log{axis:y}"},
        {pos: [7, 14, 8], state: "sullysmod:stripped_petrified_log{axis:y}"},
        {pos: [8, 14, 5], state: "sullysmod:petrified_log{axis:y}"},
        {pos: [8, 14, 6], state: "sullysmod:petrified_log{axis:y}"},
        {pos: [8, 14, 7], state: "sullysmod:petrified_log{axis:y}"},
        {pos: [3, 15, 6], state: "minecraft:air"},
        {pos: [4, 15, 5], state: "sullysmod:stripped_petrified_log{axis:y}"},
        {pos: [4, 15, 6], state: "sullysmod:petrified_log{axis:y}"},
        {pos: [4, 15, 7], state: "sullysmod:petrified_log{axis:y}"},
        {pos: [5, 15, 4], state: "minecraft:air"},
        {pos: [5, 15, 5], state: "sullysmod:rough_amber{is_melted:false}"},
        {pos: [5, 15, 6], state: "sullysmod:stripped_petrified_log{axis:y}"},
        {pos: [5, 15, 7], state: "sullysmod:rough_amber{is_melted:false}"},
        {pos: [5, 15, 8], state: "sullysmod:petrified_log{axis:y}"},
        {pos: [6, 15, 3], state: "minecraft:air"},
        {pos: [6, 15, 4], state: "sullysmod:rough_amber{is_melted:false}"},
        {pos: [6, 15, 5], state: "sullysmod:rough_amber{is_melted:false}"},
        {pos: [6, 15, 6], state: "sullysmod:stripped_petrified_log{axis:y}"},
        {pos: [6, 15, 7], state: "sullysmod:rough_amber{is_melted:false}"},
        {pos: [6, 15, 8], state: "sullysmod:petrified_log{axis:y}"},
        {pos: [6, 15, 9], state: "sullysmod:petrified_log{axis:z}"},
        {pos: [7, 15, 4], state: "minecraft:air"},
        {pos: [7, 15, 5], state: "sullysmod:rough_amber{is_melted:false}"},
        {pos: [7, 15, 6], state: "sullysmod:stripped_petrified_log{axis:y}"},
        {pos: [7, 15, 7], state: "sullysmod:stripped_petrified_log{axis:y}"},
        {pos: [7, 15, 8], state: "sullysmod:petrified_log{axis:y}"},
        {pos: [8, 15, 5], state: "sullysmod:stripped_petrified_log{axis:y}"},
        {pos: [8, 15, 6], state: "sullysmod:petrified_log{axis:y}"},
        {pos: [8, 15, 7], state: "sullysmod:petrified_log{axis:y}"},
        {pos: [9, 15, 4], state: "minecraft:air"},
        {pos: [9, 15, 5], state: "minecraft:air"},
        {pos: [3, 16, 6], state: "minecraft:air"},
        {pos: [4, 16, 5], state: "sullysmod:stripped_petrified_log{axis:y}"},
        {pos: [4, 16, 6], state: "sullysmod:petrified_log{axis:y}"},
        {pos: [4, 16, 7], state: "sullysmod:petrified_log{axis:y}"},
        {pos: [5, 16, 4], state: "minecraft:air"},
        {pos: [5, 16, 5], state: "sullysmod:rough_amber{is_melted:false}"},
        {pos: [5, 16, 6], state: "sullysmod:stripped_petrified_log{axis:y}"},
        {pos: [5, 16, 7], state: "sullysmod:rough_amber{is_melted:false}"},
        {pos: [5, 16, 8], state: "sullysmod:petrified_log{axis:y}"},
        {pos: [6, 16, 2], state: "minecraft:air"},
        {pos: [6, 16, 3], state: "minecraft:air"},
        {pos: [6, 16, 4], state: "minecraft:air"},
        {pos: [6, 16, 5], state: "sullysmod:rough_amber{is_melted:false}"},
        {pos: [6, 16, 6], state: "sullysmod:stripped_petrified_log{axis:y}"},
        {pos: [6, 16, 7], state: "sullysmod:stripped_petrified_log{axis:y}"},
        {pos: [6, 16, 8], state: "sullysmod:petrified_log{axis:y}"},
        {pos: [7, 16, 4], state: "sullysmod:stripped_petrified_log{axis:y}"},
        {pos: [7, 16, 5], state: "sullysmod:stripped_petrified_log{axis:y}"},
        {pos: [7, 16, 6], state: "sullysmod:stripped_petrified_log{axis:y}"},
        {pos: [7, 16, 7], state: "sullysmod:stripped_petrified_log{axis:y}"},
        {pos: [7, 16, 8], state: "sullysmod:petrified_log{axis:y}"},
        {pos: [8, 16, 4], state: "minecraft:air"},
        {pos: [8, 16, 5], state: "sullysmod:stripped_petrified_log{axis:y}"},
        {pos: [8, 16, 6], state: "sullysmod:petrified_log{axis:y}"},
        {pos: [8, 16, 7], state: "sullysmod:petrified_log{axis:y}"},
        {pos: [9, 16, 5], state: "minecraft:air"},
        {pos: [3, 17, 6], state: "minecraft:air"},
        {pos: [4, 17, 5], state: "minecraft:air"},
        {pos: [4, 17, 6], state: "sullysmod:petrified_log{axis:y}"},
        {pos: [4, 17, 7], state: "minecraft:air"},
        {pos: [5, 17, 4], state: "sullysmod:amber{is_melted:false}", nbt: {RenderEntity: 0b, StuckEntity: [], id: "sullysmod:amber"}},
        {pos: [5, 17, 5], state: "sullysmod:rough_amber{is_melted:false}"},
        {pos: [5, 17, 6], state: "sullysmod:stripped_petrified_log{axis:y}"},
        {pos: [5, 17, 7], state: "sullysmod:stripped_petrified_log{axis:y}"},
        {pos: [5, 17, 8], state: "sullysmod:petrified_log{axis:y}"},
        {pos: [6, 17, 2], state: "minecraft:air"},
        {pos: [6, 17, 3], state: "minecraft:air"},
        {pos: [6, 17, 4], state: "sullysmod:petrified_log{axis:y}"},
        {pos: [6, 17, 5], state: "sullysmod:stripped_petrified_log{axis:y}"},
        {pos: [6, 17, 6], state: "sullysmod:stripped_petrified_log{axis:y}"},
        {pos: [6, 17, 7], state: "sullysmod:stripped_petrified_log{axis:y}"},
        {pos: [6, 17, 8], state: "sullysmod:petrified_log{axis:y}"},
        {pos: [7, 17, 4], state: "sullysmod:stripped_petrified_log{axis:y}"},
        {pos: [7, 17, 5], state: "sullysmod:stripped_petrified_log{axis:y}"},
        {pos: [7, 17, 6], state: "sullysmod:stripped_petrified_log{axis:y}"},
        {pos: [7, 17, 7], state: "sullysmod:stripped_petrified_log{axis:y}"},
        {pos: [7, 17, 8], state: "sullysmod:petrified_log{axis:y}"},
        {pos: [8, 17, 5], state: "sullysmod:petrified_log{axis:y}"},
        {pos: [8, 17, 6], state: "sullysmod:petrified_log{axis:y}"},
        {pos: [8, 17, 7], state: "sullysmod:petrified_log{axis:y}"},
        {pos: [9, 17, 5], state: "minecraft:air"},
        {pos: [3, 18, 6], state: "sullysmod:petrified_log{axis:x}"},
        {pos: [3, 18, 7], state: "minecraft:air"},
        {pos: [4, 18, 5], state: "sullysmod:petrified_log{axis:y}"},
        {pos: [4, 18, 6], state: "sullysmod:petrified_log{axis:y}"},
        {pos: [4, 18, 7], state: "minecraft:air"},
        {pos: [5, 18, 4], state: "sullysmod:stripped_petrified_log{axis:y}"},
        {pos: [5, 18, 5], state: "sullysmod:stripped_petrified_log{axis:y}"},
        {pos: [5, 18, 6], state: "sullysmod:stripped_petrified_log{axis:y}"},
        {pos: [5, 18, 7], state: "sullysmod:stripped_petrified_log{axis:y}"},
        {pos: [5, 18, 8], state: "minecraft:air"},
        {pos: [6, 18, 2], state: "sullysmod:amber{is_melted:false}", nbt: {RenderEntity: 0b, StuckEntity: [], id: "sullysmod:amber"}},
        {pos: [6, 18, 3], state: "minecraft:air"},
        {pos: [6, 18, 4], state: "sullysmod:petrified_log{axis:y}"},
        {pos: [6, 18, 5], state: "sullysmod:stripped_petrified_log{axis:y}"},
        {pos: [6, 18, 6], state: "sullysmod:stripped_petrified_log{axis:y}"},
        {pos: [6, 18, 7], state: "sullysmod:stripped_petrified_log{axis:y}"},
        {pos: [6, 18, 8], state: "sullysmod:petrified_log{axis:y}"},
        {pos: [7, 18, 4], state: "sullysmod:petrified_log{axis:y}"},
        {pos: [7, 18, 5], state: "sullysmod:stripped_petrified_log{axis:y}"},
        {pos: [7, 18, 6], state: "sullysmod:stripped_petrified_log{axis:y}"},
        {pos: [7, 18, 7], state: "sullysmod:stripped_petrified_log{axis:y}"},
        {pos: [7, 18, 8], state: "sullysmod:petrified_log{axis:y}"},
        {pos: [8, 18, 5], state: "sullysmod:petrified_log{axis:y}"},
        {pos: [8, 18, 6], state: "sullysmod:petrified_log{axis:y}"},
        {pos: [8, 18, 7], state: "sullysmod:petrified_log{axis:y}"},
        {pos: [9, 18, 5], state: "sullysmod:petrified_log{axis:x}"},
        {pos: [9, 18, 7], state: "minecraft:air"},
        {pos: [10, 18, 8], state: "minecraft:air"},
        {pos: [4, 19, 5], state: "sullysmod:petrified_log{axis:y}"},
        {pos: [4, 19, 6], state: "sullysmod:petrified_log{axis:y}"},
        {pos: [4, 19, 7], state: "minecraft:air"},
        {pos: [4, 19, 8], state: "minecraft:air"},
        {pos: [5, 19, 4], state: "sullysmod:stripped_petrified_log{axis:y}"},
        {pos: [5, 19, 5], state: "sullysmod:stripped_petrified_log{axis:y}"},
        {pos: [5, 19, 6], state: "sullysmod:stripped_petrified_log{axis:y}"},
        {pos: [5, 19, 7], state: "sullysmod:stripped_petrified_log{axis:y}"},
        {pos: [5, 19, 8], state: "sullysmod:petrified_log{axis:y}"},
        {pos: [6, 19, 2], state: "sullysmod:petrified_log{axis:z}"},
        {pos: [6, 19, 3], state: "sullysmod:petrified_log{axis:z}"},
        {pos: [6, 19, 4], state: "sullysmod:petrified_log{axis:y}"},
        {pos: [6, 19, 5], state: "sullysmod:stripped_petrified_log{axis:y}"},
        {pos: [6, 19, 6], state: "sullysmod:stripped_petrified_log{axis:y}"},
        {pos: [6, 19, 7], state: "sullysmod:stripped_petrified_log{axis:y}"},
        {pos: [6, 19, 8], state: "sullysmod:petrified_log{axis:y}"},
        {pos: [7, 19, 4], state: "sullysmod:stripped_petrified_log{axis:y}"},
        {pos: [7, 19, 5], state: "sullysmod:stripped_petrified_log{axis:y}"},
        {pos: [7, 19, 6], state: "sullysmod:stripped_petrified_log{axis:y}"},
        {pos: [7, 19, 7], state: "sullysmod:stripped_petrified_log{axis:y}"},
        {pos: [7, 19, 8], state: "sullysmod:stripped_petrified_log{axis:y}"},
        {pos: [8, 19, 5], state: "sullysmod:petrified_log{axis:y}"},
        {pos: [8, 19, 6], state: "sullysmod:petrified_log{axis:y}"},
        {pos: [8, 19, 7], state: "sullysmod:petrified_log{axis:y}"},
        {pos: [9, 19, 7], state: "minecraft:air"},
        {pos: [10, 19, 7], state: "minecraft:air"},
        {pos: [4, 20, 5], state: "sullysmod:petrified_log{axis:y}"},
        {pos: [4, 20, 6], state: "sullysmod:petrified_log{axis:y}"},
        {pos: [4, 20, 7], state: "sullysmod:petrified_log{axis:y}"},
        {pos: [5, 20, 4], state: "sullysmod:petrified_log{axis:y}"},
        {pos: [5, 20, 5], state: "sullysmod:stripped_petrified_log{axis:y}"},
        {pos: [5, 20, 6], state: "sullysmod:stripped_petrified_log{axis:y}"},
        {pos: [5, 20, 7], state: "sullysmod:rough_amber{is_melted:false}"},
        {pos: [5, 20, 8], state: "sullysmod:petrified_log{axis:y}"},
        {pos: [6, 20, 4], state: "sullysmod:petrified_log{axis:y}"},
        {pos: [6, 20, 5], state: "sullysmod:stripped_petrified_log{axis:y}"},
        {pos: [6, 20, 6], state: "sullysmod:stripped_petrified_log{axis:y}"},
        {pos: [6, 20, 7], state: "sullysmod:stripped_petrified_log{axis:y}"},
        {pos: [6, 20, 8], state: "sullysmod:stripped_petrified_log{axis:y}"},
        {pos: [7, 20, 3], state: "minecraft:air"},
        {pos: [7, 20, 4], state: "minecraft:air"},
        {pos: [7, 20, 5], state: "sullysmod:stripped_petrified_log{axis:y}"},
        {pos: [7, 20, 6], state: "sullysmod:stripped_petrified_log{axis:y}"},
        {pos: [7, 20, 7], state: "sullysmod:stripped_petrified_log{axis:y}"},
        {pos: [7, 20, 8], state: "sullysmod:stripped_petrified_log{axis:y}"},
        {pos: [8, 20, 4], state: "minecraft:air"},
        {pos: [8, 20, 5], state: "sullysmod:stripped_petrified_log{axis:y}"},
        {pos: [8, 20, 6], state: "sullysmod:petrified_log{axis:y}"},
        {pos: [8, 20, 7], state: "sullysmod:petrified_log{axis:y}"},
        {pos: [9, 20, 7], state: "minecraft:air"},
        {pos: [10, 20, 7], state: "minecraft:air"},
        {pos: [4, 21, 5], state: "sullysmod:petrified_log{axis:y}"},
        {pos: [4, 21, 6], state: "sullysmod:petrified_log{axis:y}"},
        {pos: [4, 21, 7], state: "sullysmod:stripped_petrified_log{axis:y}"},
        {pos: [5, 21, 4], state: "sullysmod:petrified_log{axis:y}"},
        {pos: [5, 21, 5], state: "sullysmod:rough_amber{is_melted:false}"},
        {pos: [5, 21, 6], state: "sullysmod:rough_amber{is_melted:false}"},
        {pos: [5, 21, 7], state: "sullysmod:rough_amber{is_melted:false}"},
        {pos: [5, 21, 8], state: "minecraft:air"},
        {pos: [6, 21, 4], state: "sullysmod:petrified_log{axis:y}"},
        {pos: [6, 21, 5], state: "sullysmod:stripped_petrified_log{axis:y}"},
        {pos: [6, 21, 6], state: "sullysmod:stripped_petrified_log{axis:y}"},
        {pos: [6, 21, 7], state: "sullysmod:rough_amber{is_melted:false}"},
        {pos: [6, 21, 8], state: "minecraft:air"},
        {pos: [7, 21, 4], state: "minecraft:air"},
        {pos: [7, 21, 5], state: "sullysmod:stripped_petrified_log{axis:y}"},
        {pos: [7, 21, 6], state: "sullysmod:stripped_petrified_log{axis:y}"},
        {pos: [7, 21, 7], state: "sullysmod:rough_amber{is_melted:false}"},
        {pos: [7, 21, 8], state: "sullysmod:stripped_petrified_log{axis:y}"},
        {pos: [8, 21, 4], state: "minecraft:air"},
        {pos: [8, 21, 5], state: "minecraft:air"},
        {pos: [8, 21, 6], state: "sullysmod:petrified_log{axis:y}"},
        {pos: [8, 21, 7], state: "sullysmod:petrified_log{axis:y}"},
        {pos: [9, 21, 7], state: "minecraft:air"},
        {pos: [10, 21, 7], state: "sullysmod:amber{is_melted:false}", nbt: {RenderEntity: 0b, StuckEntity: [], id: "sullysmod:amber"}},
        {pos: [4, 22, 5], state: "sullysmod:stripped_petrified_log{axis:y}"},
        {pos: [4, 22, 6], state: "sullysmod:amber{is_melted:false}", nbt: {RenderEntity: 0b, StuckEntity: [], id: "sullysmod:amber"}},
        {pos: [4, 22, 7], state: "minecraft:air"},
        {pos: [5, 22, 4], state: "sullysmod:petrified_log{axis:y}"},
        {pos: [5, 22, 5], state: "sullysmod:rough_amber{is_melted:false}"},
        {pos: [5, 22, 6], state: "sullysmod:rough_amber{is_melted:false}"},
        {pos: [5, 22, 7], state: "sullysmod:rough_amber{is_melted:false}"},
        {pos: [5, 22, 8], state: "minecraft:air"},
        {pos: [6, 22, 4], state: "sullysmod:petrified_log{axis:y}"},
        {pos: [6, 22, 5], state: "sullysmod:stripped_petrified_log{axis:y}"},
        {pos: [6, 22, 6], state: "sullysmod:stripped_petrified_log{axis:y}"},
        {pos: [6, 22, 8], state: "sullysmod:stripped_petrified_log{axis:y}"},
        {pos: [7, 22, 4], state: "sullysmod:petrified_log{axis:y}"},
        {pos: [7, 22, 5], state: "sullysmod:rough_amber{is_melted:false}"},
        {pos: [7, 22, 6], state: "sullysmod:rough_amber{is_melted:false}"},
        {pos: [7, 22, 8], state: "sullysmod:petrified_log{axis:y}"},
        {pos: [8, 22, 5], state: "minecraft:air"},
        {pos: [8, 22, 6], state: "sullysmod:petrified_log{axis:y}"},
        {pos: [8, 22, 7], state: "sullysmod:petrified_log{axis:y}"},
        {pos: [9, 22, 7], state: "sullysmod:petrified_log{axis:x}"},
        {pos: [10, 22, 7], state: "sullysmod:petrified_log{axis:x}"},
        {pos: [4, 23, 5], state: "minecraft:air"},
        {pos: [4, 23, 7], state: "minecraft:air"},
        {pos: [5, 23, 4], state: "sullysmod:petrified_log{axis:y}"},
        {pos: [5, 23, 5], state: "sullysmod:rough_amber{is_melted:false}"},
        {pos: [5, 23, 6], state: "sullysmod:rough_amber{is_melted:false}"},
        {pos: [5, 23, 7], state: "sullysmod:rough_amber{is_melted:false}"},
        {pos: [5, 23, 8], state: "sullysmod:stripped_petrified_log{axis:y}"},
        {pos: [6, 23, 4], state: "sullysmod:petrified_log{axis:y}"},
        {pos: [6, 23, 5], state: "sullysmod:rough_amber{is_melted:false}"},
        {pos: [6, 23, 6], state: "sullysmod:stripped_petrified_log{axis:y}"},
        {pos: [6, 23, 8], state: "sullysmod:petrified_log{axis:y}"},
        {pos: [7, 23, 4], state: "sullysmod:petrified_log{axis:y}"},
        {pos: [7, 23, 5], state: "sullysmod:rough_amber{is_melted:false}"},
        {pos: [7, 23, 8], state: "sullysmod:petrified_log{axis:y}"},
        {pos: [8, 23, 5], state: "sullysmod:stripped_petrified_log{axis:y}"},
        {pos: [8, 23, 6], state: "sullysmod:petrified_log{axis:y}"},
        {pos: [8, 23, 7], state: "sullysmod:petrified_log{axis:y}"},
        {pos: [4, 24, 5], state: "sullysmod:petrified_log{axis:y}"},
        {pos: [4, 24, 7], state: "sullysmod:stripped_petrified_log{axis:y}"},
        {pos: [5, 24, 4], state: "sullysmod:petrified_log{axis:y}"},
        {pos: [5, 24, 5], state: "sullysmod:rough_amber{is_melted:false}"},
        {pos: [5, 24, 6], state: "sullysmod:rough_amber{is_melted:false}"},
        {pos: [5, 24, 8], state: "sullysmod:petrified_log{axis:y}"},
        {pos: [6, 24, 4], state: "sullysmod:petrified_log{axis:y}"},
        {pos: [6, 24, 6], state: "sullysmod:rough_amber{is_melted:false}"},
        {pos: [6, 24, 8], state: "sullysmod:petrified_log{axis:y}"},
        {pos: [7, 24, 4], state: "sullysmod:petrified_log{axis:y}"},
        {pos: [7, 24, 8], state: "sullysmod:petrified_log{axis:y}"},
        {pos: [8, 24, 5], state: "sullysmod:petrified_log{axis:y}"},
        {pos: [8, 24, 6], state: "sullysmod:petrified_log{axis:y}"},
        {pos: [8, 24, 7], state: "sullysmod:petrified_log{axis:y}"},
        {pos: [4, 25, 5], state: "sullysmod:petrified_log{axis:y}"},
        {pos: [4, 25, 7], state: "sullysmod:petrified_log{axis:y}"},
        {pos: [5, 25, 4], state: "sullysmod:petrified_log{axis:y}"},
        {pos: [5, 25, 6], state: "sullysmod:rough_amber{is_melted:false}"},
        {pos: [5, 25, 8], state: "sullysmod:petrified_log{axis:y}"},
        {pos: [6, 25, 4], state: "sullysmod:stripped_petrified_log{axis:y}"},
        {pos: [6, 25, 8], state: "sullysmod:petrified_log{axis:y}"},
        {pos: [7, 25, 4], state: "sullysmod:petrified_log{axis:y}"},
        {pos: [8, 25, 5], state: "sullysmod:petrified_log{axis:y}"},
        {pos: [8, 25, 6], state: "sullysmod:petrified_log{axis:y}"},
        {pos: [8, 25, 7], state: "sullysmod:petrified_log{axis:y}"},
        {pos: [4, 26, 5], state: "sullysmod:stripped_petrified_log{axis:y}"},
        {pos: [4, 26, 7], state: "sullysmod:petrified_log{axis:y}"},
        {pos: [5, 26, 4], state: "sullysmod:petrified_log{axis:y}"},
        {pos: [5, 26, 8], state: "sullysmod:stripped_petrified_log{axis:y}"},
        {pos: [6, 26, 8], state: "sullysmod:petrified_log{axis:y}"},
        {pos: [7, 26, 4], state: "sullysmod:stripped_petrified_log{axis:y}"},
        {pos: [8, 26, 5], state: "sullysmod:petrified_log{axis:y}"},
        {pos: [8, 26, 6], state: "sullysmod:stripped_petrified_log{axis:y}"},
        {pos: [8, 26, 7], state: "sullysmod:petrified_log{axis:y}"},
        {pos: [4, 27, 7], state: "sullysmod:stripped_petrified_log{axis:y}"},
        {pos: [5, 27, 4], state: "sullysmod:stripped_petrified_log{axis:y}"},
        {pos: [6, 27, 8], state: "sullysmod:stripped_petrified_log{axis:y}"},
        {pos: [8, 27, 5], state: "sullysmod:stripped_petrified_log{axis:y}"},
        {pos: [8, 27, 6], state: "sullysmod:stripped_petrified_log{axis:y}"},
        {pos: [8, 27, 7], state: "sullysmod:stripped_petrified_log{axis:y}"},
        {pos: [8, 28, 5], state: "sullysmod:stripped_petrified_log{axis:y}"},
        {pos: [8, 28, 7], state: "sullysmod:stripped_petrified_log{axis:y}"}
    ],
    entities: [],
    palette: [
        "sullysmod:petrified_log{axis:y}",
        "sullysmod:stripped_petrified_log{axis:y}",
        "minecraft:gravel",
        "sullysmod:stripped_petrified_log{axis:x}",
        "sullysmod:stripped_petrified_log{axis:z}",
        "sullysmod:petrified_log{axis:z}",
        "sullysmod:petrified_log{axis:x}",
        "sullysmod:rough_amber{is_melted:false}",
        "sullysmod:petrified_sapling{stage:0}",
        "minecraft:air",
        "sullysmod:amber{is_melted:false}",
        "minecraft:suspicious_gravel{dusted:0}"
    ]
}
