{
    DataVersion: 3465,
    size: [18, 45, 18],
    data: [
        {pos: [5, 0, 9], state: "sullysmod:stripped_petrified_log{axis:y}"},
        {pos: [12, 0, 12], state: "sullysmod:petrified_log{axis:y}"},
        {pos: [5, 1, 9], state: "sullysmod:stripped_petrified_log{axis:y}"},
        {pos: [7, 1, 13], state: "sullysmod:stripped_petrified_log{axis:y}"},
        {pos: [12, 1, 12], state: "sullysmod:stripped_petrified_log{axis:y}"},
        {pos: [2, 2, 11], state: "minecraft:gravel"},
        {pos: [2, 2, 12], state: "minecraft:gravel"},
        {pos: [3, 2, 9], state: "minecraft:gravel"},
        {pos: [3, 2, 10], state: "minecraft:gravel"},
        {pos: [3, 2, 11], state: "minecraft:gravel"},
        {pos: [3, 2, 12], state: "minecraft:gravel"},
        {pos: [3, 2, 13], state: "minecraft:gravel"},
        {pos: [4, 2, 8], state: "minecraft:gravel"},
        {pos: [4, 2, 9], state: "minecraft:gravel"},
        {pos: [4, 2, 10], state: "minecraft:gravel"},
        {pos: [4, 2, 11], state: "minecraft:gravel"},
        {pos: [4, 2, 12], state: "minecraft:gravel"},
        {pos: [4, 2, 13], state: "minecraft:gravel"},
        {pos: [5, 2, 7], state: "minecraft:gravel"},
        {pos: [5, 2, 8], state: "sullysmod:stripped_petrified_log{axis:z}"},
        {pos: [5, 2, 9], state: "sullysmod:petrified_log{axis:y}"},
        {pos: [5, 2, 10], state: "minecraft:gravel"},
        {pos: [5, 2, 11], state: "minecraft:gravel"},
        {pos: [5, 2, 12], state: "minecraft:gravel"},
        {pos: [5, 2, 13], state: "minecraft:gravel"},
        {pos: [5, 2, 14], state: "minecraft:gravel"},
        {pos: [6, 2, 7], state: "minecraft:gravel"},
        {pos: [6, 2, 8], state: "minecraft:gravel"},
        {pos: [6, 2, 9], state: "minecraft:gravel"},
        {pos: [6, 2, 10], state: "minecraft:gravel"},
        {pos: [6, 2, 11], state: "minecraft:gravel"},
        {pos: [6, 2, 12], state: "minecraft:gravel"},
        {pos: [6, 2, 13], state: "minecraft:gravel"},
        {pos: [6, 2, 14], state: "minecraft:gravel"},
        {pos: [6, 2, 15], state: "minecraft:gravel"},
        {pos: [7, 2, 6], state: "minecraft:gravel"},
        {pos: [7, 2, 7], state: "minecraft:gravel"},
        {pos: [7, 2, 8], state: "minecraft:gravel"},
        {pos: [7, 2, 9], state: "minecraft:gravel"},
        {pos: [7, 2, 10], state: "minecraft:gravel"},
        {pos: [7, 2, 11], state: "minecraft:gravel"},
        {pos: [7, 2, 12], state: "minecraft:gravel"},
        {pos: [7, 2, 13], state: "sullysmod:petrified_log{axis:y}"},
        {pos: [7, 2, 14], state: "minecraft:gravel"},
        {pos: [7, 2, 15], state: "minecraft:gravel"},
        {pos: [8, 2, 5], state: "sullysmod:stripped_petrified_log{axis:z}"},
        {pos: [8, 2, 6], state: "sullysmod:stripped_petrified_log{axis:z}"},
        {pos: [8, 2, 7], state: "minecraft:gravel"},
        {pos: [8, 2, 8], state: "minecraft:gravel"},
        {pos: [8, 2, 9], state: "minecraft:gravel"},
        {pos: [8, 2, 10], state: "minecraft:gravel"},
        {pos: [8, 2, 11], state: "minecraft:gravel"},
        {pos: [8, 2, 12], state: "minecraft:gravel"},
        {pos: [8, 2, 13], state: "minecraft:gravel"},
        {pos: [8, 2, 14], state: "minecraft:gravel"},
        {pos: [8, 2, 15], state: "minecraft:gravel"},
        {pos: [9, 2, 4], state: "minecraft:gravel"},
        {pos: [9, 2, 5], state: "minecraft:gravel"},
        {pos: [9, 2, 6], state: "minecraft:gravel"},
        {pos: [9, 2, 7], state: "minecraft:gravel"},
        {pos: [9, 2, 8], state: "minecraft:gravel"},
        {pos: [9, 2, 9], state: "minecraft:gravel"},
        {pos: [9, 2, 10], state: "minecraft:gravel"},
        {pos: [9, 2, 11], state: "minecraft:gravel"},
        {pos: [9, 2, 12], state: "minecraft:gravel"},
        {pos: [9, 2, 13], state: "minecraft:gravel"},
        {pos: [9, 2, 14], state: "minecraft:gravel"},
        {pos: [9, 2, 15], state: "minecraft:gravel"},
        {pos: [10, 2, 4], state: "minecraft:gravel"},
        {pos: [10, 2, 5], state: "minecraft:gravel"},
        {pos: [10, 2, 6], state: "minecraft:gravel"},
        {pos: [10, 2, 7], state: "minecraft:gravel"},
        {pos: [10, 2, 8], state: "minecraft:gravel"},
        {pos: [10, 2, 9], state: "minecraft:gravel"},
        {pos: [10, 2, 10], state: "minecraft:gravel"},
        {pos: [10, 2, 11], state: "minecraft:gravel"},
        {pos: [10, 2, 12], state: "minecraft:gravel"},
        {pos: [10, 2, 13], state: "minecraft:gravel"},
        {pos: [10, 2, 14], state: "minecraft:gravel"},
        {pos: [10, 2, 15], state: "minecraft:gravel"},
        {pos: [11, 2, 5], state: "minecraft:gravel"},
        {pos: [11, 2, 6], state: "minecraft:gravel"},
        {pos: [11, 2, 7], state: "minecraft:gravel"},
        {pos: [11, 2, 8], state: "minecraft:gravel"},
        {pos: [11, 2, 9], state: "sullysmod:stripped_petrified_log{axis:y}"},
        {pos: [11, 2, 10], state: "minecraft:gravel"},
        {pos: [11, 2, 11], state: "minecraft:gravel"},
        {pos: [11, 2, 12], state: "sullysmod:petrified_log{axis:y}"},
        {pos: [11, 2, 13], state: "minecraft:gravel"},
        {pos: [11, 2, 14], state: "minecraft:gravel"},
        {pos: [12, 2, 7], state: "sullysmod:stripped_petrified_log{axis:y}"},
        {pos: [12, 2, 8], state: "minecraft:gravel"},
        {pos: [12, 2, 9], state: "minecraft:gravel"},
        {pos: [12, 2, 10], state: "minecraft:gravel"},
        {pos: [12, 2, 11], state: "minecraft:gravel"},
        {pos: [12, 2, 12], state: "sullysmod:stripped_petrified_log{axis:y}"},
        {pos: [12, 2, 13], state: "minecraft:gravel"},
        {pos: [12, 2, 14], state: "minecraft:gravel"},
        {pos: [13, 2, 9], state: "minecraft:gravel"},
        {pos: [13, 2, 10], state: "minecraft:gravel"},
        {pos: [13, 2, 11], state: "minecraft:gravel"},
        {pos: [13, 2, 12], state: "minecraft:gravel"},
        {pos: [14, 2, 10], state: "minecraft:gravel"},
        {pos: [14, 2, 11], state: "minecraft:gravel"},
        {pos: [1, 3, 9], state: "minecraft:gravel"},
        {pos: [1, 3, 10], state: "minecraft:gravel"},
        {pos: [1, 3, 11], state: "minecraft:gravel"},
        {pos: [1, 3, 12], state: "minecraft:gravel"},
        {pos: [2, 3, 8], state: "minecraft:gravel"},
        {pos: [2, 3, 9], state: "minecraft:gravel"},
        {pos: [2, 3, 10], state: "minecraft:gravel"},
        {pos: [2, 3, 11], state: "minecraft:gravel"},
        {pos: [2, 3, 12], state: "minecraft:gravel"},
        {pos: [2, 3, 13], state: "minecraft:gravel"},
        {pos: [3, 3, 8], state: "minecraft:gravel"},
        {pos: [3, 3, 9], state: "minecraft:gravel"},
        {pos: [3, 3, 10], state: "minecraft:gravel"},
        {pos: [3, 3, 11], state: "sullysmod:stripped_petrified_log{axis:y}"},
        {pos: [3, 3, 12], state: "minecraft:gravel"},
        {pos: [3, 3, 13], state: "minecraft:gravel"},
        {pos: [3, 3, 14], state: "minecraft:gravel"},
        {pos: [4, 3, 7], state: "minecraft:gravel"},
        {pos: [4, 3, 8], state: "minecraft:gravel"},
        {pos: [4, 3, 9], state: "minecraft:gravel"},
        {pos: [4, 3, 10], state: "minecraft:gravel"},
        {pos: [4, 3, 11], state: "minecraft:gravel"},
        {pos: [4, 3, 12], state: "minecraft:gravel"},
        {pos: [4, 3, 13], state: "minecraft:gravel"},
        {pos: [4, 3, 14], state: "minecraft:gravel"},
        {pos: [4, 3, 15], state: "minecraft:gravel"},
        {pos: [5, 3, 6], state: "minecraft:gravel"},
        {pos: [5, 3, 7], state: "minecraft:gravel"},
        {pos: [5, 3, 8], state: "minecraft:gravel"},
        {pos: [5, 3, 9], state: "sullysmod:petrified_log{axis:y}"},
        {pos: [5, 3, 10], state: "minecraft:gravel"},
        {pos: [5, 3, 11], state: "minecraft:gravel"},
        {pos: [5, 3, 12], state: "minecraft:gravel"},
        {pos: [5, 3, 13], state: "minecraft:gravel"},
        {pos: [5, 3, 14], state: "minecraft:gravel"},
        {pos: [5, 3, 15], state: "minecraft:gravel"},
        {pos: [6, 3, 5], state: "minecraft:gravel"},
        {pos: [6, 3, 6], state: "minecraft:gravel"},
        {pos: [6, 3, 7], state: "minecraft:gravel"},
        {pos: [6, 3, 8], state: "minecraft:gravel"},
        {pos: [6, 3, 9], state: "minecraft:gravel"},
        {pos: [6, 3, 10], state: "minecraft:gravel"},
        {pos: [6, 3, 11], state: "minecraft:gravel"},
        {pos: [6, 3, 12], state: "sullysmod:stripped_petrified_log{axis:y}"},
        {pos: [6, 3, 13], state: "minecraft:gravel"},
        {pos: [6, 3, 14], state: "minecraft:gravel"},
        {pos: [6, 3, 15], state: "minecraft:gravel"},
        {pos: [7, 3, 3], state: "minecraft:gravel"},
        {pos: [7, 3, 4], state: "minecraft:gravel"},
        {pos: [7, 3, 5], state: "minecraft:gravel"},
        {pos: [7, 3, 6], state: "minecraft:gravel"},
        {pos: [7, 3, 7], state: "minecraft:gravel"},
        {pos: [7, 3, 8], state: "minecraft:gravel"},
        {pos: [7, 3, 9], state: "minecraft:gravel"},
        {pos: [7, 3, 10], state: "minecraft:gravel"},
        {pos: [7, 3, 11], state: "minecraft:gravel"},
        {pos: [7, 3, 12], state: "minecraft:gravel"},
        {pos: [7, 3, 13], state: "sullysmod:petrified_log{axis:y}"},
        {pos: [7, 3, 14], state: "minecraft:gravel"},
        {pos: [7, 3, 15], state: "minecraft:gravel"},
        {pos: [7, 3, 16], state: "minecraft:gravel"},
        {pos: [8, 3, 3], state: "minecraft:gravel"},
        {pos: [8, 3, 4], state: "minecraft:gravel"},
        {pos: [8, 3, 5], state: "minecraft:gravel"},
        {pos: [8, 3, 6], state: "sullysmod:petrified_log{axis:y}"},
        {pos: [8, 3, 7], state: "minecraft:gravel"},
        {pos: [8, 3, 8], state: "minecraft:gravel"},
        {pos: [8, 3, 9], state: "minecraft:gravel"},
        {pos: [8, 3, 10], state: "minecraft:gravel"},
        {pos: [8, 3, 11], state: "minecraft:gravel"},
        {pos: [8, 3, 12], state: "minecraft:gravel"},
        {pos: [8, 3, 13], state: "minecraft:gravel"},
        {pos: [8, 3, 14], state: "minecraft:gravel"},
        {pos: [8, 3, 15], state: "minecraft:gravel"},
        {pos: [8, 3, 16], state: "minecraft:gravel"},
        {pos: [9, 3, 3], state: "minecraft:gravel"},
        {pos: [9, 3, 4], state: "minecraft:gravel"},
        {pos: [9, 3, 5], state: "minecraft:gravel"},
        {pos: [9, 3, 6], state: "minecraft:gravel"},
        {pos: [9, 3, 7], state: "minecraft:gravel"},
        {pos: [9, 3, 8], state: "minecraft:gravel"},
        {pos: [9, 3, 9], state: "minecraft:gravel"},
        {pos: [9, 3, 10], state: "minecraft:gravel"},
        {pos: [9, 3, 11], state: "minecraft:gravel"},
        {pos: [9, 3, 12], state: "minecraft:gravel"},
        {pos: [9, 3, 13], state: "minecraft:gravel"},
        {pos: [9, 3, 14], state: "minecraft:gravel"},
        {pos: [9, 3, 15], state: "minecraft:gravel"},
        {pos: [10, 3, 4], state: "minecraft:gravel"},
        {pos: [10, 3, 5], state: "minecraft:gravel"},
        {pos: [10, 3, 6], state: "minecraft:gravel"},
        {pos: [10, 3, 7], state: "minecraft:gravel"},
        {pos: [10, 3, 8], state: "minecraft:gravel"},
        {pos: [10, 3, 9], state: "minecraft:gravel"},
        {pos: [10, 3, 10], state: "minecraft:gravel"},
        {pos: [10, 3, 11], state: "minecraft:gravel"},
        {pos: [10, 3, 12], state: "sullysmod:petrified_log{axis:x}"},
        {pos: [10, 3, 13], state: "minecraft:gravel"},
        {pos: [10, 3, 14], state: "minecraft:gravel"},
        {pos: [10, 3, 15], state: "minecraft:gravel"},
        {pos: [11, 3, 4], state: "minecraft:gravel"},
        {pos: [11, 3, 5], state: "minecraft:gravel"},
        {pos: [11, 3, 6], state: "minecraft:gravel"},
        {pos: [11, 3, 7], state: "minecraft:gravel"},
        {pos: [11, 3, 8], state: "minecraft:gravel"},
        {pos: [11, 3, 9], state: "sullysmod:stripped_petrified_log{axis:y}"},
        {pos: [11, 3, 10], state: "minecraft:gravel"},
        {pos: [11, 3, 11], state: "minecraft:gravel"},
        {pos: [11, 3, 12], state: "sullysmod:petrified_log{axis:y}"},
        {pos: [11, 3, 13], state: "minecraft:gravel"},
        {pos: [11, 3, 14], state: "minecraft:gravel"},
        {pos: [11, 3, 15], state: "minecraft:gravel"},
        {pos: [12, 3, 4], state: "minecraft:gravel"},
        {pos: [12, 3, 5], state: "minecraft:gravel"},
        {pos: [12, 3, 6], state: "minecraft:gravel"},
        {pos: [12, 3, 7], state: "sullysmod:petrified_log{axis:y}"},
        {pos: [12, 3, 8], state: "minecraft:gravel"},
        {pos: [12, 3, 9], state: "minecraft:gravel"},
        {pos: [12, 3, 10], state: "minecraft:gravel"},
        {pos: [12, 3, 11], state: "minecraft:gravel"},
        {pos: [12, 3, 12], state: "minecraft:gravel"},
        {pos: [12, 3, 13], state: "minecraft:gravel"},
        {pos: [12, 3, 14], state: "minecraft:gravel"},
        {pos: [12, 3, 15], state: "minecraft:gravel"},
        {pos: [13, 3, 6], state: "minecraft:gravel"},
        {pos: [13, 3, 7], state: "minecraft:gravel"},
        {pos: [13, 3, 8], state: "minecraft:gravel"},
        {pos: [13, 3, 9], state: "minecraft:gravel"},
        {pos: [13, 3, 10], state: "minecraft:gravel"},
        {pos: [13, 3, 11], state: "minecraft:gravel"},
        {pos: [13, 3, 12], state: "minecraft:gravel"},
        {pos: [13, 3, 13], state: "minecraft:gravel"},
        {pos: [13, 3, 14], state: "minecraft:gravel"},
        {pos: [13, 3, 15], state: "sullysmod:petrified_log{axis:y}"},
        {pos: [13, 3, 16], state: "sullysmod:petrified_log{axis:z}"},
        {pos: [13, 3, 17], state: "sullysmod:petrified_log{axis:z}"},
        {pos: [14, 3, 8], state: "minecraft:gravel"},
        {pos: [14, 3, 9], state: "minecraft:gravel"},
        {pos: [14, 3, 10], state: "minecraft:gravel"},
        {pos: [14, 3, 11], state: "minecraft:gravel"},
        {pos: [14, 3, 12], state: "minecraft:gravel"},
        {pos: [14, 3, 13], state: "minecraft:gravel"},
        {pos: [14, 3, 14], state: "minecraft:gravel"},
        {pos: [15, 3, 10], state: "minecraft:gravel"},
        {pos: [15, 3, 11], state: "minecraft:gravel"},
        {pos: [15, 3, 12], state: "minecraft:gravel"},
        {pos: [15, 3, 13], state: "minecraft:gravel"},
        {pos: [0, 4, 9], state: "sullysmod:amber{is_melted:false}", nbt: {RenderEntity: 0b, StuckEntity: [], id: "sullysmod:amber"}},
        {pos: [1, 4, 8], state: "minecraft:gravel"},
        {pos: [1, 4, 9], state: "minecraft:gravel"},
        {pos: [1, 4, 10], state: "minecraft:gravel"},
        {pos: [1, 4, 11], state: "sullysmod:stripped_petrified_log{axis:y}"},
        {pos: [1, 4, 12], state: "minecraft:gravel"},
        {pos: [1, 4, 13], state: "minecraft:gravel"},
        {pos: [2, 4, 7], state: "minecraft:gravel"},
        {pos: [2, 4, 8], state: "minecraft:gravel"},
        {pos: [2, 4, 9], state: "minecraft:gravel"},
        {pos: [2, 4, 10], state: "minecraft:gravel"},
        {pos: [2, 4, 11], state: "minecraft:gravel"},
        {pos: [2, 4, 12], state: "minecraft:gravel"},
        {pos: [2, 4, 13], state: "minecraft:gravel"},
        {pos: [2, 4, 14], state: "minecraft:gravel"},
        {pos: [3, 4, 7], state: "minecraft:gravel"},
        {pos: [3, 4, 8], state: "minecraft:gravel"},
        {pos: [3, 4, 9], state: "minecraft:gravel"},
        {pos: [3, 4, 10], state: "minecraft:gravel"},
        {pos: [3, 4, 11], state: "sullysmod:petrified_log{axis:y}"},
        {pos: [3, 4, 12], state: "minecraft:gravel"},
        {pos: [3, 4, 13], state: "minecraft:gravel"},
        {pos: [3, 4, 14], state: "minecraft:gravel"},
        {pos: [3, 4, 15], state: "minecraft:gravel"},
        {pos: [3, 4, 16], state: "sullysmod:amber{is_melted:false}", nbt: {RenderEntity: 0b, StuckEntity: [], id: "sullysmod:amber"}},
        {pos: [4, 4, 6], state: "minecraft:gravel"},
        {pos: [4, 4, 7], state: "minecraft:gravel"},
        {pos: [4, 4, 8], state: "minecraft:gravel"},
        {pos: [4, 4, 9], state: "minecraft:gravel"},
        {pos: [4, 4, 10], state: "minecraft:gravel"},
        {pos: [4, 4, 11], state: "minecraft:gravel"},
        {pos: [4, 4, 12], state: "minecraft:gravel"},
        {pos: [4, 4, 13], state: "minecraft:gravel"},
        {pos: [4, 4, 14], state: "minecraft:gravel"},
        {pos: [4, 4, 15], state: "minecraft:gravel"},
        {pos: [5, 4, 5], state: "minecraft:gravel"},
        {pos: [5, 4, 6], state: "minecraft:gravel"},
        {pos: [5, 4, 7], state: "minecraft:gravel"},
        {pos: [5, 4, 8], state: "minecraft:gravel"},
        {pos: [5, 4, 9], state: "sullysmod:petrified_log{axis:y}"},
        {pos: [5, 4, 10], state: "minecraft:gravel"},
        {pos: [5, 4, 11], state: "minecraft:gravel"},
        {pos: [5, 4, 12], state: "minecraft:gravel"},
        {pos: [5, 4, 13], state: "minecraft:gravel"},
        {pos: [5, 4, 14], state: "minecraft:gravel"},
        {pos: [5, 4, 15], state: "minecraft:gravel"},
        {pos: [6, 4, 3], state: "minecraft:gravel"},
        {pos: [6, 4, 4], state: "sullysmod:stripped_petrified_log{axis:y}"},
        {pos: [6, 4, 5], state: "minecraft:gravel"},
        {pos: [6, 4, 6], state: "minecraft:gravel"},
        {pos: [6, 4, 7], state: "minecraft:gravel"},
        {pos: [6, 4, 8], state: "minecraft:gravel"},
        {pos: [6, 4, 9], state: "sullysmod:petrified_log{axis:y}"},
        {pos: [6, 4, 10], state: "sullysmod:stripped_petrified_log{axis:y}"},
        {pos: [6, 4, 11], state: "minecraft:gravel"},
        {pos: [6, 4, 12], state: "sullysmod:petrified_log{axis:y}"},
        {pos: [6, 4, 13], state: "minecraft:gravel"},
        {pos: [6, 4, 14], state: "minecraft:gravel"},
        {pos: [6, 4, 15], state: "minecraft:gravel"},
        {pos: [6, 4, 16], state: "minecraft:gravel"},
        {pos: [7, 4, 3], state: "minecraft:gravel"},
        {pos: [7, 4, 4], state: "minecraft:gravel"},
        {pos: [7, 4, 5], state: "minecraft:gravel"},
        {pos: [7, 4, 6], state: "minecraft:gravel"},
        {pos: [7, 4, 7], state: "minecraft:gravel"},
        {pos: [7, 4, 8], state: "minecraft:gravel"},
        {pos: [7, 4, 9], state: "minecraft:gravel"},
        {pos: [7, 4, 10], state: "minecraft:gravel"},
        {pos: [7, 4, 11], state: "minecraft:gravel"},
        {pos: [7, 4, 12], state: "minecraft:gravel"},
        {pos: [7, 4, 13], state: "sullysmod:stripped_petrified_log{axis:y}"},
        {pos: [7, 4, 14], state: "minecraft:gravel"},
        {pos: [7, 4, 15], state: "minecraft:gravel"},
        {pos: [7, 4, 16], state: "minecraft:gravel"},
        {pos: [8, 4, 3], state: "minecraft:gravel"},
        {pos: [8, 4, 4], state: "minecraft:gravel"},
        {pos: [8, 4, 5], state: "minecraft:gravel"},
        {pos: [8, 4, 6], state: "sullysmod:petrified_log{axis:y}"},
        {pos: [8, 4, 7], state: "sullysmod:stripped_petrified_log{axis:y}"},
        {pos: [8, 4, 8], state: "minecraft:gravel"},
        {pos: [8, 4, 9], state: "minecraft:gravel"},
        {pos: [8, 4, 10], state: "minecraft:gravel"},
        {pos: [8, 4, 11], state: "minecraft:gravel"},
        {pos: [8, 4, 12], state: "minecraft:gravel"},
        {pos: [8, 4, 13], state: "minecraft:gravel"},
        {pos: [8, 4, 14], state: "minecraft:gravel"},
        {pos: [8, 4, 15], state: "minecraft:gravel"},
        {pos: [8, 4, 16], state: "minecraft:gravel"},
        {pos: [9, 4, 3], state: "minecraft:gravel"},
        {pos: [9, 4, 4], state: "minecraft:gravel"},
        {pos: [9, 4, 5], state: "minecraft:gravel"},
        {pos: [9, 4, 6], state: "minecraft:gravel"},
        {pos: [9, 4, 7], state: "sullysmod:stripped_petrified_log{axis:y}"},
        {pos: [9, 4, 8], state: "minecraft:gravel"},
        {pos: [9, 4, 9], state: "minecraft:gravel"},
        {pos: [9, 4, 10], state: "minecraft:gravel"},
        {pos: [9, 4, 11], state: "minecraft:gravel"},
        {pos: [9, 4, 12], state: "minecraft:gravel"},
        {pos: [9, 4, 13], state: "minecraft:gravel"},
        {pos: [9, 4, 14], state: "minecraft:gravel"},
        {pos: [9, 4, 15], state: "minecraft:gravel"},
        {pos: [9, 4, 16], state: "minecraft:gravel"},
        {pos: [10, 4, 3], state: "minecraft:gravel"},
        {pos: [10, 4, 4], state: "minecraft:gravel"},
        {pos: [10, 4, 5], state: "minecraft:gravel"},
        {pos: [10, 4, 6], state: "minecraft:gravel"},
        {pos: [10, 4, 7], state: "minecraft:gravel"},
        {pos: [10, 4, 8], state: "minecraft:gravel"},
        {pos: [10, 4, 9], state: "minecraft:gravel"},
        {pos: [10, 4, 10], state: "minecraft:gravel"},
        {pos: [10, 4, 11], state: "minecraft:gravel"},
        {pos: [10, 4, 12], state: "minecraft:gravel"},
        {pos: [10, 4, 13], state: "minecraft:gravel"},
        {pos: [10, 4, 14], state: "minecraft:gravel"},
        {pos: [10, 4, 15], state: "minecraft:gravel"},
        {pos: [11, 4, 4], state: "minecraft:gravel"},
        {pos: [11, 4, 5], state: "minecraft:gravel"},
        {pos: [11, 4, 6], state: "minecraft:gravel"},
        {pos: [11, 4, 7], state: "minecraft:gravel"},
        {pos: [11, 4, 8], state: "minecraft:gravel"},
        {pos: [11, 4, 9], state: "sullysmod:stripped_petrified_log{axis:y}"},
        {pos: [11, 4, 10], state: "sullysmod:petrified_log{axis:y}"},
        {pos: [11, 4, 11], state: "minecraft:gravel"},
        {pos: [11, 4, 12], state: "sullysmod:petrified_log{axis:y}"},
        {pos: [11, 4, 13], state: "minecraft:gravel"},
        {pos: [11, 4, 14], state: "minecraft:gravel"},
        {pos: [11, 4, 15], state: "minecraft:gravel"},
        {pos: [12, 4, 4], state: "minecraft:gravel"},
        {pos: [12, 4, 5], state: "minecraft:gravel"},
        {pos: [12, 4, 6], state: "minecraft:gravel"},
        {pos: [12, 4, 7], state: "sullysmod:petrified_log{axis:y}"},
        {pos: [12, 4, 8], state: "minecraft:gravel"},
        {pos: [12, 4, 9], state: "minecraft:gravel"},
        {pos: [12, 4, 10], state: "minecraft:gravel"},
        {pos: [12, 4, 11], state: "minecraft:gravel"},
        {pos: [12, 4, 12], state: "minecraft:gravel"},
        {pos: [12, 4, 13], state: "minecraft:gravel"},
        {pos: [12, 4, 14], state: "minecraft:gravel"},
        {pos: [12, 4, 15], state: "minecraft:gravel"},
        {pos: [13, 4, 5], state: "minecraft:gravel"},
        {pos: [13, 4, 6], state: "minecraft:gravel"},
        {pos: [13, 4, 7], state: "minecraft:gravel"},
        {pos: [13, 4, 8], state: "minecraft:gravel"},
        {pos: [13, 4, 9], state: "minecraft:gravel"},
        {pos: [13, 4, 10], state: "minecraft:gravel"},
        {pos: [13, 4, 11], state: "minecraft:gravel"},
        {pos: [13, 4, 12], state: "minecraft:gravel"},
        {pos: [13, 4, 13], state: "minecraft:gravel"},
        {pos: [13, 4, 14], state: "minecraft:gravel"},
        {pos: [13, 4, 15], state: "sullysmod:petrified_log{axis:y}"},
        {pos: [13, 4, 17], state: "sullysmod:petrified_log{axis:y}"},
        {pos: [14, 4, 5], state: "sullysmod:amber{is_melted:false}", nbt: {RenderEntity: 0b, StuckEntity: [], id: "sullysmod:amber"}},
        {pos: [14, 4, 7], state: "minecraft:gravel"},
        {pos: [14, 4, 8], state: "minecraft:gravel"},
        {pos: [14, 4, 9], state: "minecraft:gravel"},
        {pos: [14, 4, 10], state: "minecraft:gravel"},
        {pos: [14, 4, 11], state: "minecraft:gravel"},
        {pos: [14, 4, 12], state: "minecraft:gravel"},
        {pos: [14, 4, 13], state: "minecraft:gravel"},
        {pos: [14, 4, 14], state: "minecraft:gravel"},
        {pos: [14, 4, 15], state: "minecraft:gravel"},
        {pos: [15, 4, 9], state: "minecraft:gravel"},
        {pos: [15, 4, 10], state: "minecraft:gravel"},
        {pos: [15, 4, 11], state: "minecraft:gravel"},
        {pos: [15, 4, 12], state: "minecraft:gravel"},
        {pos: [15, 4, 13], state: "minecraft:gravel"},
        {pos: [16, 4, 10], state: "minecraft:gravel"},
        {pos: [16, 4, 11], state: "minecraft:gravel"},
        {pos: [16, 4, 12], state: "minecraft:gravel"},
        {pos: [17, 4, 10], state: "sullysmod:amber{is_melted:false}", nbt: {RenderEntity: 0b, StuckEntity: [], id: "sullysmod:amber"}},
        {pos: [0, 5, 9], state: "sullysmod:stripped_petrified_log{axis:x}"},
        {pos: [0, 5, 10], state: "sullysmod:petrified_log{axis:z}"},
        {pos: [0, 5, 11], state: "sullysmod:stripped_petrified_log{axis:z}"},
        {pos: [0, 5, 12], state: "minecraft:gravel"},
        {pos: [0, 5, 13], state: "minecraft:gravel"},
        {pos: [1, 5, 8], state: "minecraft:gravel"},
        {pos: [1, 5, 9], state: "sullysmod:petrified_log{axis:y}"},
        {pos: [1, 5, 10], state: "minecraft:gravel"},
        {pos: [1, 5, 11], state: "sullysmod:stripped_petrified_log{axis:x}"},
        {pos: [1, 5, 12], state: "minecraft:gravel"},
        {pos: [1, 5, 13], state: "minecraft:gravel"},
        {pos: [1, 5, 14], state: "minecraft:gravel"},
        {pos: [2, 5, 6], state: "minecraft:gravel"},
        {pos: [2, 5, 7], state: "minecraft:gravel"},
        {pos: [2, 5, 8], state: "minecraft:gravel"},
        {pos: [2, 5, 9], state: "minecraft:gravel"},
        {pos: [2, 5, 10], state: "minecraft:gravel"},
        {pos: [2, 5, 11], state: "minecraft:gravel"},
        {pos: [2, 5, 12], state: "minecraft:gravel"},
        {pos: [2, 5, 13], state: "minecraft:gravel"},
        {pos: [2, 5, 14], state: "minecraft:gravel"},
        {pos: [2, 5, 15], state: "minecraft:gravel"},
        {pos: [3, 5, 6], state: "minecraft:gravel"},
        {pos: [3, 5, 7], state: "minecraft:gravel"},
        {pos: [3, 5, 8], state: "minecraft:gravel"},
        {pos: [3, 5, 9], state: "minecraft:gravel"},
        {pos: [3, 5, 10], state: "minecraft:gravel"},
        {pos: [3, 5, 11], state: "sullysmod:petrified_log{axis:y}"},
        {pos: [3, 5, 12], state: "minecraft:gravel"},
        {pos: [3, 5, 13], state: "minecraft:gravel"},
        {pos: [3, 5, 14], state: "minecraft:gravel"},
        {pos: [3, 5, 15], state: "sullysmod:stripped_petrified_log{axis:y}"},
        {pos: [3, 5, 16], state: "sullysmod:stripped_petrified_log{axis:z}"},
        {pos: [4, 5, 5], state: "minecraft:gravel"},
        {pos: [4, 5, 6], state: "minecraft:gravel"},
        {pos: [4, 5, 7], state: "minecraft:gravel"},
        {pos: [4, 5, 8], state: "minecraft:gravel"},
        {pos: [4, 5, 9], state: "minecraft:gravel"},
        {pos: [4, 5, 10], state: "minecraft:gravel"},
        {pos: [4, 5, 11], state: "sullysmod:petrified_log{axis:x}"},
        {pos: [4, 5, 12], state: "sullysmod:stripped_petrified_log{axis:z}"},
        {pos: [4, 5, 13], state: "minecraft:gravel"},
        {pos: [4, 5, 14], state: "minecraft:gravel"},
        {pos: [4, 5, 15], state: "minecraft:gravel"},
        {pos: [5, 5, 2], state: "sullysmod:amber{is_melted:false}", nbt: {RenderEntity: 0b, StuckEntity: [], id: "sullysmod:amber"}},
        {pos: [5, 5, 3], state: "minecraft:gravel"},
        {pos: [5, 5, 4], state: "minecraft:gravel"},
        {pos: [5, 5, 5], state: "minecraft:gravel"},
        {pos: [5, 5, 6], state: "minecraft:gravel"},
        {pos: [5, 5, 7], state: "minecraft:gravel"},
        {pos: [5, 5, 8], state: "minecraft:gravel"},
        {pos: [5, 5, 9], state: "sullysmod:stripped_petrified_log{axis:y}"},
        {pos: [5, 5, 10], state: "minecraft:gravel"},
        {pos: [5, 5, 11], state: "minecraft:gravel"},
        {pos: [5, 5, 12], state: "minecraft:gravel"},
        {pos: [5, 5, 13], state: "minecraft:gravel"},
        {pos: [5, 5, 14], state: "minecraft:gravel"},
        {pos: [5, 5, 15], state: "minecraft:gravel"},
        {pos: [5, 5, 16], state: "minecraft:gravel"},
        {pos: [6, 5, 3], state: "minecraft:gravel"},
        {pos: [6, 5, 4], state: "sullysmod:petrified_log{axis:y}"},
        {pos: [6, 5, 5], state: "minecraft:gravel"},
        {pos: [6, 5, 6], state: "minecraft:gravel"},
        {pos: [6, 5, 7], state: "minecraft:gravel"},
        {pos: [6, 5, 8], state: "minecraft:gravel"},
        {pos: [6, 5, 9], state: "sullysmod:petrified_log{axis:y}"},
        {pos: [6, 5, 10], state: "sullysmod:petrified_log{axis:y}"},
        {pos: [6, 5, 11], state: "minecraft:gravel"},
        {pos: [6, 5, 12], state: "sullysmod:petrified_log{axis:y}"},
        {pos: [6, 5, 13], state: "minecraft:gravel"},
        {pos: [6, 5, 14], state: "minecraft:gravel"},
        {pos: [6, 5, 15], state: "minecraft:gravel"},
        {pos: [6, 5, 16], state: "minecraft:gravel"},
        {pos: [7, 5, 2], state: "minecraft:gravel"},
        {pos: [7, 5, 3], state: "minecraft:gravel"},
        {pos: [7, 5, 4], state: "minecraft:gravel"},
        {pos: [7, 5, 5], state: "minecraft:gravel"},
        {pos: [7, 5, 6], state: "minecraft:gravel"},
        {pos: [7, 5, 7], state: "minecraft:gravel"},
        {pos: [7, 5, 8], state: "minecraft:gravel"},
        {pos: [7, 5, 9], state: "minecraft:gravel"},
        {pos: [7, 5, 10], state: "minecraft:gravel"},
        {pos: [7, 5, 11], state: "minecraft:gravel"},
        {pos: [7, 5, 12], state: "sullysmod:stripped_petrified_log{axis:y}"},
        {pos: [7, 5, 13], state: "sullysmod:stripped_petrified_log{axis:y}"},
        {pos: [7, 5, 14], state: "minecraft:gravel"},
        {pos: [7, 5, 15], state: "minecraft:gravel"},
        {pos: [7, 5, 16], state: "minecraft:gravel"},
        {pos: [8, 5, 2], state: "minecraft:gravel"},
        {pos: [8, 5, 3], state: "minecraft:gravel"},
        {pos: [8, 5, 4], state: "minecraft:gravel"},
        {pos: [8, 5, 5], state: "minecraft:gravel"},
        {pos: [8, 5, 6], state: "sullysmod:petrified_log{axis:y}"},
        {pos: [8, 5, 7], state: "sullysmod:petrified_log{axis:y}"},
        {pos: [8, 5, 8], state: "sullysmod:stripped_petrified_log{axis:y}"},
        {pos: [8, 5, 9], state: "minecraft:gravel"},
        {pos: [8, 5, 10], state: "minecraft:gravel"},
        {pos: [8, 5, 11], state: "minecraft:gravel"},
        {pos: [8, 5, 12], state: "minecraft:gravel"},
        {pos: [8, 5, 13], state: "minecraft:gravel"},
        {pos: [8, 5, 14], state: "minecraft:gravel"},
        {pos: [8, 5, 15], state: "minecraft:gravel"},
        {pos: [8, 5, 16], state: "minecraft:gravel"},
        {pos: [8, 5, 17], state: "minecraft:gravel"},
        {pos: [9, 5, 2], state: "minecraft:gravel"},
        {pos: [9, 5, 3], state: "minecraft:gravel"},
        {pos: [9, 5, 4], state: "minecraft:gravel"},
        {pos: [9, 5, 5], state: "minecraft:gravel"},
        {pos: [9, 5, 6], state: "minecraft:gravel"},
        {pos: [9, 5, 7], state: "sullysmod:stripped_petrified_log{axis:y}"},
        {pos: [9, 5, 8], state: "minecraft:gravel"},
        {pos: [9, 5, 9], state: "minecraft:gravel"},
        {pos: [9, 5, 10], state: "minecraft:gravel"},
        {pos: [9, 5, 11], state: "minecraft:gravel"},
        {pos: [9, 5, 12], state: "minecraft:gravel"},
        {pos: [9, 5, 13], state: "minecraft:gravel"},
        {pos: [9, 5, 14], state: "minecraft:gravel"},
        {pos: [9, 5, 15], state: "minecraft:gravel"},
        {pos: [9, 5, 16], state: "minecraft:gravel"},
        {pos: [9, 5, 17], state: "minecraft:gravel"},
        {pos: [10, 5, 2], state: "minecraft:gravel"},
        {pos: [10, 5, 3], state: "minecraft:gravel"},
        {pos: [10, 5, 4], state: "minecraft:gravel"},
        {pos: [10, 5, 5], state: "minecraft:gravel"},
        {pos: [10, 5, 6], state: "minecraft:gravel"},
        {pos: [10, 5, 7], state: "minecraft:gravel"},
        {pos: [10, 5, 8], state: "minecraft:gravel"},
        {pos: [10, 5, 9], state: "minecraft:gravel"},
        {pos: [10, 5, 10], state: "minecraft:gravel"},
        {pos: [10, 5, 11], state: "minecraft:gravel"},
        {pos: [10, 5, 12], state: "minecraft:gravel"},
        {pos: [10, 5, 13], state: "minecraft:gravel"},
        {pos: [10, 5, 14], state: "minecraft:gravel"},
        {pos: [10, 5, 15], state: "minecraft:gravel"},
        {pos: [10, 5, 16], state: "minecraft:gravel"},
        {pos: [11, 5, 3], state: "minecraft:gravel"},
        {pos: [11, 5, 4], state: "minecraft:gravel"},
        {pos: [11, 5, 5], state: "minecraft:gravel"},
        {pos: [11, 5, 6], state: "minecraft:gravel"},
        {pos: [11, 5, 7], state: "sullysmod:petrified_log{axis:x}"},
        {pos: [11, 5, 8], state: "minecraft:gravel"},
        {pos: [11, 5, 9], state: "sullysmod:petrified_log{axis:y}"},
        {pos: [11, 5, 10], state: "sullysmod:petrified_log{axis:y}"},
        {pos: [11, 5, 11], state: "minecraft:gravel"},
        {pos: [11, 5, 12], state: "sullysmod:petrified_log{axis:y}"},
        {pos: [11, 5, 13], state: "minecraft:gravel"},
        {pos: [11, 5, 14], state: "minecraft:gravel"},
        {pos: [11, 5, 15], state: "minecraft:gravel"},
        {pos: [11, 5, 16], state: "minecraft:gravel"},
        {pos: [12, 5, 3], state: "sullysmod:stripped_petrified_log{axis:z}"},
        {pos: [12, 5, 4], state: "sullysmod:stripped_petrified_log{axis:z}"},
        {pos: [12, 5, 5], state: "sullysmod:petrified_log{axis:z}"},
        {pos: [12, 5, 6], state: "sullysmod:petrified_log{axis:z}"},
        {pos: [12, 5, 7], state: "sullysmod:petrified_log{axis:y}"},
        {pos: [12, 5, 8], state: "minecraft:gravel"},
        {pos: [12, 5, 9], state: "minecraft:gravel"},
        {pos: [12, 5, 10], state: "minecraft:gravel"},
        {pos: [12, 5, 11], state: "minecraft:gravel"},
        {pos: [12, 5, 12], state: "sullysmod:petrified_log{axis:x}"},
        {pos: [12, 5, 13], state: "minecraft:gravel"},
        {pos: [12, 5, 14], state: "minecraft:gravel"},
        {pos: [12, 5, 15], state: "minecraft:gravel"},
        {pos: [13, 5, 4], state: "minecraft:gravel"},
        {pos: [13, 5, 5], state: "sullysmod:petrified_log{axis:x}"},
        {pos: [13, 5, 6], state: "minecraft:gravel"},
        {pos: [13, 5, 7], state: "minecraft:gravel"},
        {pos: [13, 5, 8], state: "minecraft:gravel"},
        {pos: [13, 5, 9], state: "minecraft:gravel"},
        {pos: [13, 5, 10], state: "minecraft:gravel"},
        {pos: [13, 5, 11], state: "minecraft:gravel"},
        {pos: [13, 5, 12], state: "sullysmod:stripped_petrified_log{axis:x}"},
        {pos: [13, 5, 13], state: "minecraft:gravel"},
        {pos: [13, 5, 14], state: "minecraft:gravel"},
        {pos: [13, 5, 15], state: "sullysmod:stripped_petrified_log{axis:y}"},
        {pos: [14, 5, 5], state: "sullysmod:stripped_petrified_log{axis:x}"},
        {pos: [14, 5, 6], state: "minecraft:gravel"},
        {pos: [14, 5, 7], state: "minecraft:gravel"},
        {pos: [14, 5, 8], state: "minecraft:gravel"},
        {pos: [14, 5, 9], state: "minecraft:gravel"},
        {pos: [14, 5, 10], state: "minecraft:gravel"},
        {pos: [14, 5, 11], state: "minecraft:gravel"},
        {pos: [14, 5, 12], state: "minecraft:gravel"},
        {pos: [14, 5, 13], state: "minecraft:gravel"},
        {pos: [14, 5, 14], state: "minecraft:gravel"},
        {pos: [14, 5, 15], state: "sullysmod:stripped_petrified_log{axis:y}"},
        {pos: [15, 5, 8], state: "minecraft:gravel"},
        {pos: [15, 5, 9], state: "minecraft:gravel"},
        {pos: [15, 5, 10], state: "minecraft:gravel"},
        {pos: [15, 5, 11], state: "minecraft:gravel"},
        {pos: [15, 5, 12], state: "minecraft:gravel"},
        {pos: [15, 5, 13], state: "minecraft:gravel"},
        {pos: [15, 5, 14], state: "minecraft:gravel"},
        {pos: [16, 5, 10], state: "sullysmod:petrified_log{axis:x}"},
        {pos: [16, 5, 11], state: "minecraft:gravel"},
        {pos: [16, 5, 12], state: "minecraft:gravel"},
        {pos: [17, 5, 10], state: "sullysmod:petrified_log{axis:x}"},
        {pos: [0, 6, 8], state: "minecraft:gravel"},
        {pos: [0, 6, 9], state: "minecraft:gravel"},
        {pos: [0, 6, 10], state: "minecraft:gravel"},
        {pos: [0, 6, 11], state: "minecraft:gravel"},
        {pos: [0, 6, 12], state: "minecraft:gravel"},
        {pos: [0, 6, 13], state: "minecraft:gravel"},
        {pos: [0, 6, 14], state: "minecraft:gravel"},
        {pos: [1, 6, 6], state: "minecraft:gravel"},
        {pos: [1, 6, 7], state: "minecraft:gravel"},
        {pos: [1, 6, 8], state: "minecraft:gravel"},
        {pos: [1, 6, 9], state: "sullysmod:petrified_log{axis:y}"},
        {pos: [1, 6, 10], state: "minecraft:gravel"},
        {pos: [1, 6, 11], state: "minecraft:gravel"},
        {pos: [1, 6, 12], state: "minecraft:gravel"},
        {pos: [1, 6, 13], state: "minecraft:gravel"},
        {pos: [1, 6, 14], state: "minecraft:gravel"},
        {pos: [2, 6, 6], state: "minecraft:gravel"},
        {pos: [2, 6, 7], state: "minecraft:gravel"},
        {pos: [2, 6, 8], state: "minecraft:gravel"},
        {pos: [2, 6, 9], state: "sullysmod:petrified_log{axis:y}"},
        {pos: [2, 6, 10], state: "minecraft:gravel"},
        {pos: [2, 6, 11], state: "minecraft:gravel"},
        {pos: [2, 6, 12], state: "minecraft:gravel"},
        {pos: [2, 6, 13], state: "minecraft:gravel"},
        {pos: [2, 6, 14], state: "sullysmod:petrified_log{axis:y}"},
        {pos: [2, 6, 15], state: "sullysmod:petrified_log{axis:y}"},
        {pos: [3, 6, 5], state: "minecraft:gravel"},
        {pos: [3, 6, 6], state: "minecraft:gravel"},
        {pos: [3, 6, 7], state: "minecraft:gravel"},
        {pos: [3, 6, 8], state: "minecraft:gravel"},
        {pos: [3, 6, 9], state: "minecraft:gravel"},
        {pos: [3, 6, 10], state: "minecraft:gravel"},
        {pos: [3, 6, 11], state: "sullysmod:petrified_log{axis:y}"},
        {pos: [3, 6, 12], state: "minecraft:gravel"},
        {pos: [3, 6, 13], state: "minecraft:gravel"},
        {pos: [3, 6, 14], state: "minecraft:gravel"},
        {pos: [3, 6, 15], state: "sullysmod:petrified_log{axis:y}"},
        {pos: [4, 6, 4], state: "minecraft:gravel"},
        {pos: [4, 6, 5], state: "minecraft:gravel"},
        {pos: [4, 6, 6], state: "minecraft:gravel"},
        {pos: [4, 6, 7], state: "minecraft:gravel"},
        {pos: [4, 6, 8], state: "minecraft:gravel"},
        {pos: [4, 6, 9], state: "minecraft:gravel"},
        {pos: [4, 6, 10], state: "minecraft:gravel"},
        {pos: [4, 6, 11], state: "minecraft:gravel"},
        {pos: [4, 6, 12], state: "minecraft:gravel"},
        {pos: [4, 6, 13], state: "minecraft:gravel"},
        {pos: [4, 6, 14], state: "minecraft:gravel"},
        {pos: [4, 6, 15], state: "minecraft:gravel"},
        {pos: [4, 6, 16], state: "minecraft:gravel"},
        {pos: [5, 6, 2], state: "sullysmod:stripped_petrified_log{axis:z}"},
        {pos: [5, 6, 3], state: "sullysmod:petrified_log{axis:x}"},
        {pos: [5, 6, 4], state: "minecraft:gravel"},
        {pos: [5, 6, 5], state: "minecraft:gravel"},
        {pos: [5, 6, 6], state: "minecraft:gravel"},
        {pos: [5, 6, 7], state: "minecraft:gravel"},
        {pos: [5, 6, 8], state: "minecraft:gravel"},
        {pos: [5, 6, 9], state: "minecraft:gravel"},
        {pos: [5, 6, 10], state: "sullysmod:petrified_log{axis:y}"},
        {pos: [5, 6, 11], state: "minecraft:gravel"},
        {pos: [5, 6, 12], state: "minecraft:gravel"},
        {pos: [5, 6, 13], state: "minecraft:gravel"},
        {pos: [5, 6, 14], state: "minecraft:gravel"},
        {pos: [5, 6, 15], state: "minecraft:gravel"},
        {pos: [5, 6, 16], state: "minecraft:gravel"},
        {pos: [6, 6, 2], state: "minecraft:gravel"},
        {pos: [6, 6, 3], state: "sullysmod:petrified_log{axis:z}"},
        {pos: [6, 6, 4], state: "sullysmod:petrified_log{axis:y}"},
        {pos: [6, 6, 5], state: "minecraft:gravel"},
        {pos: [6, 6, 6], state: "minecraft:gravel"},
        {pos: [6, 6, 7], state: "minecraft:gravel"},
        {pos: [6, 6, 8], state: "minecraft:gravel"},
        {pos: [6, 6, 9], state: "sullysmod:petrified_log{axis:y}"},
        {pos: [6, 6, 10], state: "sullysmod:petrified_log{axis:y}"},
        {pos: [6, 6, 11], state: "minecraft:gravel"},
        {pos: [6, 6, 12], state: "sullysmod:petrified_log{axis:y}"},
        {pos: [6, 6, 13], state: "minecraft:gravel"},
        {pos: [6, 6, 14], state: "minecraft:gravel"},
        {pos: [6, 6, 15], state: "minecraft:gravel"},
        {pos: [6, 6, 16], state: "minecraft:gravel"},
        {pos: [7, 6, 2], state: "minecraft:gravel"},
        {pos: [7, 6, 3], state: "minecraft:gravel"},
        {pos: [7, 6, 4], state: "minecraft:gravel"},
        {pos: [7, 6, 5], state: "minecraft:gravel"},
        {pos: [7, 6, 6], state: "minecraft:gravel"},
        {pos: [7, 6, 7], state: "minecraft:gravel"},
        {pos: [7, 6, 8], state: "minecraft:gravel"},
        {pos: [7, 6, 9], state: "minecraft:gravel"},
        {pos: [7, 6, 10], state: "minecraft:gravel"},
        {pos: [7, 6, 11], state: "minecraft:gravel"},
        {pos: [7, 6, 12], state: "sullysmod:stripped_petrified_log{axis:y}"},
        {pos: [7, 6, 13], state: "sullysmod:petrified_log{axis:y}"},
        {pos: [7, 6, 14], state: "minecraft:gravel"},
        {pos: [7, 6, 15], state: "minecraft:gravel"},
        {pos: [7, 6, 16], state: "minecraft:gravel"},
        {pos: [7, 6, 17], state: "minecraft:gravel"},
        {pos: [8, 6, 1], state: "minecraft:gravel"},
        {pos: [8, 6, 2], state: "minecraft:gravel"},
        {pos: [8, 6, 3], state: "minecraft:gravel"},
        {pos: [8, 6, 4], state: "sullysmod:stripped_petrified_log{axis:y}"},
        {pos: [8, 6, 5], state: "minecraft:gravel"},
        {pos: [8, 6, 6], state: "minecraft:gravel"},
        {pos: [8, 6, 7], state: "sullysmod:petrified_log{axis:y}"},
        {pos: [8, 6, 8], state: "sullysmod:petrified_log{axis:y}"},
        {pos: [8, 6, 9], state: "minecraft:gravel"},
        {pos: [8, 6, 10], state: "minecraft:gravel"},
        {pos: [8, 6, 11], state: "minecraft:gravel"},
        {pos: [8, 6, 12], state: "minecraft:gravel"},
        {pos: [8, 6, 13], state: "minecraft:gravel"},
        {pos: [8, 6, 14], state: "minecraft:gravel"},
        {pos: [8, 6, 15], state: "minecraft:gravel"},
        {pos: [8, 6, 16], state: "minecraft:gravel"},
        {pos: [8, 6, 17], state: "minecraft:gravel"},
        {pos: [9, 6, 1], state: "minecraft:gravel"},
        {pos: [9, 6, 2], state: "minecraft:gravel"},
        {pos: [9, 6, 3], state: "minecraft:gravel"},
        {pos: [9, 6, 4], state: "minecraft:gravel"},
        {pos: [9, 6, 5], state: "minecraft:gravel"},
        {pos: [9, 6, 6], state: "minecraft:gravel"},
        {pos: [9, 6, 7], state: "sullysmod:petrified_log{axis:y}"},
        {pos: [9, 6, 8], state: "minecraft:gravel"},
        {pos: [9, 6, 9], state: "minecraft:gravel"},
        {pos: [9, 6, 10], state: "minecraft:gravel"},
        {pos: [9, 6, 11], state: "minecraft:gravel"},
        {pos: [9, 6, 12], state: "minecraft:gravel"},
        {pos: [9, 6, 13], state: "minecraft:gravel"},
        {pos: [9, 6, 14], state: "sullysmod:amber{is_melted:false}", nbt: {RenderEntity: 0b, StuckEntity: [], id: "sullysmod:amber"}},
        {pos: [9, 6, 15], state: "minecraft:gravel"},
        {pos: [9, 6, 16], state: "minecraft:gravel"},
        {pos: [9, 6, 17], state: "minecraft:gravel"},
        {pos: [10, 6, 1], state: "minecraft:gravel"},
        {pos: [10, 6, 2], state: "minecraft:gravel"},
        {pos: [10, 6, 3], state: "minecraft:gravel"},
        {pos: [10, 6, 4], state: "minecraft:gravel"},
        {pos: [10, 6, 5], state: "minecraft:gravel"},
        {pos: [10, 6, 6], state: "minecraft:gravel"},
        {pos: [10, 6, 7], state: "minecraft:gravel"},
        {pos: [10, 6, 8], state: "minecraft:gravel"},
        {pos: [10, 6, 9], state: "minecraft:gravel"},
        {pos: [10, 6, 10], state: "minecraft:gravel"},
        {pos: [10, 6, 11], state: "minecraft:gravel"},
        {pos: [10, 6, 12], state: "minecraft:gravel"},
        {pos: [10, 6, 13], state: "minecraft:gravel"},
        {pos: [10, 6, 14], state: "minecraft:gravel"},
        {pos: [10, 6, 15], state: "minecraft:gravel"},
        {pos: [10, 6, 16], state: "minecraft:gravel"},
        {pos: [10, 6, 17], state: "minecraft:gravel"},
        {pos: [11, 6, 2], state: "minecraft:gravel"},
        {pos: [11, 6, 3], state: "minecraft:gravel"},
        {pos: [11, 6, 4], state: "minecraft:gravel"},
        {pos: [11, 6, 5], state: "minecraft:gravel"},
        {pos: [11, 6, 6], state: "minecraft:gravel"},
        {pos: [11, 6, 7], state: "minecraft:gravel"},
        {pos: [11, 6, 8], state: "minecraft:gravel"},
        {pos: [11, 6, 9], state: "sullysmod:petrified_log{axis:y}"},
        {pos: [11, 6, 10], state: "sullysmod:petrified_log{axis:y}"},
        {pos: [11, 6, 11], state: "minecraft:gravel"},
        {pos: [11, 6, 12], state: "sullysmod:petrified_log{axis:y}"},
        {pos: [11, 6, 13], state: "minecraft:gravel"},
        {pos: [11, 6, 14], state: "minecraft:gravel"},
        {pos: [11, 6, 15], state: "minecraft:gravel"},
        {pos: [11, 6, 16], state: "minecraft:gravel"},
        {pos: [12, 6, 2], state: "minecraft:gravel"},
        {pos: [12, 6, 3], state: "minecraft:gravel"},
        {pos: [12, 6, 4], state: "minecraft:gravel"},
        {pos: [12, 6, 5], state: "minecraft:gravel"},
        {pos: [12, 6, 6], state: "sullysmod:petrified_log{axis:y}"},
        {pos: [12, 6, 7], state: "sullysmod:petrified_log{axis:y}"},
        {pos: [12, 6, 8], state: "minecraft:gravel"},
        {pos: [12, 6, 9], state: "minecraft:gravel"},
        {pos: [12, 6, 10], state: "sullysmod:petrified_log{axis:y}"},
        {pos: [12, 6, 11], state: "minecraft:gravel"},
        {pos: [12, 6, 12], state: "minecraft:gravel"},
        {pos: [12, 6, 13], state: "minecraft:gravel"},
        {pos: [12, 6, 14], state: "minecraft:gravel"},
        {pos: [12, 6, 15], state: "minecraft:gravel"},
        {pos: [12, 6, 16], state: "minecraft:gravel"},
        {pos: [13, 6, 4], state: "minecraft:gravel"},
        {pos: [13, 6, 5], state: "minecraft:gravel"},
        {pos: [13, 6, 6], state: "minecraft:gravel"},
        {pos: [13, 6, 7], state: "minecraft:gravel"},
        {pos: [13, 6, 8], state: "minecraft:gravel"},
        {pos: [13, 6, 9], state: "minecraft:gravel"},
        {pos: [13, 6, 10], state: "minecraft:gravel"},
        {pos: [13, 6, 11], state: "minecraft:gravel"},
        {pos: [13, 6, 12], state: "minecraft:gravel"},
        {pos: [13, 6, 13], state: "minecraft:gravel"},
        {pos: [13, 6, 14], state: "minecraft:gravel"},
        {pos: [13, 6, 15], state: "minecraft:gravel"},
        {pos: [14, 6, 5], state: "minecraft:gravel"},
        {pos: [14, 6, 6], state: "minecraft:gravel"},
        {pos: [14, 6, 7], state: "minecraft:gravel"},
        {pos: [14, 6, 8], state: "sullysmod:petrified_log{axis:z}"},
        {pos: [14, 6, 9], state: "sullysmod:petrified_log{axis:z}"},
        {pos: [14, 6, 10], state: "sullysmod:petrified_log{axis:y}"},
        {pos: [14, 6, 11], state: "minecraft:gravel"},
        {pos: [14, 6, 12], state: "minecraft:gravel"},
        {pos: [14, 6, 13], state: "minecraft:gravel"},
        {pos: [14, 6, 14], state: "minecraft:gravel"},
        {pos: [14, 6, 15], state: "sullysmod:petrified_log{axis:y}"},
        {pos: [15, 6, 7], state: "minecraft:gravel"},
        {pos: [15, 6, 8], state: "minecraft:gravel"},
        {pos: [15, 6, 9], state: "minecraft:gravel"},
        {pos: [15, 6, 10], state: "sullysmod:petrified_log{axis:x}"},
        {pos: [15, 6, 11], state: "minecraft:gravel"},
        {pos: [15, 6, 12], state: "minecraft:gravel"},
        {pos: [15, 6, 13], state: "minecraft:gravel"},
        {pos: [15, 6, 14], state: "minecraft:gravel"},
        {pos: [16, 6, 9], state: "minecraft:gravel"},
        {pos: [16, 6, 10], state: "sullysmod:stripped_petrified_log{axis:x}"},
        {pos: [16, 6, 11], state: "minecraft:gravel"},
        {pos: [16, 6, 12], state: "minecraft:gravel"},
        {pos: [16, 6, 13], state: "minecraft:gravel"},
        {pos: [0, 7, 7], state: "minecraft:gravel"},
        {pos: [0, 7, 8], state: "minecraft:gravel"},
        {pos: [0, 7, 9], state: "minecraft:gravel"},
        {pos: [0, 7, 10], state: "minecraft:gravel"},
        {pos: [0, 7, 11], state: "minecraft:gravel"},
        {pos: [0, 7, 12], state: "minecraft:gravel"},
        {pos: [0, 7, 13], state: "minecraft:gravel"},
        {pos: [1, 7, 6], state: "minecraft:gravel"},
        {pos: [1, 7, 7], state: "minecraft:gravel"},
        {pos: [1, 7, 8], state: "minecraft:gravel"},
        {pos: [1, 7, 9], state: "minecraft:gravel"},
        {pos: [1, 7, 10], state: "minecraft:gravel"},
        {pos: [1, 7, 11], state: "minecraft:gravel"},
        {pos: [1, 7, 12], state: "minecraft:gravel"},
        {pos: [1, 7, 13], state: "minecraft:gravel"},
        {pos: [1, 7, 14], state: "minecraft:gravel"},
        {pos: [2, 7, 6], state: "minecraft:gravel"},
        {pos: [2, 7, 7], state: "minecraft:gravel"},
        {pos: [2, 7, 8], state: "minecraft:gravel"},
        {pos: [2, 7, 9], state: "sullysmod:petrified_log{axis:y}"},
        {pos: [2, 7, 10], state: "minecraft:gravel"},
        {pos: [2, 7, 11], state: "minecraft:gravel"},
        {pos: [2, 7, 12], state: "minecraft:gravel"},
        {pos: [2, 7, 13], state: "minecraft:gravel"},
        {pos: [2, 7, 14], state: "sullysmod:petrified_log{axis:y}"},
        {pos: [2, 7, 15], state: "minecraft:gravel"},
        {pos: [2, 7, 16], state: "minecraft:gravel"},
        {pos: [3, 7, 5], state: "minecraft:gravel"},
        {pos: [3, 7, 6], state: "minecraft:gravel"},
        {pos: [3, 7, 7], state: "minecraft:gravel"},
        {pos: [3, 7, 8], state: "minecraft:gravel"},
        {pos: [3, 7, 9], state: "sullysmod:amber{is_melted:false}", nbt: {RenderEntity: 0b, StuckEntity: [], id: "sullysmod:amber"}},
        {pos: [3, 7, 10], state: "minecraft:gravel"},
        {pos: [3, 7, 11], state: "sullysmod:petrified_log{axis:y}"},
        {pos: [3, 7, 12], state: "minecraft:gravel"},
        {pos: [3, 7, 13], state: "minecraft:gravel"},
        {pos: [3, 7, 14], state: "sullysmod:petrified_log{axis:y}"},
        {pos: [3, 7, 15], state: "minecraft:gravel"},
        {pos: [3, 7, 16], state: "minecraft:gravel"},
        {pos: [4, 7, 4], state: "minecraft:gravel"},
        {pos: [4, 7, 5], state: "minecraft:gravel"},
        {pos: [4, 7, 6], state: "minecraft:gravel"},
        {pos: [4, 7, 7], state: "minecraft:gravel"},
        {pos: [4, 7, 8], state: "minecraft:gravel"},
        {pos: [4, 7, 9], state: "minecraft:gravel"},
        {pos: [4, 7, 10], state: "minecraft:gravel"},
        {pos: [4, 7, 11], state: "sullysmod:petrified_log{axis:y}"},
        {pos: [4, 7, 12], state: "minecraft:gravel"},
        {pos: [4, 7, 13], state: "minecraft:gravel"},
        {pos: [4, 7, 14], state: "sullysmod:stripped_petrified_log{axis:y}"},
        {pos: [4, 7, 15], state: "minecraft:gravel"},
        {pos: [4, 7, 16], state: "minecraft:gravel"},
        {pos: [5, 7, 3], state: "minecraft:gravel"},
        {pos: [5, 7, 4], state: "minecraft:gravel"},
        {pos: [5, 7, 5], state: "minecraft:gravel"},
        {pos: [5, 7, 6], state: "minecraft:gravel"},
        {pos: [5, 7, 7], state: "minecraft:gravel"},
        {pos: [5, 7, 8], state: "minecraft:gravel"},
        {pos: [5, 7, 9], state: "minecraft:gravel"},
        {pos: [5, 7, 10], state: "sullysmod:stripped_petrified_log{axis:y}"},
        {pos: [5, 7, 11], state: "minecraft:gravel"},
        {pos: [5, 7, 12], state: "minecraft:gravel"},
        {pos: [5, 7, 13], state: "minecraft:gravel"},
        {pos: [5, 7, 14], state: "minecraft:gravel"},
        {pos: [5, 7, 15], state: "minecraft:gravel"},
        {pos: [5, 7, 16], state: "minecraft:gravel"},
        {pos: [5, 7, 17], state: "minecraft:gravel"},
        {pos: [6, 7, 2], state: "minecraft:gravel"},
        {pos: [6, 7, 3], state: "minecraft:gravel"},
        {pos: [6, 7, 4], state: "sullysmod:petrified_log{axis:y}"},
        {pos: [6, 7, 5], state: "minecraft:gravel"},
        {pos: [6, 7, 6], state: "minecraft:gravel"},
        {pos: [6, 7, 7], state: "sullysmod:amber{is_melted:false}", nbt: {RenderEntity: 0b, StuckEntity: [], id: "sullysmod:amber"}},
        {pos: [6, 7, 8], state: "minecraft:gravel"},
        {pos: [6, 7, 9], state: "sullysmod:stripped_petrified_log{axis:y}"},
        {pos: [6, 7, 10], state: "sullysmod:petrified_log{axis:y}"},
        {pos: [6, 7, 11], state: "sullysmod:amber{is_melted:false}", nbt: {RenderEntity: 0b, StuckEntity: [], id: "sullysmod:amber"}},
        {pos: [6, 7, 12], state: "sullysmod:stripped_petrified_log{axis:y}"},
        {pos: [6, 7, 13], state: "minecraft:gravel"},
        {pos: [6, 7, 14], state: "minecraft:gravel"},
        {pos: [6, 7, 15], state: "minecraft:gravel"},
        {pos: [6, 7, 16], state: "minecraft:gravel"},
        {pos: [6, 7, 17], state: "minecraft:gravel"},
        {pos: [7, 7, 2], state: "minecraft:gravel"},
        {pos: [7, 7, 3], state: "minecraft:gravel"},
        {pos: [7, 7, 4], state: "minecraft:gravel"},
        {pos: [7, 7, 5], state: "sullysmod:stripped_petrified_log{axis:y}"},
        {pos: [7, 7, 6], state: "minecraft:gravel"},
        {pos: [7, 7, 7], state: "minecraft:gravel"},
        {pos: [7, 7, 8], state: "minecraft:gravel"},
        {pos: [7, 7, 9], state: "minecraft:gravel"},
        {pos: [7, 7, 10], state: "minecraft:gravel"},
        {pos: [7, 7, 11], state: "minecraft:gravel"},
        {pos: [7, 7, 12], state: "sullysmod:petrified_log{axis:y}"},
        {pos: [7, 7, 13], state: "sullysmod:petrified_log{axis:y}"},
        {pos: [7, 7, 14], state: "minecraft:gravel"},
        {pos: [7, 7, 15], state: "sullysmod:stripped_petrified_log{axis:y}"},
        {pos: [7, 7, 16], state: "sullysmod:petrified_log{axis:z}"},
        {pos: [7, 7, 17], state: "sullysmod:petrified_log{axis:x}"},
        {pos: [8, 7, 1], state: "minecraft:gravel"},
        {pos: [8, 7, 2], state: "minecraft:gravel"},
        {pos: [8, 7, 3], state: "minecraft:gravel"},
        {pos: [8, 7, 4], state: "sullysmod:petrified_log{axis:y}"},
        {pos: [8, 7, 5], state: "minecraft:gravel"},
        {pos: [8, 7, 6], state: "minecraft:gravel"},
        {pos: [8, 7, 7], state: "sullysmod:petrified_log{axis:y}"},
        {pos: [8, 7, 8], state: "sullysmod:petrified_log{axis:y}"},
        {pos: [8, 7, 9], state: "minecraft:gravel"},
        {pos: [8, 7, 10], state: "sullysmod:amber{is_melted:false}", nbt: {RenderEntity: 0b, StuckEntity: [], id: "sullysmod:amber"}},
        {pos: [8, 7, 11], state: "sullysmod:amber{is_melted:false}", nbt: {RenderEntity: 0b, StuckEntity: [], id: "sullysmod:amber"}},
        {pos: [8, 7, 12], state: "sullysmod:petrified_log{axis:y}"},
        {pos: [8, 7, 13], state: "minecraft:gravel"},
        {pos: [8, 7, 14], state: "minecraft:gravel"},
        {pos: [8, 7, 15], state: "sullysmod:amber{is_melted:false}", nbt: {RenderEntity: 0b, StuckEntity: [], id: "sullysmod:amber"}},
        {pos: [8, 7, 16], state: "sullysmod:petrified_log{axis:z}"},
        {pos: [8, 7, 17], state: "sullysmod:petrified_log{axis:x}"},
        {pos: [9, 7, 1], state: "minecraft:gravel"},
        {pos: [9, 7, 2], state: "minecraft:gravel"},
        {pos: [9, 7, 3], state: "minecraft:gravel"},
        {pos: [9, 7, 4], state: "minecraft:gravel"},
        {pos: [9, 7, 5], state: "minecraft:gravel"},
        {pos: [9, 7, 6], state: "sullysmod:amber{is_melted:false}", nbt: {RenderEntity: 0b, StuckEntity: [], id: "sullysmod:amber"}},
        {pos: [9, 7, 7], state: "sullysmod:petrified_log{axis:y}"},
        {pos: [9, 7, 8], state: "sullysmod:stripped_petrified_log{axis:y}"},
        {pos: [9, 7, 9], state: "minecraft:gravel"},
        {pos: [9, 7, 10], state: "minecraft:gravel"},
        {pos: [9, 7, 11], state: "minecraft:gravel"},
        {pos: [9, 7, 12], state: "minecraft:gravel"},
        {pos: [9, 7, 13], state: "minecraft:gravel"},
        {pos: [9, 7, 14], state: "sullysmod:amber{is_melted:false}", nbt: {RenderEntity: 0b, StuckEntity: [], id: "sullysmod:amber"}},
        {pos: [9, 7, 15], state: "minecraft:gravel"},
        {pos: [9, 7, 16], state: "minecraft:gravel"},
        {pos: [9, 7, 17], state: "sullysmod:petrified_log{axis:x}"},
        {pos: [10, 7, 1], state: "minecraft:gravel"},
        {pos: [10, 7, 2], state: "minecraft:gravel"},
        {pos: [10, 7, 3], state: "minecraft:gravel"},
        {pos: [10, 7, 4], state: "minecraft:gravel"},
        {pos: [10, 7, 5], state: "minecraft:gravel"},
        {pos: [10, 7, 6], state: "minecraft:gravel"},
        {pos: [10, 7, 7], state: "minecraft:gravel"},
        {pos: [10, 7, 8], state: "minecraft:gravel"},
        {pos: [10, 7, 9], state: "minecraft:gravel"},
        {pos: [10, 7, 10], state: "minecraft:gravel"},
        {pos: [10, 7, 11], state: "minecraft:gravel"},
        {pos: [10, 7, 12], state: "minecraft:gravel"},
        {pos: [10, 7, 13], state: "minecraft:gravel"},
        {pos: [10, 7, 14], state: "minecraft:gravel"},
        {pos: [10, 7, 15], state: "minecraft:gravel"},
        {pos: [10, 7, 16], state: "minecraft:gravel"},
        {pos: [10, 7, 17], state: "sullysmod:petrified_log{axis:x}"},
        {pos: [11, 7, 1], state: "minecraft:gravel"},
        {pos: [11, 7, 2], state: "minecraft:gravel"},
        {pos: [11, 7, 3], state: "minecraft:gravel"},
        {pos: [11, 7, 4], state: "minecraft:gravel"},
        {pos: [11, 7, 5], state: "minecraft:gravel"},
        {pos: [11, 7, 6], state: "minecraft:gravel"},
        {pos: [11, 7, 7], state: "minecraft:gravel"},
        {pos: [11, 7, 8], state: "minecraft:gravel"},
        {pos: [11, 7, 9], state: "sullysmod:petrified_log{axis:y}"},
        {pos: [11, 7, 10], state: "sullysmod:stripped_petrified_log{axis:y}"},
        {pos: [11, 7, 11], state: "minecraft:gravel"},
        {pos: [11, 7, 12], state: "sullysmod:stripped_petrified_log{axis:y}"},
        {pos: [11, 7, 13], state: "sullysmod:petrified_log{axis:y}"},
        {pos: [11, 7, 14], state: "sullysmod:petrified_log{axis:z}"},
        {pos: [11, 7, 15], state: "minecraft:gravel"},
        {pos: [11, 7, 16], state: "minecraft:gravel"},
        {pos: [11, 7, 17], state: "minecraft:gravel"},
        {pos: [12, 7, 2], state: "minecraft:gravel"},
        {pos: [12, 7, 3], state: "minecraft:gravel"},
        {pos: [12, 7, 4], state: "minecraft:gravel"},
        {pos: [12, 7, 5], state: "minecraft:gravel"},
        {pos: [12, 7, 6], state: "minecraft:gravel"},
        {pos: [12, 7, 7], state: "sullysmod:stripped_petrified_log{axis:y}"},
        {pos: [12, 7, 8], state: "minecraft:gravel"},
        {pos: [12, 7, 9], state: "sullysmod:petrified_log{axis:y}"},
        {pos: [12, 7, 10], state: "sullysmod:petrified_log{axis:y}"},
        {pos: [12, 7, 11], state: "minecraft:gravel"},
        {pos: [12, 7, 12], state: "minecraft:gravel"},
        {pos: [12, 7, 13], state: "sullysmod:petrified_log{axis:x}"},
        {pos: [12, 7, 14], state: "sullysmod:petrified_log{axis:z}"},
        {pos: [12, 7, 15], state: "minecraft:gravel"},
        {pos: [12, 7, 16], state: "minecraft:gravel"},
        {pos: [13, 7, 3], state: "minecraft:gravel"},
        {pos: [13, 7, 4], state: "minecraft:gravel"},
        {pos: [13, 7, 5], state: "minecraft:suspicious_gravel{dusted:0}", nbt: {id: "minecraft:brushable_block", item: {Count: 0b, id: "minecraft:air"}}},
        {pos: [13, 7, 6], state: "minecraft:gravel"},
        {pos: [13, 7, 7], state: "minecraft:gravel"},
        {pos: [13, 7, 8], state: "minecraft:gravel"},
        {pos: [13, 7, 9], state: "minecraft:gravel"},
        {pos: [13, 7, 10], state: "minecraft:gravel"},
        {pos: [13, 7, 11], state: "minecraft:gravel"},
        {pos: [13, 7, 12], state: "minecraft:gravel"},
        {pos: [13, 7, 13], state: "minecraft:gravel"},
        {pos: [13, 7, 14], state: "sullysmod:petrified_log{axis:x}"},
        {pos: [13, 7, 15], state: "minecraft:gravel"},
        {pos: [13, 7, 16], state: "minecraft:gravel"},
        {pos: [14, 7, 4], state: "minecraft:gravel"},
        {pos: [14, 7, 5], state: "minecraft:gravel"},
        {pos: [14, 7, 6], state: "minecraft:gravel"},
        {pos: [14, 7, 7], state: "minecraft:gravel"},
        {pos: [14, 7, 8], state: "minecraft:gravel"},
        {pos: [14, 7, 9], state: "minecraft:gravel"},
        {pos: [14, 7, 10], state: "sullysmod:stripped_petrified_log{axis:y}"},
        {pos: [14, 7, 11], state: "sullysmod:stripped_petrified_log{axis:y}"},
        {pos: [14, 7, 12], state: "minecraft:gravel"},
        {pos: [14, 7, 13], state: "sullysmod:petrified_log{axis:z}"},
        {pos: [14, 7, 14], state: "sullysmod:petrified_log{axis:x}"},
        {pos: [14, 7, 15], state: "sullysmod:petrified_log{axis:z}"},
        {pos: [15, 7, 6], state: "minecraft:gravel"},
        {pos: [15, 7, 7], state: "minecraft:gravel"},
        {pos: [15, 7, 8], state: "minecraft:gravel"},
        {pos: [15, 7, 9], state: "minecraft:gravel"},
        {pos: [15, 7, 10], state: "minecraft:gravel"},
        {pos: [15, 7, 11], state: "minecraft:gravel"},
        {pos: [15, 7, 12], state: "minecraft:gravel"},
        {pos: [15, 7, 13], state: "minecraft:gravel"},
        {pos: [15, 7, 14], state: "sullysmod:petrified_log{axis:x}"},
        {pos: [15, 7, 15], state: "minecraft:gravel"},
        {pos: [16, 7, 8], state: "minecraft:gravel"},
        {pos: [16, 7, 9], state: "minecraft:gravel"},
        {pos: [16, 7, 10], state: "minecraft:gravel"},
        {pos: [16, 7, 11], state: "minecraft:gravel"},
        {pos: [16, 7, 12], state: "minecraft:gravel"},
        {pos: [16, 7, 13], state: "minecraft:gravel"},
        {pos: [16, 7, 14], state: "sullysmod:stripped_petrified_log{axis:x}"},
        {pos: [17, 7, 11], state: "minecraft:gravel"},
        {pos: [17, 7, 12], state: "minecraft:gravel"},
        {pos: [0, 8, 6], state: "minecraft:gravel"},
        {pos: [0, 8, 7], state: "minecraft:gravel"},
        {pos: [0, 8, 8], state: "minecraft:gravel"},
        {pos: [0, 8, 9], state: "minecraft:gravel"},
        {pos: [0, 8, 10], state: "minecraft:gravel"},
        {pos: [0, 8, 11], state: "minecraft:gravel"},
        {pos: [0, 8, 12], state: "minecraft:gravel"},
        {pos: [1, 8, 6], state: "minecraft:gravel"},
        {pos: [1, 8, 7], state: "minecraft:gravel"},
        {pos: [1, 8, 8], state: "minecraft:gravel"},
        {pos: [1, 8, 9], state: "minecraft:gravel"},
        {pos: [1, 8, 10], state: "minecraft:gravel"},
        {pos: [1, 8, 11], state: "minecraft:gravel"},
        {pos: [1, 8, 12], state: "minecraft:gravel"},
        {pos: [1, 8, 13], state: "minecraft:gravel"},
        {pos: [1, 8, 14], state: "minecraft:gravel"},
        {pos: [2, 8, 6], state: "minecraft:gravel"},
        {pos: [2, 8, 7], state: "minecraft:gravel"},
        {pos: [2, 8, 8], state: "minecraft:gravel"},
        {pos: [2, 8, 9], state: "sullysmod:petrified_log{axis:y}"},
        {pos: [2, 8, 10], state: "minecraft:gravel"},
        {pos: [2, 8, 11], state: "minecraft:gravel"},
        {pos: [2, 8, 12], state: "minecraft:gravel"},
        {pos: [2, 8, 13], state: "minecraft:gravel"},
        {pos: [2, 8, 14], state: "minecraft:gravel"},
        {pos: [2, 8, 15], state: "minecraft:suspicious_gravel{dusted:0}", nbt: {id: "minecraft:brushable_block", item: {Count: 0b, id: "minecraft:air"}}},
        {pos: [2, 8, 16], state: "minecraft:gravel"},
        {pos: [3, 8, 5], state: "minecraft:gravel"},
        {pos: [3, 8, 6], state: "minecraft:gravel"},
        {pos: [3, 8, 7], state: "minecraft:gravel"},
        {pos: [3, 8, 8], state: "minecraft:gravel"},
        {pos: [3, 8, 9], state: "sullysmod:stripped_petrified_log{axis:y}"},
        {pos: [3, 8, 10], state: "minecraft:gravel"},
        {pos: [3, 8, 11], state: "minecraft:gravel"},
        {pos: [3, 8, 12], state: "minecraft:gravel"},
        {pos: [3, 8, 13], state: "sullysmod:petrified_log{axis:y}"},
        {pos: [3, 8, 14], state: "sullysmod:petrified_log{axis:y}"},
        {pos: [3, 8, 15], state: "minecraft:gravel"},
        {pos: [3, 8, 16], state: "minecraft:gravel"},
        {pos: [4, 8, 4], state: "minecraft:gravel"},
        {pos: [4, 8, 5], state: "minecraft:gravel"},
        {pos: [4, 8, 6], state: "minecraft:gravel"},
        {pos: [4, 8, 7], state: "minecraft:gravel"},
        {pos: [4, 8, 8], state: "minecraft:gravel"},
        {pos: [4, 8, 9], state: "minecraft:gravel"},
        {pos: [4, 8, 10], state: "minecraft:gravel"},
        {pos: [4, 8, 11], state: "sullysmod:petrified_log{axis:y}"},
        {pos: [4, 8, 12], state: "minecraft:gravel"},
        {pos: [4, 8, 13], state: "minecraft:gravel"},
        {pos: [4, 8, 14], state: "sullysmod:petrified_log{axis:y}"},
        {pos: [4, 8, 15], state: "minecraft:gravel"},
        {pos: [4, 8, 16], state: "minecraft:gravel"},
        {pos: [5, 8, 3], state: "minecraft:gravel"},
        {pos: [5, 8, 4], state: "minecraft:gravel"},
        {pos: [5, 8, 5], state: "minecraft:gravel"},
        {pos: [5, 8, 6], state: "minecraft:gravel"},
        {pos: [5, 8, 7], state: "minecraft:gravel"},
        {pos: [5, 8, 8], state: "minecraft:gravel"},
        {pos: [5, 8, 9], state: "minecraft:gravel"},
        {pos: [5, 8, 10], state: "sullysmod:petrified_log{axis:y}"},
        {pos: [5, 8, 11], state: "sullysmod:petrified_log{axis:y}"},
        {pos: [5, 8, 12], state: "minecraft:gravel"},
        {pos: [5, 8, 13], state: "minecraft:gravel"},
        {pos: [5, 8, 14], state: "minecraft:gravel"},
        {pos: [5, 8, 15], state: "minecraft:gravel"},
        {pos: [5, 8, 16], state: "minecraft:gravel"},
        {pos: [5, 8, 17], state: "minecraft:gravel"},
        {pos: [6, 8, 2], state: "minecraft:gravel"},
        {pos: [6, 8, 3], state: "minecraft:gravel"},
        {pos: [6, 8, 4], state: "minecraft:gravel"},
        {pos: [6, 8, 5], state: "sullysmod:petrified_log{axis:x}"},
        {pos: [6, 8, 6], state: "minecraft:gravel"},
        {pos: [6, 8, 7], state: "sullysmod:stripped_petrified_log{axis:y}"},
        {pos: [6, 8, 8], state: "minecraft:gravel"},
        {pos: [6, 8, 9], state: "sullysmod:petrified_log{axis:y}"},
        {pos: [6, 8, 10], state: "sullysmod:amber{is_melted:false}", nbt: {RenderEntity: 0b, StuckEntity: [], id: "sullysmod:amber"}},
        {pos: [6, 8, 11], state: "sullysmod:amber{is_melted:false}", nbt: {RenderEntity: 0b, StuckEntity: [], id: "sullysmod:amber"}},
        {pos: [6, 8, 12], state: "sullysmod:petrified_log{axis:y}"},
        {pos: [6, 8, 13], state: "sullysmod:petrified_log{axis:y}"},
        {pos: [6, 8, 14], state: "minecraft:gravel"},
        {pos: [6, 8, 15], state: "minecraft:gravel"},
        {pos: [6, 8, 16], state: "minecraft:gravel"},
        {pos: [6, 8, 17], state: "minecraft:gravel"},
        {pos: [7, 8, 2], state: "minecraft:gravel"},
        {pos: [7, 8, 3], state: "minecraft:gravel"},
        {pos: [7, 8, 4], state: "minecraft:gravel"},
        {pos: [7, 8, 5], state: "sullysmod:petrified_log{axis:y}"},
        {pos: [7, 8, 6], state: "minecraft:gravel"},
        {pos: [7, 8, 7], state: "minecraft:gravel"},
        {pos: [7, 8, 8], state: "sullysmod:petrified_log{axis:y}"},
        {pos: [7, 8, 9], state: "sullysmod:petrified_log{axis:y}"},
        {pos: [7, 8, 10], state: "sullysmod:amber{is_melted:false}", nbt: {RenderEntity: 0b, StuckEntity: [], id: "sullysmod:amber"}},
        {pos: [7, 8, 11], state: "minecraft:gravel"},
        {pos: [7, 8, 12], state: "sullysmod:petrified_log{axis:y}"},
        {pos: [7, 8, 13], state: "sullysmod:petrified_log{axis:y}"},
        {pos: [7, 8, 14], state: "sullysmod:petrified_log{axis:y}"},
        {pos: [7, 8, 15], state: "sullysmod:petrified_log{axis:y}"},
        {pos: [7, 8, 16], state: "sullysmod:petrified_log{axis:z}"},
        {pos: [7, 8, 17], state: "minecraft:gravel"},
        {pos: [8, 8, 1], state: "minecraft:gravel"},
        {pos: [8, 8, 2], state: "minecraft:gravel"},
        {pos: [8, 8, 3], state: "minecraft:gravel"},
        {pos: [8, 8, 4], state: "sullysmod:petrified_log{axis:y}"},
        {pos: [8, 8, 5], state: "minecraft:gravel"},
        {pos: [8, 8, 6], state: "minecraft:gravel"},
        {pos: [8, 8, 7], state: "sullysmod:petrified_log{axis:y}"},
        {pos: [8, 8, 8], state: "sullysmod:petrified_log{axis:y}"},
        {pos: [8, 8, 9], state: "sullysmod:amber{is_melted:false}", nbt: {RenderEntity: 0b, StuckEntity: [], id: "sullysmod:amber"}},
        {pos: [8, 8, 10], state: "sullysmod:amber{is_melted:false}", nbt: {RenderEntity: 0b, StuckEntity: [], id: "sullysmod:amber"}},
        {pos: [8, 8, 11], state: "sullysmod:rough_amber{is_melted:false}"},
        {pos: [8, 8, 12], state: "sullysmod:petrified_log{axis:y}"},
        {pos: [8, 8, 13], state: "minecraft:gravel"},
        {pos: [8, 8, 14], state: "sullysmod:amber{is_melted:false}", nbt: {RenderEntity: 0b, StuckEntity: [], id: "sullysmod:amber"}},
        {pos: [8, 8, 15], state: "sullysmod:stripped_petrified_log{axis:y}"},
        {pos: [8, 8, 16], state: "minecraft:gravel"},
        {pos: [8, 8, 17], state: "minecraft:gravel"},
        {pos: [9, 8, 1], state: "minecraft:gravel"},
        {pos: [9, 8, 2], state: "sullysmod:stripped_petrified_log{axis:z}"},
        {pos: [9, 8, 3], state: "sullysmod:petrified_log{axis:z}"},
        {pos: [9, 8, 4], state: "sullysmod:petrified_log{axis:y}"},
        {pos: [9, 8, 5], state: "minecraft:gravel"},
        {pos: [9, 8, 6], state: "sullysmod:petrified_log{axis:y}"},
        {pos: [9, 8, 7], state: "sullysmod:petrified_log{axis:y}"},
        {pos: [9, 8, 8], state: "sullysmod:amber{is_melted:false}", nbt: {RenderEntity: 0b, StuckEntity: [], id: "sullysmod:amber"}},
        {pos: [9, 8, 9], state: "sullysmod:amber{is_melted:false}", nbt: {RenderEntity: 0b, StuckEntity: [], id: "sullysmod:amber"}},
        {pos: [9, 8, 10], state: "minecraft:gravel"},
        {pos: [9, 8, 11], state: "minecraft:gravel"},
        {pos: [9, 8, 12], state: "sullysmod:amber{is_melted:false}", nbt: {RenderEntity: 0b, StuckEntity: [], id: "sullysmod:amber"}},
        {pos: [9, 8, 13], state: "sullysmod:amber{is_melted:false}", nbt: {RenderEntity: 0b, StuckEntity: [], id: "sullysmod:amber"}},
        {pos: [9, 8, 14], state: "sullysmod:amber{is_melted:false}", nbt: {RenderEntity: 0b, StuckEntity: [], id: "sullysmod:amber"}},
        {pos: [9, 8, 15], state: "minecraft:gravel"},
        {pos: [9, 8, 16], state: "minecraft:gravel"},
        {pos: [9, 8, 17], state: "minecraft:gravel"},
        {pos: [10, 8, 1], state: "minecraft:gravel"},
        {pos: [10, 8, 2], state: "minecraft:gravel"},
        {pos: [10, 8, 3], state: "sullysmod:petrified_log{axis:x}"},
        {pos: [10, 8, 4], state: "minecraft:gravel"},
        {pos: [10, 8, 5], state: "minecraft:gravel"},
        {pos: [10, 8, 6], state: "minecraft:gravel"},
        {pos: [10, 8, 7], state: "minecraft:gravel"},
        {pos: [10, 8, 8], state: "sullysmod:petrified_log{axis:y}"},
        {pos: [10, 8, 9], state: "sullysmod:rough_amber{is_melted:false}"},
        {pos: [10, 8, 10], state: "minecraft:gravel"},
        {pos: [10, 8, 11], state: "sullysmod:petrified_log{axis:y}"},
        {pos: [10, 8, 12], state: "sullysmod:amber{is_melted:false}", nbt: {RenderEntity: 0b, StuckEntity: [], id: "sullysmod:amber"}},
        {pos: [10, 8, 13], state: "sullysmod:amber{is_melted:false}", nbt: {RenderEntity: 0b, StuckEntity: [], id: "sullysmod:amber"}},
        {pos: [10, 8, 14], state: "minecraft:gravel"},
        {pos: [10, 8, 15], state: "minecraft:gravel"},
        {pos: [10, 8, 16], state: "minecraft:gravel"},
        {pos: [10, 8, 17], state: "sullysmod:petrified_log{axis:y}"},
        {pos: [11, 8, 1], state: "minecraft:gravel"},
        {pos: [11, 8, 2], state: "minecraft:gravel"},
        {pos: [11, 8, 3], state: "sullysmod:stripped_petrified_log{axis:x}"},
        {pos: [11, 8, 4], state: "minecraft:gravel"},
        {pos: [11, 8, 5], state: "minecraft:gravel"},
        {pos: [11, 8, 6], state: "minecraft:gravel"},
        {pos: [11, 8, 7], state: "sullysmod:stripped_petrified_log{axis:y}"},
        {pos: [11, 8, 8], state: "sullysmod:petrified_log{axis:y}"},
        {pos: [11, 8, 9], state: "sullysmod:petrified_log{axis:y}"},
        {pos: [11, 8, 10], state: "sullysmod:petrified_log{axis:y}"},
        {pos: [11, 8, 11], state: "minecraft:gravel"},
        {pos: [11, 8, 12], state: "sullysmod:petrified_log{axis:y}"},
        {pos: [11, 8, 13], state: "sullysmod:petrified_log{axis:y}"},
        {pos: [11, 8, 14], state: "minecraft:gravel"},
        {pos: [11, 8, 15], state: "minecraft:gravel"},
        {pos: [11, 8, 16], state: "minecraft:gravel"},
        {pos: [11, 8, 17], state: "minecraft:gravel"},
        {pos: [12, 8, 2], state: "minecraft:gravel"},
        {pos: [12, 8, 3], state: "minecraft:gravel"},
        {pos: [12, 8, 4], state: "minecraft:gravel"},
        {pos: [12, 8, 5], state: "minecraft:gravel"},
        {pos: [12, 8, 6], state: "minecraft:gravel"},
        {pos: [12, 8, 7], state: "sullysmod:petrified_log{axis:y}"},
        {pos: [12, 8, 8], state: "minecraft:gravel"},
        {pos: [12, 8, 9], state: "sullysmod:petrified_log{axis:y}"},
        {pos: [12, 8, 10], state: "sullysmod:petrified_log{axis:y}"},
        {pos: [12, 8, 11], state: "minecraft:gravel"},
        {pos: [12, 8, 12], state: "minecraft:gravel"},
        {pos: [12, 8, 13], state: "sullysmod:petrified_log{axis:x}"},
        {pos: [12, 8, 14], state: "minecraft:gravel"},
        {pos: [12, 8, 15], state: "minecraft:gravel"},
        {pos: [12, 8, 16], state: "minecraft:gravel"},
        {pos: [13, 8, 3], state: "minecraft:gravel"},
        {pos: [13, 8, 4], state: "minecraft:gravel"},
        {pos: [13, 8, 5], state: "minecraft:gravel"},
        {pos: [13, 8, 6], state: "minecraft:gravel"},
        {pos: [13, 8, 7], state: "minecraft:gravel"},
        {pos: [13, 8, 8], state: "minecraft:gravel"},
        {pos: [13, 8, 9], state: "minecraft:gravel"},
        {pos: [13, 8, 10], state: "sullysmod:petrified_log{axis:y}"},
        {pos: [13, 8, 11], state: "sullysmod:petrified_log{axis:y}"},
        {pos: [13, 8, 12], state: "minecraft:gravel"},
        {pos: [13, 8, 13], state: "minecraft:gravel"},
        {pos: [13, 8, 14], state: "minecraft:gravel"},
        {pos: [13, 8, 15], state: "minecraft:gravel"},
        {pos: [13, 8, 16], state: "minecraft:gravel"},
        {pos: [14, 8, 3], state: "minecraft:gravel"},
        {pos: [14, 8, 4], state: "minecraft:gravel"},
        {pos: [14, 8, 5], state: "minecraft:gravel"},
        {pos: [14, 8, 6], state: "minecraft:gravel"},
        {pos: [14, 8, 7], state: "minecraft:gravel"},
        {pos: [14, 8, 8], state: "minecraft:gravel"},
        {pos: [14, 8, 9], state: "minecraft:gravel"},
        {pos: [14, 8, 10], state: "minecraft:gravel"},
        {pos: [14, 8, 11], state: "sullysmod:stripped_petrified_log{axis:y}"},
        {pos: [14, 8, 12], state: "minecraft:gravel"},
        {pos: [14, 8, 13], state: "minecraft:gravel"},
        {pos: [14, 8, 14], state: "sullysmod:petrified_log{axis:y}"},
        {pos: [14, 8, 15], state: "minecraft:gravel"},
        {pos: [15, 8, 6], state: "minecraft:gravel"},
        {pos: [15, 8, 7], state: "minecraft:gravel"},
        {pos: [15, 8, 8], state: "minecraft:gravel"},
        {pos: [15, 8, 9], state: "minecraft:gravel"},
        {pos: [15, 8, 10], state: "minecraft:gravel"},
        {pos: [15, 8, 11], state: "minecraft:gravel"},
        {pos: [15, 8, 12], state: "minecraft:gravel"},
        {pos: [15, 8, 13], state: "minecraft:gravel"},
        {pos: [15, 8, 14], state: "minecraft:gravel"},
        {pos: [15, 8, 15], state: "minecraft:gravel"},
        {pos: [16, 8, 8], state: "minecraft:gravel"},
        {pos: [16, 8, 9], state: "minecraft:gravel"},
        {pos: [16, 8, 10], state: "minecraft:gravel"},
        {pos: [16, 8, 11], state: "minecraft:gravel"},
        {pos: [16, 8, 12], state: "minecraft:gravel"},
        {pos: [16, 8, 13], state: "minecraft:gravel"},
        {pos: [16, 8, 14], state: "minecraft:gravel"},
        {pos: [17, 8, 10], state: "minecraft:gravel"},
        {pos: [17, 8, 11], state: "minecraft:gravel"},
        {pos: [17, 8, 12], state: "minecraft:gravel"},
        {pos: [0, 9, 9], state: "minecraft:gravel"},
        {pos: [0, 9, 10], state: "minecraft:gravel"},
        {pos: [1, 9, 7], state: "minecraft:gravel"},
        {pos: [1, 9, 8], state: "minecraft:gravel"},
        {pos: [1, 9, 9], state: "minecraft:gravel"},
        {pos: [1, 9, 10], state: "minecraft:gravel"},
        {pos: [1, 9, 11], state: "minecraft:gravel"},
        {pos: [2, 9, 7], state: "minecraft:gravel"},
        {pos: [2, 9, 8], state: "minecraft:gravel"},
        {pos: [2, 9, 9], state: "sullysmod:petrified_log{axis:y}"},
        {pos: [2, 9, 10], state: "minecraft:gravel"},
        {pos: [2, 9, 11], state: "minecraft:gravel"},
        {pos: [2, 9, 12], state: "minecraft:gravel"},
        {pos: [2, 9, 13], state: "minecraft:gravel"},
        {pos: [3, 9, 6], state: "minecraft:gravel"},
        {pos: [3, 9, 7], state: "minecraft:gravel"},
        {pos: [3, 9, 8], state: "minecraft:gravel"},
        {pos: [3, 9, 9], state: "sullysmod:petrified_log{axis:y}"},
        {pos: [3, 9, 10], state: "sullysmod:petrified_log{axis:y}"},
        {pos: [3, 9, 11], state: "minecraft:gravel"},
        {pos: [3, 9, 12], state: "minecraft:gravel"},
        {pos: [3, 9, 13], state: "minecraft:gravel"},
        {pos: [3, 9, 14], state: "minecraft:gravel"},
        {pos: [3, 9, 15], state: "minecraft:gravel"},
        {pos: [4, 9, 6], state: "minecraft:gravel"},
        {pos: [4, 9, 7], state: "minecraft:gravel"},
        {pos: [4, 9, 8], state: "sullysmod:petrified_log{axis:y}"},
        {pos: [4, 9, 9], state: "sullysmod:petrified_log{axis:y}"},
        {pos: [4, 9, 10], state: "minecraft:gravel"},
        {pos: [4, 9, 11], state: "minecraft:gravel"},
        {pos: [4, 9, 12], state: "minecraft:gravel"},
        {pos: [4, 9, 13], state: "sullysmod:petrified_log{axis:y}"},
        {pos: [4, 9, 14], state: "sullysmod:petrified_log{axis:y}"},
        {pos: [4, 9, 15], state: "minecraft:gravel"},
        {pos: [4, 9, 16], state: "minecraft:gravel"},
        {pos: [5, 9, 4], state: "minecraft:gravel"},
        {pos: [5, 9, 5], state: "minecraft:gravel"},
        {pos: [5, 9, 6], state: "minecraft:gravel"},
        {pos: [5, 9, 7], state: "minecraft:gravel"},
        {pos: [5, 9, 8], state: "minecraft:gravel"},
        {pos: [5, 9, 9], state: "minecraft:gravel"},
        {pos: [5, 9, 10], state: "sullysmod:petrified_log{axis:y}"},
        {pos: [5, 9, 11], state: "sullysmod:petrified_log{axis:y}"},
        {pos: [5, 9, 12], state: "minecraft:gravel"},
        {pos: [5, 9, 13], state: "sullysmod:petrified_log{axis:y}"},
        {pos: [5, 9, 14], state: "sullysmod:stripped_petrified_log{axis:y}"},
        {pos: [5, 9, 15], state: "minecraft:gravel"},
        {pos: [6, 9, 3], state: "minecraft:gravel"},
        {pos: [6, 9, 4], state: "minecraft:gravel"},
        {pos: [6, 9, 5], state: "minecraft:gravel"},
        {pos: [6, 9, 6], state: "minecraft:gravel"},
        {pos: [6, 9, 7], state: "sullysmod:petrified_log{axis:y}"},
        {pos: [6, 9, 8], state: "minecraft:gravel"},
        {pos: [6, 9, 9], state: "sullysmod:petrified_log{axis:y}"},
        {pos: [6, 9, 10], state: "sullysmod:amber{is_melted:false}", nbt: {RenderEntity: 0b, StuckEntity: [], id: "sullysmod:amber"}},
        {pos: [6, 9, 11], state: "sullysmod:rough_amber{is_melted:false}"},
        {pos: [6, 9, 12], state: "sullysmod:petrified_log{axis:y}"},
        {pos: [6, 9, 13], state: "sullysmod:petrified_log{axis:y}"},
        {pos: [6, 9, 14], state: "minecraft:gravel"},
        {pos: [6, 9, 15], state: "minecraft:gravel"},
        {pos: [6, 9, 16], state: "minecraft:gravel"},
        {pos: [7, 9, 3], state: "minecraft:gravel"},
        {pos: [7, 9, 4], state: "minecraft:gravel"},
        {pos: [7, 9, 5], state: "sullysmod:petrified_log{axis:y}"},
        {pos: [7, 9, 6], state: "sullysmod:petrified_log{axis:y}"},
        {pos: [7, 9, 7], state: "sullysmod:petrified_log{axis:y}"},
        {pos: [7, 9, 8], state: "sullysmod:petrified_log{axis:y}"},
        {pos: [7, 9, 9], state: "sullysmod:petrified_log{axis:y}"},
        {pos: [7, 9, 10], state: "sullysmod:rough_amber{is_melted:false}"},
        {pos: [7, 9, 11], state: "sullysmod:amber{is_melted:false}", nbt: {RenderEntity: 0b, StuckEntity: [], id: "sullysmod:amber"}},
        {pos: [7, 9, 12], state: "sullysmod:petrified_log{axis:y}"},
        {pos: [7, 9, 13], state: "sullysmod:petrified_log{axis:y}"},
        {pos: [7, 9, 14], state: "sullysmod:petrified_log{axis:y}"},
        {pos: [7, 9, 15], state: "minecraft:gravel"},
        {pos: [7, 9, 16], state: "minecraft:gravel"},
        {pos: [8, 9, 2], state: "minecraft:gravel"},
        {pos: [8, 9, 3], state: "minecraft:gravel"},
        {pos: [8, 9, 4], state: "minecraft:gravel"},
        {pos: [8, 9, 5], state: "sullysmod:petrified_log{axis:y}"},
        {pos: [8, 9, 6], state: "minecraft:gravel"},
        {pos: [8, 9, 7], state: "sullysmod:petrified_log{axis:y}"},
        {pos: [8, 9, 8], state: "sullysmod:rough_amber{is_melted:false}"},
        {pos: [8, 9, 9], state: "sullysmod:amber{is_melted:false}", nbt: {RenderEntity: 0b, StuckEntity: [], id: "sullysmod:amber"}},
        {pos: [8, 9, 10], state: "sullysmod:rough_amber{is_melted:false}"},
        {pos: [8, 9, 11], state: "sullysmod:rough_amber{is_melted:false}"},
        {pos: [8, 9, 12], state: "sullysmod:petrified_log{axis:y}"},
        {pos: [8, 9, 13], state: "sullysmod:petrified_log{axis:y}"},
        {pos: [8, 9, 14], state: "sullysmod:petrified_log{axis:y}"},
        {pos: [8, 9, 15], state: "sullysmod:petrified_log{axis:y}"},
        {pos: [8, 9, 16], state: "minecraft:gravel"},
        {pos: [8, 9, 17], state: "minecraft:gravel"},
        {pos: [9, 9, 2], state: "minecraft:gravel"},
        {pos: [9, 9, 3], state: "minecraft:gravel"},
        {pos: [9, 9, 4], state: "sullysmod:petrified_log{axis:y}"},
        {pos: [9, 9, 5], state: "sullysmod:petrified_log{axis:y}"},
        {pos: [9, 9, 6], state: "sullysmod:petrified_log{axis:y}"},
        {pos: [9, 9, 7], state: "sullysmod:petrified_log{axis:y}"},
        {pos: [9, 9, 8], state: "sullysmod:rough_amber{is_melted:false}"},
        {pos: [9, 9, 9], state: "sullysmod:petrified_log{axis:y}"},
        {pos: [9, 9, 10], state: "sullysmod:amber{is_melted:false}", nbt: {RenderEntity: 0b, StuckEntity: [], id: "sullysmod:amber"}},
        {pos: [9, 9, 11], state: "minecraft:gravel"},
        {pos: [9, 9, 12], state: "sullysmod:amber{is_melted:false}", nbt: {RenderEntity: 0b, StuckEntity: [], id: "sullysmod:amber"}},
        {pos: [9, 9, 13], state: "sullysmod:amber{is_melted:false}", nbt: {RenderEntity: 0b, StuckEntity: [], id: "sullysmod:amber"}},
        {pos: [9, 9, 14], state: "minecraft:gravel"},
        {pos: [9, 9, 15], state: "minecraft:gravel"},
        {pos: [9, 9, 16], state: "minecraft:gravel"},
        {pos: [9, 9, 17], state: "minecraft:gravel"},
        {pos: [10, 9, 2], state: "minecraft:gravel"},
        {pos: [10, 9, 3], state: "minecraft:gravel"},
        {pos: [10, 9, 4], state: "minecraft:gravel"},
        {pos: [10, 9, 5], state: "minecraft:gravel"},
        {pos: [10, 9, 6], state: "minecraft:gravel"},
        {pos: [10, 9, 7], state: "sullysmod:petrified_log{axis:y}"},
        {pos: [10, 9, 8], state: "sullysmod:petrified_log{axis:y}"},
        {pos: [10, 9, 9], state: "sullysmod:rough_amber{is_melted:false}"},
        {pos: [10, 9, 10], state: "sullysmod:petrified_log{axis:y}"},
        {pos: [10, 9, 11], state: "sullysmod:petrified_log{axis:y}"},
        {pos: [10, 9, 12], state: "sullysmod:amber{is_melted:false}", nbt: {RenderEntity: 0b, StuckEntity: [], id: "sullysmod:amber"}},
        {pos: [10, 9, 13], state: "sullysmod:amber{is_melted:false}", nbt: {RenderEntity: 0b, StuckEntity: [], id: "sullysmod:amber"}},
        {pos: [10, 9, 14], state: "minecraft:gravel"},
        {pos: [10, 9, 15], state: "minecraft:gravel"},
        {pos: [10, 9, 16], state: "minecraft:gravel"},
        {pos: [11, 9, 3], state: "minecraft:gravel"},
        {pos: [11, 9, 4], state: "minecraft:gravel"},
        {pos: [11, 9, 5], state: "minecraft:gravel"},
        {pos: [11, 9, 6], state: "minecraft:gravel"},
        {pos: [11, 9, 7], state: "sullysmod:petrified_log{axis:y}"},
        {pos: [11, 9, 8], state: "sullysmod:petrified_log{axis:y}"},
        {pos: [11, 9, 9], state: "sullysmod:petrified_log{axis:y}"},
        {pos: [11, 9, 10], state: "sullysmod:petrified_log{axis:y}"},
        {pos: [11, 9, 11], state: "sullysmod:petrified_log{axis:y}"},
        {pos: [11, 9, 12], state: "sullysmod:petrified_log{axis:y}"},
        {pos: [11, 9, 13], state: "sullysmod:petrified_log{axis:y}"},
        {pos: [11, 9, 14], state: "minecraft:gravel"},
        {pos: [11, 9, 15], state: "minecraft:gravel"},
        {pos: [12, 9, 3], state: "minecraft:gravel"},
        {pos: [12, 9, 4], state: "minecraft:gravel"},
        {pos: [12, 9, 5], state: "minecraft:gravel"},
        {pos: [12, 9, 6], state: "minecraft:gravel"},
        {pos: [12, 9, 7], state: "minecraft:gravel"},
        {pos: [12, 9, 8], state: "minecraft:gravel"},
        {pos: [12, 9, 9], state: "sullysmod:petrified_log{axis:y}"},
        {pos: [12, 9, 10], state: "sullysmod:petrified_log{axis:y}"},
        {pos: [12, 9, 11], state: "minecraft:gravel"},
        {pos: [12, 9, 12], state: "minecraft:gravel"},
        {pos: [12, 9, 13], state: "minecraft:gravel"},
        {pos: [12, 9, 14], state: "minecraft:gravel"},
        {pos: [12, 9, 15], state: "minecraft:gravel"},
        {pos: [13, 9, 4], state: "minecraft:gravel"},
        {pos: [13, 9, 5], state: "minecraft:gravel"},
        {pos: [13, 9, 6], state: "minecraft:gravel"},
        {pos: [13, 9, 7], state: "minecraft:gravel"},
        {pos: [13, 9, 8], state: "minecraft:gravel"},
        {pos: [13, 9, 9], state: "minecraft:gravel"},
        {pos: [13, 9, 10], state: "sullysmod:petrified_log{axis:y}"},
        {pos: [13, 9, 11], state: "sullysmod:petrified_log{axis:y}"},
        {pos: [13, 9, 12], state: "minecraft:gravel"},
        {pos: [13, 9, 13], state: "minecraft:gravel"},
        {pos: [13, 9, 14], state: "minecraft:gravel"},
        {pos: [14, 9, 6], state: "minecraft:gravel"},
        {pos: [14, 9, 8], state: "minecraft:gravel"},
        {pos: [14, 9, 9], state: "minecraft:gravel"},
        {pos: [14, 9, 10], state: "minecraft:gravel"},
        {pos: [14, 9, 11], state: "minecraft:gravel"},
        {pos: [14, 9, 12], state: "minecraft:gravel"},
        {pos: [14, 9, 14], state: "sullysmod:petrified_log{axis:y}"},
        {pos: [15, 9, 9], state: "minecraft:gravel"},
        {pos: [15, 9, 10], state: "minecraft:gravel"},
        {pos: [15, 9, 11], state: "minecraft:gravel"},
        {pos: [15, 9, 13], state: "minecraft:gravel"},
        {pos: [16, 9, 10], state: "minecraft:gravel"},
        {pos: [16, 9, 11], state: "minecraft:gravel"},
        {pos: [2, 10, 7], state: "sullysmod:petrified_sapling{stage:0}"},
        {pos: [2, 10, 11], state: "minecraft:gravel"},
        {pos: [2, 10, 13], state: "sullysmod:petrified_sapling{stage:0}"},
        {pos: [3, 10, 9], state: "sullysmod:petrified_log{axis:y}"},
        {pos: [3, 10, 10], state: "sullysmod:petrified_log{axis:y}"},
        {pos: [3, 10, 11], state: "minecraft:gravel"},
        {pos: [3, 10, 12], state: "minecraft:gravel"},
        {pos: [4, 10, 7], state: "minecraft:gravel"},
        {pos: [4, 10, 8], state: "sullysmod:petrified_log{axis:y}"},
        {pos: [4, 10, 9], state: "sullysmod:petrified_log{axis:y}"},
        {pos: [4, 10, 10], state: "sullysmod:petrified_log{axis:y}"},
        {pos: [4, 10, 11], state: "minecraft:gravel"},
        {pos: [4, 10, 12], state: "minecraft:gravel"},
        {pos: [4, 10, 13], state: "sullysmod:petrified_log{axis:y}"},
        {pos: [4, 10, 14], state: "minecraft:gravel"},
        {pos: [5, 10, 6], state: "minecraft:gravel"},
        {pos: [5, 10, 7], state: "sullysmod:stripped_petrified_log{axis:y}"},
        {pos: [5, 10, 8], state: "sullysmod:petrified_log{axis:y}"},
        {pos: [5, 10, 9], state: "sullysmod:petrified_log{axis:y}"},
        {pos: [5, 10, 10], state: "sullysmod:petrified_log{axis:y}"},
        {pos: [5, 10, 11], state: "sullysmod:petrified_log{axis:y}"},
        {pos: [5, 10, 12], state: "sullysmod:petrified_log{axis:y}"},
        {pos: [5, 10, 13], state: "sullysmod:petrified_log{axis:y}"},
        {pos: [5, 10, 14], state: "sullysmod:petrified_log{axis:y}"},
        {pos: [6, 10, 5], state: "minecraft:gravel"},
        {pos: [6, 10, 6], state: "minecraft:gravel"},
        {pos: [6, 10, 7], state: "sullysmod:petrified_log{axis:y}"},
        {pos: [6, 10, 8], state: "sullysmod:stripped_petrified_log{axis:y}"},
        {pos: [6, 10, 9], state: "sullysmod:stripped_petrified_log{axis:y}"},
        {pos: [6, 10, 10], state: "sullysmod:stripped_petrified_log{axis:y}"},
        {pos: [6, 10, 11], state: "sullysmod:stripped_petrified_log{axis:y}"},
        {pos: [6, 10, 12], state: "sullysmod:stripped_petrified_log{axis:y}"},
        {pos: [6, 10, 13], state: "sullysmod:petrified_log{axis:y}"},
        {pos: [6, 10, 14], state: "minecraft:gravel"},
        {pos: [7, 10, 5], state: "minecraft:gravel"},
        {pos: [7, 10, 6], state: "sullysmod:petrified_log{axis:y}"},
        {pos: [7, 10, 7], state: "sullysmod:petrified_log{axis:y}"},
        {pos: [7, 10, 8], state: "sullysmod:stripped_petrified_log{axis:y}"},
        {pos: [7, 10, 9], state: "sullysmod:stripped_petrified_log{axis:y}"},
        {pos: [7, 10, 10], state: "sullysmod:stripped_petrified_log{axis:y}"},
        {pos: [7, 10, 11], state: "sullysmod:stripped_petrified_log{axis:y}"},
        {pos: [7, 10, 12], state: "sullysmod:stripped_petrified_log{axis:y}"},
        {pos: [7, 10, 13], state: "sullysmod:petrified_log{axis:y}"},
        {pos: [7, 10, 14], state: "sullysmod:petrified_log{axis:y}"},
        {pos: [7, 10, 15], state: "minecraft:gravel"},
        {pos: [8, 10, 4], state: "minecraft:gravel"},
        {pos: [8, 10, 5], state: "sullysmod:petrified_log{axis:y}"},
        {pos: [8, 10, 6], state: "sullysmod:petrified_log{axis:y}"},
        {pos: [8, 10, 7], state: "sullysmod:petrified_log{axis:y}"},
        {pos: [8, 10, 8], state: "sullysmod:rough_amber{is_melted:false}"},
        {pos: [8, 10, 9], state: "sullysmod:rough_amber{is_melted:false}"},
        {pos: [8, 10, 10], state: "sullysmod:stripped_petrified_log{axis:y}"},
        {pos: [8, 10, 11], state: "sullysmod:rough_amber{is_melted:false}"},
        {pos: [8, 10, 12], state: "sullysmod:stripped_petrified_log{axis:y}"},
        {pos: [8, 10, 13], state: "sullysmod:petrified_log{axis:y}"},
        {pos: [8, 10, 14], state: "sullysmod:petrified_log{axis:y}"},
        {pos: [8, 10, 15], state: "sullysmod:petrified_log{axis:y}"},
        {pos: [9, 10, 5], state: "sullysmod:petrified_log{axis:y}"},
        {pos: [9, 10, 6], state: "sullysmod:petrified_log{axis:y}"},
        {pos: [9, 10, 7], state: "sullysmod:petrified_log{axis:y}"},
        {pos: [9, 10, 8], state: "sullysmod:rough_amber{is_melted:false}"},
        {pos: [9, 10, 9], state: "sullysmod:rough_amber{is_melted:false}"},
        {pos: [9, 10, 10], state: "sullysmod:rough_amber{is_melted:false}"},
        {pos: [9, 10, 11], state: "sullysmod:rough_amber{is_melted:false}"},
        {pos: [9, 10, 12], state: "sullysmod:amber{is_melted:false}", nbt: {RenderEntity: 0b, StuckEntity: [], id: "sullysmod:amber"}},
        {pos: [9, 10, 14], state: "minecraft:gravel"},
        {pos: [10, 10, 6], state: "minecraft:gravel"},
        {pos: [10, 10, 7], state: "sullysmod:petrified_log{axis:y}"},
        {pos: [10, 10, 8], state: "sullysmod:rough_amber{is_melted:false}"},
        {pos: [10, 10, 9], state: "sullysmod:rough_amber{is_melted:false}"},
        {pos: [10, 10, 10], state: "sullysmod:stripped_petrified_log{axis:y}"},
        {pos: [10, 10, 11], state: "sullysmod:stripped_petrified_log{axis:y}"},
        {pos: [10, 10, 12], state: "sullysmod:rough_amber{is_melted:false}"},
        {pos: [11, 10, 4], state: "sullysmod:petrified_sapling{stage:0}"},
        {pos: [11, 10, 7], state: "sullysmod:petrified_log{axis:y}"},
        {pos: [11, 10, 8], state: "sullysmod:petrified_log{axis:y}"},
        {pos: [11, 10, 9], state: "sullysmod:petrified_log{axis:y}"},
        {pos: [11, 10, 10], state: "sullysmod:petrified_log{axis:y}"},
        {pos: [11, 10, 11], state: "sullysmod:petrified_log{axis:y}"},
        {pos: [11, 10, 12], state: "sullysmod:petrified_log{axis:y}"},
        {pos: [11, 10, 15], state: "sullysmod:petrified_sapling{stage:0}"},
        {pos: [12, 10, 7], state: "minecraft:gravel"},
        {pos: [12, 10, 8], state: "minecraft:gravel"},
        {pos: [12, 10, 9], state: "sullysmod:petrified_log{axis:y}"},
        {pos: [12, 10, 10], state: "sullysmod:petrified_log{axis:y}"},
        {pos: [12, 10, 11], state: "sullysmod:petrified_log{axis:y}"},
        {pos: [12, 10, 12], state: "sullysmod:petrified_log{axis:y}"},
        {pos: [12, 10, 13], state: "minecraft:suspicious_gravel{dusted:0}", nbt: {id: "minecraft:brushable_block", item: {Count: 0b, id: "minecraft:air"}}},
        {pos: [13, 10, 9], state: "minecraft:gravel"},
        {pos: [13, 10, 10], state: "sullysmod:petrified_log{axis:y}"},
        {pos: [13, 10, 11], state: "sullysmod:petrified_log{axis:y}"},
        {pos: [14, 10, 10], state: "sullysmod:petrified_sapling{stage:0}"},
        {pos: [14, 10, 11], state: "minecraft:gravel"},
        {pos: [14, 10, 14], state: "sullysmod:petrified_log{axis:y}"},
        {pos: [3, 11, 9], state: "sullysmod:petrified_log{axis:y}"},
        {pos: [3, 11, 10], state: "minecraft:gravel"},
        {pos: [4, 11, 7], state: "minecraft:gravel"},
        {pos: [4, 11, 8], state: "sullysmod:petrified_log{axis:y}"},
        {pos: [4, 11, 9], state: "sullysmod:petrified_log{axis:y}"},
        {pos: [4, 11, 10], state: "sullysmod:petrified_log{axis:y}"},
        {pos: [4, 11, 11], state: "minecraft:suspicious_gravel{dusted:0}", nbt: {id: "minecraft:brushable_block", item: {Count: 0b, id: "minecraft:air"}}},
        {pos: [4, 11, 12], state: "sullysmod:petrified_log{axis:y}"},
        {pos: [4, 11, 13], state: "minecraft:gravel"},
        {pos: [5, 11, 7], state: "sullysmod:petrified_log{axis:y}"},
        {pos: [5, 11, 8], state: "sullysmod:petrified_log{axis:y}"},
        {pos: [5, 11, 9], state: "sullysmod:petrified_log{axis:y}"},
        {pos: [5, 11, 10], state: "sullysmod:petrified_log{axis:y}"},
        {pos: [5, 11, 11], state: "sullysmod:petrified_log{axis:y}"},
        {pos: [5, 11, 12], state: "sullysmod:petrified_log{axis:y}"},
        {pos: [5, 11, 13], state: "sullysmod:petrified_log{axis:y}"},
        {pos: [5, 11, 14], state: "sullysmod:petrified_log{axis:y}"},
        {pos: [6, 11, 6], state: "sullysmod:petrified_log{axis:y}"},
        {pos: [6, 11, 7], state: "sullysmod:petrified_log{axis:y}"},
        {pos: [6, 11, 8], state: "sullysmod:stripped_petrified_log{axis:y}"},
        {pos: [6, 11, 9], state: "sullysmod:stripped_petrified_log{axis:y}"},
        {pos: [6, 11, 10], state: "sullysmod:stripped_petrified_log{axis:y}"},
        {pos: [6, 11, 11], state: "sullysmod:stripped_petrified_log{axis:y}"},
        {pos: [6, 11, 12], state: "sullysmod:stripped_petrified_log{axis:y}"},
        {pos: [6, 11, 13], state: "sullysmod:petrified_log{axis:y}"},
        {pos: [7, 11, 5], state: "minecraft:gravel"},
        {pos: [7, 11, 6], state: "sullysmod:petrified_log{axis:y}"},
        {pos: [7, 11, 7], state: "sullysmod:petrified_log{axis:y}"},
        {pos: [7, 11, 8], state: "sullysmod:stripped_petrified_log{axis:y}"},
        {pos: [7, 11, 9], state: "sullysmod:stripped_petrified_log{axis:y}"},
        {pos: [7, 11, 10], state: "sullysmod:stripped_petrified_log{axis:y}"},
        {pos: [7, 11, 11], state: "sullysmod:stripped_petrified_log{axis:y}"},
        {pos: [7, 11, 12], state: "sullysmod:stripped_petrified_log{axis:y}"},
        {pos: [7, 11, 13], state: "sullysmod:petrified_log{axis:y}"},
        {pos: [7, 11, 14], state: "sullysmod:petrified_log{axis:y}"},
        {pos: [8, 11, 5], state: "sullysmod:petrified_log{axis:y}"},
        {pos: [8, 11, 6], state: "sullysmod:petrified_log{axis:y}"},
        {pos: [8, 11, 7], state: "sullysmod:petrified_log{axis:y}"},
        {pos: [8, 11, 8], state: "sullysmod:stripped_petrified_log{axis:y}"},
        {pos: [8, 11, 9], state: "sullysmod:rough_amber{is_melted:false}"},
        {pos: [8, 11, 10], state: "sullysmod:stripped_petrified_log{axis:y}"},
        {pos: [8, 11, 11], state: "sullysmod:stripped_petrified_log{axis:y}"},
        {pos: [8, 11, 12], state: "sullysmod:stripped_petrified_log{axis:y}"},
        {pos: [8, 11, 13], state: "sullysmod:petrified_log{axis:y}"},
        {pos: [8, 11, 14], state: "sullysmod:petrified_log{axis:y}"},
        {pos: [8, 11, 15], state: "sullysmod:stripped_petrified_log{axis:y}"},
        {pos: [9, 11, 6], state: "sullysmod:petrified_log{axis:y}"},
        {pos: [9, 11, 7], state: "sullysmod:petrified_log{axis:y}"},
        {pos: [9, 11, 8], state: "sullysmod:stripped_petrified_log{axis:y}"},
        {pos: [9, 11, 9], state: "sullysmod:rough_amber{is_melted:false}"},
        {pos: [9, 11, 10], state: "sullysmod:rough_amber{is_melted:false}"},
        {pos: [9, 11, 11], state: "sullysmod:stripped_petrified_log{axis:y}"},
        {pos: [9, 11, 12], state: "sullysmod:stripped_petrified_log{axis:y}"},
        {pos: [9, 11, 13], state: "sullysmod:petrified_log{axis:y}"},
        {pos: [9, 11, 14], state: "sullysmod:petrified_log{axis:y}"},
        {pos: [10, 11, 6], state: "sullysmod:petrified_log{axis:y}"},
        {pos: [10, 11, 7], state: "sullysmod:petrified_log{axis:y}"},
        {pos: [10, 11, 8], state: "sullysmod:rough_amber{is_melted:false}"},
        {pos: [10, 11, 9], state: "sullysmod:rough_amber{is_melted:false}"},
        {pos: [10, 11, 10], state: "sullysmod:stripped_petrified_log{axis:y}"},
        {pos: [10, 11, 11], state: "sullysmod:stripped_petrified_log{axis:y}"},
        {pos: [10, 11, 12], state: "sullysmod:stripped_petrified_log{axis:y}"},
        {pos: [11, 11, 7], state: "sullysmod:petrified_log{axis:y}"},
        {pos: [11, 11, 8], state: "sullysmod:petrified_log{axis:y}"},
        {pos: [11, 11, 9], state: "sullysmod:petrified_log{axis:y}"},
        {pos: [11, 11, 10], state: "sullysmod:petrified_log{axis:y}"},
        {pos: [11, 11, 11], state: "sullysmod:petrified_log{axis:y}"},
        {pos: [11, 11, 12], state: "sullysmod:petrified_log{axis:y}"},
        {pos: [12, 11, 8], state: "minecraft:gravel"},
        {pos: [12, 11, 9], state: "sullysmod:petrified_log{axis:y}"},
        {pos: [12, 11, 10], state: "sullysmod:petrified_log{axis:y}"},
        {pos: [12, 11, 11], state: "sullysmod:petrified_log{axis:y}"},
        {pos: [12, 11, 12], state: "sullysmod:petrified_log{axis:y}"},
        {pos: [13, 11, 10], state: "sullysmod:petrified_log{axis:y}"},
        {pos: [13, 11, 11], state: "minecraft:gravel"},
        {pos: [14, 11, 14], state: "sullysmod:petrified_log{axis:y}"},
        {pos: [3, 12, 9], state: "minecraft:gravel"},
        {pos: [4, 12, 8], state: "sullysmod:petrified_log{axis:y}"},
        {pos: [4, 12, 9], state: "sullysmod:petrified_log{axis:y}"},
        {pos: [4, 12, 10], state: "sullysmod:petrified_log{axis:y}"},
        {pos: [4, 12, 11], state: "sullysmod:petrified_log{axis:y}"},
        {pos: [4, 12, 12], state: "sullysmod:petrified_log{axis:y}"},
        {pos: [5, 12, 7], state: "sullysmod:petrified_log{axis:y}"},
        {pos: [5, 12, 8], state: "sullysmod:petrified_log{axis:y}"},
        {pos: [5, 12, 9], state: "sullysmod:petrified_log{axis:y}"},
        {pos: [5, 12, 10], state: "sullysmod:petrified_log{axis:y}"},
        {pos: [5, 12, 11], state: "sullysmod:petrified_log{axis:y}"},
        {pos: [5, 12, 12], state: "sullysmod:petrified_log{axis:y}"},
        {pos: [5, 12, 13], state: "sullysmod:petrified_log{axis:y}"},
        {pos: [6, 12, 6], state: "sullysmod:petrified_log{axis:y}"},
        {pos: [6, 12, 7], state: "sullysmod:petrified_log{axis:y}"},
        {pos: [6, 12, 8], state: "sullysmod:stripped_petrified_log{axis:y}"},
        {pos: [6, 12, 9], state: "sullysmod:stripped_petrified_log{axis:y}"},
        {pos: [6, 12, 10], state: "sullysmod:stripped_petrified_log{axis:y}"},
        {pos: [6, 12, 11], state: "sullysmod:stripped_petrified_log{axis:y}"},
        {pos: [6, 12, 12], state: "sullysmod:stripped_petrified_log{axis:y}"},
