{
    DataVersion: 3465,
    size: [7, 6, 5],
    data: [
        {pos: [4, 0, 3], state: "minecraft:gravel"},
        {pos: [5, 0, 2], state: "minecraft:gravel"},
        {pos: [5, 0, 3], state: "minecraft:gravel"},
        {pos: [1, 1, 1], state: "minecraft:gravel"},
        {pos: [1, 1, 2], state: "minecraft:gravel"},
        {pos: [2, 1, 1], state: "minecraft:gravel"},
        {pos: [2, 1, 2], state: "minecraft:gravel"},
        {pos: [2, 1, 3], state: "minecraft:gravel"},
        {pos: [3, 1, 0], state: "minecraft:gravel"},
        {pos: [3, 1, 1], state: "minecraft:gravel"},
        {pos: [3, 1, 2], state: "minecraft:gravel"},
        {pos: [3, 1, 3], state: "minecraft:gravel"},
        {pos: [3, 1, 4], state: "minecraft:gravel"},
        {pos: [4, 1, 0], state: "minecraft:gravel"},
        {pos: [4, 1, 1], state: "minecraft:gravel"},
        {pos: [4, 1, 2], state: "minecraft:gravel"},
        {pos: [4, 1, 3], state: "minecraft:gravel"},
        {pos: [5, 1, 2], state: "sullysmod:petrified_log{axis:y}"},
        {pos: [5, 1, 3], state: "minecraft:gravel"},
        {pos: [6, 1, 3], state: "minecraft:gravel"},
        {pos: [0, 2, 1], state: "minecraft:gravel"},
        {pos: [0, 2, 2], state: "minecraft:gravel"},
        {pos: [1, 2, 1], state: "minecraft:gravel"},
        {pos: [1, 2, 2], state: "minecraft:gravel"},
        {pos: [1, 2, 3], state: "minecraft:gravel"},
        {pos: [1, 2, 4], state: "minecraft:gravel"},
        {pos: [2, 2, 0], state: "minecraft:gravel"},
        {pos: [2, 2, 1], state: "minecraft:gravel"},
        {pos: [2, 2, 2], state: "minecraft:gravel"},
        {pos: [2, 2, 3], state: "sullysmod:petrified_log{axis:y}"},
        {pos: [2, 2, 4], state: "minecraft:gravel"},
        {pos: [3, 2, 0], state: "minecraft:gravel"},
        {pos: [3, 2, 1], state: "minecraft:gravel"},
        {pos: [3, 2, 3], state: "minecraft:gravel"},
        {pos: [3, 2, 4], state: "minecraft:gravel"},
        {pos: [4, 2, 0], state: "minecraft:gravel"},
        {pos: [4, 2, 1], state: "minecraft:gravel"},
        {pos: [4, 2, 2], state: "minecraft:gravel"},
        {pos: [5, 2, 1], state: "minecraft:gravel"},
        {pos: [5, 2, 2], state: "sullysmod:petrified_log{axis:y}"},
        {pos: [6, 2, 2], state: "minecraft:gravel"},
        {pos: [1, 3, 1], state: "sullysmod:petrified_log{axis:x}"},
        {pos: [1, 3, 3], state: "minecraft:air"},
        {pos: [2, 3, 1], state: "sullysmod:petrified_log{axis:x}"},
        {pos: [2, 3, 2], state: "minecraft:air"},
        {pos: [2, 3, 3], state: "sullysmod:petrified_log{axis:y}"},
        {pos: [3, 3, 1], state: "sullysmod:petrified_log{axis:x}"},
        {pos: [4, 3, 2], state: "minecraft:air"},
        {pos: [5, 3, 2], state: "sullysmod:stripped_petrified_log{axis:y}"},
        {pos: [2, 4, 3], state: "sullysmod:petrified_log{axis:y}"},
        {pos: [4, 4, 1], state: "minecraft:air"},
        {pos: [5, 4, 2], state: "minecraft:air"},
        {pos: [2, 5, 3], state: "sullysmod:stripped_petrified_log{axis:y}"},
        {pos: [3, 5, 2], state: "minecraft:air"}
    ],
    entities: [],
    palette: [
        "minecraft:gravel",
        "sullysmod:petrified_log{axis:y}",
        "sullysmod:petrified_log{axis:x}",
        "sullysmod:stripped_petrified_log{axis:y}",
        "minecraft:air"
    ]
}
