{
    DataVersion: 3465,
    size: [16, 18, 16],
    data: [
        {pos: [5, 0, 14], state: "sullysmod:stripped_petrified_log{axis:y}"},
        {pos: [11, 0, 13], state: "sullysmod:stripped_petrified_log{axis:y}"},
        {pos: [13, 0, 8], state: "sullysmod:stripped_petrified_log{axis:y}"},
        {pos: [1, 1, 9], state: "sullysmod:stripped_petrified_log{axis:y}"},
        {pos: [2, 1, 11], state: "sullysmod:stripped_petrified_log{axis:y}"},
        {pos: [3, 1, 7], state: "minecraft:gravel"},
        {pos: [4, 1, 6], state: "minecraft:gravel"},
        {pos: [4, 1, 7], state: "minecraft:gravel"},
        {pos: [4, 1, 8], state: "minecraft:gravel"},
        {pos: [4, 1, 9], state: "minecraft:gravel"},
        {pos: [4, 1, 13], state: "sullysmod:stripped_petrified_log{axis:y}"},
        {pos: [5, 1, 6], state: "minecraft:gravel"},
        {pos: [5, 1, 7], state: "minecraft:gravel"},
        {pos: [5, 1, 8], state: "minecraft:gravel"},
        {pos: [5, 1, 9], state: "minecraft:gravel"},
        {pos: [5, 1, 10], state: "minecraft:gravel"},
        {pos: [5, 1, 14], state: "sullysmod:stripped_petrified_log{axis:y}"},
        {pos: [6, 1, 2], state: "sullysmod:stripped_petrified_log{axis:y}"},
        {pos: [6, 1, 5], state: "minecraft:gravel"},
        {pos: [6, 1, 6], state: "minecraft:gravel"},
        {pos: [6, 1, 7], state: "minecraft:gravel"},
        {pos: [6, 1, 8], state: "minecraft:gravel"},
        {pos: [6, 1, 9], state: "minecraft:gravel"},
        {pos: [6, 1, 10], state: "minecraft:gravel"},
        {pos: [7, 1, 4], state: "minecraft:gravel"},
        {pos: [7, 1, 5], state: "minecraft:gravel"},
        {pos: [7, 1, 6], state: "minecraft:gravel"},
        {pos: [7, 1, 7], state: "minecraft:gravel"},
        {pos: [7, 1, 8], state: "minecraft:gravel"},
        {pos: [7, 1, 9], state: "minecraft:gravel"},
        {pos: [7, 1, 10], state: "minecraft:gravel"},
        {pos: [7, 1, 11], state: "minecraft:gravel"},
        {pos: [7, 1, 14], state: "sullysmod:stripped_petrified_log{axis:y}"},
        {pos: [8, 1, 5], state: "minecraft:gravel"},
        {pos: [8, 1, 6], state: "minecraft:gravel"},
        {pos: [8, 1, 7], state: "minecraft:gravel"},
        {pos: [8, 1, 8], state: "minecraft:gravel"},
        {pos: [8, 1, 9], state: "minecraft:gravel"},
        {pos: [8, 1, 10], state: "minecraft:gravel"},
        {pos: [8, 1, 11], state: "minecraft:gravel"},
        {pos: [9, 1, 2], state: "sullysmod:stripped_petrified_log{axis:y}"},
        {pos: [9, 1, 6], state: "minecraft:gravel"},
        {pos: [9, 1, 7], state: "minecraft:gravel"},
        {pos: [9, 1, 8], state: "minecraft:gravel"},
        {pos: [9, 1, 9], state: "minecraft:gravel"},
        {pos: [9, 1, 10], state: "minecraft:gravel"},
        {pos: [9, 1, 11], state: "minecraft:gravel"},
        {pos: [9, 1, 14], state: "sullysmod:stripped_petrified_log{axis:y}"},
        {pos: [10, 1, 7], state: "minecraft:gravel"},
        {pos: [10, 1, 8], state: "minecraft:gravel"},
        {pos: [10, 1, 9], state: "minecraft:gravel"},
        {pos: [10, 1, 10], state: "minecraft:gravel"},
        {pos: [11, 1, 3], state: "sullysmod:stripped_petrified_log{axis:y}"},
        {pos: [11, 1, 13], state: "sullysmod:petrified_log{axis:y}"},
        {pos: [12, 1, 5], state: "sullysmod:stripped_petrified_log{axis:y}"},
        {pos: [13, 1, 8], state: "sullysmod:petrified_log{axis:y}"},
        {pos: [13, 1, 10], state: "sullysmod:stripped_petrified_log{axis:y}"},
        {pos: [1, 2, 7], state: "sullysmod:stripped_petrified_log{axis:y}"},
        {pos: [1, 2, 9], state: "sullysmod:petrified_log{axis:y}"},
        {pos: [2, 2, 6], state: "minecraft:gravel"},
        {pos: [2, 2, 11], state: "sullysmod:stripped_petrified_log{axis:y}"},
        {pos: [3, 2, 4], state: "minecraft:gravel"},
        {pos: [3, 2, 5], state: "minecraft:gravel"},
        {pos: [3, 2, 6], state: "minecraft:gravel"},
        {pos: [3, 2, 7], state: "minecraft:gravel"},
        {pos: [3, 2, 8], state: "minecraft:gravel"},
        {pos: [3, 2, 9], state: "minecraft:gravel"},
        {pos: [4, 2, 3], state: "sullysmod:stripped_petrified_log{axis:y}"},
        {pos: [4, 2, 4], state: "minecraft:gravel"},
        {pos: [4, 2, 5], state: "minecraft:gravel"},
        {pos: [4, 2, 6], state: "minecraft:gravel"},
        {pos: [4, 2, 7], state: "minecraft:gravel"},
        {pos: [4, 2, 8], state: "minecraft:gravel"},
        {pos: [4, 2, 9], state: "minecraft:gravel"},
        {pos: [4, 2, 10], state: "minecraft:gravel"},
        {pos: [4, 2, 13], state: "sullysmod:stripped_petrified_log{axis:y}"},
        {pos: [5, 2, 4], state: "minecraft:gravel"},
        {pos: [5, 2, 5], state: "minecraft:gravel"},
        {pos: [5, 2, 6], state: "minecraft:gravel"},
        {pos: [5, 2, 7], state: "minecraft:gravel"},
        {pos: [5, 2, 8], state: "minecraft:gravel"},
        {pos: [5, 2, 9], state: "minecraft:gravel"},
        {pos: [5, 2, 10], state: "minecraft:gravel"},
        {pos: [5, 2, 11], state: "minecraft:gravel"},
        {pos: [5, 2, 14], state: "sullysmod:petrified_log{axis:y}"},
        {pos: [6, 2, 2], state: "sullysmod:petrified_log{axis:y}"},
        {pos: [6, 2, 4], state: "minecraft:gravel"},
        {pos: [6, 2, 5], state: "minecraft:gravel"},
        {pos: [6, 2, 6], state: "minecraft:gravel"},
        {pos: [6, 2, 7], state: "minecraft:gravel"},
        {pos: [6, 2, 8], state: "minecraft:gravel"},
        {pos: [6, 2, 9], state: "minecraft:gravel"},
        {pos: [6, 2, 10], state: "minecraft:gravel"},
        {pos: [6, 2, 11], state: "minecraft:gravel"},
        {pos: [6, 2, 12], state: "minecraft:gravel"},
        {pos: [7, 2, 2], state: "sullysmod:stripped_petrified_log{axis:y}"},
        {pos: [7, 2, 3], state: "minecraft:gravel"},
        {pos: [7, 2, 4], state: "minecraft:gravel"},
        {pos: [7, 2, 5], state: "minecraft:gravel"},
        {pos: [7, 2, 6], state: "minecraft:gravel"},
        {pos: [7, 2, 7], state: "minecraft:gravel"},
        {pos: [7, 2, 8], state: "minecraft:gravel"},
        {pos: [7, 2, 9], state: "minecraft:gravel"},
        {pos: [7, 2, 10], state: "minecraft:gravel"},
        {pos: [7, 2, 11], state: "minecraft:gravel"},
        {pos: [7, 2, 12], state: "minecraft:gravel"},
        {pos: [7, 2, 14], state: "sullysmod:stripped_petrified_log{axis:y}"},
        {pos: [8, 2, 3], state: "minecraft:gravel"},
        {pos: [8, 2, 4], state: "minecraft:gravel"},
        {pos: [8, 2, 5], state: "minecraft:gravel"},
        {pos: [8, 2, 6], state: "minecraft:gravel"},
        {pos: [8, 2, 7], state: "minecraft:gravel"},
        {pos: [8, 2, 8], state: "minecraft:gravel"},
        {pos: [8, 2, 9], state: "minecraft:gravel"},
        {pos: [8, 2, 10], state: "minecraft:gravel"},
        {pos: [8, 2, 11], state: "minecraft:gravel"},
        {pos: [8, 2, 12], state: "minecraft:gravel"},
        {pos: [8, 2, 14], state: "sullysmod:stripped_petrified_log{axis:y}"},
        {pos: [9, 2, 2], state: "sullysmod:petrified_log{axis:y}"},
        {pos: [9, 2, 5], state: "minecraft:gravel"},
        {pos: [9, 2, 6], state: "minecraft:gravel"},
        {pos: [9, 2, 7], state: "minecraft:gravel"},
        {pos: [9, 2, 8], state: "minecraft:gravel"},
        {pos: [9, 2, 9], state: "minecraft:gravel"},
        {pos: [9, 2, 10], state: "minecraft:gravel"},
        {pos: [9, 2, 11], state: "minecraft:gravel"},
        {pos: [9, 2, 14], state: "sullysmod:petrified_log{axis:y}"},
        {pos: [10, 2, 5], state: "minecraft:gravel"},
        {pos: [10, 2, 6], state: "minecraft:gravel"},
        {pos: [10, 2, 7], state: "minecraft:gravel"},
        {pos: [10, 2, 8], state: "minecraft:gravel"},
        {pos: [10, 2, 9], state: "minecraft:gravel"},
        {pos: [10, 2, 10], state: "minecraft:gravel"},
        {pos: [10, 2, 11], state: "minecraft:gravel"},
        {pos: [10, 2, 13], state: "sullysmod:stripped_petrified_log{axis:y}"},
        {pos: [11, 2, 3], state: "sullysmod:stripped_petrified_log{axis:y}"},
        {pos: [11, 2, 7], state: "minecraft:gravel"},
        {pos: [11, 2, 8], state: "minecraft:gravel"},
        {pos: [11, 2, 9], state: "minecraft:gravel"},
        {pos: [11, 2, 13], state: "sullysmod:petrified_log{axis:y}"},
        {pos: [12, 2, 5], state: "sullysmod:stripped_petrified_log{axis:y}"},
        {pos: [12, 2, 6], state: "sullysmod:stripped_petrified_log{axis:y}"},
        {pos: [12, 2, 9], state: "minecraft:gravel"},
        {pos: [12, 2, 11], state: "sullysmod:stripped_petrified_log{axis:y}"},
        {pos: [13, 2, 8], state: "sullysmod:petrified_log{axis:y}"},
        {pos: [13, 2, 9], state: "sullysmod:stripped_petrified_log{axis:y}"},
        {pos: [13, 2, 10], state: "sullysmod:petrified_log{axis:y}"},
        {pos: [1, 3, 5], state: "minecraft:gravel"},
        {pos: [1, 3, 7], state: "sullysmod:stripped_petrified_log{axis:y}"},
        {pos: [1, 3, 9], state: "sullysmod:petrified_log{axis:y}"},
        {pos: [1, 3, 10], state: "sullysmod:stripped_petrified_log{axis:y}"},
        {pos: [2, 3, 4], state: "minecraft:gravel"},
        {pos: [2, 3, 5], state: "minecraft:gravel"},
        {pos: [2, 3, 6], state: "minecraft:gravel"},
        {pos: [2, 3, 7], state: "minecraft:gravel"},
        {pos: [2, 3, 8], state: "minecraft:gravel"},
        {pos: [2, 3, 9], state: "minecraft:gravel"},
        {pos: [2, 3, 10], state: "minecraft:gravel"},
        {pos: [2, 3, 11], state: "sullysmod:petrified_log{axis:y}"},
        {pos: [2, 3, 12], state: "sullysmod:petrified_log{axis:y}"},
        {pos: [3, 3, 3], state: "minecraft:gravel"},
        {pos: [3, 3, 4], state: "minecraft:gravel"},
        {pos: [3, 3, 5], state: "minecraft:gravel"},
        {pos: [3, 3, 6], state: "minecraft:gravel"},
        {pos: [3, 3, 7], state: "minecraft:gravel"},
        {pos: [3, 3, 8], state: "minecraft:gravel"},
        {pos: [3, 3, 9], state: "minecraft:gravel"},
        {pos: [3, 3, 10], state: "minecraft:gravel"},
        {pos: [3, 3, 11], state: "minecraft:gravel"},
        {pos: [3, 3, 12], state: "minecraft:gravel"},
        {pos: [3, 3, 13], state: "sullysmod:stripped_petrified_log{axis:y}"},
        {pos: [4, 3, 3], state: "sullysmod:stripped_petrified_log{axis:y}"},
        {pos: [4, 3, 4], state: "minecraft:gravel"},
        {pos: [4, 3, 5], state: "minecraft:gravel"},
        {pos: [4, 3, 6], state: "minecraft:gravel"},
        {pos: [4, 3, 7], state: "minecraft:gravel"},
        {pos: [4, 3, 8], state: "minecraft:gravel"},
        {pos: [4, 3, 9], state: "minecraft:gravel"},
        {pos: [4, 3, 10], state: "minecraft:gravel"},
        {pos: [4, 3, 11], state: "minecraft:gravel"},
        {pos: [4, 3, 12], state: "minecraft:gravel"},
        {pos: [4, 3, 13], state: "sullysmod:petrified_log{axis:y}"},
        {pos: [5, 3, 2], state: "sullysmod:stripped_petrified_log{axis:y}"},
        {pos: [5, 3, 3], state: "minecraft:gravel"},
        {pos: [5, 3, 4], state: "minecraft:gravel"},
        {pos: [5, 3, 5], state: "minecraft:gravel"},
        {pos: [5, 3, 6], state: "minecraft:gravel"},
        {pos: [5, 3, 7], state: "minecraft:gravel"},
        {pos: [5, 3, 8], state: "minecraft:gravel"},
        {pos: [5, 3, 9], state: "minecraft:gravel"},
        {pos: [5, 3, 10], state: "minecraft:gravel"},
        {pos: [5, 3, 11], state: "minecraft:gravel"},
        {pos: [5, 3, 12], state: "minecraft:gravel"},
        {pos: [5, 3, 13], state: "minecraft:gravel"},
        {pos: [5, 3, 14], state: "sullysmod:petrified_log{axis:y}"},
        {pos: [6, 3, 2], state: "sullysmod:petrified_log{axis:y}"},
        {pos: [6, 3, 3], state: "minecraft:gravel"},
        {pos: [6, 3, 4], state: "minecraft:gravel"},
        {pos: [6, 3, 5], state: "minecraft:gravel"},
        {pos: [6, 3, 6], state: "minecraft:gravel"},
        {pos: [6, 3, 7], state: "minecraft:gravel"},
        {pos: [6, 3, 8], state: "minecraft:gravel"},
        {pos: [6, 3, 9], state: "minecraft:gravel"},
        {pos: [6, 3, 10], state: "minecraft:gravel"},
        {pos: [6, 3, 11], state: "minecraft:gravel"},
        {pos: [6, 3, 12], state: "minecraft:gravel"},
        {pos: [6, 3, 13], state: "minecraft:gravel"},
        {pos: [6, 3, 14], state: "sullysmod:stripped_petrified_log{axis:y}"},
        {pos: [7, 3, 2], state: "sullysmod:stripped_petrified_log{axis:y}"},
        {pos: [7, 3, 3], state: "minecraft:gravel"},
        {pos: [7, 3, 4], state: "minecraft:gravel"},
        {pos: [7, 3, 5], state: "minecraft:gravel"},
        {pos: [7, 3, 6], state: "minecraft:gravel"},
        {pos: [7, 3, 7], state: "minecraft:gravel"},
        {pos: [7, 3, 8], state: "minecraft:gravel"},
        {pos: [7, 3, 9], state: "minecraft:gravel"},
        {pos: [7, 3, 10], state: "minecraft:gravel"},
        {pos: [7, 3, 11], state: "minecraft:gravel"},
        {pos: [7, 3, 12], state: "minecraft:gravel"},
        {pos: [7, 3, 13], state: "minecraft:gravel"},
        {pos: [7, 3, 14], state: "sullysmod:stripped_petrified_log{axis:y}"},
        {pos: [8, 3, 3], state: "minecraft:gravel"},
        {pos: [8, 3, 4], state: "minecraft:gravel"},
        {pos: [8, 3, 5], state: "minecraft:gravel"},
        {pos: [8, 3, 6], state: "minecraft:gravel"},
        {pos: [8, 3, 7], state: "minecraft:gravel"},
        {pos: [8, 3, 8], state: "minecraft:gravel"},
        {pos: [8, 3, 9], state: "minecraft:gravel"},
        {pos: [8, 3, 10], state: "minecraft:gravel"},
        {pos: [8, 3, 11], state: "minecraft:gravel"},
        {pos: [8, 3, 12], state: "minecraft:gravel"},
        {pos: [8, 3, 13], state: "minecraft:gravel"},
        {pos: [8, 3, 14], state: "sullysmod:petrified_log{axis:y}"},
        {pos: [9, 3, 2], state: "sullysmod:petrified_log{axis:y}"},
        {pos: [9, 3, 3], state: "minecraft:gravel"},
        {pos: [9, 3, 4], state: "minecraft:gravel"},
        {pos: [9, 3, 5], state: "minecraft:gravel"},
        {pos: [9, 3, 6], state: "minecraft:gravel"},
        {pos: [9, 3, 7], state: "minecraft:gravel"},
        {pos: [9, 3, 8], state: "minecraft:gravel"},
        {pos: [9, 3, 9], state: "minecraft:gravel"},
        {pos: [9, 3, 10], state: "minecraft:gravel"},
        {pos: [9, 3, 11], state: "minecraft:gravel"},
        {pos: [9, 3, 12], state: "minecraft:gravel"},
        {pos: [9, 3, 13], state: "minecraft:gravel"},
        {pos: [9, 3, 14], state: "sullysmod:petrified_log{axis:y}"},
        {pos: [10, 3, 3], state: "sullysmod:stripped_petrified_log{axis:y}"},
        {pos: [10, 3, 4], state: "minecraft:gravel"},
        {pos: [10, 3, 5], state: "minecraft:gravel"},
        {pos: [10, 3, 6], state: "minecraft:gravel"},
        {pos: [10, 3, 7], state: "minecraft:gravel"},
        {pos: [10, 3, 8], state: "minecraft:gravel"},
        {pos: [10, 3, 9], state: "minecraft:gravel"},
        {pos: [10, 3, 10], state: "minecraft:gravel"},
        {pos: [10, 3, 11], state: "minecraft:gravel"},
        {pos: [10, 3, 12], state: "minecraft:gravel"},
        {pos: [10, 3, 13], state: "minecraft:suspicious_gravel{dusted:0}", nbt: {id: "minecraft:brushable_block", item: {Count: 0b, id: "minecraft:air"}}},
        {pos: [11, 3, 3], state: "sullysmod:stripped_petrified_log{axis:y}"},
        {pos: [11, 3, 4], state: "minecraft:gravel"},
        {pos: [11, 3, 5], state: "minecraft:gravel"},
        {pos: [11, 3, 6], state: "minecraft:gravel"},
        {pos: [11, 3, 7], state: "minecraft:gravel"},
        {pos: [11, 3, 8], state: "minecraft:gravel"},
        {pos: [11, 3, 9], state: "minecraft:gravel"},
        {pos: [11, 3, 10], state: "minecraft:gravel"},
        {pos: [11, 3, 11], state: "minecraft:gravel"},
        {pos: [11, 3, 13], state: "sullysmod:petrified_log{axis:y}"},
        {pos: [12, 3, 4], state: "sullysmod:stripped_petrified_log{axis:y}"},
        {pos: [12, 3, 5], state: "sullysmod:petrified_log{axis:y}"},
        {pos: [12, 3, 6], state: "sullysmod:petrified_log{axis:y}"},
        {pos: [12, 3, 7], state: "minecraft:gravel"},
        {pos: [12, 3, 8], state: "minecraft:gravel"},
        {pos: [12, 3, 9], state: "minecraft:gravel"},
        {pos: [12, 3, 10], state: "minecraft:gravel"},
        {pos: [12, 3, 11], state: "sullysmod:stripped_petrified_log{axis:y}"},
        {pos: [13, 3, 6], state: "sullysmod:stripped_petrified_log{axis:y}"},
        {pos: [13, 3, 7], state: "sullysmod:stripped_petrified_log{axis:y}"},
        {pos: [13, 3, 8], state: "sullysmod:petrified_log{axis:y}"},
        {pos: [13, 3, 9], state: "sullysmod:petrified_log{axis:y}"},
        {pos: [13, 3, 10], state: "sullysmod:petrified_log{axis:y}"},
        {pos: [1, 4, 6], state: "minecraft:gravel"},
        {pos: [1, 4, 7], state: "sullysmod:stripped_petrified_log{axis:y}"},
        {pos: [1, 4, 8], state: "sullysmod:stripped_petrified_log{axis:y}"},
        {pos: [1, 4, 9], state: "sullysmod:petrified_log{axis:y}"},
        {pos: [1, 4, 10], state: "sullysmod:stripped_petrified_log{axis:y}"},
        {pos: [2, 4, 6], state: "minecraft:gravel"},
        {pos: [2, 4, 7], state: "minecraft:gravel"},
        {pos: [2, 4, 8], state: "minecraft:gravel"},
        {pos: [2, 4, 9], state: "minecraft:gravel"},
        {pos: [2, 4, 10], state: "minecraft:gravel"},
        {pos: [2, 4, 11], state: "sullysmod:petrified_log{axis:y}"},
        {pos: [2, 4, 12], state: "sullysmod:petrified_log{axis:y}"},
        {pos: [3, 4, 4], state: "minecraft:gravel"},
        {pos: [3, 4, 5], state: "minecraft:gravel"},
        {pos: [3, 4, 6], state: "minecraft:gravel"},
        {pos: [3, 4, 7], state: "minecraft:gravel"},
        {pos: [3, 4, 8], state: "minecraft:gravel"},
        {pos: [3, 4, 9], state: "minecraft:gravel"},
        {pos: [3, 4, 10], state: "minecraft:gravel"},
        {pos: [3, 4, 11], state: "minecraft:gravel"},
        {pos: [3, 4, 12], state: "minecraft:gravel"},
        {pos: [3, 4, 13], state: "sullysmod:stripped_petrified_log{axis:y}"},
        {pos: [4, 4, 3], state: "sullysmod:stripped_petrified_log{axis:y}"},
        {pos: [4, 4, 4], state: "minecraft:gravel"},
        {pos: [4, 4, 5], state: "minecraft:gravel"},
        {pos: [4, 4, 6], state: "minecraft:gravel"},
        {pos: [4, 4, 7], state: "minecraft:gravel"},
        {pos: [4, 4, 8], state: "minecraft:gravel"},
        {pos: [4, 4, 9], state: "minecraft:gravel"},
        {pos: [4, 4, 10], state: "minecraft:gravel"},
        {pos: [4, 4, 11], state: "minecraft:gravel"},
        {pos: [4, 4, 12], state: "minecraft:gravel"},
        {pos: [4, 4, 13], state: "sullysmod:petrified_log{axis:y}"},
        {pos: [5, 4, 2], state: "sullysmod:petrified_log{axis:y}"},
        {pos: [5, 4, 3], state: "minecraft:gravel"},
        {pos: [5, 4, 4], state: "minecraft:gravel"},
        {pos: [5, 4, 5], state: "minecraft:gravel"},
        {pos: [5, 4, 6], state: "minecraft:gravel"},
        {pos: [5, 4, 7], state: "minecraft:gravel"},
        {pos: [5, 4, 8], state: "minecraft:gravel"},
        {pos: [5, 4, 9], state: "minecraft:gravel"},
        {pos: [5, 4, 10], state: "minecraft:gravel"},
        {pos: [5, 4, 11], state: "minecraft:gravel"},
        {pos: [5, 4, 12], state: "minecraft:gravel"},
        {pos: [5, 4, 13], state: "minecraft:gravel"},
        {pos: [5, 4, 14], state: "sullysmod:petrified_log{axis:y}"},
        {pos: [6, 4, 2], state: "sullysmod:petrified_log{axis:y}"},
        {pos: [6, 4, 3], state: "minecraft:gravel"},
        {pos: [6, 4, 4], state: "minecraft:gravel"},
        {pos: [6, 4, 5], state: "minecraft:gravel"},
        {pos: [6, 4, 6], state: "minecraft:gravel"},
        {pos: [6, 4, 9], state: "minecraft:gravel"},
        {pos: [6, 4, 10], state: "minecraft:gravel"},
        {pos: [6, 4, 11], state: "minecraft:gravel"},
        {pos: [6, 4, 12], state: "minecraft:gravel"},
        {pos: [6, 4, 13], state: "minecraft:gravel"},
        {pos: [6, 4, 14], state: "sullysmod:stripped_petrified_log{axis:y}"},
        {pos: [7, 4, 2], state: "sullysmod:stripped_petrified_log{axis:y}"},
        {pos: [7, 4, 3], state: "minecraft:gravel"},
        {pos: [7, 4, 4], state: "minecraft:gravel"},
        {pos: [7, 4, 5], state: "minecraft:gravel"},
        {pos: [7, 4, 6], state: "minecraft:gravel"},
        {pos: [7, 4, 8], state: "minecraft:gravel"},
        {pos: [7, 4, 9], state: "minecraft:gravel"},
        {pos: [7, 4, 10], state: "minecraft:gravel"},
        {pos: [7, 4, 11], state: "minecraft:gravel"},
        {pos: [7, 4, 12], state: "minecraft:gravel"},
        {pos: [7, 4, 13], state: "minecraft:gravel"},
        {pos: [7, 4, 14], state: "sullysmod:petrified_log{axis:y}"},
        {pos: [8, 4, 2], state: "sullysmod:stripped_petrified_log{axis:y}"},
        {pos: [8, 4, 3], state: "minecraft:gravel"},
        {pos: [8, 4, 4], state: "minecraft:gravel"},
        {pos: [8, 4, 5], state: "minecraft:gravel"},
        {pos: [8, 4, 6], state: "minecraft:gravel"},
        {pos: [8, 4, 7], state: "minecraft:gravel"},
        {pos: [8, 4, 8], state: "minecraft:gravel"},
        {pos: [8, 4, 9], state: "minecraft:gravel"},
        {pos: [8, 4, 10], state: "minecraft:gravel"},
        {pos: [8, 4, 11], state: "minecraft:gravel"},
        {pos: [8, 4, 12], state: "minecraft:gravel"},
        {pos: [8, 4, 13], state: "minecraft:gravel"},
        {pos: [8, 4, 14], state: "sullysmod:petrified_log{axis:y}"},
        {pos: [9, 4, 2], state: "sullysmod:petrified_log{axis:y}"},
        {pos: [9, 4, 3], state: "sullysmod:petrified_log{axis:y}"},
        {pos: [9, 4, 4], state: "minecraft:gravel"},
        {pos: [9, 4, 5], state: "minecraft:gravel"},
        {pos: [9, 4, 6], state: "minecraft:gravel"},
        {pos: [9, 4, 7], state: "minecraft:gravel"},
        {pos: [9, 4, 8], state: "minecraft:gravel"},
        {pos: [9, 4, 9], state: "minecraft:gravel"},
        {pos: [9, 4, 10], state: "minecraft:gravel"},
        {pos: [9, 4, 11], state: "minecraft:gravel"},
        {pos: [9, 4, 12], state: "minecraft:gravel"},
        {pos: [9, 4, 13], state: "sullysmod:petrified_log{axis:y}"},
        {pos: [9, 4, 14], state: "sullysmod:petrified_log{axis:y}"},
        {pos: [10, 4, 3], state: "sullysmod:stripped_petrified_log{axis:y}"},
        {pos: [10, 4, 4], state: "minecraft:gravel"},
        {pos: [10, 4, 5], state: "minecraft:gravel"},
        {pos: [10, 4, 6], state: "minecraft:gravel"},
        {pos: [10, 4, 7], state: "minecraft:gravel"},
        {pos: [10, 4, 8], state: "minecraft:gravel"},
        {pos: [10, 4, 9], state: "minecraft:gravel"},
        {pos: [10, 4, 10], state: "minecraft:gravel"},
        {pos: [10, 4, 11], state: "minecraft:gravel"},
        {pos: [10, 4, 12], state: "minecraft:gravel"},
        {pos: [10, 4, 13], state: "sullysmod:petrified_log{axis:y}"},
        {pos: [11, 4, 3], state: "sullysmod:petrified_log{axis:y}"},
        {pos: [11, 4, 4], state: "minecraft:gravel"},
        {pos: [11, 4, 5], state: "minecraft:gravel"},
        {pos: [11, 4, 6], state: "minecraft:gravel"},
        {pos: [11, 4, 7], state: "minecraft:gravel"},
        {pos: [11, 4, 8], state: "minecraft:gravel"},
        {pos: [11, 4, 9], state: "minecraft:gravel"},
        {pos: [11, 4, 10], state: "minecraft:gravel"},
        {pos: [11, 4, 11], state: "minecraft:gravel"},
        {pos: [11, 4, 12], state: "minecraft:gravel"},
        {pos: [11, 4, 13], state: "sullysmod:petrified_log{axis:y}"},
        {pos: [12, 4, 4], state: "sullysmod:stripped_petrified_log{axis:y}"},
        {pos: [12, 4, 5], state: "sullysmod:petrified_log{axis:y}"},
        {pos: [12, 4, 6], state: "sullysmod:petrified_log{axis:y}"},
        {pos: [12, 4, 7], state: "minecraft:gravel"},
        {pos: [12, 4, 8], state: "minecraft:gravel"},
        {pos: [12, 4, 9], state: "minecraft:gravel"},
        {pos: [12, 4, 10], state: "minecraft:gravel"},
        {pos: [12, 4, 11], state: "sullysmod:petrified_log{axis:y}"},
        {pos: [12, 4, 12], state: "sullysmod:petrified_log{axis:y}"},
        {pos: [13, 4, 6], state: "sullysmod:stripped_petrified_log{axis:y}"},
        {pos: [13, 4, 7], state: "sullysmod:petrified_log{axis:y}"},
        {pos: [13, 4, 8], state: "sullysmod:petrified_log{axis:y}"},
        {pos: [13, 4, 9], state: "sullysmod:petrified_log{axis:y}"},
        {pos: [13, 4, 10], state: "sullysmod:petrified_log{axis:y}"},
        {pos: [1, 5, 7], state: "sullysmod:petrified_log{axis:y}"},
        {pos: [1, 5, 8], state: "sullysmod:stripped_petrified_log{axis:y}"},
        {pos: [1, 5, 9], state: "sullysmod:petrified_log{axis:y}"},
        {pos: [1, 5, 10], state: "sullysmod:petrified_log{axis:y}"},
        {pos: [2, 5, 8], state: "minecraft:gravel"},
        {pos: [2, 5, 9], state: "minecraft:gravel"},
        {pos: [2, 5, 10], state: "sullysmod:petrified_log{axis:y}"},
        {pos: [2, 5, 11], state: "sullysmod:petrified_log{axis:y}"},
        {pos: [2, 5, 12], state: "sullysmod:petrified_log{axis:y}"},
        {pos: [3, 5, 10], state: "minecraft:gravel"},
        {pos: [3, 5, 11], state: "minecraft:gravel"},
        {pos: [3, 5, 12], state: "minecraft:gravel"},
        {pos: [3, 5, 13], state: "sullysmod:petrified_log{axis:y}"},
        {pos: [4, 5, 3], state: "sullysmod:petrified_log{axis:y}"},
        {pos: [4, 5, 8], state: "sullysmod:petrified_sapling{stage:0}"},
        {pos: [4, 5, 11], state: "minecraft:gravel"},
        {pos: [4, 5, 12], state: "minecraft:gravel"},
        {pos: [4, 5, 13], state: "sullysmod:petrified_log{axis:y}"},
        {pos: [5, 5, 2], state: "sullysmod:petrified_log{axis:y}"},
        {pos: [5, 5, 3], state: "sullysmod:petrified_log{axis:y}"},
        {pos: [5, 5, 5], state: "sullysmod:petrified_sapling{stage:0}"},
        {pos: [5, 5, 12], state: "minecraft:gravel"},
        {pos: [5, 5, 13], state: "sullysmod:petrified_log{axis:y}"},
        {pos: [5, 5, 14], state: "sullysmod:petrified_log{axis:y}"},
        {pos: [6, 5, 2], state: "sullysmod:petrified_log{axis:y}"},
        {pos: [6, 5, 13], state: "minecraft:gravel"},
        {pos: [6, 5, 14], state: "sullysmod:petrified_log{axis:y}"},
        {pos: [7, 5, 2], state: "sullysmod:petrified_log{axis:y}"},
        {pos: [7, 5, 9], state: "sullysmod:petrified_sapling{stage:0}"},
        {pos: [7, 5, 12], state: "minecraft:gravel"},
        {pos: [7, 5, 13], state: "minecraft:gravel"},
        {pos: [7, 5, 14], state: "sullysmod:petrified_log{axis:y}"},
        {pos: [8, 5, 2], state: "sullysmod:stripped_petrified_log{axis:y}"},
        {pos: [8, 5, 3], state: "minecraft:gravel"},
        {pos: [8, 5, 5], state: "sullysmod:petrified_sapling{stage:0}"},
        {pos: [8, 5, 7], state: "sullysmod:petrified_sapling{stage:0}"},
        {pos: [8, 5, 11], state: "minecraft:gravel"},
        {pos: [8, 5, 12], state: "minecraft:gravel"},
        {pos: [8, 5, 13], state: "minecraft:gravel"},
        {pos: [8, 5, 14], state: "sullysmod:petrified_log{axis:y}"},
        {pos: [9, 5, 2], state: "sullysmod:petrified_log{axis:y}"},
        {pos: [9, 5, 3], state: "sullysmod:petrified_log{axis:y}"},
        {pos: [9, 5, 4], state: "minecraft:gravel"},
        {pos: [9, 5, 10], state: "minecraft:gravel"},
        {pos: [9, 5, 11], state: "minecraft:gravel"},
        {pos: [9, 5, 12], state: "minecraft:gravel"},
        {pos: [9, 5, 13], state: "sullysmod:petrified_log{axis:y}"},
        {pos: [9, 5, 14], state: "sullysmod:petrified_log{axis:y}"},
        {pos: [10, 5, 3], state: "sullysmod:petrified_log{axis:y}"},
        {pos: [10, 5, 4], state: "minecraft:gravel"},
        {pos: [10, 5, 10], state: "minecraft:gravel"},
        {pos: [10, 5, 11], state: "minecraft:gravel"},
        {pos: [10, 5, 12], state: "minecraft:gravel"},
        {pos: [10, 5, 13], state: "sullysmod:petrified_log{axis:y}"},
        {pos: [11, 5, 3], state: "sullysmod:petrified_log{axis:y}"},
        {pos: [11, 5, 4], state: "minecraft:gravel"},
        {pos: [11, 5, 5], state: "minecraft:gravel"},
        {pos: [11, 5, 6], state: "minecraft:gravel"},
        {pos: [11, 5, 10], state: "minecraft:gravel"},
        {pos: [11, 5, 11], state: "minecraft:gravel"},
        {pos: [11, 5, 12], state: "minecraft:gravel"},
        {pos: [11, 5, 13], state: "sullysmod:petrified_log{axis:y}"},
        {pos: [12, 5, 4], state: "sullysmod:petrified_log{axis:y}"},
        {pos: [12, 5, 5], state: "sullysmod:petrified_log{axis:y}"},
        {pos: [12, 5, 6], state: "sullysmod:petrified_log{axis:y}"},
        {pos: [12, 5, 7], state: "minecraft:gravel"},
        {pos: [12, 5, 9], state: "minecraft:gravel"},
        {pos: [12, 5, 10], state: "sullysmod:petrified_log{axis:y}"},
        {pos: [12, 5, 11], state: "sullysmod:petrified_log{axis:y}"},
        {pos: [12, 5, 12], state: "sullysmod:petrified_log{axis:y}"},
        {pos: [13, 5, 6], state: "sullysmod:petrified_log{axis:y}"},
        {pos: [13, 5, 7], state: "sullysmod:petrified_log{axis:y}"},
        {pos: [13, 5, 8], state: "sullysmod:petrified_log{axis:y}"},
        {pos: [13, 5, 9], state: "sullysmod:petrified_log{axis:y}"},
        {pos: [13, 5, 10], state: "sullysmod:petrified_log{axis:y}"},
        {pos: [1, 6, 7], state: "sullysmod:petrified_log{axis:y}"},
        {pos: [1, 6, 8], state: "sullysmod:petrified_log{axis:y}"},
        {pos: [1, 6, 9], state: "sullysmod:petrified_log{axis:y}"},
        {pos: [1, 6, 10], state: "sullysmod:petrified_log{axis:y}"},
        {pos: [2, 6, 10], state: "sullysmod:petrified_log{axis:y}"},
        {pos: [2, 6, 11], state: "sullysmod:petrified_log{axis:y}"},
        {pos: [2, 6, 12], state: "sullysmod:petrified_log{axis:y}"},
        {pos: [3, 6, 11], state: "minecraft:gravel"},
        {pos: [3, 6, 12], state: "minecraft:gravel"},
        {pos: [3, 6, 13], state: "sullysmod:petrified_log{axis:y}"},
        {pos: [4, 6, 3], state: "sullysmod:petrified_log{axis:y}"},
        {pos: [4, 6, 12], state: "minecraft:gravel"},
        {pos: [4, 6, 13], state: "sullysmod:petrified_log{axis:y}"},
        {pos: [5, 6, 2], state: "sullysmod:petrified_log{axis:y}"},
        {pos: [5, 6, 3], state: "sullysmod:petrified_log{axis:y}"},
        {pos: [5, 6, 13], state: "sullysmod:petrified_log{axis:y}"},
        {pos: [5, 6, 14], state: "sullysmod:petrified_log{axis:y}"},
        {pos: [6, 6, 2], state: "sullysmod:petrified_log{axis:y}"},
        {pos: [6, 6, 14], state: "sullysmod:petrified_log{axis:y}"},
        {pos: [7, 6, 2], state: "sullysmod:petrified_log{axis:y}"},
        {pos: [7, 6, 14], state: "sullysmod:petrified_log{axis:y}"},
        {pos: [8, 6, 2], state: "sullysmod:petrified_log{axis:y}"},
        {pos: [8, 6, 13], state: "minecraft:gravel"},
        {pos: [8, 6, 14], state: "sullysmod:petrified_log{axis:y}"},
        {pos: [9, 6, 2], state: "sullysmod:petrified_log{axis:y}"},
        {pos: [9, 6, 3], state: "sullysmod:petrified_log{axis:y}"},
        {pos: [9, 6, 12], state: "minecraft:gravel"},
        {pos: [9, 6, 13], state: "sullysmod:petrified_log{axis:y}"},
        {pos: [9, 6, 14], state: "sullysmod:petrified_log{axis:y}"},
        {pos: [10, 6, 3], state: "sullysmod:petrified_log{axis:y}"},
        {pos: [10, 6, 4], state: "minecraft:gravel"},
        {pos: [10, 6, 12], state: "minecraft:gravel"},
        {pos: [10, 6, 13], state: "sullysmod:petrified_log{axis:y}"},
        {pos: [11, 6, 3], state: "sullysmod:petrified_log{axis:y}"},
        {pos: [11, 6, 4], state: "sullysmod:petrified_log{axis:y}"},
        {pos: [11, 6, 5], state: "minecraft:gravel"},
        {pos: [11, 6, 11], state: "minecraft:gravel"},
        {pos: [11, 6, 12], state: "sullysmod:petrified_log{axis:y}"},
        {pos: [11, 6, 13], state: "sullysmod:petrified_log{axis:y}"},
        {pos: [12, 6, 4], state: "sullysmod:petrified_log{axis:y}"},
        {pos: [12, 6, 5], state: "sullysmod:petrified_log{axis:y}"},
        {pos: [12, 6, 6], state: "minecraft:suspicious_gravel{dusted:0}", nbt: {id: "minecraft:brushable_block", item: {Count: 0b, id: "minecraft:air"}}},
        {pos: [12, 6, 10], state: "sullysmod:petrified_log{axis:y}"},
        {pos: [12, 6, 11], state: "sullysmod:petrified_log{axis:y}"},
        {pos: [12, 6, 12], state: "sullysmod:petrified_log{axis:y}"},
        {pos: [13, 6, 6], state: "sullysmod:petrified_log{axis:y}"},
        {pos: [13, 6, 7], state: "sullysmod:petrified_log{axis:y}"},
        {pos: [13, 6, 8], state: "sullysmod:petrified_log{axis:y}"},
        {pos: [13, 6, 9], state: "sullysmod:petrified_log{axis:y}"},
        {pos: [13, 6, 10], state: "sullysmod:petrified_log{axis:y}"},
        {pos: [1, 7, 7], state: "sullysmod:petrified_log{axis:y}"},
        {pos: [1, 7, 8], state: "sullysmod:petrified_log{axis:y}"},
        {pos: [1, 7, 9], state: "sullysmod:petrified_log{axis:y}"},
        {pos: [1, 7, 10], state: "sullysmod:petrified_log{axis:y}"},
        {pos: [2, 7, 10], state: "sullysmod:petrified_log{axis:y}"},
        {pos: [2, 7, 11], state: "sullysmod:petrified_log{axis:y}"},
        {pos: [2, 7, 12], state: "sullysmod:petrified_log{axis:y}"},
        {pos: [3, 7, 12], state: "sullysmod:petrified_log{axis:y}"},
        {pos: [3, 7, 13], state: "sullysmod:petrified_log{axis:y}"},
        {pos: [4, 7, 3], state: "sullysmod:petrified_log{axis:y}"},
        {pos: [4, 7, 13], state: "sullysmod:petrified_log{axis:y}"},
        {pos: [5, 7, 2], state: "sullysmod:petrified_log{axis:y}"},
        {pos: [5, 7, 3], state: "sullysmod:petrified_log{axis:y}"},
        {pos: [5, 7, 13], state: "sullysmod:petrified_log{axis:y}"},
        {pos: [5, 7, 14], state: "sullysmod:petrified_log{axis:y}"},
        {pos: [6, 7, 2], state: "sullysmod:petrified_log{axis:y}"},
        {pos: [6, 7, 14], state: "sullysmod:petrified_log{axis:y}"},
        {pos: [7, 7, 2], state: "sullysmod:petrified_log{axis:y}"},
        {pos: [7, 7, 14], state: "sullysmod:stripped_petrified_log{axis:y}"},
        {pos: [8, 7, 2], state: "sullysmod:petrified_log{axis:y}"},
        {pos: [8, 7, 14], state: "sullysmod:petrified_log{axis:y}"},
        {pos: [9, 7, 2], state: "sullysmod:petrified_log{axis:y}"},
        {pos: [9, 7, 3], state: "sullysmod:petrified_log{axis:y}"},
        {pos: [9, 7, 13], state: "minecraft:gravel"},
        {pos: [9, 7, 14], state: "sullysmod:petrified_log{axis:y}"},
        {pos: [10, 7, 3], state: "sullysmod:petrified_log{axis:y}"},
        {pos: [10, 7, 13], state: "sullysmod:petrified_log{axis:y}"},
        {pos: [11, 7, 3], state: "sullysmod:petrified_log{axis:y}"},
        {pos: [11, 7, 4], state: "sullysmod:petrified_log{axis:y}"},
        {pos: [11, 7, 12], state: "sullysmod:petrified_log{axis:y}"},
        {pos: [11, 7, 13], state: "sullysmod:petrified_log{axis:y}"},
        {pos: [12, 7, 4], state: "sullysmod:petrified_log{axis:y}"},
        {pos: [12, 7, 5], state: "sullysmod:petrified_log{axis:y}"},
        {pos: [12, 7, 10], state: "sullysmod:petrified_log{axis:y}"},
        {pos: [12, 7, 11], state: "sullysmod:petrified_log{axis:y}"},
        {pos: [12, 7, 12], state: "sullysmod:petrified_log{axis:y}"},
        {pos: [13, 7, 6], state: "sullysmod:petrified_log{axis:y}"},
        {pos: [13, 7, 7], state: "sullysmod:petrified_log{axis:y}"},
        {pos: [13, 7, 8], state: "sullysmod:petrified_log{axis:y}"},
        {pos: [13, 7, 9], state: "sullysmod:petrified_log{axis:y}"},
        {pos: [13, 7, 10], state: "sullysmod:petrified_log{axis:y}"},
        {pos: [1, 8, 7], state: "sullysmod:petrified_log{axis:y}"},
        {pos: [1, 8, 8], state: "sullysmod:petrified_log{axis:y}"},
        {pos: [1, 8, 9], state: "sullysmod:petrified_log{axis:y}"},
        {pos: [1, 8, 10], state: "sullysmod:petrified_log{axis:y}"},
        {pos: [2, 8, 10], state: "sullysmod:petrified_log{axis:y}"},
        {pos: [2, 8, 11], state: "sullysmod:petrified_log{axis:y}"},
        {pos: [2, 8, 12], state: "sullysmod:petrified_log{axis:y}"},
        {pos: [3, 8, 12], state: "sullysmod:petrified_log{axis:y}"},
        {pos: [3, 8, 13], state: "sullysmod:petrified_log{axis:y}"},
        {pos: [4, 8, 3], state: "sullysmod:stripped_petrified_log{axis:y}"},
        {pos: [4, 8, 13], state: "sullysmod:petrified_log{axis:y}"},
        {pos: [5, 8, 2], state: "sullysmod:petrified_log{axis:y}"},
        {pos: [5, 8, 13], state: "sullysmod:petrified_log{axis:y}"},
        {pos: [5, 8, 14], state: "sullysmod:petrified_log{axis:y}"},
        {pos: [6, 8, 2], state: "sullysmod:petrified_log{axis:y}"},
        {pos: [6, 8, 14], state: "sullysmod:petrified_log{axis:y}"},
        {pos: [7, 8, 2], state: "sullysmod:petrified_log{axis:y}"},
        {pos: [7, 8, 13], state: "minecraft:air"},
        {pos: [7, 8, 14], state: "minecraft:suspicious_gravel{dusted:0}", nbt: {id: "minecraft:brushable_block", item: {Count: 0b, id: "minecraft:air"}}},
        {pos: [8, 8, 2], state: "sullysmod:petrified_log{axis:y}"},
        {pos: [8, 8, 14], state: "sullysmod:petrified_log{axis:y}"},
        {pos: [9, 8, 2], state: "sullysmod:petrified_log{axis:y}"},
        {pos: [9, 8, 3], state: "sullysmod:petrified_log{axis:y}"},
        {pos: [9, 8, 14], state: "sullysmod:petrified_log{axis:y}"},
        {pos: [10, 8, 3], state: "sullysmod:petrified_log{axis:y}"},
        {pos: [10, 8, 13], state: "sullysmod:petrified_log{axis:y}"},
        {pos: [11, 8, 3], state: "sullysmod:petrified_log{axis:y}"},
        {pos: [11, 8, 4], state: "sullysmod:petrified_log{axis:y}"},
        {pos: [11, 8, 12], state: "sullysmod:petrified_log{axis:y}"},
        {pos: [11, 8, 13], state: "sullysmod:petrified_log{axis:y}"},
        {pos: [12, 8, 4], state: "sullysmod:petrified_log{axis:y}"},
        {pos: [12, 8, 5], state: "sullysmod:petrified_log{axis:y}"},
        {pos: [12, 8, 10], state: "sullysmod:petrified_log{axis:y}"},
        {pos: [12, 8, 11], state: "sullysmod:petrified_log{axis:y}"},
        {pos: [12, 8, 12], state: "sullysmod:petrified_log{axis:y}"},
        {pos: [13, 8, 6], state: "sullysmod:petrified_log{axis:y}"},
        {pos: [13, 8, 7], state: "sullysmod:petrified_log{axis:y}"},
        {pos: [13, 8, 8], state: "sullysmod:petrified_log{axis:y}"},
        {pos: [13, 8, 9], state: "sullysmod:petrified_log{axis:y}"},
        {pos: [13, 8, 10], state: "sullysmod:petrified_log{axis:y}"},
        {pos: [1, 9, 7], state: "sullysmod:petrified_log{axis:y}"},
        {pos: [1, 9, 8], state: "sullysmod:stripped_petrified_log{axis:y}"},
        {pos: [1, 9, 9], state: "sullysmod:petrified_log{axis:y}"},
        {pos: [1, 9, 10], state: "sullysmod:petrified_log{axis:y}"},
        {pos: [2, 9, 11], state: "sullysmod:petrified_log{axis:y}"},
        {pos: [2, 9, 12], state: "sullysmod:petrified_log{axis:y}"},
        {pos: [3, 9, 12], state: "sullysmod:petrified_log{axis:y}"},
        {pos: [3, 9, 13], state: "sullysmod:petrified_log{axis:y}"},
        {pos: [4, 9, 13], state: "sullysmod:petrified_log{axis:y}"},
        {pos: [5, 9, 2], state: "sullysmod:petrified_log{axis:y}"},
        {pos: [5, 9, 13], state: "sullysmod:petrified_log{axis:y}"},
        {pos: [5, 9, 14], state: "sullysmod:petrified_log{axis:y}"},
        {pos: [6, 9, 2], state: "sullysmod:petrified_log{axis:y}"},
        {pos: [6, 9, 14], state: "sullysmod:petrified_log{axis:y}"},
        {pos: [7, 9, 2], state: "sullysmod:petrified_log{axis:y}"},
        {pos: [7, 9, 14], state: "sullysmod:stripped_petrified_log{axis:y}"},
        {pos: [8, 9, 2], state: "sullysmod:petrified_log{axis:y}"},
        {pos: [8, 9, 14], state: "minecraft:air"},
        {pos: [9, 9, 2], state: "sullysmod:petrified_log{axis:y}"},
        {pos: [9, 9, 3], state: "sullysmod:petrified_log{axis:y}"},
        {pos: [9, 9, 14], state: "sullysmod:petrified_log{axis:y}"},
        {pos: [10, 9, 3], state: "sullysmod:petrified_log{axis:y}"},
        {pos: [10, 9, 13], state: "sullysmod:petrified_log{axis:y}"},
        {pos: [11, 9, 3], state: "sullysmod:petrified_log{axis:y}"},
        {pos: [11, 9, 4], state: "sullysmod:petrified_log{axis:y}"},
        {pos: [11, 9, 12], state: "sullysmod:petrified_log{axis:y}"},
        {pos: [11, 9, 13], state: "sullysmod:petrified_log{axis:y}"},
        {pos: [12, 9, 4], state: "sullysmod:petrified_log{axis:y}"},
        {pos: [12, 9, 5], state: "sullysmod:petrified_log{axis:y}"},
        {pos: [12, 9, 10], state: "minecraft:suspicious_gravel{dusted:0}", nbt: {id: "minecraft:brushable_block", item: {Count: 0b, id: "minecraft:air"}}},
        {pos: [12, 9, 11], state: "sullysmod:petrified_log{axis:y}"},
        {pos: [12, 9, 12], state: "sullysmod:petrified_log{axis:y}"},
        {pos: [13, 9, 6], state: "sullysmod:petrified_log{axis:y}"},
        {pos: [13, 9, 7], state: "sullysmod:petrified_log{axis:y}"},
        {pos: [13, 9, 8], state: "sullysmod:petrified_log{axis:y}"},
        {pos: [13, 9, 9], state: "sullysmod:petrified_log{axis:y}"},
        {pos: [13, 9, 10], state: "sullysmod:petrified_log{axis:y}"},
        {pos: [1, 10, 7], state: "sullysmod:petrified_log{axis:y}"},
        {pos: [1, 10, 9], state: "sullysmod:petrified_log{axis:y}"},
        {pos: [1, 10, 10], state: "sullysmod:petrified_log{axis:y}"},
        {pos: [2, 10, 11], state: "sullysmod:petrified_log{axis:y}"},
        {pos: [2, 10, 12], state: "sullysmod:petrified_log{axis:y}"},
        {pos: [3, 10, 12], state: "sullysmod:petrified_log{axis:y}"},
        {pos: [3, 10, 13], state: "sullysmod:petrified_log{axis:y}"},
        {pos: [4, 10, 13], state: "sullysmod:petrified_log{axis:y}"},
        {pos: [5, 10, 2], state: "sullysmod:stripped_petrified_log{axis:y}"},
        {pos: [5, 10, 14], state: "sullysmod:petrified_log{axis:y}"},
        {pos: [6, 10, 2], state: "sullysmod:petrified_log{axis:y}"},
        {pos: [6, 10, 14], state: "sullysmod:petrified_log{axis:y}"},
        {pos: [7, 10, 2], state: "sullysmod:petrified_log{axis:y}"},
        {pos: [7, 10, 14], state: "sullysmod:petrified_log{axis:y}"},
        {pos: [8, 10, 2], state: "sullysmod:petrified_log{axis:y}"},
        {pos: [8, 10, 14], state: "minecraft:air"},
        {pos: [9, 10, 2], state: "sullysmod:petrified_log{axis:y}"},
        {pos: [9, 10, 3], state: "sullysmod:petrified_log{axis:y}"},
        {pos: [9, 10, 14], state: "sullysmod:stripped_petrified_log{axis:y}"},
        {pos: [10, 10, 3], state: "sullysmod:petrified_log{axis:y}"},
        {pos: [10, 10, 13], state: "sullysmod:petrified_log{axis:y}"},
        {pos: [11, 10, 3], state: "sullysmod:petrified_log{axis:y}"},
        {pos: [11, 10, 4], state: "sullysmod:petrified_log{axis:y}"},
        {pos: [11, 10, 12], state: "sullysmod:petrified_log{axis:y}"},
        {pos: [11, 10, 13], state: "sullysmod:petrified_log{axis:y}"},
        {pos: [12, 10, 4], state: "sullysmod:petrified_log{axis:y}"},
        {pos: [12, 10, 5], state: "sullysmod:petrified_log{axis:y}"},
        {pos: [12, 10, 11], state: "sullysmod:petrified_log{axis:y}"},
        {pos: [12, 10, 12], state: "sullysmod:petrified_log{axis:y}"},
        {pos: [13, 10, 6], state: "sullysmod:petrified_log{axis:y}"},
        {pos: [13, 10, 7], state: "sullysmod:petrified_log{axis:y}"},
        {pos: [13, 10, 8], state: "sullysmod:petrified_log{axis:y}"},
        {pos: [13, 10, 9], state: "sullysmod:petrified_log{axis:y}"},
        {pos: [13, 10, 10], state: "sullysmod:petrified_log{axis:y}"},
        {pos: [1, 11, 7], state: "sullysmod:stripped_petrified_log{axis:y}"},
        {pos: [1, 11, 9], state: "sullysmod:petrified_log{axis:y}"},
        {pos: [1, 11, 10], state: "sullysmod:petrified_log{axis:y}"},
        {pos: [2, 11, 11], state: "sullysmod:petrified_log{axis:y}"},
        {pos: [2, 11, 12], state: "sullysmod:petrified_log{axis:y}"},
        {pos: [3, 11, 12], state: "sullysmod:petrified_log{axis:y}"},
        {pos: [3, 11, 13], state: "sullysmod:petrified_log{axis:y}"},
        {pos: [4, 11, 13], state: "sullysmod:petrified_log{axis:y}"},
        {pos: [5, 11, 14], state: "sullysmod:petrified_log{axis:y}"},
        {pos: [6, 11, 2], state: "sullysmod:petrified_log{axis:y}"},
        {pos: [6, 11, 14], state: "sullysmod:petrified_log{axis:y}"},
        {pos: [7, 11, 2], state: "sullysmod:stripped_petrified_log{axis:y}"},
        {pos: [7, 11, 14], state: "sullysmod:petrified_log{axis:y}"},
        {pos: [8, 11, 2], state: "sullysmod:petrified_log{axis:y}"},
        {pos: [8, 11, 14], state: "sullysmod:stripped_petrified_log{axis:y}"},
        {pos: [9, 11, 2], state: "sullysmod:petrified_log{axis:y}"},
        {pos: [9, 11, 3], state: "sullysmod:petrified_log{axis:y}"},
        {pos: [9, 11, 14], state: "minecraft:air"},
        {pos: [10, 11, 3], state: "sullysmod:petrified_log{axis:y}"},
        {pos: [10, 11, 13], state: "sullysmod:petrified_log{axis:y}"},
        {pos: [11, 11, 3], state: "sullysmod:petrified_log{axis:y}"},
        {pos: [11, 11, 4], state: "sullysmod:petrified_log{axis:y}"},
        {pos: [11, 11, 13], state: "sullysmod:petrified_log{axis:y}"},
        {pos: [12, 11, 4], state: "sullysmod:petrified_log{axis:y}"},
        {pos: [12, 11, 5], state: "sullysmod:petrified_log{axis:y}"},
        {pos: [12, 11, 11], state: "sullysmod:petrified_log{axis:y}"},
        {pos: [12, 11, 12], state: "sullysmod:petrified_log{axis:y}"},
        {pos: [13, 11, 6], state: "sullysmod:petrified_log{axis:y}"},
        {pos: [13, 11, 7], state: "sullysmod:petrified_log{axis:y}"},
        {pos: [13, 11, 8], state: "sullysmod:petrified_log{axis:y}"},
        {pos: [13, 11, 9], state: "sullysmod:petrified_log{axis:y}"},
        {pos: [13, 11, 10], state: "sullysmod:petrified_log{axis:y}"},
        {pos: [1, 12, 9], state: "sullysmod:stripped_petrified_log{axis:y}"},
        {pos: [1, 12, 10], state: "sullysmod:petrified_log{axis:y}"},
        {pos: [2, 12, 11], state: "sullysmod:petrified_log{axis:y}"},
        {pos: [2, 12, 12], state: "sullysmod:petrified_log{axis:y}"},
        {pos: [3, 12, 13], state: "sullysmod:petrified_log{axis:y}"},
        {pos: [4, 12, 13], state: "sullysmod:petrified_log{axis:y}"},
        {pos: [5, 12, 14], state: "sullysmod:petrified_log{axis:y}"},
        {pos: [6, 12, 2], state: "sullysmod:petrified_log{axis:y}"},
        {pos: [6, 12, 14], state: "sullysmod:petrified_log{axis:y}"},
        {pos: [7, 12, 14], state: "sullysmod:petrified_log{axis:y}"},
        {pos: [8, 12, 2], state: "sullysmod:petrified_log{axis:y}"},
        {pos: [8, 12, 14], state: "sullysmod:stripped_petrified_log{axis:y}"},
        {pos: [9, 12, 2], state: "sullysmod:petrified_log{axis:y}"},
        {pos: [9, 12, 14], state: "sullysmod:stripped_petrified_log{axis:y}"},
        {pos: [10, 12, 3], state: "sullysmod:petrified_log{axis:y}"},
        {pos: [10, 12, 13], state: "sullysmod:stripped_petrified_log{axis:y}"},
        {pos: [11, 12, 3], state: "sullysmod:petrified_log{axis:y}"},
        {pos: [11, 12, 13], state: "sullysmod:petrified_log{axis:y}"},
        {pos: [12, 12, 4], state: "sullysmod:petrified_log{axis:y}"},
        {pos: [12, 12, 5], state: "sullysmod:petrified_log{axis:y}"},
        {pos: [12, 12, 11], state: "sullysmod:petrified_log{axis:y}"},
        {pos: [12, 12, 12], state: "sullysmod:petrified_log{axis:y}"},
        {pos: [13, 12, 6], state: "sullysmod:petrified_log{axis:y}"},
        {pos: [13, 12, 7], state: "sullysmod:petrified_log{axis:y}"},
        {pos: [13, 12, 8], state: "sullysmod:petrified_log{axis:y}"},
        {pos: [13, 12, 9], state: "sullysmod:petrified_log{axis:y}"},
        {pos: [13, 12, 10], state: "sullysmod:petrified_log{axis:y}"},
        {pos: [1, 13, 10], state: "sullysmod:petrified_log{axis:y}"},
        {pos: [2, 13, 11], state: "sullysmod:stripped_petrified_log{axis:y}"},
        {pos: [2, 13, 12], state: "sullysmod:petrified_log{axis:y}"},
        {pos: [3, 13, 13], state: "sullysmod:petrified_log{axis:y}"},
        {pos: [5, 13, 14], state: "sullysmod:petrified_log{axis:y}"},
        {pos: [6, 13, 2], state: "sullysmod:stripped_petrified_log{axis:y}"},
        {pos: [6, 13, 14], state: "sullysmod:stripped_petrified_log{axis:y}"},
        {pos: [7, 13, 14], state: "sullysmod:petrified_log{axis:y}"},
        {pos: [8, 13, 2], state: "sullysmod:petrified_log{axis:y}"},
        {pos: [8, 13, 14], state: "sullysmod:petrified_log{axis:y}"},
        {pos: [9, 13, 2], state: "sullysmod:petrified_log{axis:y}"},
        {pos: [9, 13, 14], state: "sullysmod:petrified_log{axis:y}"},
        {pos: [10, 13, 3], state: "sullysmod:petrified_log{axis:y}"},
        {pos: [10, 13, 13], state: "sullysmod:stripped_petrified_log{axis:y}"},
        {pos: [11, 13, 13], state: "sullysmod:petrified_log{axis:y}"},
        {pos: [12, 13, 4], state: "sullysmod:petrified_log{axis:y}"},
        {pos: [12, 13, 5], state: "sullysmod:petrified_log{axis:y}"},
        {pos: [12, 13, 11], state: "sullysmod:petrified_log{axis:y}"},
        {pos: [12, 13, 12], state: "sullysmod:petrified_log{axis:y}"},
        {pos: [13, 13, 6], state: "sullysmod:petrified_log{axis:y}"},
        {pos: [13, 13, 7], state: "sullysmod:petrified_log{axis:y}"},
        {pos: [13, 13, 8], state: "sullysmod:petrified_log{axis:y}"},
        {pos: [13, 13, 9], state: "sullysmod:stripped_petrified_log{axis:y}"},
        {pos: [13, 13, 10], state: "sullysmod:petrified_log{axis:y}"},
        {pos: [1, 14, 10], state: "sullysmod:stripped_petrified_log{axis:y}"},
        {pos: [2, 14, 12], state: "sullysmod:petrified_log{axis:y}"},
        {pos: [3, 14, 13], state: "sullysmod:stripped_petrified_log{axis:y}"},
        {pos: [5, 14, 14], state: "sullysmod:petrified_log{axis:y}"},
        {pos: [7, 14, 14], state: "sullysmod:stripped_petrified_log{axis:y}"},
        {pos: [8, 14, 2], state: "sullysmod:stripped_petrified_log{axis:y}"},
        {pos: [8, 14, 14], state: "sullysmod:petrified_log{axis:y}"},
        {pos: [9, 14, 2], state: "sullysmod:petrified_log{axis:y}"},
        {pos: [9, 14, 14], state: "sullysmod:petrified_log{axis:y}"},
        {pos: [10, 14, 3], state: "sullysmod:petrified_log{axis:y}"},
        {pos: [10, 14, 13], state: "sullysmod:petrified_log{axis:y}"},
        {pos: [11, 14, 13], state: "sullysmod:petrified_log{axis:y}"},
        {pos: [12, 14, 4], state: "sullysmod:petrified_log{axis:y}"},
        {pos: [12, 14, 5], state: "sullysmod:petrified_log{axis:y}"},
        {pos: [12, 14, 11], state: "sullysmod:petrified_log{axis:y}"},
        {pos: [12, 14, 12], state: "sullysmod:stripped_petrified_log{axis:y}"},
        {pos: [13, 14, 6], state: "sullysmod:petrified_log{axis:y}"},
        {pos: [13, 14, 7], state: "sullysmod:petrified_log{axis:y}"},
        {pos: [13, 14, 8], state: "sullysmod:stripped_petrified_log{axis:y}"},
        {pos: [13, 14, 9], state: "sullysmod:stripped_petrified_log{axis:y}"},
        {pos: [2, 15, 12], state: "sullysmod:stripped_petrified_log{axis:y}"},
        {pos: [5, 15, 14], state: "sullysmod:petrified_log{axis:y}"},
        {pos: [8, 15, 14], state: "sullysmod:stripped_petrified_log{axis:y}"},
        {pos: [9, 15, 2], state: "sullysmod:petrified_log{axis:y}"},
        {pos: [9, 15, 14], state: "sullysmod:petrified_log{axis:y}"},
        {pos: [10, 15, 3], state: "sullysmod:stripped_petrified_log{axis:y}"},
        {pos: [10, 15, 13], state: "sullysmod:stripped_petrified_log{axis:y}"},
        {pos: [11, 15, 13], state: "sullysmod:petrified_log{axis:y}"},
        {pos: [12, 15, 4], state: "sullysmod:petrified_log{axis:y}"},
        {pos: [12, 15, 5], state: "sullysmod:stripped_petrified_log{axis:y}"},
        {pos: [12, 15, 11], state: "sullysmod:stripped_petrified_log{axis:y}"},
        {pos: [13, 15, 6], state: "sullysmod:petrified_log{axis:y}"},
        {pos: [13, 15, 8], state: "sullysmod:stripped_petrified_log{axis:y}"},
        {pos: [2, 16, 12], state: "sullysmod:stripped_petrified_log{axis:y}"},
        {pos: [5, 16, 14], state: "sullysmod:stripped_petrified_log{axis:y}"},
        {pos: [9, 16, 2], state: "sullysmod:stripped_petrified_log{axis:y}"},
        {pos: [9, 16, 14], state: "sullysmod:stripped_petrified_log{axis:y}"},
        {pos: [11, 16, 13], state: "sullysmod:petrified_log{axis:y}"},
        {pos: [12, 16, 4], state: "sullysmod:stripped_petrified_log{axis:y}"},
        {pos: [13, 16, 6], state: "sullysmod:stripped_petrified_log{axis:y}"},
        {pos: [13, 16, 8], state: "sullysmod:stripped_petrified_log{axis:y}"},
        {pos: [11, 17, 13], state: "sullysmod:stripped_petrified_log{axis:y}"}
    ],
    entities: [],
    palette: [
        "sullysmod:stripped_petrified_log{axis:y}",
        "minecraft:gravel",
        "sullysmod:petrified_log{axis:y}",
        "sullysmod:petrified_sapling{stage:0}",
        "minecraft:air",
        "minecraft:suspicious_gravel{dusted:0}"
    ]
}
