{
    DataVersion: 3465,
    size: [11, 17, 11],
    data: [
        {pos: [5, 0, 3], state: "sullysmod:amber{is_melted:false}", nbt: {RenderEntity: 0b, StuckEntity: [], id: "sullysmod:amber"}},
        {pos: [5, 1, 3], state: "sullysmod:petrified_log{axis:y}"},
        {pos: [5, 2, 3], state: "sullysmod:stripped_petrified_log{axis:y}"},
        {pos: [6, 2, 3], state: "sullysmod:petrified_log{axis:x}"},
        {pos: [0, 3, 4], state: "sullysmod:amber{is_melted:false}", nbt: {RenderEntity: 0b, StuckEntity: [], id: "sullysmod:amber"}},
        {pos: [3, 3, 4], state: "minecraft:gravel"},
        {pos: [3, 3, 5], state: "sullysmod:amber{is_melted:false}", nbt: {RenderEntity: 0b, StuckEntity: [], id: "sullysmod:amber"}},
        {pos: [3, 3, 6], state: "minecraft:gravel"},
        {pos: [4, 3, 2], state: "minecraft:gravel"},
        {pos: [4, 3, 3], state: "minecraft:gravel"},
        {pos: [4, 3, 4], state: "minecraft:gravel"},
        {pos: [4, 3, 5], state: "minecraft:gravel"},
        {pos: [4, 3, 6], state: "minecraft:gravel"},
        {pos: [5, 3, 1], state: "minecraft:gravel"},
        {pos: [5, 3, 2], state: "minecraft:gravel"},
        {pos: [5, 3, 3], state: "sullysmod:stripped_petrified_log{axis:y}"},
        {pos: [5, 3, 4], state: "sullysmod:stripped_petrified_log{axis:y}"},
        {pos: [5, 3, 5], state: "minecraft:gravel"},
        {pos: [5, 3, 6], state: "minecraft:gravel"},
        {pos: [5, 3, 7], state: "minecraft:gravel"},
        {pos: [6, 3, 1], state: "minecraft:gravel"},
        {pos: [6, 3, 2], state: "minecraft:gravel"},
        {pos: [6, 3, 3], state: "minecraft:gravel"},
        {pos: [6, 3, 4], state: "minecraft:gravel"},
        {pos: [6, 3, 5], state: "minecraft:gravel"},
        {pos: [6, 3, 6], state: "minecraft:gravel"},
        {pos: [6, 3, 7], state: "minecraft:gravel"},
        {pos: [7, 3, 2], state: "minecraft:gravel"},
        {pos: [7, 3, 3], state: "minecraft:gravel"},
        {pos: [7, 3, 4], state: "minecraft:gravel"},
        {pos: [7, 3, 5], state: "minecraft:gravel"},
        {pos: [7, 3, 6], state: "sullysmod:stripped_petrified_log{axis:y}"},
        {pos: [7, 3, 7], state: "minecraft:gravel"},
        {pos: [8, 3, 4], state: "minecraft:gravel"},
        {pos: [8, 3, 5], state: "minecraft:gravel"},
        {pos: [10, 3, 4], state: "sullysmod:amber{is_melted:false}", nbt: {RenderEntity: 0b, StuckEntity: [], id: "sullysmod:amber"}},
        {pos: [0, 4, 4], state: "sullysmod:petrified_log{axis:z}"},
        {pos: [0, 4, 5], state: "sullysmod:petrified_log{axis:x}"},
        {pos: [1, 4, 5], state: "sullysmod:petrified_log{axis:x}"},
        {pos: [2, 4, 3], state: "minecraft:gravel"},
        {pos: [2, 4, 4], state: "minecraft:gravel"},
        {pos: [2, 4, 5], state: "sullysmod:stripped_petrified_log{axis:x}"},
        {pos: [2, 4, 6], state: "sullysmod:stripped_petrified_log{axis:z}"},
        {pos: [3, 4, 2], state: "minecraft:gravel"},
        {pos: [3, 4, 3], state: "minecraft:gravel"},
        {pos: [3, 4, 4], state: "minecraft:gravel"},
        {pos: [3, 4, 5], state: "sullysmod:stripped_petrified_log{axis:x}"},
        {pos: [3, 4, 6], state: "minecraft:gravel"},
        {pos: [3, 4, 7], state: "minecraft:gravel"},
        {pos: [3, 4, 8], state: "minecraft:gravel"},
        {pos: [4, 4, 1], state: "minecraft:gravel"},
        {pos: [4, 4, 2], state: "minecraft:gravel"},
        {pos: [4, 4, 3], state: "minecraft:gravel"},
        {pos: [4, 4, 4], state: "minecraft:gravel"},
        {pos: [4, 4, 5], state: "minecraft:gravel"},
        {pos: [4, 4, 6], state: "minecraft:gravel"},
        {pos: [4, 4, 7], state: "minecraft:gravel"},
        {pos: [4, 4, 8], state: "minecraft:gravel"},
        {pos: [4, 4, 9], state: "minecraft:gravel"},
        {pos: [5, 4, 0], state: "minecraft:gravel"},
        {pos: [5, 4, 1], state: "minecraft:gravel"},
        {pos: [5, 4, 2], state: "minecraft:gravel"},
        {pos: [5, 4, 3], state: "minecraft:gravel"},
        {pos: [5, 4, 4], state: "sullysmod:stripped_petrified_log{axis:y}"},
        {pos: [5, 4, 5], state: "sullysmod:petrified_log{axis:z}"},
        {pos: [5, 4, 6], state: "minecraft:gravel"},
        {pos: [5, 4, 7], state: "minecraft:gravel"},
        {pos: [5, 4, 8], state: "minecraft:gravel"},
        {pos: [5, 4, 9], state: "minecraft:gravel"},
        {pos: [5, 4, 10], state: "sullysmod:amber{is_melted:false}", nbt: {RenderEntity: 0b, StuckEntity: [], id: "sullysmod:amber"}},
        {pos: [6, 4, 0], state: "minecraft:gravel"},
        {pos: [6, 4, 1], state: "minecraft:gravel"},
        {pos: [6, 4, 2], state: "minecraft:gravel"},
        {pos: [6, 4, 3], state: "minecraft:gravel"},
        {pos: [6, 4, 4], state: "minecraft:gravel"},
        {pos: [6, 4, 5], state: "minecraft:gravel"},
        {pos: [6, 4, 6], state: "minecraft:gravel"},
        {pos: [6, 4, 7], state: "minecraft:gravel"},
        {pos: [6, 4, 8], state: "minecraft:gravel"},
        {pos: [7, 4, 0], state: "sullysmod:stripped_petrified_log{axis:y}"},
        {pos: [7, 4, 1], state: "minecraft:gravel"},
        {pos: [7, 4, 2], state: "minecraft:gravel"},
        {pos: [7, 4, 3], state: "minecraft:gravel"},
        {pos: [7, 4, 4], state: "minecraft:gravel"},
        {pos: [7, 4, 5], state: "minecraft:gravel"},
        {pos: [7, 4, 6], state: "sullysmod:petrified_log{axis:y}"},
        {pos: [7, 4, 7], state: "minecraft:gravel"},
        {pos: [8, 4, 1], state: "minecraft:gravel"},
        {pos: [8, 4, 2], state: "minecraft:gravel"},
        {pos: [8, 4, 3], state: "minecraft:gravel"},
        {pos: [8, 4, 4], state: "minecraft:gravel"},
        {pos: [8, 4, 5], state: "minecraft:gravel"},
        {pos: [8, 4, 6], state: "minecraft:gravel"},
        {pos: [9, 4, 3], state: "minecraft:gravel"},
        {pos: [9, 4, 4], state: "minecraft:gravel"},
        {pos: [9, 4, 5], state: "minecraft:gravel"},
        {pos: [9, 4, 8], state: "sullysmod:amber{is_melted:false}", nbt: {RenderEntity: 0b, StuckEntity: [], id: "sullysmod:amber"}},
        {pos: [10, 4, 4], state: "sullysmod:petrified_log{axis:y}"},
        {pos: [1, 5, 7], state: "sullysmod:amber{is_melted:false}", nbt: {RenderEntity: 0b, StuckEntity: [], id: "sullysmod:amber"}},
        {pos: [2, 5, 3], state: "minecraft:gravel"},
        {pos: [2, 5, 4], state: "minecraft:gravel"},
        {pos: [2, 5, 5], state: "minecraft:suspicious_gravel{dusted:0}", nbt: {id: "minecraft:brushable_block", item: {Count: 0b, id: "minecraft:air"}}},
        {pos: [2, 5, 6], state: "minecraft:gravel"},
        {pos: [2, 5, 7], state: "minecraft:gravel"},
        {pos: [3, 5, 1], state: "minecraft:gravel"},
        {pos: [3, 5, 2], state: "minecraft:gravel"},
        {pos: [3, 5, 3], state: "sullysmod:amber{is_melted:false}", nbt: {RenderEntity: 0b, StuckEntity: [], id: "sullysmod:amber"}},
        {pos: [3, 5, 4], state: "sullysmod:stripped_petrified_log{axis:z}"},
        {pos: [3, 5, 5], state: "sullysmod:stripped_petrified_log{axis:y}"},
        {pos: [3, 5, 6], state: "minecraft:gravel"},
        {pos: [3, 5, 7], state: "minecraft:gravel"},
        {pos: [3, 5, 8], state: "minecraft:gravel"},
        {pos: [3, 5, 9], state: "minecraft:gravel"},
        {pos: [4, 5, 0], state: "sullysmod:stripped_petrified_log{axis:z}"},
        {pos: [4, 5, 1], state: "sullysmod:petrified_log{axis:z}"},
        {pos: [4, 5, 2], state: "sullysmod:petrified_log{axis:y}"},
        {pos: [4, 5, 3], state: "minecraft:gravel"},
        {pos: [4, 5, 4], state: "minecraft:gravel"},
        {pos: [4, 5, 5], state: "minecraft:gravel"},
        {pos: [4, 5, 6], state: "minecraft:gravel"},
        {pos: [4, 5, 7], state: "minecraft:gravel"},
        {pos: [4, 5, 8], state: "minecraft:gravel"},
        {pos: [4, 5, 9], state: "minecraft:gravel"},
        {pos: [4, 5, 10], state: "minecraft:gravel"},
        {pos: [5, 5, 0], state: "minecraft:gravel"},
        {pos: [5, 5, 1], state: "minecraft:gravel"},
        {pos: [5, 5, 2], state: "minecraft:gravel"},
        {pos: [5, 5, 3], state: "minecraft:gravel"},
        {pos: [5, 5, 4], state: "sullysmod:stripped_petrified_log{axis:y}"},
        {pos: [5, 5, 5], state: "minecraft:gravel"},
        {pos: [5, 5, 6], state: "minecraft:gravel"},
        {pos: [5, 5, 7], state: "minecraft:gravel"},
        {pos: [5, 5, 8], state: "sullysmod:stripped_petrified_log{axis:y}"},
        {pos: [5, 5, 9], state: "sullysmod:petrified_log{axis:z}"},
        {pos: [5, 5, 10], state: "sullysmod:petrified_log{axis:z}"},
        {pos: [6, 5, 0], state: "minecraft:gravel"},
        {pos: [6, 5, 1], state: "minecraft:gravel"},
        {pos: [6, 5, 2], state: "minecraft:gravel"},
        {pos: [6, 5, 3], state: "minecraft:gravel"},
        {pos: [6, 5, 4], state: "minecraft:gravel"},
        {pos: [6, 5, 5], state: "minecraft:gravel"},
        {pos: [6, 5, 6], state: "minecraft:gravel"},
        {pos: [6, 5, 7], state: "minecraft:gravel"},
        {pos: [6, 5, 8], state: "minecraft:gravel"},
        {pos: [6, 5, 9], state: "minecraft:gravel"},
        {pos: [7, 5, 0], state: "sullysmod:petrified_log{axis:z}"},
        {pos: [7, 5, 1], state: "sullysmod:petrified_log{axis:z}"},
        {pos: [7, 5, 2], state: "sullysmod:stripped_petrified_log{axis:y}"},
        {pos: [7, 5, 3], state: "minecraft:gravel"},
        {pos: [7, 5, 4], state: "sullysmod:amber{is_melted:false}", nbt: {RenderEntity: 0b, StuckEntity: [], id: "sullysmod:amber"}},
        {pos: [7, 5, 5], state: "minecraft:gravel"},
        {pos: [7, 5, 6], state: "sullysmod:petrified_log{axis:y}"},
        {pos: [7, 5, 7], state: "minecraft:gravel"},
        {pos: [7, 5, 8], state: "minecraft:gravel"},
        {pos: [8, 5, 1], state: "minecraft:gravel"},
        {pos: [8, 5, 2], state: "minecraft:gravel"},
        {pos: [8, 5, 3], state: "minecraft:gravel"},
        {pos: [8, 5, 4], state: "minecraft:gravel"},
        {pos: [8, 5, 5], state: "minecraft:gravel"},
        {pos: [8, 5, 6], state: "sullysmod:petrified_log{axis:x}"},
        {pos: [8, 5, 7], state: "minecraft:gravel"},
        {pos: [8, 5, 8], state: "minecraft:gravel"},
        {pos: [9, 5, 2], state: "minecraft:gravel"},
        {pos: [9, 5, 3], state: "minecraft:gravel"},
        {pos: [9, 5, 4], state: "sullysmod:stripped_petrified_log{axis:x}"},
        {pos: [9, 5, 5], state: "minecraft:gravel"},
        {pos: [9, 5, 6], state: "sullysmod:petrified_log{axis:x}"},
        {pos: [9, 5, 7], state: "sullysmod:petrified_log{axis:z}"},
        {pos: [9, 5, 8], state: "sullysmod:stripped_petrified_log{axis:z}"},
        {pos: [10, 5, 3], state: "minecraft:gravel"},
        {pos: [10, 5, 4], state: "sullysmod:stripped_petrified_log{axis:x}"},
        {pos: [10, 5, 5], state: "minecraft:gravel"},
        {pos: [1, 6, 3], state: "sullysmod:stripped_petrified_log{axis:x}"},
        {pos: [1, 6, 4], state: "minecraft:gravel"},
        {pos: [1, 6, 5], state: "sullysmod:petrified_log{axis:z}"},
        {pos: [1, 6, 6], state: "sullysmod:petrified_log{axis:z}"},
        {pos: [1, 6, 7], state: "sullysmod:stripped_petrified_log{axis:z}"},
        {pos: [2, 6, 3], state: "sullysmod:petrified_log{axis:x}"},
        {pos: [2, 6, 4], state: "minecraft:gravel"},
        {pos: [2, 6, 5], state: "sullysmod:petrified_log{axis:x}"},
        {pos: [2, 6, 6], state: "minecraft:gravel"},
        {pos: [2, 6, 7], state: "minecraft:gravel"},
        {pos: [2, 6, 8], state: "minecraft:gravel"},
        {pos: [3, 6, 1], state: "minecraft:gravel"},
        {pos: [3, 6, 2], state: "minecraft:gravel"},
        {pos: [3, 6, 3], state: "sullysmod:stripped_petrified_log{axis:y}"},
        {pos: [3, 6, 4], state: "minecraft:gravel"},
        {pos: [3, 6, 5], state: "sullysmod:petrified_log{axis:y}"},
        {pos: [3, 6, 6], state: "minecraft:gravel"},
        {pos: [3, 6, 7], state: "minecraft:gravel"},
        {pos: [3, 6, 8], state: "minecraft:gravel"},
        {pos: [3, 6, 9], state: "minecraft:gravel"},
        {pos: [3, 6, 10], state: "minecraft:gravel"},
        {pos: [4, 6, 0], state: "minecraft:gravel"},
        {pos: [4, 6, 1], state: "minecraft:gravel"},
        {pos: [4, 6, 2], state: "sullysmod:petrified_log{axis:y}"},
        {pos: [4, 6, 3], state: "minecraft:gravel"},
        {pos: [4, 6, 4], state: "sullysmod:rough_amber{is_melted:false}"},
        {pos: [4, 6, 5], state: "minecraft:gravel"},
        {pos: [4, 6, 6], state: "sullysmod:amber{is_melted:false}", nbt: {RenderEntity: 0b, StuckEntity: [], id: "sullysmod:amber"}},
        {pos: [4, 6, 7], state: "minecraft:gravel"},
        {pos: [4, 6, 8], state: "sullysmod:stripped_petrified_log{axis:x}"},
        {pos: [4, 6, 9], state: "minecraft:gravel"},
        {pos: [4, 6, 10], state: "minecraft:gravel"},
        {pos: [5, 6, 0], state: "minecraft:gravel"},
        {pos: [5, 6, 1], state: "minecraft:gravel"},
        {pos: [5, 6, 2], state: "minecraft:gravel"},
        {pos: [5, 6, 3], state: "minecraft:gravel"},
        {pos: [5, 6, 4], state: "sullysmod:petrified_log{axis:y}"},
        {pos: [5, 6, 5], state: "sullysmod:amber{is_melted:false}", nbt: {RenderEntity: 0b, StuckEntity: [], id: "sullysmod:amber"}},
        {pos: [5, 6, 6], state: "minecraft:gravel"},
        {pos: [5, 6, 7], state: "sullysmod:stripped_petrified_log{axis:y}"},
        {pos: [5, 6, 8], state: "sullysmod:petrified_log{axis:y}"},
        {pos: [5, 6, 9], state: "minecraft:gravel"},
        {pos: [5, 6, 10], state: "minecraft:gravel"},
        {pos: [6, 6, 0], state: "minecraft:gravel"},
        {pos: [6, 6, 1], state: "minecraft:gravel"},
        {pos: [6, 6, 2], state: "minecraft:gravel"},
        {pos: [6, 6, 3], state: "minecraft:gravel"},
        {pos: [6, 6, 4], state: "sullysmod:amber{is_melted:false}", nbt: {RenderEntity: 0b, StuckEntity: [], id: "sullysmod:amber"}},
        {pos: [6, 6, 5], state: "minecraft:gravel"},
        {pos: [6, 6, 6], state: "minecraft:gravel"},
        {pos: [6, 6, 7], state: "minecraft:gravel"},
        {pos: [6, 6, 8], state: "minecraft:gravel"},
        {pos: [6, 6, 9], state: "minecraft:gravel"},
        {pos: [7, 6, 1], state: "minecraft:gravel"},
        {pos: [7, 6, 2], state: "sullysmod:petrified_log{axis:y}"},
        {pos: [7, 6, 3], state: "minecraft:gravel"},
        {pos: [7, 6, 4], state: "sullysmod:amber{is_melted:false}", nbt: {RenderEntity: 0b, StuckEntity: [], id: "sullysmod:amber"}},
        {pos: [7, 6, 5], state: "minecraft:gravel"},
        {pos: [7, 6, 6], state: "sullysmod:stripped_petrified_log{axis:y}"},
        {pos: [7, 6, 7], state: "minecraft:gravel"},
        {pos: [7, 6, 8], state: "minecraft:gravel"},
        {pos: [8, 6, 1], state: "minecraft:gravel"},
        {pos: [8, 6, 2], state: "minecraft:gravel"},
        {pos: [8, 6, 3], state: "sullysmod:petrified_log{axis:y}"},
        {pos: [8, 6, 4], state: "sullysmod:petrified_log{axis:y}"},
        {pos: [8, 6, 5], state: "minecraft:gravel"},
        {pos: [8, 6, 6], state: "minecraft:gravel"},
        {pos: [8, 6, 7], state: "minecraft:gravel"},
        {pos: [8, 6, 8], state: "minecraft:gravel"},
        {pos: [9, 6, 2], state: "minecraft:gravel"},
        {pos: [9, 6, 3], state: "minecraft:gravel"},
        {pos: [9, 6, 4], state: "minecraft:suspicious_gravel{dusted:0}", nbt: {id: "minecraft:brushable_block", item: {Count: 0b, id: "minecraft:air"}}},
        {pos: [9, 6, 5], state: "minecraft:gravel"},
        {pos: [9, 6, 6], state: "minecraft:gravel"},
        {pos: [9, 6, 7], state: "minecraft:suspicious_gravel{dusted:0}", nbt: {id: "minecraft:brushable_block", item: {Count: 0b, id: "minecraft:air"}}},
        {pos: [10, 6, 2], state: "minecraft:gravel"},
        {pos: [10, 6, 3], state: "minecraft:gravel"},
        {pos: [10, 6, 4], state: "minecraft:gravel"},
        {pos: [10, 6, 5], state: "minecraft:gravel"},
        {pos: [1, 7, 4], state: "minecraft:gravel"},
        {pos: [2, 7, 3], state: "minecraft:gravel"},
        {pos: [2, 7, 4], state: "minecraft:gravel"},
        {pos: [2, 7, 5], state: "minecraft:gravel"},
        {pos: [2, 7, 6], state: "minecraft:gravel"},
        {pos: [2, 7, 7], state: "minecraft:gravel"},
        {pos: [3, 7, 2], state: "minecraft:gravel"},
        {pos: [3, 7, 3], state: "minecraft:gravel"},
        {pos: [3, 7, 4], state: "sullysmod:petrified_log{axis:y}"},
        {pos: [3, 7, 5], state: "sullysmod:petrified_log{axis:y}"},
        {pos: [3, 7, 6], state: "minecraft:gravel"},
        {pos: [3, 7, 7], state: "minecraft:gravel"},
        {pos: [3, 7, 8], state: "minecraft:gravel"},
        {pos: [4, 7, 2], state: "sullysmod:petrified_log{axis:y}"},
        {pos: [4, 7, 3], state: "sullysmod:petrified_log{axis:y}"},
        {pos: [4, 7, 4], state: "sullysmod:petrified_log{axis:y}"},
        {pos: [4, 7, 5], state: "minecraft:gravel"},
        {pos: [4, 7, 6], state: "sullysmod:petrified_log{axis:y}"},
        {pos: [4, 7, 7], state: "minecraft:gravel"},
        {pos: [4, 7, 8], state: "minecraft:gravel"},
        {pos: [4, 7, 9], state: "minecraft:gravel"},
        {pos: [5, 7, 1], state: "minecraft:gravel"},
        {pos: [5, 7, 2], state: "sullysmod:petrified_log{axis:y}"},
        {pos: [5, 7, 3], state: "minecraft:gravel"},
        {pos: [5, 7, 4], state: "sullysmod:petrified_log{axis:y}"},
        {pos: [5, 7, 5], state: "sullysmod:stripped_petrified_log{axis:y}"},
        {pos: [5, 7, 6], state: "minecraft:gravel"},
        {pos: [5, 7, 7], state: "sullysmod:petrified_log{axis:y}"},
        {pos: [5, 7, 8], state: "sullysmod:petrified_log{axis:y}"},
        {pos: [5, 7, 9], state: "minecraft:gravel"},
        {pos: [6, 7, 1], state: "minecraft:gravel"},
        {pos: [6, 7, 2], state: "minecraft:gravel"},
        {pos: [6, 7, 3], state: "minecraft:gravel"},
        {pos: [6, 7, 4], state: "sullysmod:rough_amber{is_melted:false}"},
        {pos: [6, 7, 5], state: "sullysmod:petrified_log{axis:y}"},
        {pos: [6, 7, 6], state: "sullysmod:petrified_log{axis:y}"},
        {pos: [6, 7, 7], state: "minecraft:gravel"},
        {pos: [6, 7, 8], state: "minecraft:gravel"},
        {pos: [7, 7, 1], state: "minecraft:gravel"},
        {pos: [7, 7, 2], state: "sullysmod:petrified_log{axis:y}"},
        {pos: [7, 7, 3], state: "sullysmod:rough_amber{is_melted:false}"},
        {pos: [7, 7, 4], state: "sullysmod:rough_amber{is_melted:false}"},
        {pos: [7, 7, 5], state: "minecraft:gravel"},
        {pos: [7, 7, 6], state: "sullysmod:stripped_petrified_log{axis:y}"},
        {pos: [7, 7, 7], state: "minecraft:gravel"},
        {pos: [7, 7, 8], state: "minecraft:gravel"},
        {pos: [8, 7, 2], state: "minecraft:gravel"},
        {pos: [8, 7, 3], state: "sullysmod:petrified_log{axis:y}"},
        {pos: [8, 7, 4], state: "sullysmod:petrified_log{axis:y}"},
        {pos: [8, 7, 5], state: "sullysmod:petrified_log{axis:y}"},
        {pos: [8, 7, 6], state: "minecraft:gravel"},
        {pos: [8, 7, 7], state: "minecraft:gravel"},
        {pos: [9, 7, 3], state: "minecraft:gravel"},
        {pos: [9, 7, 5], state: "minecraft:gravel"},
        {pos: [9, 7, 6], state: "minecraft:gravel"},
        {pos: [10, 7, 4], state: "minecraft:gravel"},
        {pos: [10, 7, 5], state: "minecraft:gravel"},
        {pos: [2, 8, 5], state: "minecraft:gravel"},
        {pos: [3, 8, 3], state: "minecraft:gravel"},
        {pos: [3, 8, 4], state: "sullysmod:petrified_log{axis:y}"},
        {pos: [3, 8, 5], state: "sullysmod:petrified_log{axis:y}"},
        {pos: [3, 8, 6], state: "minecraft:gravel"},
        {pos: [4, 8, 3], state: "sullysmod:petrified_log{axis:y}"},
        {pos: [4, 8, 4], state: "sullysmod:petrified_log{axis:y}"},
        {pos: [4, 8, 5], state: "sullysmod:petrified_log{axis:y}"},
        {pos: [4, 8, 6], state: "sullysmod:petrified_log{axis:y}"},
        {pos: [4, 8, 7], state: "minecraft:gravel"},
        {pos: [5, 8, 2], state: "sullysmod:petrified_log{axis:y}"},
        {pos: [5, 8, 3], state: "sullysmod:petrified_log{axis:y}"},
        {pos: [5, 8, 4], state: "sullysmod:stripped_petrified_log{axis:y}"},
        {pos: [5, 8, 5], state: "sullysmod:stripped_petrified_log{axis:y}"},
        {pos: [5, 8, 6], state: "sullysmod:petrified_log{axis:y}"},
        {pos: [5, 8, 7], state: "sullysmod:petrified_log{axis:y}"},
        {pos: [6, 8, 2], state: "sullysmod:petrified_log{axis:y}"},
        {pos: [6, 8, 3], state: "sullysmod:petrified_log{axis:y}"},
        {pos: [6, 8, 4], state: "sullysmod:stripped_petrified_log{axis:y}"},
        {pos: [6, 8, 5], state: "sullysmod:stripped_petrified_log{axis:y}"},
        {pos: [6, 8, 6], state: "sullysmod:petrified_log{axis:y}"},
        {pos: [6, 8, 7], state: "sullysmod:petrified_log{axis:y}"},
        {pos: [7, 8, 2], state: "minecraft:suspicious_gravel{dusted:0}", nbt: {id: "minecraft:brushable_block", item: {Count: 0b, id: "minecraft:air"}}},
        {pos: [7, 8, 3], state: "sullysmod:petrified_log{axis:y}"},
        {pos: [7, 8, 4], state: "sullysmod:petrified_log{axis:y}"},
        {pos: [7, 8, 5], state: "sullysmod:petrified_log{axis:y}"},
        {pos: [7, 8, 6], state: "sullysmod:petrified_log{axis:y}"},
        {pos: [8, 8, 3], state: "sullysmod:petrified_log{axis:y}"},
        {pos: [8, 8, 4], state: "sullysmod:petrified_log{axis:y}"},
        {pos: [8, 8, 5], state: "sullysmod:petrified_log{axis:y}"},
        {pos: [3, 9, 4], state: "minecraft:gravel"},
        {pos: [3, 9, 5], state: "sullysmod:petrified_log{axis:y}"},
        {pos: [4, 9, 3], state: "sullysmod:petrified_log{axis:y}"},
        {pos: [4, 9, 4], state: "sullysmod:stripped_petrified_log{axis:y}"},
        {pos: [4, 9, 5], state: "sullysmod:petrified_log{axis:y}"},
        {pos: [4, 9, 6], state: "sullysmod:petrified_log{axis:y}"},
        {pos: [5, 9, 3], state: "sullysmod:petrified_log{axis:y}"},
        {pos: [5, 9, 4], state: "sullysmod:stripped_petrified_log{axis:y}"},
        {pos: [5, 9, 5], state: "sullysmod:rough_amber{is_melted:false}"},
        {pos: [5, 9, 6], state: "sullysmod:petrified_log{axis:y}"},
        {pos: [5, 9, 7], state: "minecraft:gravel"},
        {pos: [6, 9, 2], state: "minecraft:gravel"},
        {pos: [6, 9, 3], state: "sullysmod:petrified_log{axis:y}"},
        {pos: [6, 9, 4], state: "sullysmod:stripped_petrified_log{axis:y}"},
        {pos: [6, 9, 5], state: "sullysmod:stripped_petrified_log{axis:y}"},
        {pos: [6, 9, 6], state: "sullysmod:petrified_log{axis:y}"},
        {pos: [6, 9, 7], state: "sullysmod:petrified_log{axis:y}"},
        {pos: [7, 9, 3], state: "sullysmod:petrified_log{axis:y}"},
        {pos: [7, 9, 4], state: "sullysmod:petrified_log{axis:y}"},
        {pos: [7, 9, 5], state: "sullysmod:petrified_log{axis:y}"},
        {pos: [7, 9, 6], state: "sullysmod:petrified_log{axis:y}"},
        {pos: [8, 9, 4], state: "sullysmod:petrified_log{axis:y}"},
        {pos: [8, 9, 5], state: "minecraft:gravel"},
        {pos: [4, 10, 4], state: "sullysmod:rough_amber{is_melted:false}"},
        {pos: [4, 10, 5], state: "sullysmod:petrified_log{axis:y}"},
        {pos: [4, 10, 6], state: "sullysmod:petrified_log{axis:y}"},
        {pos: [5, 10, 3], state: "sullysmod:stripped_petrified_log{axis:y}"},
        {pos: [5, 10, 4], state: "sullysmod:rough_amber{is_melted:false}"},
        {pos: [5, 10, 5], state: "sullysmod:stripped_petrified_log{axis:y}"},
        {pos: [5, 10, 6], state: "sullysmod:petrified_log{axis:y}"},
        {pos: [6, 10, 3], state: "sullysmod:petrified_log{axis:y}"},
        {pos: [6, 10, 4], state: "sullysmod:stripped_petrified_log{axis:y}"},
        {pos: [6, 10, 5], state: "sullysmod:stripped_petrified_log{axis:y}"},
        {pos: [6, 10, 6], state: "sullysmod:petrified_log{axis:y}"},
        {pos: [7, 10, 3], state: "sullysmod:petrified_log{axis:y}"},
        {pos: [7, 10, 4], state: "sullysmod:petrified_log{axis:y}"},
        {pos: [7, 10, 5], state: "sullysmod:petrified_log{axis:y}"},
        {pos: [7, 10, 6], state: "sullysmod:petrified_log{axis:y}"},
        {pos: [8, 10, 4], state: "minecraft:gravel"},
        {pos: [4, 11, 3], state: "sullysmod:stripped_petrified_log{axis:y}"},
        {pos: [4, 11, 4], state: "sullysmod:petrified_log{axis:y}"},
        {pos: [4, 11, 5], state: "sullysmod:petrified_log{axis:y}"},
        {pos: [4, 11, 6], state: "sullysmod:petrified_log{axis:y}"},
        {pos: [5, 11, 3], state: "sullysmod:rough_amber{is_melted:false}"},
        {pos: [5, 11, 4], state: "sullysmod:stripped_petrified_log{axis:y}"},
        {pos: [5, 11, 5], state: "sullysmod:stripped_petrified_log{axis:y}"},
        {pos: [5, 11, 6], state: "sullysmod:petrified_log{axis:y}"},
        {pos: [6, 11, 3], state: "sullysmod:petrified_log{axis:y}"},
        {pos: [6, 11, 4], state: "sullysmod:stripped_petrified_log{axis:y}"},
        {pos: [6, 11, 5], state: "sullysmod:stripped_petrified_log{axis:y}"},
        {pos: [6, 11, 6], state: "sullysmod:petrified_log{axis:y}"},
        {pos: [7, 11, 3], state: "sullysmod:petrified_log{axis:y}"},
        {pos: [7, 11, 4], state: "sullysmod:petrified_log{axis:y}"},
        {pos: [7, 11, 5], state: "sullysmod:petrified_log{axis:y}"},
        {pos: [7, 11, 6], state: "sullysmod:petrified_log{axis:y}"},
        {pos: [3, 12, 5], state: "sullysmod:petrified_log{axis:x}"},
        {pos: [4, 12, 3], state: "sullysmod:petrified_log{axis:y}"},
        {pos: [4, 12, 4], state: "sullysmod:stripped_petrified_log{axis:y}"},
        {pos: [4, 12, 5], state: "sullysmod:petrified_log{axis:y}"},
        {pos: [4, 12, 6], state: "sullysmod:petrified_log{axis:y}"},
        {pos: [5, 12, 3], state: "sullysmod:petrified_log{axis:y}"},
        {pos: [5, 12, 4], state: "sullysmod:stripped_petrified_log{axis:y}"},
        {pos: [5, 12, 5], state: "sullysmod:stripped_petrified_log{axis:y}"},
        {pos: [5, 12, 6], state: "sullysmod:petrified_log{axis:y}"},
        {pos: [6, 12, 3], state: "sullysmod:petrified_log{axis:y}"},
        {pos: [6, 12, 4], state: "sullysmod:stripped_petrified_log{axis:y}"},
        {pos: [6, 12, 5], state: "sullysmod:stripped_petrified_log{axis:y}"},
        {pos: [6, 12, 6], state: "sullysmod:petrified_log{axis:y}"},
        {pos: [7, 12, 3], state: "sullysmod:petrified_log{axis:y}"},
        {pos: [7, 12, 4], state: "sullysmod:petrified_log{axis:y}"},
        {pos: [7, 12, 5], state: "sullysmod:petrified_log{axis:y}"},
        {pos: [7, 12, 6], state: "sullysmod:petrified_log{axis:y}"},
        {pos: [4, 13, 3], state: "sullysmod:petrified_log{axis:y}"},
        {pos: [4, 13, 4], state: "sullysmod:stripped_petrified_log{axis:y}"},
        {pos: [4, 13, 5], state: "sullysmod:stripped_petrified_log{axis:y}"},
        {pos: [4, 13, 6], state: "sullysmod:petrified_log{axis:y}"},
        {pos: [5, 13, 3], state: "sullysmod:petrified_log{axis:y}"},
        {pos: [5, 13, 4], state: "sullysmod:stripped_petrified_log{axis:y}"},
        {pos: [5, 13, 5], state: "sullysmod:stripped_petrified_log{axis:y}"},
        {pos: [5, 13, 6], state: "sullysmod:petrified_log{axis:y}"},
        {pos: [6, 13, 3], state: "sullysmod:petrified_log{axis:y}"},
        {pos: [6, 13, 4], state: "sullysmod:stripped_petrified_log{axis:y}"},
        {pos: [6, 13, 5], state: "sullysmod:stripped_petrified_log{axis:y}"},
        {pos: [6, 13, 6], state: "sullysmod:petrified_log{axis:y}"},
        {pos: [7, 13, 3], state: "sullysmod:petrified_log{axis:y}"},
        {pos: [7, 13, 4], state: "sullysmod:petrified_log{axis:y}"},
        {pos: [7, 13, 5], state: "sullysmod:petrified_log{axis:y}"},
        {pos: [7, 13, 6], state: "sullysmod:petrified_log{axis:y}"},
        {pos: [4, 14, 3], state: "sullysmod:petrified_log{axis:y}"},
        {pos: [4, 14, 5], state: "sullysmod:stripped_petrified_log{axis:y}"},
        {pos: [4, 14, 6], state: "sullysmod:petrified_log{axis:y}"},
        {pos: [5, 14, 3], state: "sullysmod:stripped_petrified_log{axis:y}"},
        {pos: [5, 14, 6], state: "sullysmod:petrified_log{axis:y}"},
        {pos: [6, 14, 3], state: "sullysmod:petrified_log{axis:y}"},
        {pos: [6, 14, 6], state: "sullysmod:stripped_petrified_log{axis:y}"},
        {pos: [7, 14, 3], state: "sullysmod:petrified_log{axis:y}"},
        {pos: [7, 14, 4], state: "sullysmod:petrified_log{axis:y}"},
        {pos: [7, 14, 5], state: "sullysmod:petrified_log{axis:y}"},
        {pos: [7, 14, 6], state: "sullysmod:petrified_log{axis:y}"},
        {pos: [4, 15, 6], state: "sullysmod:petrified_log{axis:y}"},
        {pos: [5, 15, 6], state: "sullysmod:stripped_petrified_log{axis:y}"},
        {pos: [6, 15, 3], state: "sullysmod:stripped_petrified_log{axis:y}"},
        {pos: [7, 15, 3], state: "sullysmod:petrified_log{axis:y}"},
        {pos: [7, 15, 5], state: "sullysmod:stripped_petrified_log{axis:y}"},
        {pos: [7, 15, 6], state: "sullysmod:petrified_log{axis:y}"},
        {pos: [4, 16, 6], state: "sullysmod:stripped_petrified_log{axis:y}"},
        {pos: [7, 16, 3], state: "sullysmod:stripped_petrified_log{axis:y}"},
        {pos: [7, 16, 6], state: "sullysmod:stripped_petrified_log{axis:y}"}
    ],
    entities: [],
    palette: [
        "sullysmod:petrified_log{axis:y}",
        "sullysmod:stripped_petrified_log{axis:y}",
        "sullysmod:petrified_log{axis:x}",
        "minecraft:gravel",
        "sullysmod:petrified_log{axis:z}",
        "sullysmod:stripped_petrified_log{axis:x}",
        "sullysmod:stripped_petrified_log{axis:z}",
        "sullysmod:rough_amber{is_melted:false}",
        "sullysmod:amber{is_melted:false}",
        "minecraft:suspicious_gravel{dusted:0}"
    ]
}
