{
    DataVersion: 3465,
    size: [18, 20, 18],
    data: [
        {pos: [8, 0, 13], state: "sullysmod:amber{is_melted:false}", nbt: {RenderEntity: 0b, StuckEntity: [], id: "sullysmod:amber"}},
        {pos: [5, 1, 9], state: "sullysmod:stripped_petrified_log{axis:y}"},
        {pos: [8, 1, 13], state: "sullysmod:stripped_petrified_log{axis:y}"},
        {pos: [10, 1, 6], state: "sullysmod:stripped_petrified_log{axis:y}"},
        {pos: [10, 1, 9], state: "sullysmod:amber{is_melted:false}", nbt: {RenderEntity: 0b, StuckEntity: [], id: "sullysmod:amber"}},
        {pos: [2, 2, 1], state: "sullysmod:amber{is_melted:false}", nbt: {RenderEntity: 0b, StuckEntity: [], id: "sullysmod:amber"}},
        {pos: [2, 2, 8], state: "minecraft:gravel"},
        {pos: [3, 2, 7], state: "minecraft:gravel"},
        {pos: [3, 2, 8], state: "minecraft:gravel"},
        {pos: [3, 2, 9], state: "minecraft:gravel"},
        {pos: [4, 2, 6], state: "minecraft:gravel"},
        {pos: [4, 2, 7], state: "minecraft:gravel"},
        {pos: [4, 2, 8], state: "minecraft:gravel"},
        {pos: [4, 2, 9], state: "minecraft:gravel"},
        {pos: [4, 2, 10], state: "minecraft:gravel"},
        {pos: [5, 2, 6], state: "minecraft:gravel"},
        {pos: [5, 2, 7], state: "minecraft:gravel"},
        {pos: [5, 2, 8], state: "minecraft:gravel"},
        {pos: [5, 2, 9], state: "sullysmod:stripped_petrified_log{axis:y}"},
        {pos: [5, 2, 10], state: "minecraft:gravel"},
        {pos: [6, 2, 5], state: "minecraft:gravel"},
        {pos: [6, 2, 6], state: "minecraft:gravel"},
        {pos: [6, 2, 7], state: "minecraft:gravel"},
        {pos: [6, 2, 8], state: "minecraft:gravel"},
        {pos: [6, 2, 9], state: "minecraft:gravel"},
        {pos: [6, 2, 10], state: "minecraft:gravel"},
        {pos: [6, 2, 11], state: "minecraft:gravel"},
        {pos: [7, 2, 4], state: "minecraft:gravel"},
        {pos: [7, 2, 5], state: "minecraft:gravel"},
        {pos: [7, 2, 6], state: "minecraft:gravel"},
        {pos: [7, 2, 7], state: "minecraft:gravel"},
        {pos: [7, 2, 8], state: "minecraft:gravel"},
        {pos: [7, 2, 9], state: "minecraft:gravel"},
        {pos: [7, 2, 10], state: "minecraft:gravel"},
        {pos: [7, 2, 11], state: "minecraft:gravel"},
        {pos: [7, 2, 12], state: "minecraft:gravel"},
        {pos: [8, 2, 4], state: "minecraft:gravel"},
        {pos: [8, 2, 5], state: "minecraft:gravel"},
        {pos: [8, 2, 6], state: "minecraft:gravel"},
        {pos: [8, 2, 7], state: "minecraft:gravel"},
        {pos: [8, 2, 8], state: "minecraft:gravel"},
        {pos: [8, 2, 9], state: "minecraft:gravel"},
        {pos: [8, 2, 10], state: "minecraft:gravel"},
        {pos: [8, 2, 11], state: "minecraft:gravel"},
        {pos: [8, 2, 12], state: "sullysmod:petrified_log{axis:y}"},
        {pos: [9, 2, 4], state: "minecraft:gravel"},
        {pos: [9, 2, 5], state: "minecraft:gravel"},
        {pos: [9, 2, 6], state: "sullysmod:stripped_petrified_log{axis:y}"},
        {pos: [9, 2, 7], state: "minecraft:gravel"},
        {pos: [9, 2, 8], state: "minecraft:gravel"},
        {pos: [9, 2, 9], state: "minecraft:gravel"},
        {pos: [9, 2, 10], state: "minecraft:gravel"},
        {pos: [9, 2, 11], state: "minecraft:gravel"},
        {pos: [9, 2, 12], state: "minecraft:gravel"},
        {pos: [10, 2, 4], state: "minecraft:gravel"},
        {pos: [10, 2, 5], state: "minecraft:gravel"},
        {pos: [10, 2, 6], state: "minecraft:gravel"},
        {pos: [10, 2, 7], state: "minecraft:gravel"},
        {pos: [10, 2, 8], state: "minecraft:gravel"},
        {pos: [10, 2, 9], state: "sullysmod:amber{is_melted:false}", nbt: {RenderEntity: 0b, StuckEntity: [], id: "sullysmod:amber"}},
        {pos: [10, 2, 10], state: "minecraft:gravel"},
        {pos: [10, 2, 11], state: "minecraft:gravel"},
        {pos: [10, 2, 12], state: "minecraft:gravel"},
        {pos: [11, 2, 5], state: "minecraft:gravel"},
        {pos: [11, 2, 6], state: "minecraft:gravel"},
        {pos: [11, 2, 7], state: "minecraft:gravel"},
        {pos: [11, 2, 8], state: "minecraft:gravel"},
        {pos: [11, 2, 9], state: "minecraft:gravel"},
        {pos: [11, 2, 10], state: "minecraft:gravel"},
        {pos: [11, 2, 11], state: "minecraft:gravel"},
        {pos: [12, 2, 6], state: "minecraft:gravel"},
        {pos: [12, 2, 7], state: "minecraft:gravel"},
        {pos: [12, 2, 8], state: "minecraft:gravel"},
        {pos: [12, 2, 9], state: "minecraft:gravel"},
        {pos: [12, 2, 10], state: "minecraft:gravel"},
        {pos: [13, 2, 7], state: "minecraft:gravel"},
        {pos: [13, 2, 8], state: "minecraft:gravel"},
        {pos: [13, 2, 9], state: "minecraft:gravel"},
        {pos: [15, 2, 3], state: "sullysmod:amber{is_melted:false}", nbt: {RenderEntity: 0b, StuckEntity: [], id: "sullysmod:amber"}},
        {pos: [1, 3, 1], state: "sullysmod:stripped_petrified_log{axis:z}"},
        {pos: [1, 3, 2], state: "sullysmod:stripped_petrified_log{axis:z}"},
        {pos: [1, 3, 3], state: "sullysmod:stripped_petrified_log{axis:y}"},
        {pos: [1, 3, 8], state: "minecraft:gravel"},
        {pos: [1, 3, 9], state: "minecraft:gravel"},
        {pos: [2, 3, 1], state: "sullysmod:stripped_petrified_log{axis:x}"},
        {pos: [2, 3, 6], state: "minecraft:gravel"},
        {pos: [2, 3, 7], state: "minecraft:gravel"},
        {pos: [2, 3, 8], state: "minecraft:gravel"},
        {pos: [2, 3, 9], state: "minecraft:gravel"},
        {pos: [2, 3, 10], state: "minecraft:gravel"},
        {pos: [3, 3, 6], state: "minecraft:gravel"},
        {pos: [3, 3, 7], state: "minecraft:gravel"},
        {pos: [3, 3, 8], state: "minecraft:gravel"},
        {pos: [3, 3, 9], state: "minecraft:gravel"},
        {pos: [3, 3, 10], state: "minecraft:gravel"},
        {pos: [3, 3, 11], state: "minecraft:gravel"},
        {pos: [4, 3, 4], state: "minecraft:gravel"},
        {pos: [4, 3, 5], state: "minecraft:gravel"},
        {pos: [4, 3, 6], state: "minecraft:gravel"},
        {pos: [4, 3, 7], state: "minecraft:gravel"},
        {pos: [4, 3, 8], state: "minecraft:gravel"},
        {pos: [4, 3, 9], state: "minecraft:gravel"},
        {pos: [4, 3, 10], state: "minecraft:gravel"},
        {pos: [4, 3, 11], state: "minecraft:gravel"},
        {pos: [4, 3, 12], state: "minecraft:gravel"},
        {pos: [5, 3, 4], state: "minecraft:gravel"},
        {pos: [5, 3, 5], state: "minecraft:gravel"},
        {pos: [5, 3, 6], state: "minecraft:gravel"},
        {pos: [5, 3, 7], state: "minecraft:gravel"},
        {pos: [5, 3, 8], state: "minecraft:gravel"},
        {pos: [5, 3, 9], state: "sullysmod:stripped_petrified_log{axis:y}"},
        {pos: [5, 3, 10], state: "minecraft:gravel"},
        {pos: [5, 3, 11], state: "minecraft:gravel"},
        {pos: [5, 3, 12], state: "minecraft:gravel"},
        {pos: [6, 3, 2], state: "minecraft:gravel"},
        {pos: [6, 3, 3], state: "minecraft:gravel"},
        {pos: [6, 3, 4], state: "minecraft:gravel"},
        {pos: [6, 3, 5], state: "minecraft:gravel"},
        {pos: [6, 3, 6], state: "minecraft:gravel"},
        {pos: [6, 3, 7], state: "minecraft:gravel"},
        {pos: [6, 3, 8], state: "minecraft:gravel"},
        {pos: [6, 3, 9], state: "sullysmod:petrified_log{axis:y}"},
        {pos: [6, 3, 10], state: "minecraft:gravel"},
        {pos: [6, 3, 11], state: "minecraft:gravel"},
        {pos: [6, 3, 12], state: "minecraft:gravel"},
        {pos: [6, 3, 13], state: "minecraft:gravel"},
        {pos: [7, 3, 2], state: "minecraft:gravel"},
        {pos: [7, 3, 3], state: "minecraft:gravel"},
        {pos: [7, 3, 4], state: "minecraft:gravel"},
        {pos: [7, 3, 5], state: "minecraft:gravel"},
        {pos: [7, 3, 6], state: "minecraft:gravel"},
        {pos: [7, 3, 7], state: "minecraft:gravel"},
        {pos: [7, 3, 8], state: "minecraft:gravel"},
        {pos: [7, 3, 9], state: "minecraft:gravel"},
        {pos: [7, 3, 10], state: "minecraft:gravel"},
        {pos: [7, 3, 11], state: "minecraft:gravel"},
        {pos: [7, 3, 12], state: "minecraft:gravel"},
        {pos: [7, 3, 13], state: "minecraft:gravel"},
        {pos: [8, 3, 2], state: "minecraft:gravel"},
        {pos: [8, 3, 3], state: "sullysmod:amber{is_melted:false}", nbt: {RenderEntity: 0b, StuckEntity: [], id: "sullysmod:amber"}},
        {pos: [8, 3, 4], state: "minecraft:gravel"},
        {pos: [8, 3, 5], state: "minecraft:gravel"},
        {pos: [8, 3, 6], state: "minecraft:gravel"},
        {pos: [8, 3, 7], state: "minecraft:gravel"},
        {pos: [8, 3, 8], state: "minecraft:gravel"},
        {pos: [8, 3, 9], state: "minecraft:gravel"},
        {pos: [8, 3, 10], state: "minecraft:gravel"},
        {pos: [8, 3, 11], state: "minecraft:gravel"},
        {pos: [8, 3, 12], state: "sullysmod:petrified_log{axis:y}"},
        {pos: [8, 3, 13], state: "minecraft:gravel"},
        {pos: [8, 3, 14], state: "minecraft:gravel"},
        {pos: [9, 3, 3], state: "minecraft:gravel"},
        {pos: [9, 3, 4], state: "minecraft:gravel"},
        {pos: [9, 3, 5], state: "minecraft:gravel"},
        {pos: [9, 3, 6], state: "sullysmod:petrified_log{axis:y}"},
        {pos: [9, 3, 7], state: "minecraft:gravel"},
        {pos: [9, 3, 8], state: "minecraft:gravel"},
        {pos: [9, 3, 9], state: "minecraft:gravel"},
        {pos: [9, 3, 10], state: "minecraft:gravel"},
        {pos: [9, 3, 11], state: "minecraft:gravel"},
        {pos: [9, 3, 12], state: "minecraft:gravel"},
        {pos: [9, 3, 13], state: "minecraft:gravel"},
        {pos: [9, 3, 14], state: "minecraft:gravel"},
        {pos: [10, 3, 3], state: "minecraft:gravel"},
        {pos: [10, 3, 4], state: "minecraft:gravel"},
        {pos: [10, 3, 5], state: "minecraft:gravel"},
        {pos: [10, 3, 6], state: "minecraft:gravel"},
        {pos: [10, 3, 7], state: "minecraft:gravel"},
        {pos: [10, 3, 8], state: "minecraft:gravel"},
        {pos: [10, 3, 9], state: "sullysmod:stripped_petrified_log{axis:y}"},
        {pos: [10, 3, 10], state: "minecraft:gravel"},
        {pos: [10, 3, 11], state: "minecraft:gravel"},
        {pos: [10, 3, 12], state: "minecraft:gravel"},
        {pos: [10, 3, 13], state: "minecraft:gravel"},
        {pos: [10, 3, 14], state: "minecraft:gravel"},
        {pos: [11, 3, 3], state: "minecraft:gravel"},
        {pos: [11, 3, 4], state: "minecraft:gravel"},
        {pos: [11, 3, 5], state: "minecraft:gravel"},
        {pos: [11, 3, 6], state: "minecraft:gravel"},
        {pos: [11, 3, 7], state: "minecraft:gravel"},
        {pos: [11, 3, 8], state: "minecraft:gravel"},
        {pos: [11, 3, 9], state: "minecraft:gravel"},
        {pos: [11, 3, 10], state: "minecraft:gravel"},
        {pos: [11, 3, 11], state: "minecraft:gravel"},
        {pos: [11, 3, 12], state: "minecraft:gravel"},
        {pos: [11, 3, 13], state: "minecraft:gravel"},
        {pos: [12, 3, 5], state: "minecraft:gravel"},
        {pos: [12, 3, 6], state: "minecraft:gravel"},
        {pos: [12, 3, 7], state: "minecraft:gravel"},
        {pos: [12, 3, 8], state: "minecraft:gravel"},
        {pos: [12, 3, 9], state: "minecraft:gravel"},
        {pos: [12, 3, 10], state: "sullysmod:amber{is_melted:false}", nbt: {RenderEntity: 0b, StuckEntity: [], id: "sullysmod:amber"}},
        {pos: [12, 3, 11], state: "minecraft:gravel"},
        {pos: [12, 3, 12], state: "minecraft:gravel"},
        {pos: [13, 3, 5], state: "minecraft:gravel"},
        {pos: [13, 3, 6], state: "minecraft:gravel"},
        {pos: [13, 3, 7], state: "minecraft:gravel"},
        {pos: [13, 3, 8], state: "minecraft:gravel"},
        {pos: [13, 3, 9], state: "minecraft:gravel"},
        {pos: [13, 3, 10], state: "minecraft:gravel"},
        {pos: [14, 3, 3], state: "sullysmod:petrified_log{axis:z}"},
        {pos: [14, 3, 4], state: "sullysmod:petrified_log{axis:y}"},
        {pos: [14, 3, 8], state: "minecraft:gravel"},
        {pos: [14, 3, 9], state: "minecraft:gravel"},
        {pos: [14, 3, 10], state: "minecraft:gravel"},
        {pos: [15, 3, 3], state: "sullysmod:petrified_log{axis:x}"},
        {pos: [0, 4, 8], state: "minecraft:gravel"},
        {pos: [0, 4, 9], state: "sullysmod:stripped_petrified_log{axis:z}"},
        {pos: [0, 4, 10], state: "sullysmod:stripped_petrified_log{axis:z}"},
        {pos: [0, 4, 11], state: "sullysmod:petrified_log{axis:x}"},
        {pos: [1, 4, 3], state: "sullysmod:stripped_petrified_log{axis:y}"},
        {pos: [1, 4, 7], state: "minecraft:gravel"},
        {pos: [1, 4, 8], state: "minecraft:gravel"},
        {pos: [1, 4, 9], state: "minecraft:gravel"},
        {pos: [1, 4, 10], state: "minecraft:gravel"},
        {pos: [1, 4, 11], state: "sullysmod:petrified_log{axis:x}"},
        {pos: [2, 4, 5], state: "minecraft:gravel"},
        {pos: [2, 4, 6], state: "minecraft:gravel"},
        {pos: [2, 4, 7], state: "minecraft:gravel"},
        {pos: [2, 4, 8], state: "minecraft:gravel"},
        {pos: [2, 4, 9], state: "minecraft:gravel"},
        {pos: [2, 4, 10], state: "minecraft:gravel"},
        {pos: [2, 4, 11], state: "sullysmod:petrified_log{axis:y}"},
        {pos: [3, 4, 3], state: "minecraft:gravel"},
        {pos: [3, 4, 4], state: "minecraft:gravel"},
        {pos: [3, 4, 5], state: "minecraft:gravel"},
        {pos: [3, 4, 6], state: "minecraft:gravel"},
        {pos: [3, 4, 7], state: "minecraft:gravel"},
        {pos: [3, 4, 8], state: "minecraft:gravel"},
        {pos: [3, 4, 9], state: "minecraft:gravel"},
        {pos: [3, 4, 10], state: "minecraft:gravel"},
        {pos: [3, 4, 11], state: "minecraft:gravel"},
        {pos: [3, 4, 12], state: "minecraft:gravel"},
        {pos: [3, 4, 13], state: "sullysmod:stripped_petrified_log{axis:x}"},
        {pos: [3, 4, 14], state: "sullysmod:petrified_log{axis:z}"},
        {pos: [3, 4, 15], state: "sullysmod:petrified_log{axis:z}"},
        {pos: [4, 4, 2], state: "minecraft:gravel"},
        {pos: [4, 4, 3], state: "minecraft:gravel"},
        {pos: [4, 4, 4], state: "sullysmod:amber{is_melted:false}", nbt: {RenderEntity: 0b, StuckEntity: [], id: "sullysmod:amber"}},
        {pos: [4, 4, 5], state: "minecraft:gravel"},
        {pos: [4, 4, 6], state: "minecraft:gravel"},
        {pos: [4, 4, 7], state: "minecraft:gravel"},
        {pos: [4, 4, 8], state: "minecraft:gravel"},
        {pos: [4, 4, 9], state: "minecraft:gravel"},
        {pos: [4, 4, 10], state: "minecraft:gravel"},
        {pos: [4, 4, 11], state: "minecraft:gravel"},
        {pos: [4, 4, 12], state: "minecraft:gravel"},
        {pos: [4, 4, 13], state: "sullysmod:stripped_petrified_log{axis:y}"},
        {pos: [5, 4, 0], state: "sullysmod:stripped_petrified_log{axis:y}"},
        {pos: [5, 4, 2], state: "minecraft:gravel"},
        {pos: [5, 4, 3], state: "minecraft:gravel"},
        {pos: [5, 4, 4], state: "minecraft:gravel"},
        {pos: [5, 4, 5], state: "minecraft:gravel"},
        {pos: [5, 4, 6], state: "minecraft:gravel"},
        {pos: [5, 4, 7], state: "minecraft:gravel"},
        {pos: [5, 4, 8], state: "minecraft:gravel"},
        {pos: [5, 4, 9], state: "minecraft:gravel"},
        {pos: [5, 4, 10], state: "minecraft:gravel"},
        {pos: [5, 4, 11], state: "minecraft:gravel"},
        {pos: [5, 4, 12], state: "minecraft:gravel"},
        {pos: [5, 4, 13], state: "minecraft:gravel"},
        {pos: [5, 4, 14], state: "minecraft:gravel"},
        {pos: [6, 4, 0], state: "sullysmod:petrified_log{axis:x}"},
        {pos: [6, 4, 1], state: "minecraft:gravel"},
        {pos: [6, 4, 2], state: "minecraft:gravel"},
        {pos: [6, 4, 3], state: "minecraft:gravel"},
        {pos: [6, 4, 4], state: "minecraft:gravel"},
        {pos: [6, 4, 5], state: "minecraft:gravel"},
        {pos: [6, 4, 6], state: "minecraft:gravel"},
        {pos: [6, 4, 7], state: "minecraft:gravel"},
        {pos: [6, 4, 8], state: "minecraft:gravel"},
        {pos: [6, 4, 9], state: "sullysmod:petrified_log{axis:y}"},
        {pos: [6, 4, 10], state: "minecraft:gravel"},
        {pos: [6, 4, 11], state: "minecraft:gravel"},
        {pos: [6, 4, 12], state: "minecraft:gravel"},
        {pos: [6, 4, 13], state: "minecraft:gravel"},
        {pos: [6, 4, 14], state: "minecraft:gravel"},
        {pos: [7, 4, 0], state: "sullysmod:petrified_log{axis:z}"},
        {pos: [7, 4, 1], state: "sullysmod:petrified_log{axis:y}"},
        {pos: [7, 4, 2], state: "minecraft:gravel"},
        {pos: [7, 4, 3], state: "minecraft:gravel"},
        {pos: [7, 4, 4], state: "minecraft:gravel"},
        {pos: [7, 4, 5], state: "minecraft:gravel"},
        {pos: [7, 4, 6], state: "minecraft:gravel"},
        {pos: [7, 4, 7], state: "minecraft:gravel"},
        {pos: [7, 4, 8], state: "minecraft:gravel"},
        {pos: [7, 4, 9], state: "minecraft:gravel"},
        {pos: [7, 4, 10], state: "minecraft:gravel"},
        {pos: [7, 4, 11], state: "minecraft:gravel"},
        {pos: [7, 4, 12], state: "minecraft:gravel"},
        {pos: [7, 4, 13], state: "minecraft:gravel"},
        {pos: [7, 4, 14], state: "minecraft:gravel"},
        {pos: [7, 4, 15], state: "minecraft:gravel"},
        {pos: [8, 4, 1], state: "minecraft:gravel"},
        {pos: [8, 4, 2], state: "minecraft:gravel"},
        {pos: [8, 4, 3], state: "sullysmod:stripped_petrified_log{axis:y}"},
        {pos: [8, 4, 4], state: "minecraft:gravel"},
        {pos: [8, 4, 5], state: "minecraft:gravel"},
        {pos: [8, 4, 6], state: "minecraft:gravel"},
        {pos: [8, 4, 7], state: "minecraft:gravel"},
        {pos: [8, 4, 8], state: "minecraft:gravel"},
        {pos: [8, 4, 9], state: "minecraft:gravel"},
        {pos: [8, 4, 10], state: "minecraft:gravel"},
        {pos: [8, 4, 11], state: "minecraft:gravel"},
        {pos: [8, 4, 12], state: "sullysmod:stripped_petrified_log{axis:y}"},
        {pos: [8, 4, 13], state: "minecraft:gravel"},
        {pos: [8, 4, 14], state: "minecraft:gravel"},
        {pos: [8, 4, 15], state: "minecraft:gravel"},
        {pos: [9, 4, 1], state: "minecraft:gravel"},
        {pos: [9, 4, 2], state: "minecraft:gravel"},
        {pos: [9, 4, 3], state: "minecraft:gravel"},
        {pos: [9, 4, 4], state: "minecraft:gravel"},
        {pos: [9, 4, 5], state: "minecraft:gravel"},
        {pos: [9, 4, 6], state: "sullysmod:petrified_log{axis:y}"},
        {pos: [9, 4, 7], state: "minecraft:gravel"},
        {pos: [9, 4, 8], state: "minecraft:gravel"},
        {pos: [9, 4, 9], state: "minecraft:gravel"},
        {pos: [9, 4, 10], state: "minecraft:gravel"},
        {pos: [9, 4, 11], state: "minecraft:gravel"},
        {pos: [9, 4, 12], state: "minecraft:gravel"},
        {pos: [9, 4, 13], state: "minecraft:gravel"},
        {pos: [9, 4, 14], state: "minecraft:gravel"},
        {pos: [9, 4, 15], state: "minecraft:gravel"},
        {pos: [10, 4, 2], state: "minecraft:gravel"},
        {pos: [10, 4, 3], state: "minecraft:gravel"},
        {pos: [10, 4, 4], state: "minecraft:gravel"},
        {pos: [10, 4, 5], state: "minecraft:gravel"},
        {pos: [10, 4, 6], state: "minecraft:gravel"},
        {pos: [10, 4, 7], state: "minecraft:gravel"},
        {pos: [10, 4, 8], state: "minecraft:gravel"},
        {pos: [10, 4, 9], state: "sullysmod:petrified_log{axis:y}"},
        {pos: [10, 4, 10], state: "minecraft:gravel"},
        {pos: [10, 4, 11], state: "minecraft:gravel"},
        {pos: [10, 4, 12], state: "minecraft:gravel"},
        {pos: [10, 4, 13], state: "minecraft:gravel"},
        {pos: [10, 4, 14], state: "minecraft:gravel"},
        {pos: [11, 4, 2], state: "minecraft:gravel"},
        {pos: [11, 4, 3], state: "minecraft:gravel"},
        {pos: [11, 4, 4], state: "minecraft:gravel"},
        {pos: [11, 4, 5], state: "minecraft:gravel"},
        {pos: [11, 4, 6], state: "minecraft:gravel"},
        {pos: [11, 4, 7], state: "minecraft:gravel"},
        {pos: [11, 4, 8], state: "minecraft:gravel"},
        {pos: [11, 4, 9], state: "minecraft:gravel"},
        {pos: [11, 4, 10], state: "minecraft:gravel"},
        {pos: [11, 4, 11], state: "minecraft:gravel"},
        {pos: [11, 4, 12], state: "sullysmod:petrified_log{axis:y}"},
        {pos: [11, 4, 13], state: "sullysmod:stripped_petrified_log{axis:z}"},
        {pos: [11, 4, 14], state: "sullysmod:petrified_log{axis:z}"},
        {pos: [12, 4, 2], state: "minecraft:gravel"},
        {pos: [12, 4, 3], state: "minecraft:gravel"},
        {pos: [12, 4, 4], state: "minecraft:gravel"},
        {pos: [12, 4, 5], state: "minecraft:gravel"},
        {pos: [12, 4, 6], state: "minecraft:gravel"},
        {pos: [12, 4, 7], state: "minecraft:gravel"},
        {pos: [12, 4, 8], state: "minecraft:gravel"},
        {pos: [12, 4, 9], state: "minecraft:gravel"},
        {pos: [12, 4, 10], state: "sullysmod:stripped_petrified_log{axis:y}"},
        {pos: [12, 4, 11], state: "minecraft:gravel"},
        {pos: [12, 4, 12], state: "minecraft:gravel"},
        {pos: [12, 4, 13], state: "minecraft:gravel"},
        {pos: [12, 4, 14], state: "sullysmod:petrified_log{axis:x}"},
        {pos: [13, 4, 3], state: "minecraft:gravel"},
        {pos: [13, 4, 4], state: "minecraft:gravel"},
        {pos: [13, 4, 5], state: "minecraft:gravel"},
        {pos: [13, 4, 6], state: "minecraft:gravel"},
        {pos: [13, 4, 7], state: "minecraft:gravel"},
        {pos: [13, 4, 8], state: "minecraft:gravel"},
        {pos: [13, 4, 9], state: "minecraft:gravel"},
        {pos: [13, 4, 10], state: "minecraft:gravel"},
        {pos: [13, 4, 11], state: "minecraft:gravel"},
        {pos: [13, 4, 12], state: "minecraft:gravel"},
        {pos: [13, 4, 13], state: "minecraft:gravel"},
        {pos: [13, 4, 14], state: "sullysmod:petrified_log{axis:x}"},
        {pos: [14, 4, 3], state: "minecraft:gravel"},
        {pos: [14, 4, 4], state: "sullysmod:stripped_petrified_log{axis:y}"},
        {pos: [14, 4, 5], state: "minecraft:gravel"},
        {pos: [14, 4, 6], state: "minecraft:gravel"},
        {pos: [14, 4, 7], state: "minecraft:gravel"},
        {pos: [14, 4, 8], state: "minecraft:gravel"},
        {pos: [14, 4, 9], state: "minecraft:gravel"},
        {pos: [14, 4, 10], state: "sullysmod:petrified_log{axis:z}"},
        {pos: [14, 4, 11], state: "sullysmod:petrified_log{axis:z}"},
        {pos: [14, 4, 12], state: "sullysmod:petrified_log{axis:x}"},
        {pos: [15, 4, 6], state: "minecraft:gravel"},
        {pos: [15, 4, 7], state: "minecraft:gravel"},
        {pos: [15, 4, 8], state: "minecraft:gravel"},
        {pos: [15, 4, 9], state: "minecraft:gravel"},
        {pos: [15, 4, 12], state: "sullysmod:petrified_log{axis:x}"},
        {pos: [16, 4, 7], state: "minecraft:gravel"},
        {pos: [16, 4, 11], state: "sullysmod:stripped_petrified_log{axis:z}"},
        {pos: [16, 4, 12], state: "sullysmod:stripped_petrified_log{axis:z}"},
        {pos: [17, 4, 6], state: "sullysmod:amber{is_melted:false}", nbt: {RenderEntity: 0b, StuckEntity: [], id: "sullysmod:amber"}},
        {pos: [0, 5, 7], state: "minecraft:gravel"},
        {pos: [0, 5, 8], state: "minecraft:gravel"},
        {pos: [0, 5, 9], state: "sullysmod:stripped_petrified_log{axis:y}"},
        {pos: [0, 5, 10], state: "minecraft:gravel"},
        {pos: [1, 5, 3], state: "sullysmod:stripped_petrified_log{axis:y}"},
        {pos: [1, 5, 6], state: "minecraft:gravel"},
        {pos: [1, 5, 7], state: "minecraft:gravel"},
        {pos: [1, 5, 8], state: "minecraft:gravel"},
        {pos: [1, 5, 9], state: "minecraft:gravel"},
        {pos: [1, 5, 10], state: "minecraft:gravel"},
        {pos: [1, 5, 11], state: "minecraft:gravel"},
        {pos: [2, 5, 3], state: "sullysmod:petrified_log{axis:x}"},
        {pos: [2, 5, 4], state: "minecraft:gravel"},
        {pos: [2, 5, 5], state: "minecraft:gravel"},
        {pos: [2, 5, 6], state: "minecraft:gravel"},
        {pos: [2, 5, 7], state: "minecraft:gravel"},
        {pos: [2, 5, 8], state: "minecraft:gravel"},
        {pos: [2, 5, 9], state: "sullysmod:petrified_log{axis:z}"},
        {pos: [2, 5, 10], state: "sullysmod:petrified_log{axis:z}"},
        {pos: [2, 5, 11], state: "sullysmod:petrified_log{axis:y}"},
        {pos: [2, 5, 12], state: "minecraft:gravel"},
        {pos: [2, 5, 13], state: "minecraft:gravel"},
        {pos: [3, 5, 3], state: "sullysmod:petrified_log{axis:x}"},
        {pos: [3, 5, 4], state: "minecraft:gravel"},
        {pos: [3, 5, 5], state: "minecraft:gravel"},
        {pos: [3, 5, 6], state: "minecraft:gravel"},
        {pos: [3, 5, 7], state: "minecraft:gravel"},
        {pos: [3, 5, 8], state: "minecraft:gravel"},
        {pos: [3, 5, 9], state: "minecraft:gravel"},
        {pos: [3, 5, 10], state: "minecraft:gravel"},
        {pos: [3, 5, 11], state: "minecraft:gravel"},
        {pos: [3, 5, 12], state: "minecraft:gravel"},
        {pos: [3, 5, 13], state: "minecraft:gravel"},
        {pos: [3, 5, 14], state: "minecraft:gravel"},
        {pos: [4, 5, 2], state: "sullysmod:petrified_log{axis:z}"},
        {pos: [4, 5, 3], state: "sullysmod:petrified_log{axis:z}"},
        {pos: [4, 5, 4], state: "sullysmod:petrified_log{axis:y}"},
        {pos: [4, 5, 5], state: "minecraft:gravel"},
        {pos: [4, 5, 6], state: "minecraft:gravel"},
        {pos: [4, 5, 7], state: "minecraft:gravel"},
        {pos: [4, 5, 8], state: "minecraft:gravel"},
        {pos: [4, 5, 9], state: "minecraft:gravel"},
        {pos: [4, 5, 10], state: "minecraft:gravel"},
        {pos: [4, 5, 11], state: "minecraft:gravel"},
        {pos: [4, 5, 12], state: "minecraft:gravel"},
        {pos: [4, 5, 13], state: "sullysmod:stripped_petrified_log{axis:y}"},
        {pos: [4, 5, 14], state: "minecraft:gravel"},
        {pos: [5, 5, 0], state: "sullysmod:stripped_petrified_log{axis:y}"},
        {pos: [5, 5, 1], state: "minecraft:gravel"},
        {pos: [5, 5, 2], state: "minecraft:gravel"},
        {pos: [5, 5, 3], state: "minecraft:gravel"},
        {pos: [5, 5, 4], state: "minecraft:gravel"},
        {pos: [5, 5, 5], state: "minecraft:gravel"},
        {pos: [5, 5, 6], state: "minecraft:gravel"},
        {pos: [5, 5, 7], state: "minecraft:gravel"},
        {pos: [5, 5, 8], state: "minecraft:gravel"},
        {pos: [5, 5, 9], state: "minecraft:gravel"},
        {pos: [5, 5, 10], state: "minecraft:gravel"},
        {pos: [5, 5, 11], state: "minecraft:gravel"},
        {pos: [5, 5, 12], state: "minecraft:gravel"},
        {pos: [5, 5, 13], state: "sullysmod:amber{is_melted:false}", nbt: {RenderEntity: 0b, StuckEntity: [], id: "sullysmod:amber"}},
        {pos: [5, 5, 14], state: "minecraft:gravel"},
        {pos: [5, 5, 15], state: "minecraft:gravel"},
        {pos: [6, 5, 1], state: "minecraft:gravel"},
        {pos: [6, 5, 2], state: "minecraft:gravel"},
        {pos: [6, 5, 3], state: "minecraft:gravel"},
        {pos: [6, 5, 4], state: "minecraft:gravel"},
        {pos: [6, 5, 5], state: "minecraft:gravel"},
        {pos: [6, 5, 6], state: "minecraft:gravel"},
        {pos: [6, 5, 7], state: "minecraft:gravel"},
        {pos: [6, 5, 8], state: "sullysmod:petrified_log{axis:y}"},
        {pos: [6, 5, 9], state: "sullysmod:petrified_log{axis:y}"},
        {pos: [6, 5, 10], state: "minecraft:gravel"},
        {pos: [6, 5, 11], state: "minecraft:gravel"},
        {pos: [6, 5, 12], state: "minecraft:gravel"},
        {pos: [6, 5, 13], state: "minecraft:gravel"},
        {pos: [6, 5, 14], state: "minecraft:gravel"},
        {pos: [6, 5, 15], state: "minecraft:gravel"},
        {pos: [7, 5, 1], state: "sullysmod:petrified_log{axis:y}"},
        {pos: [7, 5, 2], state: "sullysmod:petrified_log{axis:y}"},
        {pos: [7, 5, 3], state: "minecraft:gravel"},
        {pos: [7, 5, 4], state: "minecraft:gravel"},
        {pos: [7, 5, 5], state: "minecraft:gravel"},
        {pos: [7, 5, 6], state: "minecraft:gravel"},
        {pos: [7, 5, 7], state: "minecraft:gravel"},
        {pos: [7, 5, 8], state: "minecraft:gravel"},
        {pos: [7, 5, 9], state: "minecraft:gravel"},
        {pos: [7, 5, 10], state: "minecraft:gravel"},
        {pos: [7, 5, 11], state: "minecraft:gravel"},
        {pos: [7, 5, 12], state: "minecraft:gravel"},
        {pos: [7, 5, 13], state: "minecraft:gravel"},
        {pos: [7, 5, 14], state: "minecraft:gravel"},
        {pos: [7, 5, 15], state: "sullysmod:stripped_petrified_log{axis:z}"},
        {pos: [7, 5, 16], state: "sullysmod:stripped_petrified_log{axis:z}"},
        {pos: [8, 5, 1], state: "minecraft:gravel"},
        {pos: [8, 5, 2], state: "minecraft:gravel"},
        {pos: [8, 5, 3], state: "sullysmod:petrified_log{axis:y}"},
        {pos: [8, 5, 4], state: "minecraft:gravel"},
        {pos: [8, 5, 5], state: "minecraft:gravel"},
        {pos: [8, 5, 6], state: "minecraft:gravel"},
        {pos: [8, 5, 7], state: "minecraft:gravel"},
        {pos: [8, 5, 8], state: "minecraft:gravel"},
        {pos: [8, 5, 9], state: "minecraft:gravel"},
        {pos: [8, 5, 10], state: "minecraft:gravel"},
        {pos: [8, 5, 11], state: "minecraft:gravel"},
        {pos: [8, 5, 12], state: "sullysmod:stripped_petrified_log{axis:y}"},
        {pos: [8, 5, 13], state: "minecraft:gravel"},
        {pos: [8, 5, 14], state: "sullysmod:stripped_petrified_log{axis:z}"},
        {pos: [8, 5, 15], state: "sullysmod:stripped_petrified_log{axis:z}"},
        {pos: [9, 5, 1], state: "minecraft:gravel"},
        {pos: [9, 5, 2], state: "minecraft:gravel"},
        {pos: [9, 5, 3], state: "minecraft:gravel"},
        {pos: [9, 5, 4], state: "minecraft:gravel"},
        {pos: [9, 5, 5], state: "minecraft:gravel"},
        {pos: [9, 5, 6], state: "sullysmod:petrified_log{axis:y}"},
        {pos: [9, 5, 7], state: "minecraft:gravel"},
        {pos: [9, 5, 8], state: "minecraft:gravel"},
        {pos: [9, 5, 9], state: "minecraft:gravel"},
        {pos: [9, 5, 10], state: "minecraft:gravel"},
        {pos: [9, 5, 11], state: "minecraft:gravel"},
        {pos: [9, 5, 12], state: "minecraft:gravel"},
        {pos: [9, 5, 13], state: "minecraft:gravel"},
        {pos: [9, 5, 14], state: "minecraft:gravel"},
        {pos: [9, 5, 15], state: "minecraft:gravel"},
        {pos: [9, 5, 16], state: "minecraft:gravel"},
        {pos: [10, 5, 1], state: "minecraft:gravel"},
        {pos: [10, 5, 2], state: "minecraft:gravel"},
        {pos: [10, 5, 3], state: "minecraft:gravel"},
        {pos: [10, 5, 4], state: "minecraft:gravel"},
        {pos: [10, 5, 5], state: "minecraft:gravel"},
        {pos: [10, 5, 6], state: "minecraft:gravel"},
        {pos: [10, 5, 7], state: "minecraft:gravel"},
        {pos: [10, 5, 8], state: "minecraft:gravel"},
        {pos: [10, 5, 9], state: "sullysmod:petrified_log{axis:y}"},
        {pos: [10, 5, 10], state: "minecraft:gravel"},
        {pos: [10, 5, 11], state: "minecraft:gravel"},
        {pos: [10, 5, 12], state: "minecraft:gravel"},
        {pos: [10, 5, 13], state: "minecraft:gravel"},
        {pos: [10, 5, 14], state: "minecraft:gravel"},
        {pos: [10, 5, 15], state: "minecraft:gravel"},
        {pos: [11, 5, 2], state: "sullysmod:petrified_log{axis:y}"},
        {pos: [11, 5, 3], state: "minecraft:gravel"},
        {pos: [11, 5, 4], state: "minecraft:gravel"},
        {pos: [11, 5, 5], state: "minecraft:gravel"},
        {pos: [11, 5, 6], state: "minecraft:gravel"},
        {pos: [11, 5, 7], state: "minecraft:gravel"},
        {pos: [11, 5, 8], state: "minecraft:gravel"},
        {pos: [11, 5, 9], state: "minecraft:gravel"},
        {pos: [11, 5, 10], state: "minecraft:gravel"},
        {pos: [11, 5, 11], state: "minecraft:gravel"},
        {pos: [11, 5, 12], state: "sullysmod:stripped_petrified_log{axis:y}"},
        {pos: [11, 5, 13], state: "minecraft:gravel"},
        {pos: [11, 5, 14], state: "minecraft:gravel"},
        {pos: [11, 5, 15], state: "minecraft:gravel"},
        {pos: [12, 5, 0], state: "sullysmod:stripped_petrified_log{axis:z}"},
        {pos: [12, 5, 1], state: "sullysmod:stripped_petrified_log{axis:z}"},
        {pos: [12, 5, 2], state: "sullysmod:stripped_petrified_log{axis:x}"},
        {pos: [12, 5, 3], state: "minecraft:gravel"},
        {pos: [12, 5, 4], state: "sullysmod:stripped_petrified_log{axis:y}"},
        {pos: [12, 5, 5], state: "minecraft:gravel"},
        {pos: [12, 5, 6], state: "sullysmod:petrified_log{axis:y}"},
        {pos: [12, 5, 7], state: "minecraft:gravel"},
        {pos: [12, 5, 8], state: "minecraft:gravel"},
        {pos: [12, 5, 9], state: "minecraft:gravel"},
        {pos: [12, 5, 10], state: "sullysmod:stripped_petrified_log{axis:y}"},
        {pos: [12, 5, 11], state: "minecraft:gravel"},
        {pos: [12, 5, 12], state: "minecraft:gravel"},
        {pos: [12, 5, 13], state: "minecraft:gravel"},
        {pos: [12, 5, 14], state: "minecraft:gravel"},
        {pos: [12, 5, 15], state: "minecraft:gravel"},
        {pos: [13, 5, 2], state: "minecraft:gravel"},
        {pos: [13, 5, 3], state: "minecraft:gravel"},
        {pos: [13, 5, 4], state: "sullysmod:stripped_petrified_log{axis:x}"},
        {pos: [13, 5, 5], state: "minecraft:gravel"},
        {pos: [13, 5, 6], state: "minecraft:gravel"},
        {pos: [13, 5, 7], state: "minecraft:gravel"},
        {pos: [13, 5, 8], state: "minecraft:gravel"},
        {pos: [13, 5, 9], state: "minecraft:gravel"},
        {pos: [13, 5, 10], state: "minecraft:gravel"},
        {pos: [13, 5, 11], state: "minecraft:gravel"},
        {pos: [13, 5, 12], state: "minecraft:gravel"},
        {pos: [13, 5, 13], state: "minecraft:gravel"},
        {pos: [13, 5, 14], state: "minecraft:gravel"},
        {pos: [14, 5, 3], state: "minecraft:gravel"},
        {pos: [14, 5, 4], state: "sullysmod:stripped_petrified_log{axis:x}"},
        {pos: [14, 5, 5], state: "minecraft:gravel"},
        {pos: [14, 5, 6], state: "sullysmod:petrified_log{axis:y}"},
        {pos: [14, 5, 7], state: "sullysmod:stripped_petrified_log{axis:y}"},
        {pos: [14, 5, 8], state: "minecraft:gravel"},
        {pos: [14, 5, 9], state: "minecraft:gravel"},
        {pos: [14, 5, 10], state: "sullysmod:petrified_log{axis:y}"},
        {pos: [14, 5, 11], state: "minecraft:gravel"},
        {pos: [14, 5, 12], state: "minecraft:suspicious_gravel{dusted:0}", nbt: {id: "minecraft:brushable_block", item: {Count: 0b, id: "minecraft:air"}}},
        {pos: [15, 5, 4], state: "minecraft:gravel"},
        {pos: [15, 5, 5], state: "minecraft:gravel"},
        {pos: [15, 5, 6], state: "sullysmod:petrified_log{axis:x}"},
        {pos: [15, 5, 7], state: "sullysmod:stripped_petrified_log{axis:x}"},
        {pos: [15, 5, 8], state: "minecraft:gravel"},
        {pos: [15, 5, 9], state: "minecraft:gravel"},
        {pos: [15, 5, 10], state: "minecraft:gravel"},
        {pos: [15, 5, 11], state: "minecraft:gravel"},
        {pos: [16, 5, 6], state: "minecraft:gravel"},
        {pos: [16, 5, 7], state: "sullysmod:stripped_petrified_log{axis:x}"},
        {pos: [17, 5, 6], state: "sullysmod:petrified_log{axis:x}"},
        {pos: [0, 6, 7], state: "minecraft:gravel"},
        {pos: [0, 6, 8], state: "minecraft:gravel"},
        {pos: [0, 6, 9], state: "minecraft:gravel"},
        {pos: [0, 6, 10], state: "minecraft:gravel"},
        {pos: [0, 6, 11], state: "minecraft:gravel"},
        {pos: [1, 6, 5], state: "minecraft:gravel"},
        {pos: [1, 6, 6], state: "minecraft:gravel"},
        {pos: [1, 6, 7], state: "minecraft:gravel"},
        {pos: [1, 6, 8], state: "minecraft:gravel"},
        {pos: [1, 6, 9], state: "minecraft:gravel"},
        {pos: [1, 6, 10], state: "minecraft:gravel"},
        {pos: [1, 6, 11], state: "minecraft:gravel"},
        {pos: [1, 6, 12], state: "minecraft:gravel"},
        {pos: [2, 6, 3], state: "minecraft:gravel"},
        {pos: [2, 6, 4], state: "minecraft:gravel"},
        {pos: [2, 6, 5], state: "minecraft:gravel"},
        {pos: [2, 6, 6], state: "minecraft:gravel"},
        {pos: [2, 6, 7], state: "minecraft:gravel"},
        {pos: [2, 6, 8], state: "minecraft:gravel"},
        {pos: [2, 6, 9], state: "sullysmod:petrified_log{axis:y}"},
        {pos: [2, 6, 10], state: "minecraft:gravel"},
        {pos: [2, 6, 11], state: "minecraft:gravel"},
        {pos: [2, 6, 12], state: "minecraft:gravel"},
        {pos: [2, 6, 13], state: "minecraft:gravel"},
        {pos: [2, 6, 14], state: "minecraft:gravel"},
        {pos: [3, 6, 2], state: "minecraft:gravel"},
        {pos: [3, 6, 3], state: "minecraft:gravel"},
        {pos: [3, 6, 4], state: "minecraft:gravel"},
        {pos: [3, 6, 5], state: "minecraft:gravel"},
        {pos: [3, 6, 6], state: "minecraft:gravel"},
        {pos: [3, 6, 7], state: "minecraft:gravel"},
        {pos: [3, 6, 8], state: "minecraft:gravel"},
        {pos: [3, 6, 9], state: "sullysmod:petrified_log{axis:y}"},
        {pos: [3, 6, 10], state: "minecraft:gravel"},
        {pos: [3, 6, 11], state: "minecraft:gravel"},
        {pos: [3, 6, 12], state: "minecraft:gravel"},
        {pos: [3, 6, 13], state: "minecraft:gravel"},
        {pos: [3, 6, 14], state: "minecraft:gravel"},
        {pos: [4, 6, 1], state: "minecraft:gravel"},
        {pos: [4, 6, 2], state: "minecraft:gravel"},
        {pos: [4, 6, 3], state: "minecraft:gravel"},
        {pos: [4, 6, 4], state: "sullysmod:petrified_log{axis:y}"},
        {pos: [4, 6, 5], state: "sullysmod:petrified_log{axis:y}"},
        {pos: [4, 6, 6], state: "sullysmod:stripped_petrified_log{axis:y}"},
        {pos: [4, 6, 7], state: "minecraft:gravel"},
        {pos: [4, 6, 8], state: "minecraft:gravel"},
        {pos: [4, 6, 9], state: "sullysmod:petrified_log{axis:y}"},
        {pos: [4, 6, 10], state: "minecraft:gravel"},
        {pos: [4, 6, 11], state: "minecraft:gravel"},
        {pos: [4, 6, 12], state: "minecraft:gravel"},
        {pos: [4, 6, 13], state: "sullysmod:stripped_petrified_log{axis:y}"},
        {pos: [4, 6, 14], state: "minecraft:gravel"},
        {pos: [4, 6, 15], state: "minecraft:gravel"},
        {pos: [5, 6, 1], state: "minecraft:gravel"},
        {pos: [5, 6, 2], state: "minecraft:gravel"},
        {pos: [5, 6, 3], state: "minecraft:gravel"},
        {pos: [5, 6, 4], state: "minecraft:gravel"},
        {pos: [5, 6, 5], state: "sullysmod:petrified_log{axis:y}"},
        {pos: [5, 6, 6], state: "minecraft:gravel"},
        {pos: [5, 6, 7], state: "minecraft:gravel"},
        {pos: [5, 6, 8], state: "minecraft:gravel"},
        {pos: [5, 6, 9], state: "minecraft:gravel"},
        {pos: [5, 6, 10], state: "sullysmod:petrified_log{axis:y}"},
        {pos: [5, 6, 11], state: "sullysmod:stripped_petrified_log{axis:y}"},
        {pos: [5, 6, 12], state: "sullysmod:stripped_petrified_log{axis:z}"},
        {pos: [5, 6, 13], state: "sullysmod:stripped_petrified_log{axis:z}"},
        {pos: [5, 6, 14], state: "minecraft:gravel"},
        {pos: [5, 6, 15], state: "minecraft:gravel"},
        {pos: [6, 6, 1], state: "minecraft:gravel"},
        {pos: [6, 6, 2], state: "minecraft:gravel"},
        {pos: [6, 6, 3], state: "minecraft:gravel"},
        {pos: [6, 6, 4], state: "sullysmod:petrified_log{axis:y}"},
        {pos: [6, 6, 5], state: "minecraft:gravel"},
        {pos: [6, 6, 6], state: "minecraft:gravel"},
        {pos: [6, 6, 7], state: "minecraft:gravel"},
        {pos: [6, 6, 8], state: "sullysmod:petrified_log{axis:y}"},
        {pos: [6, 6, 9], state: "sullysmod:amber{is_melted:false}", nbt: {RenderEntity: 0b, StuckEntity: [], id: "sullysmod:amber"}},
        {pos: [6, 6, 10], state: "minecraft:gravel"},
        {pos: [6, 6, 11], state: "minecraft:gravel"},
        {pos: [6, 6, 12], state: "minecraft:gravel"},
        {pos: [6, 6, 13], state: "minecraft:gravel"},
        {pos: [6, 6, 14], state: "minecraft:gravel"},
        {pos: [6, 6, 15], state: "minecraft:gravel"},
        {pos: [7, 6, 0], state: "minecraft:gravel"},
        {pos: [7, 6, 1], state: "minecraft:gravel"},
        {pos: [7, 6, 2], state: "sullysmod:petrified_log{axis:y}"},
        {pos: [7, 6, 3], state: "minecraft:gravel"},
        {pos: [7, 6, 4], state: "minecraft:gravel"},
        {pos: [7, 6, 5], state: "minecraft:gravel"},
        {pos: [7, 6, 6], state: "minecraft:gravel"},
        {pos: [7, 6, 7], state: "minecraft:gravel"},
        {pos: [7, 6, 8], state: "minecraft:gravel"},
        {pos: [7, 6, 9], state: "minecraft:gravel"},
        {pos: [7, 6, 10], state: "sullysmod:stripped_petrified_log{axis:y}"},
        {pos: [7, 6, 11], state: "minecraft:gravel"},
        {pos: [7, 6, 12], state: "minecraft:gravel"},
        {pos: [7, 6, 13], state: "minecraft:gravel"},
        {pos: [7, 6, 14], state: "minecraft:gravel"},
        {pos: [7, 6, 15], state: "minecraft:gravel"},
        {pos: [7, 6, 16], state: "sullysmod:stripped_petrified_log{axis:y}"},
        {pos: [8, 6, 0], state: "minecraft:gravel"},
        {pos: [8, 6, 1], state: "minecraft:gravel"},
        {pos: [8, 6, 2], state: "sullysmod:petrified_log{axis:y}"},
        {pos: [8, 6, 3], state: "sullysmod:petrified_log{axis:y}"},
        {pos: [8, 6, 4], state: "minecraft:gravel"},
        {pos: [8, 6, 5], state: "minecraft:gravel"},
        {pos: [8, 6, 6], state: "sullysmod:petrified_log{axis:y}"},
        {pos: [8, 6, 7], state: "minecraft:gravel"},
        {pos: [8, 6, 8], state: "minecraft:gravel"},
        {pos: [8, 6, 9], state: "sullysmod:stripped_petrified_log{axis:y}"},
        {pos: [8, 6, 10], state: "minecraft:gravel"},
        {pos: [8, 6, 11], state: "minecraft:gravel"},
        {pos: [8, 6, 12], state: "sullysmod:petrified_log{axis:y}"},
        {pos: [8, 6, 13], state: "sullysmod:stripped_petrified_log{axis:y}"},
        {pos: [8, 6, 14], state: "sullysmod:stripped_petrified_log{axis:y}"},
        {pos: [8, 6, 15], state: "minecraft:gravel"},
        {pos: [8, 6, 16], state: "minecraft:gravel"},
        {pos: [9, 6, 1], state: "sullysmod:stripped_petrified_log{axis:z}"},
        {pos: [9, 6, 2], state: "sullysmod:stripped_petrified_log{axis:y}"},
        {pos: [9, 6, 3], state: "minecraft:gravel"},
        {pos: [9, 6, 4], state: "minecraft:gravel"},
        {pos: [9, 6, 5], state: "minecraft:gravel"},
        {pos: [9, 6, 6], state: "sullysmod:petrified_log{axis:y}"},
        {pos: [9, 6, 7], state: "sullysmod:petrified_log{axis:y}"},
        {pos: [9, 6, 8], state: "minecraft:gravel"},
        {pos: [9, 6, 9], state: "minecraft:gravel"},
        {pos: [9, 6, 10], state: "minecraft:gravel"},
        {pos: [9, 6, 11], state: "minecraft:gravel"},
        {pos: [9, 6, 12], state: "sullysmod:stripped_petrified_log{axis:y}"},
        {pos: [9, 6, 13], state: "minecraft:gravel"},
        {pos: [9, 6, 14], state: "minecraft:gravel"},
        {pos: [9, 6, 15], state: "minecraft:gravel"},
        {pos: [9, 6, 16], state: "minecraft:gravel"},
        {pos: [10, 6, 1], state: "minecraft:gravel"},
        {pos: [10, 6, 2], state: "minecraft:gravel"},
        {pos: [10, 6, 3], state: "sullysmod:petrified_log{axis:y}"},
        {pos: [10, 6, 4], state: "minecraft:gravel"},
        {pos: [10, 6, 5], state: "minecraft:gravel"},
        {pos: [10, 6, 6], state: "minecraft:gravel"},
        {pos: [10, 6, 7], state: "minecraft:gravel"},
        {pos: [10, 6, 8], state: "minecraft:gravel"},
        {pos: [10, 6, 9], state: "sullysmod:stripped_petrified_log{axis:y}"},
        {pos: [10, 6, 10], state: "minecraft:gravel"},
        {pos: [10, 6, 11], state: "minecraft:gravel"},
        {pos: [10, 6, 12], state: "minecraft:gravel"},
        {pos: [10, 6, 13], state: "minecraft:gravel"},
        {pos: [10, 6, 14], state: "minecraft:gravel"},
        {pos: [10, 6, 15], state: "minecraft:gravel"},
        {pos: [10, 6, 16], state: "minecraft:gravel"},
        {pos: [11, 6, 1], state: "minecraft:gravel"},
        {pos: [11, 6, 2], state: "sullysmod:petrified_log{axis:y}"},
        {pos: [11, 6, 3], state: "sullysmod:petrified_log{axis:y}"},
        {pos: [11, 6, 4], state: "minecraft:gravel"},
        {pos: [11, 6, 5], state: "minecraft:gravel"},
        {pos: [11, 6, 6], state: "minecraft:gravel"},
        {pos: [11, 6, 7], state: "sullysmod:petrified_log{axis:y}"},
        {pos: [11, 6, 8], state: "minecraft:gravel"},
        {pos: [11, 6, 9], state: "minecraft:gravel"},
        {pos: [11, 6, 10], state: "sullysmod:amber{is_melted:false}", nbt: {RenderEntity: 0b, StuckEntity: [], id: "sullysmod:amber"}},
        {pos: [11, 6, 11], state: "sullysmod:stripped_petrified_log{axis:y}"},
        {pos: [11, 6, 12], state: "minecraft:gravel"},
        {pos: [11, 6, 13], state: "minecraft:gravel"},
        {pos: [11, 6, 14], state: "minecraft:gravel"},
        {pos: [11, 6, 15], state: "minecraft:gravel"},
        {pos: [12, 6, 0], state: "sullysmod:stripped_petrified_log{axis:y}"},
        {pos: [12, 6, 2], state: "minecraft:gravel"},
        {pos: [12, 6, 3], state: "minecraft:gravel"},
        {pos: [12, 6, 4], state: "sullysmod:stripped_petrified_log{axis:y}"},
        {pos: [12, 6, 5], state: "minecraft:gravel"},
        {pos: [12, 6, 6], state: "sullysmod:stripped_petrified_log{axis:y}"},
        {pos: [12, 6, 7], state: "minecraft:gravel"},
        {pos: [12, 6, 8], state: "minecraft:gravel"},
        {pos: [12, 6, 9], state: "minecraft:gravel"},
        {pos: [12, 6, 10], state: "sullysmod:stripped_petrified_log{axis:y}"},
        {pos: [12, 6, 11], state: "minecraft:gravel"},
        {pos: [12, 6, 12], state: "minecraft:gravel"},
        {pos: [12, 6, 13], state: "minecraft:gravel"},
        {pos: [12, 6, 14], state: "minecraft:gravel"},
        {pos: [12, 6, 15], state: "sullysmod:petrified_log{axis:y}"},
        {pos: [12, 6, 16], state: "sullysmod:stripped_petrified_log{axis:z}"},
        {pos: [12, 6, 17], state: "sullysmod:stripped_petrified_log{axis:z}"},
        {pos: [13, 6, 2], state: "minecraft:gravel"},
        {pos: [13, 6, 3], state: "minecraft:gravel"},
        {pos: [13, 6, 4], state: "minecraft:gravel"},
        {pos: [13, 6, 5], state: "minecraft:gravel"},
        {pos: [13, 6, 6], state: "sullysmod:petrified_log{axis:y}"},
        {pos: [13, 6, 7], state: "sullysmod:petrified_log{axis:y}"},
        {pos: [13, 6, 8], state: "minecraft:gravel"},
        {pos: [13, 6, 9], state: "minecraft:gravel"},
        {pos: [13, 6, 10], state: "sullysmod:petrified_log{axis:y}"},
        {pos: [13, 6, 11], state: "sullysmod:petrified_log{axis:y}"},
        {pos: [13, 6, 12], state: "minecraft:gravel"},
        {pos: [13, 6, 13], state: "minecraft:gravel"},
        {pos: [13, 6, 14], state: "minecraft:gravel"},
        {pos: [13, 6, 15], state: "minecraft:gravel"},
        {pos: [14, 6, 2], state: "minecraft:gravel"},
        {pos: [14, 6, 3], state: "minecraft:gravel"},
        {pos: [14, 6, 4], state: "minecraft:gravel"},
        {pos: [14, 6, 5], state: "minecraft:gravel"},
        {pos: [14, 6, 6], state: "sullysmod:petrified_log{axis:y}"},
        {pos: [14, 6, 7], state: "sullysmod:stripped_petrified_log{axis:y}"},
        {pos: [14, 6, 8], state: "minecraft:gravel"},
        {pos: [14, 6, 9], state: "minecraft:gravel"},
        {pos: [14, 6, 10], state: "sullysmod:petrified_log{axis:y}"},
        {pos: [14, 6, 11], state: "minecraft:gravel"},
        {pos: [14, 6, 12], state: "minecraft:gravel"},
        {pos: [14, 6, 13], state: "minecraft:gravel"},
        {pos: [15, 6, 4], state: "minecraft:gravel"},
        {pos: [15, 6, 5], state: "minecraft:gravel"},
        {pos: [15, 6, 6], state: "minecraft:gravel"},
        {pos: [15, 6, 7], state: "sullysmod:petrified_log{axis:y}"},
        {pos: [15, 6, 8], state: "minecraft:gravel"},
        {pos: [15, 6, 9], state: "minecraft:gravel"},
        {pos: [15, 6, 10], state: "minecraft:gravel"},
        {pos: [15, 6, 11], state: "minecraft:gravel"},
        {pos: [15, 6, 12], state: "minecraft:gravel"},
        {pos: [16, 6, 5], state: "minecraft:gravel"},
        {pos: [16, 6, 6], state: "minecraft:gravel"},
        {pos: [16, 6, 7], state: "minecraft:gravel"},
        {pos: [16, 6, 8], state: "minecraft:gravel"},
        {pos: [16, 6, 9], state: "minecraft:gravel"},
        {pos: [0, 7, 8], state: "minecraft:gravel"},
        {pos: [0, 7, 9], state: "minecraft:gravel"},
        {pos: [0, 7, 10], state: "minecraft:gravel"},
        {pos: [1, 7, 5], state: "minecraft:gravel"},
        {pos: [1, 7, 6], state: "minecraft:gravel"},
        {pos: [1, 7, 7], state: "minecraft:gravel"},
        {pos: [1, 7, 8], state: "minecraft:gravel"},
        {pos: [1, 7, 9], state: "minecraft:gravel"},
        {pos: [1, 7, 10], state: "minecraft:gravel"},
        {pos: [1, 7, 11], state: "minecraft:gravel"},
        {pos: [2, 7, 3], state: "minecraft:gravel"},
        {pos: [2, 7, 4], state: "minecraft:gravel"},
        {pos: [2, 7, 5], state: "minecraft:gravel"},
        {pos: [2, 7, 6], state: "minecraft:gravel"},
        {pos: [2, 7, 7], state: "minecraft:gravel"},
        {pos: [2, 7, 8], state: "minecraft:gravel"},
        {pos: [2, 7, 9], state: "minecraft:gravel"},
        {pos: [2, 7, 10], state: "minecraft:gravel"},
        {pos: [2, 7, 11], state: "minecraft:gravel"},
        {pos: [2, 7, 12], state: "minecraft:gravel"},
        {pos: [2, 7, 13], state: "minecraft:gravel"},
        {pos: [3, 7, 2], state: "minecraft:gravel"},
        {pos: [3, 7, 3], state: "minecraft:gravel"},
        {pos: [3, 7, 4], state: "minecraft:gravel"},
        {pos: [3, 7, 5], state: "minecraft:gravel"},
        {pos: [3, 7, 6], state: "minecraft:gravel"},
        {pos: [3, 7, 7], state: "minecraft:gravel"},
        {pos: [3, 7, 8], state: "minecraft:gravel"},
        {pos: [3, 7, 9], state: "sullysmod:petrified_log{axis:y}"},
        {pos: [3, 7, 10], state: "minecraft:gravel"},
        {pos: [3, 7, 11], state: "minecraft:gravel"},
        {pos: [3, 7, 12], state: "minecraft:gravel"},
        {pos: [3, 7, 13], state: "minecraft:gravel"},
        {pos: [3, 7, 14], state: "minecraft:gravel"},
        {pos: [4, 7, 1], state: "minecraft:gravel"},
        {pos: [4, 7, 2], state: "minecraft:gravel"},
        {pos: [4, 7, 3], state: "minecraft:gravel"},
        {pos: [4, 7, 4], state: "minecraft:gravel"},
        {pos: [4, 7, 5], state: "sullysmod:petrified_log{axis:y}"},
        {pos: [4, 7, 6], state: "sullysmod:petrified_log{axis:y}"},
        {pos: [4, 7, 7], state: "minecraft:gravel"},
        {pos: [4, 7, 8], state: "sullysmod:petrified_log{axis:y}"},
        {pos: [4, 7, 9], state: "sullysmod:petrified_log{axis:y}"},
        {pos: [4, 7, 10], state: "sullysmod:petrified_log{axis:y}"},
        {pos: [4, 7, 11], state: "minecraft:gravel"},
        {pos: [4, 7, 12], state: "minecraft:gravel"},
        {pos: [4, 7, 13], state: "minecraft:gravel"},
        {pos: [4, 7, 14], state: "minecraft:gravel"},
        {pos: [4, 7, 15], state: "minecraft:gravel"},
        {pos: [5, 7, 1], state: "minecraft:gravel"},
        {pos: [5, 7, 2], state: "minecraft:gravel"},
        {pos: [5, 7, 3], state: "minecraft:gravel"},
        {pos: [5, 7, 4], state: "sullysmod:petrified_log{axis:y}"},
        {pos: [5, 7, 5], state: "sullysmod:petrified_log{axis:y}"},
        {pos: [5, 7, 6], state: "sullysmod:petrified_log{axis:y}"},
        {pos: [5, 7, 7], state: "sullysmod:petrified_log{axis:y}"},
        {pos: [5, 7, 8], state: "sullysmod:petrified_log{axis:y}"},
        {pos: [5, 7, 9], state: "minecraft:gravel"},
        {pos: [5, 7, 10], state: "sullysmod:petrified_log{axis:y}"},
        {pos: [5, 7, 11], state: "sullysmod:petrified_log{axis:y}"},
        {pos: [5, 7, 12], state: "minecraft:gravel"},
        {pos: [5, 7, 13], state: "minecraft:gravel"},
        {pos: [5, 7, 14], state: "minecraft:gravel"},
        {pos: [5, 7, 15], state: "minecraft:gravel"},
        {pos: [6, 7, 0], state: "minecraft:gravel"},
        {pos: [6, 7, 1], state: "minecraft:gravel"},
        {pos: [6, 7, 2], state: "minecraft:gravel"},
        {pos: [6, 7, 3], state: "minecraft:gravel"},
        {pos: [6, 7, 4], state: "sullysmod:petrified_log{axis:y}"},
        {pos: [6, 7, 5], state: "sullysmod:petrified_log{axis:y}"},
        {pos: [6, 7, 6], state: "minecraft:gravel"},
        {pos: [6, 7, 7], state: "sullysmod:stripped_petrified_log{axis:y}"},
        {pos: [6, 7, 8], state: "sullysmod:petrified_log{axis:y}"},
        {pos: [6, 7, 9], state: "sullysmod:amber{is_melted:false}", nbt: {RenderEntity: 0b, StuckEntity: [], id: "sullysmod:amber"}},
        {pos: [6, 7, 10], state: "minecraft:gravel"},
        {pos: [6, 7, 11], state: "minecraft:gravel"},
        {pos: [6, 7, 12], state: "minecraft:gravel"},
        {pos: [6, 7, 13], state: "minecraft:gravel"},
        {pos: [6, 7, 14], state: "minecraft:gravel"},
        {pos: [6, 7, 15], state: "minecraft:gravel"},
        {pos: [7, 7, 0], state: "minecraft:gravel"},
        {pos: [7, 7, 1], state: "minecraft:gravel"},
        {pos: [7, 7, 2], state: "minecraft:gravel"},
        {pos: [7, 7, 3], state: "sullysmod:petrified_log{axis:y}"},
        {pos: [7, 7, 4], state: "minecraft:gravel"},
        {pos: [7, 7, 5], state: "minecraft:gravel"},
        {pos: [7, 7, 6], state: "minecraft:gravel"},
        {pos: [7, 7, 7], state: "minecraft:gravel"},
        {pos: [7, 7, 8], state: "minecraft:gravel"},
        {pos: [7, 7, 9], state: "sullysmod:petrified_log{axis:y}"},
        {pos: [7, 7, 10], state: "sullysmod:petrified_log{axis:y}"},
        {pos: [7, 7, 11], state: "minecraft:gravel"},
        {pos: [7, 7, 12], state: "minecraft:gravel"},
        {pos: [7, 7, 13], state: "minecraft:gravel"},
        {pos: [7, 7, 14], state: "minecraft:gravel"},
        {pos: [7, 7, 15], state: "minecraft:suspicious_gravel{dusted:0}", nbt: {id: "minecraft:brushable_block", item: {Count: 0b, id: "minecraft:air"}}},
        {pos: [7, 7, 16], state: "minecraft:gravel"},
        {pos: [8, 7, 0], state: "minecraft:gravel"},
        {pos: [8, 7, 1], state: "minecraft:gravel"},
        {pos: [8, 7, 2], state: "sullysmod:petrified_log{axis:y}"},
        {pos: [8, 7, 3], state: "sullysmod:petrified_log{axis:y}"},
        {pos: [8, 7, 4], state: "sullysmod:petrified_log{axis:y}"},
        {pos: [8, 7, 5], state: "minecraft:gravel"},
        {pos: [8, 7, 6], state: "sullysmod:petrified_log{axis:y}"},
        {pos: [8, 7, 7], state: "minecraft:gravel"},
        {pos: [8, 7, 8], state: "minecraft:gravel"},
        {pos: [8, 7, 9], state: "sullysmod:petrified_log{axis:y}"},
        {pos: [8, 7, 10], state: "minecraft:gravel"},
        {pos: [8, 7, 11], state: "sullysmod:petrified_log{axis:y}"},
        {pos: [8, 7, 12], state: "sullysmod:petrified_log{axis:y}"},
        {pos: [8, 7, 13], state: "sullysmod:petrified_log{axis:y}"},
        {pos: [8, 7, 14], state: "minecraft:gravel"},
        {pos: [8, 7, 15], state: "minecraft:gravel"},
        {pos: [8, 7, 16], state: "minecraft:gravel"},
        {pos: [9, 7, 1], state: "minecraft:gravel"},
        {pos: [9, 7, 2], state: "sullysmod:petrified_log{axis:y}"},
        {pos: [9, 7, 3], state: "minecraft:gravel"},
        {pos: [9, 7, 4], state: "sullysmod:petrified_log{axis:y}"},
        {pos: [9, 7, 5], state: "minecraft:gravel"},
        {pos: [9, 7, 6], state: "sullysmod:petrified_log{axis:y}"},
        {pos: [9, 7, 7], state: "sullysmod:petrified_log{axis:y}"},
        {pos: [9, 7, 8], state: "minecraft:gravel"},
        {pos: [9, 7, 9], state: "minecraft:gravel"},
        {pos: [9, 7, 10], state: "sullysmod:petrified_log{axis:y}"},
        {pos: [9, 7, 11], state: "sullysmod:petrified_log{axis:y}"},
        {pos: [9, 7, 12], state: "sullysmod:petrified_log{axis:y}"},
        {pos: [9, 7, 13], state: "minecraft:gravel"},
        {pos: [9, 7, 14], state: "minecraft:gravel"},
        {pos: [9, 7, 15], state: "minecraft:gravel"},
        {pos: [9, 7, 16], state: "minecraft:gravel"},
        {pos: [10, 7, 1], state: "minecraft:gravel"},
        {pos: [10, 7, 2], state: "minecraft:gravel"},
        {pos: [10, 7, 3], state: "sullysmod:petrified_log{axis:y}"},
        {pos: [10, 7, 4], state: "minecraft:gravel"},
        {pos: [10, 7, 5], state: "minecraft:gravel"},
        {pos: [10, 7, 6], state: "minecraft:gravel"},
        {pos: [10, 7, 7], state: "minecraft:gravel"},
        {pos: [10, 7, 8], state: "minecraft:gravel"},
        {pos: [10, 7, 9], state: "sullysmod:petrified_log{axis:y}"},
        {pos: [10, 7, 10], state: "minecraft:gravel"},
        {pos: [10, 7, 11], state: "minecraft:gravel"},
        {pos: [10, 7, 12], state: "sullysmod:stripped_petrified_log{axis:y}"},
        {pos: [10, 7, 13], state: "sullysmod:petrified_log{axis:z}"},
        {pos: [10, 7, 14], state: "sullysmod:petrified_log{axis:z}"},
        {pos: [10, 7, 15], state: "minecraft:gravel"},
        {pos: [10, 7, 16], state: "minecraft:gravel"},
        {pos: [11, 7, 1], state: "minecraft:gravel"},
        {pos: [11, 7, 2], state: "minecraft:gravel"},
        {pos: [11, 7, 3], state: "sullysmod:petrified_log{axis:y}"},
        {pos: [11, 7, 4], state: "minecraft:gravel"},
        {pos: [11, 7, 5], state: "minecraft:gravel"},
        {pos: [11, 7, 6], state: "minecraft:gravel"},
        {pos: [11, 7, 7], state: "sullysmod:petrified_log{axis:y}"},
        {pos: [11, 7, 8], state: "sullysmod:petrified_log{axis:y}"},
        {pos: [11, 7, 9], state: "minecraft:gravel"},
        {pos: [11, 7, 10], state: "sullysmod:amber{is_melted:false}", nbt: {RenderEntity: 0b, StuckEntity: [], id: "sullysmod:amber"}},
        {pos: [11, 7, 11], state: "sullysmod:petrified_log{axis:y}"},
        {pos: [11, 7, 12], state: "minecraft:gravel"},
        {pos: [11, 7, 13], state: "minecraft:gravel"},
        {pos: [11, 7, 14], state: "sullysmod:petrified_log{axis:x}"},
        {pos: [11, 7, 15], state: "minecraft:gravel"},
        {pos: [11, 7, 16], state: "minecraft:gravel"},
        {pos: [12, 7, 2], state: "minecraft:gravel"},
        {pos: [12, 7, 3], state: "minecraft:gravel"},
        {pos: [12, 7, 4], state: "sullysmod:petrified_log{axis:y}"},
        {pos: [12, 7, 5], state: "minecraft:gravel"},
        {pos: [12, 7, 6], state: "sullysmod:petrified_log{axis:y}"},
        {pos: [12, 7, 7], state: "minecraft:gravel"},
        {pos: [12, 7, 8], state: "minecraft:gravel"},
        {pos: [12, 7, 9], state: "minecraft:gravel"},
        {pos: [12, 7, 10], state: "sullysmod:petrified_log{axis:y}"},
        {pos: [12, 7, 11], state: "minecraft:gravel"},
        {pos: [12, 7, 12], state: "minecraft:gravel"},
        {pos: [12, 7, 13], state: "minecraft:gravel"},
        {pos: [12, 7, 14], state: "minecraft:gravel"},
        {pos: [12, 7, 15], state: "sullysmod:petrified_log{axis:z}"},
        {pos: [13, 7, 2], state: "minecraft:gravel"},
        {pos: [13, 7, 3], state: "minecraft:gravel"},
        {pos: [13, 7, 4], state: "minecraft:gravel"},
        {pos: [13, 7, 5], state: "minecraft:gravel"},
        {pos: [13, 7, 6], state: "sullysmod:stripped_petrified_log{axis:y}"},
        {pos: [13, 7, 7], state: "sullysmod:petrified_log{axis:y}"},
        {pos: [13, 7, 8], state: "minecraft:gravel"},
        {pos: [13, 7, 9], state: "sullysmod:stripped_petrified_log{axis:y}"},
        {pos: [13, 7, 10], state: "sullysmod:petrified_log{axis:y}"},
        {pos: [13, 7, 11], state: "minecraft:gravel"},
        {pos: [13, 7, 12], state: "minecraft:gravel"},
        {pos: [13, 7, 13], state: "minecraft:gravel"},
        {pos: [13, 7, 14], state: "minecraft:gravel"},
        {pos: [13, 7, 15], state: "minecraft:gravel"},
        {pos: [14, 7, 2], state: "minecraft:gravel"},
        {pos: [14, 7, 3], state: "minecraft:gravel"},
        {pos: [14, 7, 4], state: "minecraft:gravel"},
        {pos: [14, 7, 5], state: "minecraft:gravel"},
        {pos: [14, 7, 6], state: "minecraft:gravel"},
        {pos: [14, 7, 7], state: "minecraft:gravel"},
        {pos: [14, 7, 8], state: "minecraft:gravel"},
        {pos: [14, 7, 9], state: "minecraft:gravel"},
        {pos: [14, 7, 10], state: "minecraft:gravel"},
        {pos: [14, 7, 11], state: "minecraft:gravel"},
        {pos: [14, 7, 12], state: "minecraft:gravel"},
        {pos: [14, 7, 13], state: "minecraft:gravel"},
        {pos: [14, 7, 14], state: "minecraft:gravel"},
        {pos: [15, 7, 3], state: "minecraft:gravel"},
        {pos: [15, 7, 4], state: "minecraft:gravel"},
        {pos: [15, 7, 5], state: "minecraft:gravel"},
        {pos: [15, 7, 6], state: "minecraft:gravel"},
        {pos: [15, 7, 7], state: "minecraft:gravel"},
        {pos: [15, 7, 8], state: "minecraft:gravel"},
        {pos: [15, 7, 9], state: "minecraft:gravel"},
        {pos: [15, 7, 10], state: "minecraft:gravel"},
        {pos: [15, 7, 11], state: "minecraft:gravel"},
        {pos: [15, 7, 12], state: "minecraft:gravel"},
        {pos: [16, 7, 5], state: "minecraft:gravel"},
        {pos: [16, 7, 6], state: "minecraft:gravel"},
        {pos: [16, 7, 7], state: "minecraft:gravel"},
        {pos: [16, 7, 8], state: "minecraft:gravel"},
        {pos: [16, 7, 9], state: "minecraft:gravel"},
        {pos: [0, 8, 8], state: "minecraft:gravel"},
        {pos: [1, 8, 7], state: "minecraft:gravel"},
        {pos: [1, 8, 8], state: "minecraft:gravel"},
        {pos: [1, 8, 9], state: "minecraft:gravel"},
        {pos: [2, 8, 5], state: "minecraft:gravel"},
        {pos: [2, 8, 6], state: "minecraft:gravel"},
        {pos: [2, 8, 8], state: "minecraft:gravel"},
        {pos: [2, 8, 9], state: "minecraft:gravel"},
        {pos: [2, 8, 10], state: "minecraft:gravel"},
        {pos: [2, 8, 11], state: "minecraft:gravel"},
        {pos: [3, 8, 3], state: "minecraft:gravel"},
        {pos: [3, 8, 4], state: "minecraft:gravel"},
        {pos: [3, 8, 5], state: "minecraft:gravel"},
        {pos: [3, 8, 6], state: "minecraft:suspicious_gravel{dusted:0}", nbt: {id: "minecraft:brushable_block", item: {Count: 0b, id: "minecraft:air"}}},
        {pos: [3, 8, 7], state: "minecraft:gravel"},
        {pos: [3, 8, 8], state: "minecraft:gravel"},
        {pos: [3, 8, 9], state: "minecraft:gravel"},
        {pos: [3, 8, 10], state: "minecraft:gravel"},
        {pos: [3, 8, 11], state: "minecraft:gravel"},
        {pos: [3, 8, 12], state: "minecraft:gravel"},
        {pos: [3, 8, 13], state: "minecraft:gravel"},
        {pos: [4, 8, 2], state: "minecraft:gravel"},
        {pos: [4, 8, 3], state: "minecraft:gravel"},
        {pos: [4, 8, 4], state: "minecraft:gravel"},
        {pos: [4, 8, 5], state: "minecraft:gravel"},
        {pos: [4, 8, 6], state: "sullysmod:petrified_log{axis:y}"},
        {pos: [4, 8, 7], state: "sullysmod:stripped_petrified_log{axis:y}"},
        {pos: [4, 8, 8], state: "sullysmod:petrified_log{axis:y}"},
        {pos: [4, 8, 9], state: "sullysmod:petrified_log{axis:y}"},
        {pos: [4, 8, 10], state: "sullysmod:petrified_log{axis:y}"},
        {pos: [4, 8, 11], state: "minecraft:gravel"},
        {pos: [4, 8, 12], state: "minecraft:suspicious_gravel{dusted:0}", nbt: {id: "minecraft:brushable_block", item: {Count: 0b, id: "minecraft:air"}}},
        {pos: [4, 8, 13], state: "minecraft:gravel"},
        {pos: [4, 8, 14], state: "minecraft:gravel"},
        {pos: [5, 8, 1], state: "minecraft:gravel"},
        {pos: [5, 8, 2], state: "minecraft:suspicious_gravel{dusted:0}", nbt: {id: "minecraft:brushable_block", item: {Count: 0b, id: "minecraft:air"}}},
        {pos: [5, 8, 3], state: "minecraft:gravel"},
        {pos: [5, 8, 4], state: "sullysmod:petrified_log{axis:y}"},
        {pos: [5, 8, 5], state: "sullysmod:petrified_log{axis:y}"},
        {pos: [5, 8, 6], state: "sullysmod:petrified_log{axis:y}"},
        {pos: [5, 8, 7], state: "sullysmod:petrified_log{axis:y}"},
        {pos: [5, 8, 8], state: "sullysmod:petrified_log{axis:y}"},
        {pos: [5, 8, 9], state: "sullysmod:rough_amber{is_melted:false}"},
        {pos: [5, 8, 10], state: "sullysmod:petrified_log{axis:y}"},
        {pos: [5, 8, 11], state: "sullysmod:petrified_log{axis:y}"},
        {pos: [5, 8, 12], state: "minecraft:gravel"},
        {pos: [5, 8, 13], state: "minecraft:gravel"},
        {pos: [5, 8, 14], state: "minecraft:gravel"},
        {pos: [5, 8, 15], state: "minecraft:gravel"},
        {pos: [6, 8, 1], state: "minecraft:gravel"},
        {pos: [6, 8, 2], state: "minecraft:gravel"},
        {pos: [6, 8, 3], state: "sullysmod:petrified_log{axis:y}"},
        {pos: [6, 8, 4], state: "sullysmod:petrified_log{axis:y}"},
        {pos: [6, 8, 5], state: "sullysmod:petrified_log{axis:y}"},
        {pos: [6, 8, 6], state: "minecraft:gravel"},
        {pos: [6, 8, 7], state: "sullysmod:stripped_petrified_log{axis:y}"},
        {pos: [6, 8, 8], state: "sullysmod:petrified_log{axis:y}"},
        {pos: [6, 8, 9], state: "sullysmod:rough_amber{is_melted:false}"},
        {pos: [6, 8, 10], state: "sullysmod:petrified_log{axis:y}"},
        {pos: [6, 8, 11], state: "minecraft:gravel"},
        {pos: [6, 8, 12], state: "minecraft:gravel"},
        {pos: [6, 8, 13], state: "minecraft:gravel"},
        {pos: [6, 8, 14], state: "minecraft:gravel"},
        {pos: [7, 8, 1], state: "minecraft:gravel"},
        {pos: [7, 8, 2], state: "minecraft:gravel"},
        {pos: [7, 8, 3], state: "sullysmod:petrified_log{axis:y}"},
        {pos: [7, 8, 4], state: "minecraft:gravel"},
        {pos: [7, 8, 5], state: "minecraft:gravel"},
        {pos: [7, 8, 6], state: "minecraft:gravel"},
        {pos: [7, 8, 7], state: "sullysmod:petrified_log{axis:y}"},
        {pos: [7, 8, 8], state: "sullysmod:petrified_log{axis:y}"},
        {pos: [7, 8, 9], state: "sullysmod:petrified_log{axis:y}"},
        {pos: [7, 8, 10], state: "sullysmod:petrified_log{axis:y}"},
        {pos: [7, 8, 11], state: "minecraft:gravel"},
        {pos: [7, 8, 12], state: "sullysmod:petrified_log{axis:y}"},
        {pos: [7, 8, 13], state: "minecraft:gravel"},
        {pos: [7, 8, 14], state: "minecraft:gravel"},
        {pos: [7, 8, 16], state: "minecraft:gravel"},
        {pos: [8, 8, 1], state: "minecraft:gravel"},
        {pos: [8, 8, 2], state: "minecraft:gravel"},
        {pos: [8, 8, 3], state: "sullysmod:petrified_log{axis:y}"},
        {pos: [8, 8, 4], state: "sullysmod:petrified_log{axis:y}"},
        {pos: [8, 8, 5], state: "minecraft:gravel"},
        {pos: [8, 8, 6], state: "sullysmod:petrified_log{axis:y}"},
        {pos: [8, 8, 7], state: "minecraft:gravel"},
        {pos: [8, 8, 8], state: "minecraft:gravel"},
        {pos: [8, 8, 9], state: "sullysmod:petrified_log{axis:y}"},
        {pos: [8, 8, 10], state: "minecraft:gravel"},
        {pos: [8, 8, 11], state: "sullysmod:petrified_log{axis:y}"},
        {pos: [8, 8, 12], state: "sullysmod:petrified_log{axis:y}"},
        {pos: [8, 8, 13], state: "sullysmod:petrified_log{axis:y}"},
        {pos: [8, 8, 14], state: "minecraft:gravel"},
        {pos: [8, 8, 15], state: "minecraft:gravel"},
        {pos: [8, 8, 16], state: "minecraft:gravel"},
        {pos: [9, 8, 1], state: "minecraft:gravel"},
        {pos: [9, 8, 2], state: "sullysmod:petrified_log{axis:y}"},
        {pos: [9, 8, 3], state: "sullysmod:petrified_log{axis:y}"},
        {pos: [9, 8, 4], state: "sullysmod:petrified_log{axis:y}"},
        {pos: [9, 8, 5], state: "sullysmod:petrified_log{axis:y}"},
        {pos: [9, 8, 6], state: "sullysmod:petrified_log{axis:y}"},
        {pos: [9, 8, 7], state: "sullysmod:petrified_log{axis:y}"},
        {pos: [9, 8, 8], state: "minecraft:gravel"},
        {pos: [9, 8, 9], state: "minecraft:gravel"},
        {pos: [9, 8, 10], state: "sullysmod:petrified_log{axis:y}"},
        {pos: [9, 8, 11], state: "sullysmod:petrified_log{axis:y}"},
        {pos: [9, 8, 12], state: "sullysmod:petrified_log{axis:y}"},
        {pos: [9, 8, 13], state: "minecraft:gravel"},
        {pos: [9, 8, 14], state: "minecraft:gravel"},
        {pos: [9, 8, 15], state: "minecraft:suspicious_gravel{dusted:0}", nbt: {id: "minecraft:brushable_block", item: {Count: 0b, id: "minecraft:air"}}},
        {pos: [9, 8, 16], state: "minecraft:gravel"},
        {pos: [10, 8, 2], state: "minecraft:gravel"},
        {pos: [10, 8, 3], state: "sullysmod:petrified_log{axis:y}"},
        {pos: [10, 8, 4], state: "minecraft:gravel"},
        {pos: [10, 8, 5], state: "minecraft:gravel"},
        {pos: [10, 8, 6], state: "sullysmod:petrified_log{axis:y}"},
        {pos: [10, 8, 7], state: "minecraft:gravel"},
        {pos: [10, 8, 8], state: "minecraft:gravel"},
        {pos: [10, 8, 9], state: "sullysmod:petrified_log{axis:y}"},
        {pos: [10, 8, 10], state: "sullysmod:rough_amber{is_melted:false}"},
        {pos: [10, 8, 11], state: "sullysmod:petrified_log{axis:y}"},
        {pos: [10, 8, 12], state: "sullysmod:petrified_log{axis:y}"},
        {pos: [10, 8, 13], state: "minecraft:gravel"},
        {pos: [10, 8, 14], state: "minecraft:gravel"},
        {pos: [10, 8, 15], state: "minecraft:gravel"},
        {pos: [11, 8, 2], state: "minecraft:gravel"},
        {pos: [11, 8, 3], state: "sullysmod:petrified_log{axis:y}"},
        {pos: [11, 8, 4], state: "sullysmod:petrified_log{axis:y}"},
        {pos: [11, 8, 5], state: "minecraft:gravel"},
        {pos: [11, 8, 6], state: "minecraft:gravel"},
        {pos: [11, 8, 7], state: "sullysmod:petrified_log{axis:y}"},
        {pos: [11, 8, 8], state: "sullysmod:petrified_log{axis:y}"},
        {pos: [11, 8, 9], state: "sullysmod:petrified_log{axis:y}"},
        {pos: [11, 8, 10], state: "sullysmod:amber{is_melted:false}", nbt: {RenderEntity: 0b, StuckEntity: [], id: "sullysmod:amber"}},
        {pos: [11, 8, 11], state: "sullysmod:petrified_log{axis:y}"},
        {pos: [11, 8, 12], state: "minecraft:gravel"},
        {pos: [11, 8, 13], state: "minecraft:gravel"},
        {pos: [11, 8, 14], state: "minecraft:gravel"},
        {pos: [11, 8, 15], state: "minecraft:gravel"},
        {pos: [12, 8, 3], state: "minecraft:gravel"},
        {pos: [12, 8, 4], state: "sullysmod:petrified_log{axis:y}"},
        {pos: [12, 8, 5], state: "sullysmod:petrified_log{axis:y}"},
        {pos: [12, 8, 6], state: "sullysmod:petrified_log{axis:y}"},
        {pos: [12, 8, 7], state: "sullysmod:petrified_log{axis:y}"},
        {pos: [12, 8, 8], state: "sullysmod:petrified_log{axis:y}"},
        {pos: [12, 8, 9], state: "minecraft:gravel"},
        {pos: [12, 8, 10], state: "sullysmod:petrified_log{axis:y}"},
        {pos: [12, 8, 11], state: "minecraft:gravel"},
        {pos: [12, 8, 12], state: "minecraft:gravel"},
        {pos: [12, 8, 13], state: "minecraft:gravel"},
        {pos: [12, 8, 14], state: "minecraft:gravel"},
        {pos: [13, 8, 3], state: "minecraft:gravel"},
        {pos: [13, 8, 4], state: "minecraft:suspicious_gravel{dusted:0}", nbt: {id: "minecraft:brushable_block", item: {Count: 0b, id: "minecraft:air"}}},
        {pos: [13, 8, 5], state: "sullysmod:petrified_log{axis:y}"},
        {pos: [13, 8, 6], state: "sullysmod:stripped_petrified_log{axis:y}"},
        {pos: [13, 8, 7], state: "sullysmod:petrified_log{axis:y}"},
        {pos: [13, 8, 8], state: "minecraft:gravel"},
        {pos: [13, 8, 9], state: "sullysmod:petrified_log{axis:y}"},
        {pos: [13, 8, 10], state: "minecraft:gravel"},
        {pos: [13, 8, 11], state: "minecraft:gravel"},
        {pos: [13, 8, 13], state: "minecraft:gravel"},
        {pos: [14, 8, 3], state: "minecraft:gravel"},
        {pos: [14, 8, 4], state: "minecraft:gravel"},
        {pos: [14, 8, 5], state: "minecraft:gravel"},
        {pos: [14, 8, 6], state: "minecraft:gravel"},
        {pos: [14, 8, 7], state: "minecraft:gravel"},
        {pos: [14, 8, 8], state: "minecraft:gravel"},
        {pos: [14, 8, 9], state: "minecraft:gravel"},
        {pos: [14, 8, 10], state: "minecraft:gravel"},
        {pos: [14, 8, 11], state: "minecraft:gravel"},
        {pos: [14, 8, 12], state: "minecraft:gravel"},
        {pos: [15, 8, 5], state: "minecraft:gravel"},
        {pos: [15, 8, 6], state: "minecraft:gravel"},
        {pos: [15, 8, 7], state: "minecraft:gravel"},
        {pos: [15, 8, 8], state: "minecraft:gravel"},
        {pos: [15, 8, 9], state: "minecraft:suspicious_gravel{dusted:0}", nbt: {id: "minecraft:brushable_block", item: {Count: 0b, id: "minecraft:air"}}},
        {pos: [15, 8, 10], state: "minecraft:gravel"},
        {pos: [16, 8, 8], state: "minecraft:gravel"},
        {pos: [16, 8, 9], state: "minecraft:gravel"},
        {pos: [3, 9, 4], state: "sullysmod:petrified_sapling{stage:0}"},
        {pos: [3, 9, 9], state: "minecraft:gravel"},
        {pos: [3, 9, 10], state: "minecraft:gravel"},
        {pos: [4, 9, 6], state: "sullysmod:petrified_log{axis:y}"},
        {pos: [4, 9, 7], state: "sullysmod:petrified_log{axis:y}"},
        {pos: [4, 9, 8], state: "sullysmod:petrified_log{axis:y}"},
        {pos: [4, 9, 9], state: "sullysmod:petrified_log{axis:y}"},
        {pos: [4, 9, 10], state: "minecraft:gravel"},
        {pos: [4, 9, 13], state: "sullysmod:petrified_sapling{stage:0}"},
        {pos: [5, 9, 3], state: "minecraft:gravel"},
        {pos: [5, 9, 4], state: "sullysmod:petrified_log{axis:y}"},
        {pos: [5, 9, 5], state: "sullysmod:petrified_log{axis:y}"},
        {pos: [5, 9, 6], state: "sullysmod:petrified_log{axis:y}"},
        {pos: [5, 9, 7], state: "sullysmod:petrified_log{axis:y}"},
        {pos: [5, 9, 8], state: "sullysmod:petrified_log{axis:y}"},
        {pos: [5, 9, 9], state: "sullysmod:petrified_log{axis:y}"},
        {pos: [5, 9, 10], state: "sullysmod:petrified_log{axis:y}"},
        {pos: [5, 9, 11], state: "sullysmod:petrified_log{axis:y}"},
        {pos: [6, 9, 3], state: "sullysmod:petrified_log{axis:y}"},
        {pos: [6, 9, 4], state: "sullysmod:petrified_log{axis:y}"},
        {pos: [6, 9, 5], state: "sullysmod:stripped_petrified_log{axis:y}"},
        {pos: [6, 9, 6], state: "sullysmod:stripped_petrified_log{axis:y}"},
        {pos: [6, 9, 7], state: "sullysmod:stripped_petrified_log{axis:y}"},
        {pos: [6, 9, 8], state: "sullysmod:stripped_petrified_log{axis:y}"},
        {pos: [6, 9, 9], state: "sullysmod:stripped_petrified_log{axis:y}"},
        {pos: [6, 9, 10], state: "sullysmod:stripped_petrified_log{axis:y}"},
        {pos: [6, 9, 11], state: "sullysmod:petrified_log{axis:y}"},
        {pos: [6, 9, 12], state: "minecraft:air"},
        {pos: [7, 9, 2], state: "minecraft:gravel"},
        {pos: [7, 9, 3], state: "sullysmod:petrified_log{axis:y}"},
        {pos: [7, 9, 4], state: "sullysmod:petrified_log{axis:y}"},
        {pos: [7, 9, 5], state: "sullysmod:stripped_petrified_log{axis:y}"},
        {pos: [7, 9, 6], state: "sullysmod:stripped_petrified_log{axis:y}"},
        {pos: [7, 9, 7], state: "sullysmod:stripped_petrified_log{axis:y}"},
        {pos: [7, 9, 8], state: "sullysmod:stripped_petrified_log{axis:y}"},
        {pos: [7, 9, 9], state: "sullysmod:stripped_petrified_log{axis:y}"},
        {pos: [7, 9, 10], state: "sullysmod:stripped_petrified_log{axis:y}"},
        {pos: [7, 9, 11], state: "sullysmod:petrified_log{axis:y}"},
        {pos: [7, 9, 12], state: "sullysmod:petrified_log{axis:y}"},
        {pos: [8, 9, 2], state: "minecraft:suspicious_gravel{dusted:0}", nbt: {id: "minecraft:brushable_block", item: {Count: 0b, id: "minecraft:air"}}},
        {pos: [8, 9, 3], state: "sullysmod:petrified_log{axis:y}"},
        {pos: [8, 9, 4], state: "sullysmod:petrified_log{axis:y}"},
        {pos: [8, 9, 5], state: "sullysmod:stripped_petrified_log{axis:y}"},
        {pos: [8, 9, 6], state: "sullysmod:stripped_petrified_log{axis:y}"},
        {pos: [8, 9, 7], state: "sullysmod:stripped_petrified_log{axis:y}"},
        {pos: [8, 9, 8], state: "sullysmod:stripped_petrified_log{axis:y}"},
        {pos: [8, 9, 9], state: "sullysmod:stripped_petrified_log{axis:y}"},
        {pos: [8, 9, 10], state: "sullysmod:stripped_petrified_log{axis:y}"},
        {pos: [8, 9, 11], state: "sullysmod:petrified_log{axis:y}"},
        {pos: [8, 9, 12], state: "sullysmod:petrified_log{axis:y}"},
        {pos: [8, 9, 13], state: "minecraft:gravel"},
        {pos: [9, 9, 3], state: "sullysmod:petrified_log{axis:y}"},
        {pos: [9, 9, 4], state: "sullysmod:petrified_log{axis:y}"},
        {pos: [9, 9, 5], state: "sullysmod:stripped_petrified_log{axis:y}"},
        {pos: [9, 9, 6], state: "sullysmod:stripped_petrified_log{axis:y}"},
        {pos: [9, 9, 7], state: "sullysmod:stripped_petrified_log{axis:y}"},
        {pos: [9, 9, 8], state: "sullysmod:stripped_petrified_log{axis:y}"},
        {pos: [9, 9, 9], state: "sullysmod:stripped_petrified_log{axis:y}"},
        {pos: [9, 9, 10], state: "sullysmod:stripped_petrified_log{axis:y}"},
        {pos: [9, 9, 11], state: "sullysmod:petrified_log{axis:y}"},
        {pos: [9, 9, 12], state: "sullysmod:petrified_log{axis:y}"},
        {pos: [9, 9, 13], state: "minecraft:gravel"},
        {pos: [10, 9, 3], state: "sullysmod:petrified_log{axis:y}"},
        {pos: [10, 9, 4], state: "sullysmod:petrified_log{axis:y}"},
        {pos: [10, 9, 5], state: "sullysmod:stripped_petrified_log{axis:y}"},
        {pos: [10, 9, 6], state: "sullysmod:stripped_petrified_log{axis:y}"},
        {pos: [10, 9, 7], state: "sullysmod:stripped_petrified_log{axis:y}"},
        {pos: [10, 9, 8], state: "sullysmod:stripped_petrified_log{axis:y}"},
        {pos: [10, 9, 9], state: "sullysmod:stripped_petrified_log{axis:y}"},
        {pos: [10, 9, 10], state: "sullysmod:stripped_petrified_log{axis:y}"},
        {pos: [10, 9, 11], state: "sullysmod:petrified_log{axis:y}"},
        {pos: [10, 9, 12], state: "sullysmod:petrified_log{axis:y}"},
        {pos: [11, 9, 3], state: "sullysmod:petrified_log{axis:y}"},
        {pos: [11, 9, 4], state: "sullysmod:petrified_log{axis:y}"},
        {pos: [11, 9, 5], state: "sullysmod:stripped_petrified_log{axis:y}"},
        {pos: [11, 9, 6], state: "sullysmod:stripped_petrified_log{axis:y}"},
        {pos: [11, 9, 7], state: "sullysmod:stripped_petrified_log{axis:y}"},
        {pos: [11, 9, 8], state: "sullysmod:stripped_petrified_log{axis:y}"},
        {pos: [11, 9, 9], state: "sullysmod:stripped_petrified_log{axis:y}"},
        {pos: [11, 9, 10], state: "sullysmod:stripped_petrified_log{axis:y}"},
        {pos: [11, 9, 11], state: "sullysmod:petrified_log{axis:y}"},
        {pos: [11, 9, 12], state: "sullysmod:petrified_log{axis:y}"},
        {pos: [12, 9, 4], state: "minecraft:gravel"},
        {pos: [12, 9, 5], state: "sullysmod:petrified_log{axis:y}"},
        {pos: [12, 9, 6], state: "sullysmod:petrified_log{axis:y}"},
        {pos: [12, 9, 7], state: "sullysmod:petrified_log{axis:y}"},
        {pos: [12, 9, 8], state: "sullysmod:petrified_log{axis:y}"},
        {pos: [12, 9, 9], state: "sullysmod:petrified_log{axis:y}"},
        {pos: [12, 9, 10], state: "sullysmod:petrified_log{axis:y}"},
        {pos: [12, 9, 11], state: "sullysmod:petrified_log{axis:y}"},
        {pos: [12, 9, 12], state: "minecraft:suspicious_gravel{dusted:0}", nbt: {id: "minecraft:brushable_block", item: {Count: 0b, id: "minecraft:air"}}},
        {pos: [13, 9, 5], state: "sullysmod:petrified_log{axis:y}"},
        {pos: [13, 9, 6], state: "sullysmod:petrified_log{axis:y}"},
        {pos: [13, 9, 7], state: "sullysmod:petrified_log{axis:y}"},
        {pos: [13, 9, 8], state: "sullysmod:petrified_log{axis:y}"},
        {pos: [13, 9, 9], state: "sullysmod:petrified_log{axis:y}"},
        {pos: [14, 9, 7], state: "minecraft:gravel"},
        {pos: [14, 9, 8], state: "minecraft:gravel"},
        {pos: [14, 9, 11], state: "sullysmod:petrified_sapling{stage:0}"},
        {pos: [4, 10, 6], state: "minecraft:suspicious_gravel{dusted:0}", nbt: {id: "minecraft:brushable_block", item: {Count: 0b, id: "minecraft:air"}}},
        {pos: [4, 10, 7], state: "sullysmod:petrified_log{axis:y}"},
        {pos: [4, 10, 8], state: "sullysmod:petrified_log{axis:y}"},
        {pos: [4, 10, 9], state: "sullysmod:petrified_log{axis:y}"},
        {pos: [5, 10, 5], state: "sullysmod:petrified_log{axis:y}"},
        {pos: [5, 10, 6], state: "sullysmod:petrified_log{axis:y}"},
        {pos: [5, 10, 7], state: "sullysmod:petrified_log{axis:y}"},
        {pos: [5, 10, 8], state: "sullysmod:petrified_log{axis:y}"},
        {pos: [5, 10, 9], state: "sullysmod:petrified_log{axis:y}"},
        {pos: [5, 10, 10], state: "sullysmod:petrified_log{axis:y}"},
        {pos: [6, 10, 3], state: "minecraft:gravel"},
        {pos: [6, 10, 4], state: "sullysmod:petrified_log{axis:y}"},
        {pos: [6, 10, 5], state: "sullysmod:stripped_petrified_log{axis:y}"},
        {pos: [6, 10, 6], state: "sullysmod:stripped_petrified_log{axis:y}"},
        {pos: [6, 10, 7], state: "sullysmod:stripped_petrified_log{axis:y}"},
        {pos: [6, 10, 8], state: "sullysmod:stripped_petrified_log{axis:y}"},
        {pos: [6, 10, 9], state: "sullysmod:stripped_petrified_log{axis:y}"},
        {pos: [6, 10, 10], state: "sullysmod:rough_amber{is_melted:false}"},
        {pos: [6, 10, 11], state: "sullysmod:petrified_log{axis:y}"},
        {pos: [6, 10, 12], state: "minecraft:air"},
        {pos: [7, 10, 3], state: "sullysmod:petrified_log{axis:y}"},
        {pos: [7, 10, 4], state: "sullysmod:petrified_log{axis:y}"},
        {pos: [7, 10, 5], state: "sullysmod:stripped_petrified_log{axis:y}"},
        {pos: [7, 10, 6], state: "sullysmod:stripped_petrified_log{axis:y}"},
        {pos: [7, 10, 7], state: "sullysmod:stripped_petrified_log{axis:y}"},
        {pos: [7, 10, 8], state: "sullysmod:stripped_petrified_log{axis:y}"},
        {pos: [7, 10, 9], state: "sullysmod:stripped_petrified_log{axis:y}"},
        {pos: [7, 10, 10], state: "sullysmod:stripped_petrified_log{axis:y}"},
        {pos: [7, 10, 11], state: "sullysmod:petrified_log{axis:y}"},
        {pos: [7, 10, 12], state: "sullysmod:petrified_log{axis:y}"},
        {pos: [8, 10, 3], state: "minecraft:gravel"},
        {pos: [8, 10, 4], state: "sullysmod:petrified_log{axis:y}"},
        {pos: [8, 10, 5], state: "sullysmod:stripped_petrified_log{axis:y}"},
        {pos: [8, 10, 6], state: "sullysmod:rough_amber{is_melted:false}"},
        {pos: [8, 10, 7], state: "sullysmod:rough_amber{is_melted:false}"},
        {pos: [8, 10, 8], state: "sullysmod:stripped_petrified_log{axis:y}"},
        {pos: [8, 10, 9], state: "sullysmod:stripped_petrified_log{axis:y}"},
        {pos: [8, 10, 10], state: "sullysmod:stripped_petrified_log{axis:y}"},
        {pos: [8, 10, 11], state: "sullysmod:petrified_log{axis:y}"},
        {pos: [8, 10, 12], state: "sullysmod:petrified_log{axis:y}"},
        {pos: [9, 10, 3], state: "sullysmod:petrified_log{axis:y}"},
        {pos: [9, 10, 4], state: "sullysmod:petrified_log{axis:y}"},
        {pos: [9, 10, 5], state: "sullysmod:rough_amber{is_melted:false}"},
        {pos: [9, 10, 6], state: "sullysmod:rough_amber{is_melted:false}"},
        {pos: [9, 10, 7], state: "sullysmod:rough_amber{is_melted:false}"},
        {pos: [9, 10, 8], state: "sullysmod:rough_amber{is_melted:false}"},
        {pos: [9, 10, 9], state: "sullysmod:stripped_petrified_log{axis:y}"},
        {pos: [9, 10, 10], state: "sullysmod:stripped_petrified_log{axis:y}"},
        {pos: [9, 10, 11], state: "sullysmod:petrified_log{axis:y}"},
        {pos: [9, 10, 12], state: "sullysmod:petrified_log{axis:y}"},
        {pos: [10, 10, 3], state: "sullysmod:petrified_log{axis:y}"},
        {pos: [10, 10, 4], state: "sullysmod:petrified_log{axis:y}"},
        {pos: [10, 10, 5], state: "sullysmod:rough_amber{is_melted:false}"},
        {pos: [10, 10, 6], state: "sullysmod:rough_amber{is_melted:false}"},
        {pos: [10, 10, 7], state: "sullysmod:rough_amber{is_melted:false}"},
        {pos: [10, 10, 8], state: "sullysmod:stripped_petrified_log{axis:y}"},
        {pos: [10, 10, 9], state: "sullysmod:stripped_petrified_log{axis:y}"},
        {pos: [10, 10, 10], state: "sullysmod:stripped_petrified_log{axis:y}"},
        {pos: [10, 10, 11], state: "sullysmod:petrified_log{axis:y}"},
        {pos: [10, 10, 12], state: "sullysmod:petrified_log{axis:y}"},
        {pos: [11, 10, 3], state: "minecraft:gravel"},
        {pos: [11, 10, 4], state: "sullysmod:petrified_log{axis:y}"},
        {pos: [11, 10, 5], state: "sullysmod:rough_amber{is_melted:false}"},
        {pos: [11, 10, 6], state: "sullysmod:stripped_petrified_log{axis:y}"},
        {pos: [11, 10, 7], state: "sullysmod:stripped_petrified_log{axis:y}"},
        {pos: [11, 10, 8], state: "sullysmod:stripped_petrified_log{axis:y}"},
        {pos: [11, 10, 9], state: "sullysmod:stripped_petrified_log{axis:y}"},
        {pos: [11, 10, 10], state: "sullysmod:stripped_petrified_log{axis:y}"},
        {pos: [11, 10, 11], state: "sullysmod:petrified_log{axis:y}"},
        {pos: [11, 10, 12], state: "sullysmod:stripped_petrified_log{axis:y}"},
        {pos: [12, 10, 5], state: "sullysmod:petrified_log{axis:y}"},
        {pos: [12, 10, 6], state: "sullysmod:petrified_log{axis:y}"},
        {pos: [12, 10, 7], state: "sullysmod:petrified_log{axis:y}"},
        {pos: [12, 10, 8], state: "sullysmod:petrified_log{axis:y}"},
        {pos: [12, 10, 9], state: "sullysmod:petrified_log{axis:y}"},
        {pos: [12, 10, 10], state: "sullysmod:petrified_log{axis:y}"},
        {pos: [12, 10, 11], state: "sullysmod:petrified_log{axis:y}"},
        {pos: [13, 10, 5], state: "minecraft:gravel"},
        {pos: [13, 10, 6], state: "sullysmod:petrified_log{axis:y}"},
        {pos: [13, 10, 7], state: "sullysmod:petrified_log{axis:y}"},
        {pos: [13, 10, 8], state: "sullysmod:petrified_log{axis:y}"},
        {pos: [13, 10, 9], state: "sullysmod:petrified_log{axis:y}"},
        {pos: [4, 11, 8], state: "sullysmod:petrified_log{axis:y}"},
        {pos: [5, 11, 5], state: "sullysmod:petrified_log{axis:y}"},
        {pos: [5, 11, 6], state: "sullysmod:petrified_log{axis:y}"},
        {pos: [5, 11, 7], state: "sullysmod:petrified_log{axis:y}"},
        {pos: [5, 11, 8], state: "sullysmod:petrified_log{axis:y}"},
        {pos: [5, 11, 9], state: "sullysmod:petrified_log{axis:y}"},
        {pos: [5, 11, 10], state: "sullysmod:petrified_log{axis:y}"},
        {pos: [5, 11, 11], state: "sullysmod:amber{is_melted:false}", nbt: {RenderEntity: 0b, StuckEntity: [], id: "sullysmod:amber"}},
        {pos: [6, 11, 4], state: "sullysmod:petrified_log{axis:y}"},
        {pos: [6, 11, 5], state: "sullysmod:stripped_petrified_log{axis:y}"},
        {pos: [6, 11, 6], state: "sullysmod:stripped_petrified_log{axis:y}"},
        {pos: [6, 11, 7], state: "sullysmod:stripped_petrified_log{axis:y}"},
        {pos: [6, 11, 8], state: "sullysmod:stripped_petrified_log{axis:y}"},
        {pos: [6, 11, 9], state: "sullysmod:stripped_petrified_log{axis:y}"},
        {pos: [6, 11, 10], state: "sullysmod:rough_amber{is_melted:false}"},
        {pos: [6, 11, 11], state: "sullysmod:stripped_petrified_log{axis:y}"},
        {pos: [7, 11, 4], state: "sullysmod:petrified_log{axis:y}"},
        {pos: [7, 11, 5], state: "sullysmod:stripped_petrified_log{axis:y}"},
        {pos: [7, 11, 6], state: "sullysmod:stripped_petrified_log{axis:y}"},
        {pos: [7, 11, 7], state: "sullysmod:stripped_petrified_log{axis:y}"},
        {pos: [7, 11, 8], state: "sullysmod:stripped_petrified_log{axis:y}"},
        {pos: [7, 11, 9], state: "sullysmod:stripped_petrified_log{axis:y}"},
        {pos: [7, 11, 10], state: "sullysmod:rough_amber{is_melted:false}"},
        {pos: [7, 11, 11], state: "sullysmod:petrified_log{axis:y}"},
        {pos: [7, 11, 12], state: "minecraft:air"},
        {pos: [8, 11, 3], state: "minecraft:air"},
        {pos: [8, 11, 4], state: "sullysmod:petrified_log{axis:y}"},
        {pos: [8, 11, 5], state: "sullysmod:stripped_petrified_log{axis:y}"},
        {pos: [8, 11, 6], state: "sullysmod:rough_amber{is_melted:false}"},
        {pos: [8, 11, 7], state: "sullysmod:rough_amber{is_melted:false}"},
        {pos: [8, 11, 8], state: "sullysmod:stripped_petrified_log{axis:y}"},
        {pos: [8, 11, 9], state: "sullysmod:stripped_petrified_log{axis:y}"},
        {pos: [8, 11, 10], state: "sullysmod:stripped_petrified_log{axis:y}"},
        {pos: [8, 11, 11], state: "sullysmod:petrified_log{axis:y}"},
        {pos: [8, 11, 12], state: "sullysmod:petrified_log{axis:y}"},
        {pos: [9, 11, 3], state: "sullysmod:petrified_log{axis:y}"},
        {pos: [9, 11, 4], state: "sullysmod:petrified_log{axis:y}"},
        {pos: [9, 11, 5], state: "sullysmod:stripped_petrified_log{axis:y}"},
        {pos: [9, 11, 6], state: "sullysmod:stripped_petrified_log{axis:y}"},
        {pos: [9, 11, 7], state: "sullysmod:stripped_petrified_log{axis:y}"},
        {pos: [9, 11, 8], state: "sullysmod:stripped_petrified_log{axis:y}"},
        {pos: [9, 11, 9], state: "sullysmod:stripped_petrified_log{axis:y}"},
        {pos: [9, 11, 10], state: "sullysmod:stripped_petrified_log{axis:y}"},
        {pos: [9, 11, 11], state: "sullysmod:petrified_log{axis:y}"},
        {pos: [9, 11, 12], state: "sullysmod:petrified_log{axis:y}"},
        {pos: [10, 11, 3], state: "sullysmod:petrified_log{axis:y}"},
        {pos: [10, 11, 4], state: "sullysmod:petrified_log{axis:y}"},
        {pos: [10, 11, 5], state: "sullysmod:stripped_petrified_log{axis:y}"},
        {pos: [10, 11, 6], state: "sullysmod:rough_amber{is_melted:false}"},
        {pos: [10, 11, 7], state: "sullysmod:stripped_petrified_log{axis:y}"},
        {pos: [10, 11, 8], state: "sullysmod:stripped_petrified_log{axis:y}"},
        {pos: [10, 11, 9], state: "sullysmod:stripped_petrified_log{axis:y}"},
        {pos: [10, 11, 10], state: "sullysmod:stripped_petrified_log{axis:y}"},
        {pos: [10, 11, 11], state: "sullysmod:petrified_log{axis:y}"},
        {pos: [10, 11, 12], state: "sullysmod:stripped_petrified_log{axis:y}"},
        {pos: [11, 11, 4], state: "sullysmod:petrified_log{axis:y}"},
        {pos: [11, 11, 5], state: "sullysmod:stripped_petrified_log{axis:y}"},
        {pos: [11, 11, 6], state: "sullysmod:stripped_petrified_log{axis:y}"},
        {pos: [11, 11, 7], state: "sullysmod:stripped_petrified_log{axis:y}"},
        {pos: [11, 11, 8], state: "sullysmod:stripped_petrified_log{axis:y}"},
        {pos: [11, 11, 9], state: "sullysmod:stripped_petrified_log{axis:y}"},
        {pos: [11, 11, 10], state: "sullysmod:stripped_petrified_log{axis:y}"},
        {pos: [11, 11, 11], state: "sullysmod:petrified_log{axis:y}"},
        {pos: [12, 11, 5], state: "sullysmod:petrified_log{axis:y}"},
        {pos: [12, 11, 6], state: "sullysmod:petrified_log{axis:y}"},
        {pos: [12, 11, 7], state: "sullysmod:petrified_log{axis:y}"},
        {pos: [12, 11, 8], state: "sullysmod:petrified_log{axis:y}"},
        {pos: [12, 11, 9], state: "sullysmod:petrified_log{axis:y}"},
        {pos: [12, 11, 10], state: "sullysmod:petrified_log{axis:y}"},
        {pos: [13, 11, 6], state: "sullysmod:petrified_log{axis:y}"},
        {pos: [13, 11, 7], state: "minecraft:gravel"},
        {pos: [13, 11, 8], state: "sullysmod:petrified_log{axis:y}"},
        {pos: [5, 12, 5], state: "sullysmod:petrified_log{axis:y}"},
        {pos: [5, 12, 6], state: "sullysmod:petrified_log{axis:y}"},
        {pos: [5, 12, 7], state: "sullysmod:petrified_log{axis:y}"},
        {pos: [5, 12, 8], state: "sullysmod:petrified_log{axis:y}"},
        {pos: [5, 12, 9], state: "sullysmod:petrified_log{axis:y}"},
        {pos: [5, 12, 10], state: "sullysmod:petrified_log{axis:y}"},
        {pos: [6, 12, 4], state: "sullysmod:petrified_log{axis:y}"},
        {pos: [6, 12, 5], state: "sullysmod:stripped_petrified_log{axis:y}"},
        {pos: [6, 12, 6], state: "sullysmod:stripped_petrified_log{axis:y}"},
        {pos: [6, 12, 7], state: "sullysmod:stripped_petrified_log{axis:y}"},
        {pos: [6, 12, 8], state: "sullysmod:stripped_petrified_log{axis:y}"},
        {pos: [6, 12, 9], state: "sullysmod:rough_amber{is_melted:false}"},
        {pos: [6, 12, 10], state: "sullysmod:rough_amber{is_melted:false}"},
        {pos: [6, 12, 11], state: "sullysmod:amber{is_melted:false}", nbt: {RenderEntity: 0b, StuckEntity: [], id: "sullysmod:amber"}},
        {pos: [7, 12, 4], state: "sullysmod:petrified_log{axis:y}"},
        {pos: [7, 12, 5], state: "sullysmod:stripped_petrified_log{axis:y}"},
        {pos: [7, 12, 6], state: "sullysmod:stripped_petrified_log{axis:y}"},
        {pos: [7, 12, 7], state: "sullysmod:stripped_petrified_log{axis:y}"},
        {pos: [7, 12, 8], state: "sullysmod:stripped_petrified_log{axis:y}"},
        {pos: [7, 12, 9], state: "sullysmod:stripped_petrified_log{axis:y}"},
        {pos: [7, 12, 10], state: "sullysmod:rough_amber{is_melted:false}"},
        {pos: [7, 12, 11], state: "sullysmod:petrified_log{axis:y}"},
        {pos: [7, 12, 12], state: "minecraft:air"},
        {pos: [8, 12, 3], state: "minecraft:air"},
        {pos: [8, 12, 4], state: "sullysmod:petrified_log{axis:y}"},
        {pos: [8, 12, 5], state: "sullysmod:stripped_petrified_log{axis:y}"},
        {pos: [8, 12, 6], state: "sullysmod:stripped_petrified_log{axis:y}"},
        {pos: [8, 12, 7], state: "sullysmod:rough_amber{is_melted:false}"},
        {pos: [8, 12, 8], state: "sullysmod:stripped_petrified_log{axis:y}"},
        {pos: [8, 12, 9], state: "sullysmod:stripped_petrified_log{axis:y}"},
        {pos: [8, 12, 10], state: "sullysmod:stripped_petrified_log{axis:y}"},
        {pos: [8, 12, 11], state: "sullysmod:petrified_log{axis:y}"},
        {pos: [8, 12, 12], state: "sullysmod:stripped_petrified_log{axis:y}"},
        {pos: [9, 12, 3], state: "sullysmod:stripped_petrified_log{axis:y}"},
        {pos: [9, 12, 4], state: "sullysmod:petrified_log{axis:y}"},
        {pos: [9, 12, 5], state: "sullysmod:stripped_petrified_log{axis:y}"},
        {pos: [9, 12, 6], state: "sullysmod:stripped_petrified_log{axis:y}"},
        {pos: [9, 12, 7], state: "sullysmod:stripped_petrified_log{axis:y}"},
        {pos: [9, 12, 8], state: "sullysmod:stripped_petrified_log{axis:y}"},
        {pos: [9, 12, 9], state: "sullysmod:stripped_petrified_log{axis:y}"},
        {pos: [9, 12, 10], state: "sullysmod:stripped_petrified_log{axis:y}"},
        {pos: [9, 12, 11], state: "sullysmod:petrified_log{axis:y}"},
        {pos: [9, 12, 12], state: "sullysmod:petrified_log{axis:y}"},
        {pos: [10, 12, 3], state: "sullysmod:petrified_log{axis:y}"},
        {pos: [10, 12, 4], state: "sullysmod:petrified_log{axis:y}"},
        {pos: [10, 12, 5], state: "sullysmod:stripped_petrified_log{axis:y}"},
        {pos: [10, 12, 6], state: "sullysmod:stripped_petrified_log{axis:y}"},
        {pos: [10, 12, 7], state: "sullysmod:stripped_petrified_log{axis:y}"},
        {pos: [10, 12, 8], state: "sullysmod:stripped_petrified_log{axis:y}"},
        {pos: [10, 12, 9], state: "sullysmod:stripped_petrified_log{axis:y}"},
        {pos: [10, 12, 10], state: "sullysmod:stripped_petrified_log{axis:y}"},
        {pos: [10, 12, 11], state: "sullysmod:petrified_log{axis:y}"},
        {pos: [11, 12, 4], state: "sullysmod:petrified_log{axis:y}"},
        {pos: [11, 12, 5], state: "sullysmod:stripped_petrified_log{axis:y}"},
        {pos: [11, 12, 6], state: "sullysmod:stripped_petrified_log{axis:y}"},
        {pos: [11, 12, 7], state: "sullysmod:stripped_petrified_log{axis:y}"},
        {pos: [11, 12, 8], state: "sullysmod:stripped_petrified_log{axis:y}"},
        {pos: [11, 12, 9], state: "sullysmod:stripped_petrified_log{axis:y}"},
        {pos: [11, 12, 10], state: "sullysmod:stripped_petrified_log{axis:y}"},
        {pos: [11, 12, 11], state: "sullysmod:petrified_log{axis:y}"},
        {pos: [12, 12, 5], state: "sullysmod:petrified_log{axis:y}"},
        {pos: [12, 12, 6], state: "sullysmod:petrified_log{axis:y}"},
        {pos: [12, 12, 7], state: "sullysmod:petrified_log{axis:y}"},
        {pos: [12, 12, 8], state: "sullysmod:petrified_log{axis:y}"},
        {pos: [12, 12, 9], state: "sullysmod:stripped_petrified_log{axis:y}"},
        {pos: [12, 12, 10], state: "sullysmod:stripped_petrified_log{axis:y}"},
        {pos: [13, 12, 6], state: "minecraft:gravel"},
        {pos: [13, 12, 8], state: "sullysmod:stripped_petrified_log{axis:y}"},
        {pos: [13, 12, 9], state: "minecraft:air"},
        {pos: [5, 13, 5], state: "sullysmod:petrified_log{axis:y}"},
        {pos: [5, 13, 6], state: "sullysmod:petrified_log{axis:y}"},
        {pos: [5, 13, 7], state: "sullysmod:petrified_log{axis:y}"},
        {pos: [5, 13, 8], state: "sullysmod:petrified_log{axis:y}"},
        {pos: [5, 13, 9], state: "sullysmod:petrified_log{axis:y}"},
        {pos: [5, 13, 10], state: "sullysmod:stripped_petrified_log{axis:y}"},
        {pos: [6, 13, 4], state: "sullysmod:petrified_log{axis:y}"},
        {pos: [6, 13, 5], state: "sullysmod:stripped_petrified_log{axis:y}"},
        {pos: [6, 13, 6], state: "sullysmod:stripped_petrified_log{axis:y}"},
        {pos: [6, 13, 7], state: "sullysmod:stripped_petrified_log{axis:y}"},
        {pos: [6, 13, 8], state: "sullysmod:stripped_petrified_log{axis:y}"},
        {pos: [6, 13, 9], state: "sullysmod:rough_amber{is_melted:false}"},
        {pos: [6, 13, 10], state: "sullysmod:rough_amber{is_melted:false}"},
        {pos: [6, 13, 11], state: "minecraft:air"},
        {pos: [7, 13, 4], state: "sullysmod:petrified_log{axis:y}"},
        {pos: [7, 13, 5], state: "sullysmod:stripped_petrified_log{axis:y}"},
        {pos: [7, 13, 6], state: "sullysmod:stripped_petrified_log{axis:y}"},
        {pos: [7, 13, 7], state: "sullysmod:stripped_petrified_log{axis:y}"},
        {pos: [7, 13, 8], state: "sullysmod:stripped_petrified_log{axis:y}"},
        {pos: [7, 13, 9], state: "sullysmod:rough_amber{is_melted:false}"},
        {pos: [7, 13, 10], state: "sullysmod:rough_amber{is_melted:false}"},
        {pos: [7, 13, 11], state: "sullysmod:petrified_log{axis:y}"},
        {pos: [7, 13, 12], state: "minecraft:air"},
        {pos: [8, 13, 4], state: "sullysmod:petrified_log{axis:y}"},
        {pos: [8, 13, 5], state: "sullysmod:stripped_petrified_log{axis:y}"},
        {pos: [8, 13, 6], state: "sullysmod:stripped_petrified_log{axis:y}"},
        {pos: [8, 13, 7], state: "sullysmod:stripped_petrified_log{axis:y}"},
        {pos: [8, 13, 8], state: "sullysmod:stripped_petrified_log{axis:y}"},
        {pos: [8, 13, 9], state: "sullysmod:stripped_petrified_log{axis:y}"},
        {pos: [8, 13, 10], state: "sullysmod:stripped_petrified_log{axis:y}"},
        {pos: [8, 13, 11], state: "sullysmod:petrified_log{axis:y}"},
        {pos: [9, 13, 3], state: "minecraft:air"},
        {pos: [9, 13, 4], state: "sullysmod:petrified_log{axis:y}"},
        {pos: [9, 13, 5], state: "sullysmod:stripped_petrified_log{axis:y}"},
        {pos: [9, 13, 6], state: "sullysmod:stripped_petrified_log{axis:y}"},
        {pos: [9, 13, 7], state: "sullysmod:stripped_petrified_log{axis:y}"},
        {pos: [9, 13, 8], state: "sullysmod:stripped_petrified_log{axis:y}"},
        {pos: [9, 13, 9], state: "sullysmod:stripped_petrified_log{axis:y}"},
        {pos: [9, 13, 10], state: "sullysmod:stripped_petrified_log{axis:y}"},
        {pos: [9, 13, 11], state: "sullysmod:petrified_log{axis:y}"},
        {pos: [9, 13, 12], state: "sullysmod:stripped_petrified_log{axis:y}"},
        {pos: [10, 13, 3], state: "sullysmod:stripped_petrified_log{axis:y}"},
        {pos: [10, 13, 4], state: "sullysmod:petrified_log{axis:y}"},
        {pos: [10, 13, 5], state: "sullysmod:stripped_petrified_log{axis:y}"},
        {pos: [10, 13, 6], state: "sullysmod:stripped_petrified_log{axis:y}"},
        {pos: [10, 13, 7], state: "sullysmod:stripped_petrified_log{axis:y}"},
        {pos: [10, 13, 8], state: "minecraft:air"},
        {pos: [10, 13, 9], state: "minecraft:air"},
        {pos: [10, 13, 10], state: "sullysmod:stripped_petrified_log{axis:y}"},
        {pos: [10, 13, 11], state: "sullysmod:petrified_log{axis:y}"},
        {pos: [11, 13, 4], state: "sullysmod:petrified_log{axis:y}"},
        {pos: [11, 13, 5], state: "sullysmod:stripped_petrified_log{axis:y}"},
        {pos: [11, 13, 6], state: "sullysmod:stripped_petrified_log{axis:y}"},
        {pos: [11, 13, 7], state: "sullysmod:stripped_petrified_log{axis:y}"},
        {pos: [11, 13, 8], state: "sullysmod:stripped_petrified_log{axis:y}"},
        {pos: [11, 13, 9], state: "minecraft:air"},
        {pos: [11, 13, 10], state: "minecraft:air"},
        {pos: [11, 13, 11], state: "sullysmod:petrified_log{axis:y}"},
        {pos: [12, 13, 5], state: "sullysmod:petrified_log{axis:y}"},
        {pos: [12, 13, 6], state: "sullysmod:petrified_log{axis:y}"},
