{
    DataVersion: 3465,
    size: [7, 6, 11],
    data: [
        {pos: [1, 0, 4], state: "minecraft:gravel"},
        {pos: [1, 0, 5], state: "minecraft:gravel"},
        {pos: [1, 0, 6], state: "minecraft:gravel"},
        {pos: [1, 0, 7], state: "minecraft:gravel"},
        {pos: [1, 0, 8], state: "minecraft:gravel"},
        {pos: [2, 0, 2], state: "minecraft:gravel"},
        {pos: [2, 0, 3], state: "minecraft:gravel"},
        {pos: [2, 0, 4], state: "minecraft:gravel"},
        {pos: [2, 0, 5], state: "minecraft:gravel"},
        {pos: [2, 0, 6], state: "minecraft:gravel"},
        {pos: [2, 0, 7], state: "minecraft:gravel"},
        {pos: [2, 0, 8], state: "minecraft:gravel"},
        {pos: [2, 0, 9], state: "minecraft:gravel"},
        {pos: [3, 0, 2], state: "minecraft:gravel"},
        {pos: [3, 0, 3], state: "minecraft:gravel"},
        {pos: [3, 0, 4], state: "minecraft:gravel"},
        {pos: [3, 0, 5], state: "minecraft:gravel"},
        {pos: [3, 0, 6], state: "minecraft:gravel"},
        {pos: [3, 0, 7], state: "minecraft:gravel"},
        {pos: [4, 0, 3], state: "minecraft:gravel"},
        {pos: [4, 0, 4], state: "minecraft:gravel"},
        {pos: [4, 0, 5], state: "minecraft:gravel"},
        {pos: [4, 0, 6], state: "minecraft:gravel"},
        {pos: [5, 0, 4], state: "minecraft:gravel"},
        {pos: [0, 1, 3], state: "minecraft:gravel"},
        {pos: [0, 1, 4], state: "minecraft:gravel"},
        {pos: [0, 1, 5], state: "minecraft:gravel"},
        {pos: [0, 1, 6], state: "minecraft:gravel"},
        {pos: [0, 1, 7], state: "minecraft:gravel"},
        {pos: [1, 1, 1], state: "minecraft:gravel"},
        {pos: [1, 1, 2], state: "minecraft:gravel"},
        {pos: [1, 1, 3], state: "minecraft:gravel"},
        {pos: [1, 1, 4], state: "minecraft:gravel"},
        {pos: [1, 1, 5], state: "minecraft:gravel"},
        {pos: [1, 1, 6], state: "minecraft:gravel"},
        {pos: [1, 1, 7], state: "minecraft:gravel"},
        {pos: [1, 1, 8], state: "minecraft:gravel"},
        {pos: [1, 1, 9], state: "minecraft:gravel"},
        {pos: [2, 1, 1], state: "sullysmod:petrified_log{axis:z}"},
        {pos: [2, 1, 2], state: "sullysmod:petrified_log{axis:z}"},
        {pos: [2, 1, 3], state: "sullysmod:petrified_log{axis:z}"},
        {pos: [2, 1, 4], state: "sullysmod:petrified_log{axis:z}"},
        {pos: [2, 1, 5], state: "sullysmod:petrified_log{axis:z}"},
        {pos: [2, 1, 6], state: "sullysmod:petrified_log{axis:z}"},
        {pos: [2, 1, 7], state: "sullysmod:petrified_log{axis:z}"},
        {pos: [2, 1, 8], state: "sullysmod:stripped_petrified_log{axis:z}"},
        {pos: [2, 1, 9], state: "minecraft:gravel"},
        {pos: [3, 1, 0], state: "minecraft:gravel"},
        {pos: [3, 1, 1], state: "minecraft:gravel"},
        {pos: [3, 1, 2], state: "sullysmod:stripped_petrified_log{axis:z}"},
        {pos: [3, 1, 3], state: "sullysmod:petrified_log{axis:z}"},
        {pos: [3, 1, 4], state: "sullysmod:petrified_log{axis:z}"},
        {pos: [3, 1, 5], state: "sullysmod:petrified_log{axis:z}"},
        {pos: [3, 1, 6], state: "sullysmod:petrified_log{axis:z}"},
        {pos: [3, 1, 7], state: "sullysmod:petrified_log{axis:z}"},
        {pos: [3, 1, 8], state: "sullysmod:petrified_log{axis:z}"},
        {pos: [3, 1, 9], state: "sullysmod:petrified_log{axis:z}"},
        {pos: [4, 1, 1], state: "sullysmod:stripped_petrified_log{axis:z}"},
        {pos: [4, 1, 2], state: "sullysmod:petrified_log{axis:z}"},
        {pos: [4, 1, 3], state: "sullysmod:petrified_log{axis:z}"},
        {pos: [4, 1, 4], state: "sullysmod:petrified_log{axis:z}"},
        {pos: [4, 1, 5], state: "sullysmod:petrified_log{axis:z}"},
        {pos: [4, 1, 6], state: "sullysmod:petrified_log{axis:z}"},
        {pos: [4, 1, 7], state: "sullysmod:stripped_petrified_log{axis:z}"},
        {pos: [4, 1, 8], state: "minecraft:gravel"},
        {pos: [5, 1, 1], state: "minecraft:gravel"},
        {pos: [5, 1, 2], state: "minecraft:gravel"},
        {pos: [5, 1, 3], state: "minecraft:gravel"},
        {pos: [5, 1, 4], state: "minecraft:gravel"},
        {pos: [5, 1, 5], state: "minecraft:gravel"},
        {pos: [5, 1, 6], state: "minecraft:gravel"},
        {pos: [6, 1, 2], state: "minecraft:gravel"},
        {pos: [6, 1, 3], state: "minecraft:gravel"},
        {pos: [0, 2, 4], state: "minecraft:gravel"},
        {pos: [0, 2, 5], state: "minecraft:gravel"},
        {pos: [0, 2, 6], state: "minecraft:gravel"},
        {pos: [0, 2, 7], state: "minecraft:gravel"},
        {pos: [0, 2, 8], state: "minecraft:gravel"},
        {pos: [1, 2, 1], state: "sullysmod:petrified_log{axis:z}"},
        {pos: [1, 2, 2], state: "sullysmod:petrified_log{axis:z}"},
        {pos: [1, 2, 3], state: "sullysmod:petrified_log{axis:z}"},
        {pos: [1, 2, 4], state: "minecraft:gravel"},
        {pos: [1, 2, 5], state: "minecraft:gravel"},
        {pos: [1, 2, 6], state: "sullysmod:petrified_log{axis:z}"},
        {pos: [1, 2, 7], state: "sullysmod:petrified_log{axis:z}"},
        {pos: [1, 2, 8], state: "sullysmod:petrified_log{axis:z}"},
        {pos: [1, 2, 9], state: "minecraft:gravel"},
        {pos: [2, 2, 1], state: "minecraft:gravel"},
        {pos: [2, 2, 3], state: "sullysmod:stripped_petrified_log{axis:z}"},
        {pos: [2, 2, 4], state: "sullysmod:petrified_log{axis:z}"},
        {pos: [2, 2, 5], state: "sullysmod:petrified_log{axis:z}"},
        {pos: [2, 2, 6], state: "minecraft:suspicious_gravel{dusted:0}", nbt: {id: "minecraft:brushable_block", item: {Count: 0b, id: "minecraft:air"}}},
        {pos: [2, 2, 7], state: "minecraft:gravel"},
        {pos: [2, 2, 8], state: "minecraft:gravel"},
        {pos: [3, 2, 2], state: "minecraft:gravel"},
        {pos: [3, 2, 3], state: "minecraft:gravel"},
        {pos: [3, 2, 4], state: "minecraft:gravel"},
        {pos: [3, 2, 5], state: "minecraft:gravel"},
        {pos: [3, 2, 6], state: "minecraft:gravel"},
        {pos: [3, 2, 7], state: "minecraft:gravel"},
        {pos: [3, 2, 8], state: "minecraft:air"},
        {pos: [4, 2, 1], state: "minecraft:gravel"},
        {pos: [4, 2, 2], state: "minecraft:gravel"},
        {pos: [4, 2, 3], state: "minecraft:gravel"},
        {pos: [4, 2, 4], state: "minecraft:gravel"},
        {pos: [4, 2, 5], state: "minecraft:gravel"},
        {pos: [4, 2, 6], state: "minecraft:gravel"},
        {pos: [4, 2, 8], state: "minecraft:gravel"},
        {pos: [5, 2, 0], state: "sullysmod:stripped_petrified_log{axis:z}"},
        {pos: [5, 2, 1], state: "sullysmod:petrified_log{axis:z}"},
        {pos: [5, 2, 2], state: "sullysmod:stripped_petrified_log{axis:z}"},
        {pos: [5, 2, 3], state: "sullysmod:stripped_petrified_log{axis:z}"},
        {pos: [5, 2, 4], state: "sullysmod:petrified_log{axis:z}"},
        {pos: [5, 2, 5], state: "sullysmod:petrified_log{axis:z}"},
        {pos: [5, 2, 6], state: "minecraft:gravel"},
        {pos: [6, 2, 2], state: "minecraft:gravel"},
        {pos: [6, 2, 3], state: "minecraft:gravel"},
        {pos: [6, 2, 4], state: "minecraft:gravel"},
        {pos: [1, 3, 1], state: "minecraft:air"},
        {pos: [1, 3, 2], state: "sullysmod:petrified_log{axis:z}"},
        {pos: [1, 3, 3], state: "sullysmod:petrified_log{axis:z}"},
        {pos: [1, 3, 4], state: "sullysmod:petrified_log{axis:z}"},
        {pos: [1, 3, 5], state: "sullysmod:petrified_log{axis:z}"},
        {pos: [1, 3, 6], state: "sullysmod:stripped_petrified_log{axis:z}"},
        {pos: [1, 3, 7], state: "sullysmod:stripped_petrified_log{axis:z}"},
        {pos: [2, 3, 2], state: "minecraft:air"},
        {pos: [2, 3, 3], state: "minecraft:air"},
        {pos: [2, 3, 4], state: "minecraft:air"},
        {pos: [2, 3, 5], state: "minecraft:air"},
        {pos: [2, 3, 6], state: "minecraft:air"},
        {pos: [2, 3, 7], state: "minecraft:air"},
        {pos: [3, 3, 3], state: "minecraft:air"},
        {pos: [3, 3, 4], state: "minecraft:air"},
        {pos: [3, 3, 5], state: "minecraft:air"},
        {pos: [4, 3, 4], state: "minecraft:air"},
        {pos: [4, 3, 5], state: "minecraft:air"},
        {pos: [4, 3, 6], state: "minecraft:air"},
        {pos: [5, 3, 3], state: "sullysmod:petrified_log{axis:z}"},
        {pos: [5, 3, 4], state: "sullysmod:petrified_log{axis:z}"},
        {pos: [5, 3, 5], state: "sullysmod:petrified_log{axis:z}"},
        {pos: [5, 3, 6], state: "sullysmod:petrified_log{axis:z}"},
        {pos: [1, 4, 1], state: "sullysmod:petrified_log{axis:z}"},
        {pos: [1, 4, 2], state: "sullysmod:petrified_log{axis:z}"},
        {pos: [1, 4, 3], state: "sullysmod:petrified_log{axis:z}"},
        {pos: [1, 4, 4], state: "sullysmod:stripped_petrified_log{axis:z}"},
        {pos: [1, 4, 7], state: "sullysmod:petrified_log{axis:z}"},
        {pos: [1, 4, 8], state: "sullysmod:petrified_log{axis:z}"},
        {pos: [1, 4, 9], state: "sullysmod:stripped_petrified_log{axis:z}"},
        {pos: [2, 4, 1], state: "minecraft:air"},
        {pos: [2, 4, 2], state: "minecraft:air"},
        {pos: [2, 4, 3], state: "minecraft:air"},
        {pos: [2, 4, 6], state: "minecraft:air"},
        {pos: [2, 4, 7], state: "minecraft:air"},
        {pos: [2, 4, 8], state: "minecraft:air"},
        {pos: [3, 4, 3], state: "minecraft:air"},
        {pos: [3, 4, 6], state: "minecraft:air"},
        {pos: [4, 4, 2], state: "minecraft:air"},
        {pos: [4, 4, 3], state: "minecraft:air"},
        {pos: [4, 4, 4], state: "minecraft:air"},
        {pos: [4, 4, 5], state: "minecraft:air"},
        {pos: [4, 4, 7], state: "minecraft:air"},
        {pos: [5, 4, 4], state: "sullysmod:petrified_log{axis:z}"},
        {pos: [2, 5, 2], state: "sullysmod:petrified_log{axis:z}"},
        {pos: [2, 5, 3], state: "sullysmod:petrified_log{axis:z}"},
        {pos: [2, 5, 6], state: "sullysmod:stripped_petrified_log{axis:z}"},
        {pos: [2, 5, 7], state: "sullysmod:petrified_log{axis:z}"},
        {pos: [2, 5, 8], state: "sullysmod:stripped_petrified_log{axis:z}"},
        {pos: [3, 5, 3], state: "sullysmod:petrified_log{axis:z}"},
        {pos: [3, 5, 4], state: "sullysmod:petrified_log{axis:z}"},
        {pos: [3, 5, 5], state: "sullysmod:petrified_log{axis:z}"},
        {pos: [3, 5, 6], state: "sullysmod:petrified_log{axis:z}"},
        {pos: [4, 5, 2], state: "sullysmod:stripped_petrified_log{axis:z}"},
        {pos: [4, 5, 3], state: "sullysmod:stripped_petrified_log{axis:z}"},
        {pos: [4, 5, 4], state: "sullysmod:petrified_log{axis:z}"},
        {pos: [4, 5, 5], state: "sullysmod:petrified_log{axis:z}"},
        {pos: [4, 5, 6], state: "sullysmod:petrified_log{axis:z}"},
        {pos: [4, 5, 7], state: "sullysmod:stripped_petrified_log{axis:z}"}
    ],
    entities: [],
    palette: [
        "minecraft:gravel",
        "sullysmod:petrified_log{axis:z}",
        "sullysmod:stripped_petrified_log{axis:z}",
        "minecraft:air",
        "minecraft:suspicious_gravel{dusted:0}"
    ]
}
