{
    DataVersion: 3465,
    size: [11, 10, 16],
    data: [
        {pos: [2, 0, 6], state: "minecraft:gravel"},
        {pos: [2, 0, 7], state: "minecraft:gravel"},
        {pos: [2, 0, 8], state: "minecraft:gravel"},
        {pos: [3, 0, 5], state: "minecraft:gravel"},
        {pos: [3, 0, 6], state: "minecraft:gravel"},
        {pos: [3, 0, 7], state: "minecraft:gravel"},
        {pos: [3, 0, 8], state: "minecraft:gravel"},
        {pos: [3, 0, 9], state: "minecraft:gravel"},
        {pos: [3, 0, 10], state: "minecraft:gravel"},
        {pos: [4, 0, 5], state: "minecraft:gravel"},
        {pos: [4, 0, 6], state: "minecraft:gravel"},
        {pos: [4, 0, 7], state: "minecraft:gravel"},
        {pos: [4, 0, 8], state: "minecraft:gravel"},
        {pos: [4, 0, 9], state: "minecraft:gravel"},
        {pos: [4, 0, 10], state: "minecraft:gravel"},
        {pos: [4, 0, 11], state: "minecraft:gravel"},
        {pos: [4, 0, 12], state: "minecraft:gravel"},
        {pos: [5, 0, 4], state: "minecraft:gravel"},
        {pos: [5, 0, 5], state: "minecraft:gravel"},
        {pos: [5, 0, 6], state: "minecraft:gravel"},
        {pos: [5, 0, 7], state: "minecraft:gravel"},
        {pos: [5, 0, 8], state: "minecraft:gravel"},
        {pos: [5, 0, 9], state: "minecraft:gravel"},
        {pos: [5, 0, 10], state: "minecraft:gravel"},
        {pos: [5, 0, 11], state: "minecraft:gravel"},
        {pos: [5, 0, 12], state: "minecraft:gravel"},
        {pos: [6, 0, 4], state: "minecraft:gravel"},
        {pos: [6, 0, 5], state: "minecraft:gravel"},
        {pos: [6, 0, 6], state: "minecraft:gravel"},
        {pos: [6, 0, 7], state: "minecraft:gravel"},
        {pos: [6, 0, 8], state: "minecraft:gravel"},
        {pos: [6, 0, 9], state: "minecraft:gravel"},
        {pos: [6, 0, 10], state: "minecraft:gravel"},
        {pos: [6, 0, 11], state: "minecraft:gravel"},
        {pos: [6, 0, 12], state: "minecraft:gravel"},
        {pos: [6, 0, 13], state: "minecraft:gravel"},
        {pos: [7, 0, 6], state: "minecraft:gravel"},
        {pos: [7, 0, 7], state: "minecraft:gravel"},
        {pos: [7, 0, 8], state: "minecraft:gravel"},
        {pos: [7, 0, 9], state: "minecraft:gravel"},
        {pos: [7, 0, 10], state: "minecraft:gravel"},
        {pos: [7, 0, 11], state: "minecraft:gravel"},
        {pos: [7, 0, 12], state: "minecraft:gravel"},
        {pos: [8, 0, 9], state: "minecraft:gravel"},
        {pos: [8, 0, 10], state: "minecraft:gravel"},
        {pos: [1, 1, 5], state: "minecraft:gravel"},
        {pos: [1, 1, 6], state: "minecraft:gravel"},
        {pos: [1, 1, 7], state: "minecraft:gravel"},
        {pos: [2, 1, 3], state: "minecraft:gravel"},
        {pos: [2, 1, 4], state: "minecraft:gravel"},
        {pos: [2, 1, 5], state: "minecraft:gravel"},
        {pos: [2, 1, 6], state: "minecraft:gravel"},
        {pos: [2, 1, 7], state: "minecraft:gravel"},
        {pos: [2, 1, 8], state: "minecraft:gravel"},
        {pos: [2, 1, 9], state: "minecraft:gravel"},
        {pos: [2, 1, 10], state: "minecraft:gravel"},
        {pos: [2, 1, 11], state: "minecraft:gravel"},
        {pos: [3, 1, 2], state: "sullysmod:stripped_petrified_log{axis:z}"},
        {pos: [3, 1, 3], state: "sullysmod:petrified_log{axis:z}"},
        {pos: [3, 1, 4], state: "sullysmod:petrified_log{axis:z}"},
        {pos: [3, 1, 5], state: "sullysmod:petrified_log{axis:z}"},
        {pos: [3, 1, 6], state: "sullysmod:petrified_log{axis:z}"},
        {pos: [3, 1, 7], state: "sullysmod:petrified_log{axis:z}"},
        {pos: [3, 1, 8], state: "sullysmod:petrified_log{axis:z}"},
        {pos: [3, 1, 9], state: "sullysmod:petrified_log{axis:z}"},
        {pos: [3, 1, 10], state: "sullysmod:petrified_log{axis:z}"},
        {pos: [3, 1, 11], state: "sullysmod:petrified_log{axis:z}"},
        {pos: [3, 1, 12], state: "sullysmod:petrified_log{axis:z}"},
        {pos: [3, 1, 13], state: "sullysmod:petrified_log{axis:z}"},
        {pos: [3, 1, 14], state: "sullysmod:petrified_log{axis:z}"},
        {pos: [4, 1, 3], state: "minecraft:gravel"},
        {pos: [4, 1, 4], state: "sullysmod:stripped_petrified_log{axis:z}"},
        {pos: [4, 1, 5], state: "sullysmod:petrified_log{axis:z}"},
        {pos: [4, 1, 6], state: "sullysmod:stripped_petrified_log{axis:z}"},
        {pos: [4, 1, 7], state: "minecraft:gravel"},
        {pos: [4, 1, 8], state: "minecraft:gravel"},
        {pos: [4, 1, 9], state: "sullysmod:petrified_log{axis:z}"},
        {pos: [4, 1, 10], state: "sullysmod:petrified_log{axis:z}"},
        {pos: [4, 1, 11], state: "sullysmod:petrified_log{axis:z}"},
        {pos: [4, 1, 12], state: "sullysmod:petrified_log{axis:z}"},
        {pos: [4, 1, 13], state: "sullysmod:stripped_petrified_log{axis:z}"},
        {pos: [5, 1, 2], state: "sullysmod:stripped_petrified_log{axis:z}"},
        {pos: [5, 1, 3], state: "sullysmod:petrified_log{axis:z}"},
        {pos: [5, 1, 4], state: "sullysmod:petrified_log{axis:z}"},
        {pos: [5, 1, 5], state: "sullysmod:petrified_log{axis:z}"},
        {pos: [5, 1, 6], state: "sullysmod:petrified_log{axis:z}"},
        {pos: [5, 1, 7], state: "sullysmod:stripped_petrified_log{axis:z}"},
        {pos: [5, 1, 8], state: "minecraft:gravel"},
        {pos: [5, 1, 9], state: "sullysmod:stripped_petrified_log{axis:z}"},
        {pos: [5, 1, 10], state: "sullysmod:petrified_log{axis:z}"},
        {pos: [5, 1, 11], state: "sullysmod:petrified_log{axis:z}"},
        {pos: [5, 1, 12], state: "sullysmod:petrified_log{axis:z}"},
        {pos: [5, 1, 13], state: "sullysmod:petrified_log{axis:z}"},
        {pos: [5, 1, 14], state: "minecraft:gravel"},
        {pos: [6, 1, 3], state: "sullysmod:petrified_log{axis:z}"},
        {pos: [6, 1, 4], state: "sullysmod:petrified_log{axis:z}"},
        {pos: [6, 1, 5], state: "sullysmod:petrified_log{axis:z}"},
        {pos: [6, 1, 6], state: "sullysmod:petrified_log{axis:z}"},
        {pos: [6, 1, 7], state: "sullysmod:petrified_log{axis:z}"},
        {pos: [6, 1, 8], state: "sullysmod:petrified_log{axis:z}"},
        {pos: [6, 1, 9], state: "sullysmod:petrified_log{axis:z}"},
        {pos: [6, 1, 10], state: "sullysmod:petrified_log{axis:z}"},
        {pos: [6, 1, 11], state: "sullysmod:petrified_log{axis:z}"},
        {pos: [6, 1, 12], state: "sullysmod:petrified_log{axis:z}"},
        {pos: [6, 1, 13], state: "minecraft:gravel"},
        {pos: [6, 1, 14], state: "minecraft:gravel"},
        {pos: [7, 1, 4], state: "minecraft:gravel"},
        {pos: [7, 1, 5], state: "minecraft:gravel"},
        {pos: [7, 1, 6], state: "minecraft:gravel"},
        {pos: [7, 1, 7], state: "minecraft:gravel"},
        {pos: [7, 1, 8], state: "minecraft:gravel"},
        {pos: [7, 1, 9], state: "minecraft:gravel"},
        {pos: [7, 1, 10], state: "minecraft:gravel"},
        {pos: [7, 1, 11], state: "minecraft:gravel"},
        {pos: [7, 1, 12], state: "minecraft:gravel"},
        {pos: [7, 1, 13], state: "minecraft:gravel"},
        {pos: [8, 1, 4], state: "minecraft:gravel"},
        {pos: [8, 1, 5], state: "minecraft:gravel"},
        {pos: [8, 1, 6], state: "minecraft:gravel"},
        {pos: [8, 1, 7], state: "minecraft:gravel"},
        {pos: [8, 1, 8], state: "minecraft:gravel"},
        {pos: [8, 1, 9], state: "minecraft:gravel"},
        {pos: [8, 1, 10], state: "minecraft:gravel"},
        {pos: [8, 1, 11], state: "minecraft:gravel"},
        {pos: [8, 1, 12], state: "minecraft:gravel"},
        {pos: [8, 1, 13], state: "minecraft:gravel"},
        {pos: [9, 1, 8], state: "minecraft:gravel"},
        {pos: [9, 1, 9], state: "minecraft:gravel"},
        {pos: [9, 1, 10], state: "minecraft:gravel"},
        {pos: [0, 2, 6], state: "minecraft:gravel"},
        {pos: [0, 2, 7], state: "minecraft:gravel"},
        {pos: [0, 2, 8], state: "minecraft:gravel"},
        {pos: [0, 2, 9], state: "minecraft:gravel"},
        {pos: [1, 2, 2], state: "minecraft:gravel"},
        {pos: [1, 2, 3], state: "minecraft:gravel"},
        {pos: [1, 2, 4], state: "minecraft:gravel"},
        {pos: [1, 2, 5], state: "minecraft:gravel"},
        {pos: [1, 2, 6], state: "minecraft:gravel"},
        {pos: [1, 2, 7], state: "minecraft:gravel"},
        {pos: [1, 2, 8], state: "minecraft:gravel"},
        {pos: [1, 2, 9], state: "minecraft:gravel"},
        {pos: [1, 2, 10], state: "minecraft:gravel"},
        {pos: [1, 2, 11], state: "minecraft:gravel"},
        {pos: [1, 2, 12], state: "minecraft:gravel"},
        {pos: [2, 2, 1], state: "sullysmod:stripped_petrified_log{axis:z}"},
        {pos: [2, 2, 2], state: "sullysmod:petrified_log{axis:z}"},
        {pos: [2, 2, 3], state: "sullysmod:petrified_log{axis:z}"},
        {pos: [2, 2, 4], state: "sullysmod:petrified_log{axis:z}"},
        {pos: [2, 2, 5], state: "sullysmod:petrified_log{axis:z}"},
        {pos: [2, 2, 6], state: "sullysmod:petrified_log{axis:z}"},
        {pos: [2, 2, 7], state: "sullysmod:petrified_log{axis:z}"},
        {pos: [2, 2, 8], state: "sullysmod:petrified_log{axis:z}"},
        {pos: [2, 2, 9], state: "sullysmod:petrified_log{axis:z}"},
        {pos: [2, 2, 10], state: "sullysmod:petrified_log{axis:z}"},
        {pos: [2, 2, 11], state: "sullysmod:stripped_petrified_log{axis:z}"},
        {pos: [2, 2, 12], state: "sullysmod:stripped_petrified_log{axis:z}"},
        {pos: [2, 2, 13], state: "minecraft:gravel"},
        {pos: [3, 2, 3], state: "minecraft:gravel"},
        {pos: [3, 2, 4], state: "minecraft:gravel"},
        {pos: [3, 2, 5], state: "minecraft:gravel"},
        {pos: [3, 2, 6], state: "minecraft:gravel"},
        {pos: [3, 2, 7], state: "minecraft:gravel"},
        {pos: [3, 2, 8], state: "minecraft:gravel"},
        {pos: [3, 2, 9], state: "sullysmod:amber{is_melted:false}", nbt: {RenderEntity: 0b, StuckEntity: [], id: "sullysmod:amber"}},
        {pos: [3, 2, 10], state: "sullysmod:rough_amber{is_melted:false}"},
        {pos: [3, 2, 11], state: "sullysmod:rough_amber{is_melted:false}"},
        {pos: [3, 2, 12], state: "minecraft:gravel"},
        {pos: [3, 2, 13], state: "minecraft:gravel"},
        {pos: [4, 2, 3], state: "minecraft:gravel"},
        {pos: [4, 2, 4], state: "minecraft:gravel"},
        {pos: [4, 2, 5], state: "minecraft:gravel"},
        {pos: [4, 2, 6], state: "minecraft:gravel"},
        {pos: [4, 2, 7], state: "minecraft:gravel"},
        {pos: [4, 2, 8], state: "minecraft:gravel"},
        {pos: [4, 2, 9], state: "minecraft:gravel"},
        {pos: [4, 2, 10], state: "sullysmod:amber{is_melted:false}", nbt: {RenderEntity: 0b, StuckEntity: [], id: "sullysmod:amber"}},
        {pos: [4, 2, 11], state: "minecraft:gravel"},
        {pos: [4, 2, 12], state: "minecraft:gravel"},
        {pos: [4, 2, 13], state: "minecraft:gravel"},
        {pos: [5, 2, 3], state: "minecraft:gravel"},
        {pos: [5, 2, 4], state: "minecraft:gravel"},
        {pos: [5, 2, 5], state: "sullysmod:rough_amber{is_melted:false}"},
        {pos: [5, 2, 6], state: "sullysmod:rough_amber{is_melted:false}"},
        {pos: [5, 2, 7], state: "minecraft:gravel"},
        {pos: [5, 2, 8], state: "minecraft:gravel"},
        {pos: [5, 2, 9], state: "minecraft:gravel"},
        {pos: [5, 2, 10], state: "minecraft:gravel"},
        {pos: [5, 2, 11], state: "minecraft:gravel"},
        {pos: [5, 2, 12], state: "minecraft:gravel"},
        {pos: [5, 2, 13], state: "minecraft:gravel"},
        {pos: [5, 2, 14], state: "minecraft:gravel"},
        {pos: [6, 2, 3], state: "minecraft:gravel"},
        {pos: [6, 2, 4], state: "minecraft:gravel"},
        {pos: [6, 2, 5], state: "sullysmod:amber{is_melted:false}", nbt: {RenderEntity: 0b, StuckEntity: [], id: "sullysmod:amber"}},
        {pos: [6, 2, 6], state: "sullysmod:amber{is_melted:false}", nbt: {RenderEntity: 0b, StuckEntity: [], id: "sullysmod:amber"}},
        {pos: [6, 2, 7], state: "sullysmod:amber{is_melted:false}", nbt: {RenderEntity: 0b, StuckEntity: [], id: "sullysmod:amber"}},
        {pos: [6, 2, 8], state: "minecraft:gravel"},
        {pos: [6, 2, 9], state: "minecraft:gravel"},
        {pos: [6, 2, 10], state: "minecraft:gravel"},
        {pos: [6, 2, 11], state: "minecraft:gravel"},
        {pos: [6, 2, 12], state: "minecraft:gravel"},
        {pos: [6, 2, 13], state: "minecraft:gravel"},
        {pos: [6, 2, 14], state: "minecraft:gravel"},
        {pos: [7, 2, 3], state: "sullysmod:stripped_petrified_log{axis:z}"},
        {pos: [7, 2, 4], state: "sullysmod:stripped_petrified_log{axis:z}"},
        {pos: [7, 2, 5], state: "sullysmod:petrified_log{axis:z}"},
        {pos: [7, 2, 6], state: "sullysmod:petrified_log{axis:z}"},
        {pos: [7, 2, 7], state: "sullysmod:petrified_log{axis:z}"},
        {pos: [7, 2, 8], state: "sullysmod:petrified_log{axis:z}"},
        {pos: [7, 2, 9], state: "sullysmod:petrified_log{axis:z}"},
        {pos: [7, 2, 10], state: "sullysmod:petrified_log{axis:z}"},
        {pos: [7, 2, 11], state: "sullysmod:petrified_log{axis:z}"},
        {pos: [7, 2, 12], state: "sullysmod:petrified_log{axis:z}"},
        {pos: [7, 2, 13], state: "sullysmod:petrified_log{axis:z}"},
        {pos: [7, 2, 14], state: "sullysmod:petrified_log{axis:z}"},
        {pos: [8, 2, 4], state: "minecraft:gravel"},
        {pos: [8, 2, 5], state: "minecraft:gravel"},
        {pos: [8, 2, 6], state: "sullysmod:petrified_log{axis:z}"},
        {pos: [8, 2, 7], state: "sullysmod:petrified_log{axis:z}"},
        {pos: [8, 2, 8], state: "sullysmod:petrified_log{axis:z}"},
        {pos: [8, 2, 9], state: "minecraft:gravel"},
        {pos: [8, 2, 10], state: "minecraft:gravel"},
        {pos: [8, 2, 11], state: "minecraft:gravel"},
        {pos: [8, 2, 12], state: "minecraft:gravel"},
        {pos: [8, 2, 13], state: "minecraft:gravel"},
        {pos: [9, 2, 4], state: "minecraft:gravel"},
        {pos: [9, 2, 5], state: "minecraft:gravel"},
        {pos: [9, 2, 6], state: "minecraft:gravel"},
        {pos: [9, 2, 7], state: "minecraft:gravel"},
        {pos: [9, 2, 8], state: "minecraft:gravel"},
        {pos: [9, 2, 9], state: "minecraft:gravel"},
        {pos: [9, 2, 10], state: "minecraft:gravel"},
        {pos: [9, 2, 11], state: "minecraft:gravel"},
        {pos: [10, 2, 7], state: "minecraft:gravel"},
        {pos: [10, 2, 8], state: "minecraft:gravel"},
        {pos: [10, 2, 9], state: "minecraft:gravel"},
        {pos: [10, 2, 10], state: "minecraft:gravel"},
        {pos: [0, 3, 5], state: "minecraft:gravel"},
        {pos: [0, 3, 6], state: "minecraft:gravel"},
        {pos: [0, 3, 7], state: "minecraft:gravel"},
        {pos: [0, 3, 8], state: "minecraft:gravel"},
        {pos: [0, 3, 9], state: "minecraft:gravel"},
        {pos: [0, 3, 10], state: "minecraft:gravel"},
        {pos: [1, 3, 2], state: "minecraft:air"},
        {pos: [1, 3, 3], state: "sullysmod:petrified_log{axis:z}"},
        {pos: [1, 3, 4], state: "sullysmod:petrified_log{axis:z}"},
        {pos: [1, 3, 5], state: "sullysmod:petrified_log{axis:z}"},
        {pos: [1, 3, 6], state: "sullysmod:petrified_log{axis:z}"},
        {pos: [1, 3, 7], state: "sullysmod:petrified_log{axis:z}"},
        {pos: [1, 3, 8], state: "sullysmod:petrified_log{axis:z}"},
        {pos: [1, 3, 9], state: "sullysmod:petrified_log{axis:z}"},
        {pos: [1, 3, 10], state: "sullysmod:petrified_log{axis:z}"},
        {pos: [1, 3, 11], state: "sullysmod:petrified_log{axis:z}"},
        {pos: [1, 3, 12], state: "sullysmod:petrified_log{axis:z}"},
        {pos: [1, 3, 13], state: "minecraft:gravel"},
        {pos: [1, 3, 15], state: "minecraft:air"},
        {pos: [2, 3, 1], state: "minecraft:air"},
        {pos: [2, 3, 2], state: "minecraft:air"},
        {pos: [2, 3, 3], state: "minecraft:gravel"},
        {pos: [2, 3, 4], state: "minecraft:gravel"},
        {pos: [2, 3, 5], state: "minecraft:gravel"},
        {pos: [2, 3, 6], state: "minecraft:gravel"},
        {pos: [2, 3, 7], state: "minecraft:gravel"},
        {pos: [2, 3, 8], state: "sullysmod:amber{is_melted:false}", nbt: {RenderEntity: 0b, StuckEntity: [], id: "sullysmod:amber"}},
        {pos: [2, 3, 9], state: "sullysmod:amber{is_melted:false}", nbt: {RenderEntity: 0b, StuckEntity: [], id: "sullysmod:amber"}},
        {pos: [2, 3, 10], state: "sullysmod:amber{is_melted:false}", nbt: {RenderEntity: 0b, StuckEntity: [], id: "sullysmod:amber"}},
        {pos: [2, 3, 11], state: "minecraft:gravel"},
        {pos: [2, 3, 12], state: "minecraft:gravel"},
        {pos: [2, 3, 13], state: "minecraft:gravel"},
        {pos: [3, 3, 3], state: "minecraft:air"},
        {pos: [3, 3, 4], state: "minecraft:gravel"},
        {pos: [3, 3, 5], state: "minecraft:gravel"},
        {pos: [3, 3, 6], state: "minecraft:gravel"},
        {pos: [3, 3, 7], state: "minecraft:gravel"},
        {pos: [3, 3, 8], state: "minecraft:gravel"},
        {pos: [3, 3, 9], state: "minecraft:gravel"},
        {pos: [3, 3, 10], state: "sullysmod:amber{is_melted:false}", nbt: {RenderEntity: 0b, StuckEntity: [], id: "sullysmod:amber"}},
        {pos: [3, 3, 11], state: "minecraft:gravel"},
        {pos: [3, 3, 12], state: "minecraft:gravel"},
        {pos: [3, 3, 13], state: "minecraft:gravel"},
        {pos: [4, 3, 3], state: "minecraft:air"},
        {pos: [4, 3, 5], state: "minecraft:gravel"},
        {pos: [4, 3, 6], state: "minecraft:gravel"},
        {pos: [4, 3, 7], state: "minecraft:gravel"},
        {pos: [4, 3, 8], state: "minecraft:gravel"},
        {pos: [4, 3, 9], state: "minecraft:gravel"},
        {pos: [4, 3, 10], state: "minecraft:gravel"},
        {pos: [4, 3, 11], state: "minecraft:gravel"},
        {pos: [4, 3, 12], state: "minecraft:gravel"},
        {pos: [4, 3, 13], state: "minecraft:gravel"},
        {pos: [4, 3, 14], state: "minecraft:air"},
        {pos: [5, 3, 3], state: "minecraft:air"},
        {pos: [5, 3, 4], state: "minecraft:gravel"},
        {pos: [5, 3, 5], state: "minecraft:gravel"},
        {pos: [5, 3, 6], state: "minecraft:gravel"},
        {pos: [5, 3, 7], state: "minecraft:gravel"},
        {pos: [5, 3, 8], state: "minecraft:suspicious_gravel{dusted:0}", nbt: {id: "minecraft:brushable_block", item: {Count: 0b, id: "minecraft:air"}}},
        {pos: [5, 3, 9], state: "minecraft:gravel"},
        {pos: [5, 3, 10], state: "minecraft:gravel"},
        {pos: [5, 3, 11], state: "minecraft:gravel"},
        {pos: [5, 3, 12], state: "minecraft:gravel"},
        {pos: [5, 3, 13], state: "minecraft:gravel"},
        {pos: [5, 3, 14], state: "minecraft:gravel"},
        {pos: [5, 3, 15], state: "minecraft:air"},
        {pos: [6, 3, 3], state: "minecraft:air"},
        {pos: [6, 3, 4], state: "minecraft:gravel"},
        {pos: [6, 3, 5], state: "minecraft:gravel"},
        {pos: [6, 3, 6], state: "minecraft:gravel"},
        {pos: [6, 3, 7], state: "minecraft:gravel"},
        {pos: [6, 3, 8], state: "minecraft:gravel"},
        {pos: [6, 3, 9], state: "minecraft:gravel"},
        {pos: [6, 3, 10], state: "minecraft:gravel"},
        {pos: [6, 3, 11], state: "minecraft:gravel"},
        {pos: [6, 3, 12], state: "minecraft:gravel"},
        {pos: [6, 3, 13], state: "minecraft:gravel"},
        {pos: [6, 3, 14], state: "minecraft:gravel"},
        {pos: [7, 3, 3], state: "minecraft:gravel"},
        {pos: [7, 3, 4], state: "minecraft:gravel"},
        {pos: [7, 3, 5], state: "sullysmod:rough_amber{is_melted:false}"},
        {pos: [7, 3, 6], state: "minecraft:gravel"},
        {pos: [7, 3, 7], state: "sullysmod:amber{is_melted:false}", nbt: {RenderEntity: 0b, StuckEntity: [], id: "sullysmod:amber"}},
        {pos: [7, 3, 8], state: "sullysmod:amber{is_melted:false}", nbt: {RenderEntity: 0b, StuckEntity: [], id: "sullysmod:amber"}},
        {pos: [7, 3, 9], state: "minecraft:gravel"},
        {pos: [7, 3, 10], state: "minecraft:gravel"},
        {pos: [7, 3, 11], state: "minecraft:gravel"},
        {pos: [7, 3, 12], state: "sullysmod:petrified_log{axis:z}"},
        {pos: [7, 3, 13], state: "minecraft:gravel"},
        {pos: [8, 3, 2], state: "sullysmod:stripped_petrified_log{axis:z}"},
        {pos: [8, 3, 3], state: "sullysmod:petrified_log{axis:z}"},
        {pos: [8, 3, 4], state: "sullysmod:petrified_log{axis:z}"},
        {pos: [8, 3, 5], state: "sullysmod:petrified_log{axis:z}"},
        {pos: [8, 3, 6], state: "sullysmod:petrified_log{axis:z}"},
        {pos: [8, 3, 7], state: "sullysmod:petrified_log{axis:z}"},
        {pos: [8, 3, 8], state: "sullysmod:petrified_log{axis:z}"},
        {pos: [8, 3, 9], state: "sullysmod:petrified_log{axis:z}"},
        {pos: [8, 3, 10], state: "sullysmod:petrified_log{axis:z}"},
        {pos: [8, 3, 11], state: "sullysmod:petrified_log{axis:z}"},
        {pos: [8, 3, 12], state: "minecraft:gravel"},
        {pos: [8, 3, 13], state: "minecraft:gravel"},
        {pos: [9, 3, 4], state: "minecraft:gravel"},
        {pos: [9, 3, 5], state: "sullysmod:stripped_petrified_log{axis:z}"},
        {pos: [9, 3, 6], state: "sullysmod:petrified_log{axis:z}"},
        {pos: [9, 3, 7], state: "sullysmod:petrified_log{axis:z}"},
        {pos: [9, 3, 8], state: "minecraft:gravel"},
        {pos: [9, 3, 9], state: "minecraft:gravel"},
        {pos: [9, 3, 10], state: "minecraft:gravel"},
        {pos: [9, 3, 11], state: "minecraft:gravel"},
        {pos: [9, 3, 12], state: "minecraft:gravel"},
        {pos: [10, 3, 6], state: "minecraft:gravel"},
        {pos: [10, 3, 7], state: "minecraft:gravel"},
        {pos: [10, 3, 8], state: "minecraft:gravel"},
        {pos: [0, 4, 6], state: "minecraft:gravel"},
        {pos: [0, 4, 7], state: "minecraft:gravel"},
        {pos: [1, 4, 1], state: "minecraft:air"},
        {pos: [1, 4, 2], state: "sullysmod:petrified_log{axis:z}"},
        {pos: [1, 4, 3], state: "sullysmod:petrified_log{axis:z}"},
        {pos: [1, 4, 4], state: "sullysmod:petrified_log{axis:z}"},
        {pos: [1, 4, 5], state: "sullysmod:petrified_log{axis:z}"},
        {pos: [1, 4, 6], state: "sullysmod:petrified_log{axis:z}"},
        {pos: [1, 4, 7], state: "sullysmod:petrified_log{axis:z}"},
        {pos: [1, 4, 8], state: "sullysmod:petrified_log{axis:z}"},
        {pos: [1, 4, 9], state: "sullysmod:petrified_log{axis:z}"},
        {pos: [1, 4, 10], state: "sullysmod:petrified_log{axis:z}"},
        {pos: [1, 4, 11], state: "sullysmod:petrified_log{axis:z}"},
        {pos: [1, 4, 12], state: "sullysmod:petrified_log{axis:z}"},
        {pos: [1, 4, 13], state: "sullysmod:stripped_petrified_log{axis:z}"},
        {pos: [1, 4, 14], state: "minecraft:air"},
        {pos: [2, 4, 0], state: "minecraft:air"},
        {pos: [2, 4, 1], state: "minecraft:air"},
        {pos: [2, 4, 3], state: "minecraft:air"},
        {pos: [2, 4, 4], state: "minecraft:air"},
        {pos: [2, 4, 5], state: "minecraft:air"},
        {pos: [2, 4, 6], state: "minecraft:gravel"},
        {pos: [2, 4, 7], state: "minecraft:gravel"},
        {pos: [2, 4, 8], state: "minecraft:air"},
        {pos: [2, 4, 9], state: "minecraft:air"},
        {pos: [2, 4, 10], state: "minecraft:gravel"},
        {pos: [2, 4, 11], state: "minecraft:gravel"},
        {pos: [2, 4, 12], state: "minecraft:air"},
        {pos: [2, 4, 13], state: "minecraft:air"},
        {pos: [2, 4, 15], state: "minecraft:air"},
        {pos: [3, 4, 3], state: "minecraft:air"},
        {pos: [3, 4, 4], state: "minecraft:air"},
        {pos: [3, 4, 5], state: "minecraft:air"},
        {pos: [3, 4, 6], state: "minecraft:air"},
        {pos: [3, 4, 7], state: "minecraft:air"},
        {pos: [3, 4, 8], state: "sullysmod:petrified_sapling{stage:0}"},
        {pos: [3, 4, 9], state: "minecraft:air"},
        {pos: [3, 4, 10], state: "minecraft:air"},
        {pos: [3, 4, 11], state: "minecraft:air"},
        {pos: [3, 4, 12], state: "minecraft:air"},
        {pos: [3, 4, 13], state: "minecraft:air"},
        {pos: [3, 4, 15], state: "minecraft:air"},
        {pos: [4, 4, 3], state: "minecraft:air"},
        {pos: [4, 4, 4], state: "minecraft:air"},
        {pos: [4, 4, 5], state: "minecraft:air"},
        {pos: [4, 4, 6], state: "minecraft:air"},
        {pos: [4, 4, 7], state: "minecraft:air"},
        {pos: [4, 4, 8], state: "minecraft:air"},
        {pos: [4, 4, 9], state: "minecraft:air"},
        {pos: [4, 4, 10], state: "minecraft:air"},
        {pos: [4, 4, 11], state: "minecraft:air"},
        {pos: [4, 4, 12], state: "minecraft:air"},
        {pos: [4, 4, 13], state: "minecraft:air"},
        {pos: [5, 4, 3], state: "minecraft:air"},
        {pos: [5, 4, 4], state: "minecraft:air"},
        {pos: [5, 4, 5], state: "minecraft:air"},
        {pos: [5, 4, 6], state: "minecraft:air"},
        {pos: [5, 4, 7], state: "minecraft:air"},
        {pos: [5, 4, 8], state: "minecraft:air"},
        {pos: [5, 4, 9], state: "minecraft:air"},
        {pos: [5, 4, 10], state: "sullysmod:petrified_sapling{stage:0}"},
        {pos: [5, 4, 11], state: "minecraft:air"},
        {pos: [5, 4, 12], state: "minecraft:air"},
        {pos: [5, 4, 13], state: "minecraft:air"},
        {pos: [5, 4, 14], state: "minecraft:air"},
        {pos: [6, 4, 1], state: "minecraft:air"},
        {pos: [6, 4, 3], state: "minecraft:air"},
        {pos: [6, 4, 4], state: "minecraft:air"},
        {pos: [6, 4, 5], state: "minecraft:air"},
        {pos: [6, 4, 6], state: "sullysmod:petrified_sapling{stage:0}"},
        {pos: [6, 4, 7], state: "minecraft:air"},
        {pos: [6, 4, 8], state: "minecraft:air"},
        {pos: [6, 4, 9], state: "minecraft:air"},
        {pos: [6, 4, 11], state: "minecraft:suspicious_gravel{dusted:0}", nbt: {id: "minecraft:brushable_block", item: {Count: 0b, id: "minecraft:air"}}},
        {pos: [6, 4, 12], state: "minecraft:gravel"},
        {pos: [7, 4, 2], state: "minecraft:air"},
        {pos: [7, 4, 3], state: "minecraft:air"},
        {pos: [7, 4, 4], state: "minecraft:air"},
        {pos: [7, 4, 5], state: "minecraft:gravel"},
        {pos: [7, 4, 6], state: "minecraft:gravel"},
        {pos: [7, 4, 7], state: "minecraft:air"},
        {pos: [7, 4, 8], state: "sullysmod:amber{is_melted:false}", nbt: {RenderEntity: 0b, StuckEntity: [], id: "sullysmod:amber"}},
        {pos: [7, 4, 9], state: "minecraft:gravel"},
        {pos: [7, 4, 10], state: "minecraft:gravel"},
        {pos: [7, 4, 11], state: "minecraft:gravel"},
        {pos: [7, 4, 12], state: "minecraft:gravel"},
        {pos: [7, 4, 13], state: "minecraft:gravel"},
        {pos: [8, 4, 4], state: "sullysmod:petrified_log{axis:z}"},
        {pos: [8, 4, 5], state: "sullysmod:petrified_log{axis:z}"},
        {pos: [8, 4, 6], state: "sullysmod:petrified_log{axis:z}"},
        {pos: [8, 4, 7], state: "sullysmod:petrified_log{axis:z}"},
        {pos: [8, 4, 8], state: "sullysmod:petrified_log{axis:z}"},
        {pos: [8, 4, 9], state: "sullysmod:petrified_log{axis:z}"},
        {pos: [8, 4, 10], state: "sullysmod:petrified_log{axis:z}"},
        {pos: [8, 4, 11], state: "sullysmod:petrified_log{axis:z}"},
        {pos: [8, 4, 12], state: "sullysmod:petrified_log{axis:z}"},
        {pos: [8, 4, 13], state: "sullysmod:petrified_log{axis:z}"},
        {pos: [8, 4, 14], state: "sullysmod:stripped_petrified_log{axis:z}"},
        {pos: [9, 4, 3], state: "minecraft:air"},
        {pos: [9, 4, 6], state: "sullysmod:stripped_petrified_log{axis:z}"},
        {pos: [9, 4, 7], state: "sullysmod:petrified_log{axis:z}"},
        {pos: [9, 4, 8], state: "sullysmod:petrified_log{axis:z}"},
        {pos: [9, 4, 9], state: "sullysmod:petrified_log{axis:z}"},
        {pos: [9, 4, 10], state: "minecraft:gravel"},
        {pos: [9, 4, 13], state: "minecraft:air"},
        {pos: [1, 5, 1], state: "minecraft:air"},
        {pos: [1, 5, 2], state: "minecraft:air"},
        {pos: [1, 5, 3], state: "minecraft:air"},
        {pos: [1, 5, 4], state: "sullysmod:stripped_petrified_log{axis:z}"},
        {pos: [1, 5, 5], state: "sullysmod:petrified_log{axis:z}"},
        {pos: [1, 5, 6], state: "sullysmod:stripped_petrified_log{axis:z}"},
        {pos: [1, 5, 7], state: "minecraft:air"},
        {pos: [1, 5, 9], state: "sullysmod:stripped_petrified_log{axis:z}"},
        {pos: [1, 5, 10], state: "sullysmod:petrified_log{axis:z}"},
        {pos: [1, 5, 11], state: "sullysmod:petrified_log{axis:z}"},
        {pos: [1, 5, 12], state: "sullysmod:petrified_log{axis:z}"},
        {pos: [2, 5, 2], state: "minecraft:air"},
        {pos: [2, 5, 3], state: "minecraft:air"},
        {pos: [2, 5, 4], state: "minecraft:air"},
        {pos: [2, 5, 5], state: "minecraft:air"},
        {pos: [2, 5, 6], state: "minecraft:air"},
        {pos: [2, 5, 7], state: "minecraft:air"},
        {pos: [2, 5, 8], state: "minecraft:air"},
        {pos: [2, 5, 9], state: "minecraft:air"},
        {pos: [2, 5, 10], state: "minecraft:air"},
        {pos: [2, 5, 11], state: "minecraft:air"},
        {pos: [2, 5, 12], state: "minecraft:air"},
        {pos: [3, 5, 2], state: "minecraft:air"},
        {pos: [3, 5, 3], state: "minecraft:air"},
        {pos: [3, 5, 4], state: "minecraft:air"},
        {pos: [3, 5, 5], state: "minecraft:air"},
        {pos: [3, 5, 6], state: "minecraft:air"},
        {pos: [3, 5, 7], state: "minecraft:air"},
        {pos: [3, 5, 8], state: "minecraft:air"},
        {pos: [3, 5, 9], state: "minecraft:air"},
        {pos: [3, 5, 10], state: "minecraft:air"},
        {pos: [3, 5, 11], state: "minecraft:air"},
        {pos: [3, 5, 12], state: "minecraft:air"},
        {pos: [3, 5, 13], state: "minecraft:air"},
        {pos: [4, 5, 2], state: "minecraft:air"},
        {pos: [4, 5, 3], state: "minecraft:air"},
        {pos: [4, 5, 4], state: "minecraft:air"},
        {pos: [4, 5, 5], state: "minecraft:air"},
        {pos: [4, 5, 6], state: "minecraft:air"},
        {pos: [4, 5, 7], state: "minecraft:air"},
        {pos: [4, 5, 8], state: "minecraft:air"},
        {pos: [4, 5, 9], state: "minecraft:air"},
        {pos: [4, 5, 10], state: "minecraft:air"},
        {pos: [4, 5, 11], state: "minecraft:air"},
        {pos: [4, 5, 12], state: "minecraft:air"},
        {pos: [4, 5, 13], state: "minecraft:air"},
        {pos: [5, 5, 3], state: "minecraft:air"},
        {pos: [5, 5, 4], state: "minecraft:air"},
        {pos: [5, 5, 5], state: "minecraft:air"},
        {pos: [5, 5, 6], state: "minecraft:air"},
        {pos: [5, 5, 7], state: "minecraft:air"},
        {pos: [5, 5, 8], state: "minecraft:air"},
        {pos: [5, 5, 9], state: "minecraft:air"},
        {pos: [5, 5, 10], state: "minecraft:air"},
        {pos: [5, 5, 11], state: "minecraft:air"},
        {pos: [5, 5, 12], state: "minecraft:air"},
        {pos: [5, 5, 13], state: "minecraft:air"},
        {pos: [6, 5, 3], state: "minecraft:air"},
        {pos: [6, 5, 4], state: "minecraft:air"},
        {pos: [6, 5, 5], state: "minecraft:air"},
        {pos: [6, 5, 6], state: "minecraft:air"},
        {pos: [6, 5, 7], state: "minecraft:air"},
        {pos: [6, 5, 8], state: "minecraft:air"},
        {pos: [6, 5, 9], state: "minecraft:air"},
        {pos: [6, 5, 11], state: "minecraft:air"},
        {pos: [6, 5, 12], state: "minecraft:air"},
        {pos: [7, 5, 2], state: "minecraft:air"},
        {pos: [7, 5, 3], state: "minecraft:air"},
        {pos: [7, 5, 4], state: "minecraft:air"},
        {pos: [7, 5, 5], state: "minecraft:air"},
        {pos: [7, 5, 6], state: "minecraft:air"},
        {pos: [7, 5, 7], state: "minecraft:air"},
        {pos: [7, 5, 8], state: "minecraft:air"},
        {pos: [7, 5, 10], state: "minecraft:gravel"},
        {pos: [7, 5, 11], state: "minecraft:gravel"},
        {pos: [7, 5, 12], state: "minecraft:air"},
        {pos: [7, 5, 13], state: "minecraft:air"},
        {pos: [8, 5, 3], state: "sullysmod:stripped_petrified_log{axis:z}"},
        {pos: [8, 5, 4], state: "sullysmod:petrified_log{axis:z}"},
        {pos: [8, 5, 5], state: "sullysmod:petrified_log{axis:z}"},
        {pos: [8, 5, 6], state: "sullysmod:petrified_log{axis:z}"},
        {pos: [8, 5, 7], state: "sullysmod:petrified_log{axis:z}"},
        {pos: [8, 5, 8], state: "sullysmod:stripped_petrified_log{axis:z}"},
        {pos: [8, 5, 9], state: "sullysmod:stripped_petrified_log{axis:z}"},
        {pos: [8, 5, 10], state: "sullysmod:petrified_log{axis:z}"},
        {pos: [8, 5, 11], state: "sullysmod:stripped_petrified_log{axis:z}"},
        {pos: [8, 5, 12], state: "sullysmod:petrified_log{axis:z}"},
        {pos: [8, 5, 13], state: "sullysmod:stripped_petrified_log{axis:z}"},
        {pos: [9, 5, 7], state: "minecraft:gravel"},
        {pos: [9, 5, 8], state: "minecraft:gravel"},
        {pos: [10, 5, 10], state: "minecraft:air"},
        {pos: [1, 6, 1], state: "sullysmod:petrified_log{axis:z}"},
        {pos: [1, 6, 2], state: "sullysmod:petrified_log{axis:z}"},
        {pos: [1, 6, 3], state: "sullysmod:petrified_log{axis:z}"},
        {pos: [1, 6, 4], state: "sullysmod:petrified_log{axis:z}"},
        {pos: [1, 6, 5], state: "sullysmod:petrified_log{axis:z}"},
        {pos: [1, 6, 6], state: "sullysmod:petrified_log{axis:z}"},
        {pos: [1, 6, 7], state: "sullysmod:stripped_petrified_log{axis:z}"},
        {pos: [1, 6, 10], state: "sullysmod:stripped_petrified_log{axis:z}"},
        {pos: [1, 6, 11], state: "sullysmod:petrified_log{axis:z}"},
        {pos: [1, 6, 12], state: "sullysmod:petrified_log{axis:z}"},
        {pos: [1, 6, 13], state: "sullysmod:petrified_log{axis:z}"},
        {pos: [2, 6, 1], state: "minecraft:air"},
        {pos: [2, 6, 2], state: "minecraft:air"},
        {pos: [2, 6, 3], state: "minecraft:air"},
        {pos: [2, 6, 4], state: "minecraft:air"},
        {pos: [2, 6, 5], state: "sullysmod:rough_amber{is_melted:false}"},
        {pos: [2, 6, 6], state: "minecraft:air"},
        {pos: [2, 6, 7], state: "minecraft:air"},
        {pos: [2, 6, 8], state: "minecraft:air"},
        {pos: [2, 6, 9], state: "minecraft:air"},
        {pos: [2, 6, 10], state: "minecraft:air"},
        {pos: [2, 6, 11], state: "minecraft:air"},
        {pos: [2, 6, 12], state: "minecraft:air"},
        {pos: [2, 6, 13], state: "minecraft:air"},
        {pos: [3, 6, 3], state: "minecraft:air"},
        {pos: [3, 6, 4], state: "minecraft:air"},
        {pos: [3, 6, 5], state: "sullysmod:amber{is_melted:false}", nbt: {RenderEntity: 0b, StuckEntity: [], id: "sullysmod:amber"}},
        {pos: [3, 6, 6], state: "minecraft:air"},
        {pos: [3, 6, 7], state: "minecraft:air"},
        {pos: [3, 6, 8], state: "minecraft:air"},
        {pos: [3, 6, 9], state: "minecraft:air"},
        {pos: [3, 6, 10], state: "minecraft:air"},
        {pos: [3, 6, 11], state: "minecraft:air"},
        {pos: [3, 6, 12], state: "minecraft:air"},
        {pos: [3, 6, 13], state: "minecraft:air"},
        {pos: [3, 6, 14], state: "minecraft:air"},
        {pos: [3, 6, 15], state: "minecraft:air"},
        {pos: [4, 6, 0], state: "minecraft:air"},
        {pos: [4, 6, 3], state: "minecraft:air"},
        {pos: [4, 6, 4], state: "minecraft:air"},
        {pos: [4, 6, 5], state: "minecraft:air"},
        {pos: [4, 6, 6], state: "minecraft:air"},
        {pos: [4, 6, 7], state: "sullysmod:amber{is_melted:false}", nbt: {RenderEntity: 0b, StuckEntity: [], id: "sullysmod:amber"}},
        {pos: [4, 6, 8], state: "minecraft:air"},
        {pos: [4, 6, 9], state: "minecraft:air"},
        {pos: [4, 6, 10], state: "minecraft:air"},
        {pos: [4, 6, 11], state: "minecraft:air"},
        {pos: [4, 6, 12], state: "minecraft:air"},
        {pos: [4, 6, 13], state: "minecraft:air"},
        {pos: [5, 6, 0], state: "minecraft:air"},
        {pos: [5, 6, 3], state: "minecraft:air"},
        {pos: [5, 6, 4], state: "minecraft:air"},
        {pos: [5, 6, 5], state: "minecraft:air"},
        {pos: [5, 6, 6], state: "minecraft:air"},
        {pos: [5, 6, 7], state: "minecraft:air"},
        {pos: [5, 6, 8], state: "minecraft:air"},
        {pos: [5, 6, 9], state: "minecraft:air"},
        {pos: [5, 6, 10], state: "minecraft:air"},
        {pos: [5, 6, 11], state: "minecraft:air"},
        {pos: [5, 6, 12], state: "minecraft:air"},
        {pos: [5, 6, 13], state: "minecraft:air"},
        {pos: [6, 6, 1], state: "minecraft:air"},
        {pos: [6, 6, 3], state: "minecraft:air"},
        {pos: [6, 6, 4], state: "minecraft:air"},
        {pos: [6, 6, 5], state: "minecraft:air"},
        {pos: [6, 6, 6], state: "minecraft:air"},
        {pos: [6, 6, 7], state: "minecraft:air"},
        {pos: [6, 6, 8], state: "minecraft:air"},
        {pos: [6, 6, 9], state: "minecraft:air"},
        {pos: [6, 6, 11], state: "minecraft:air"},
        {pos: [6, 6, 12], state: "minecraft:air"},
        {pos: [6, 6, 13], state: "minecraft:air"},
        {pos: [6, 6, 15], state: "minecraft:air"},
        {pos: [7, 6, 0], state: "minecraft:air"},
        {pos: [7, 6, 2], state: "minecraft:air"},
        {pos: [7, 6, 3], state: "minecraft:air"},
        {pos: [7, 6, 4], state: "minecraft:air"},
        {pos: [7, 6, 5], state: "minecraft:air"},
        {pos: [7, 6, 6], state: "minecraft:air"},
        {pos: [7, 6, 7], state: "minecraft:air"},
        {pos: [7, 6, 8], state: "minecraft:air"},
        {pos: [7, 6, 12], state: "minecraft:air"},
        {pos: [7, 6, 13], state: "minecraft:air"},
        {pos: [8, 6, 2], state: "sullysmod:petrified_log{axis:z}"},
        {pos: [8, 6, 3], state: "sullysmod:petrified_log{axis:z}"},
        {pos: [8, 6, 4], state: "sullysmod:petrified_log{axis:z}"},
        {pos: [8, 6, 5], state: "sullysmod:petrified_log{axis:z}"},
        {pos: [8, 6, 6], state: "sullysmod:petrified_log{axis:z}"},
        {pos: [8, 6, 10], state: "sullysmod:stripped_petrified_log{axis:z}"},
        {pos: [8, 6, 11], state: "sullysmod:petrified_log{axis:z}"},
        {pos: [8, 6, 12], state: "sullysmod:petrified_log{axis:z}"},
        {pos: [8, 6, 13], state: "sullysmod:petrified_log{axis:z}"},
        {pos: [8, 6, 14], state: "sullysmod:petrified_log{axis:z}"},
        {pos: [10, 6, 8], state: "minecraft:air"},
        {pos: [10, 6, 9], state: "minecraft:air"},
        {pos: [10, 6, 13], state: "minecraft:air"},
        {pos: [2, 7, 2], state: "sullysmod:petrified_log{axis:z}"},
        {pos: [2, 7, 3], state: "sullysmod:petrified_log{axis:z}"},
        {pos: [2, 7, 4], state: "sullysmod:petrified_log{axis:z}"},
        {pos: [2, 7, 5], state: "sullysmod:stripped_petrified_log{axis:z}"},
        {pos: [2, 7, 6], state: "sullysmod:stripped_petrified_log{axis:z}"},
        {pos: [2, 7, 7], state: "sullysmod:petrified_log{axis:z}"},
        {pos: [2, 7, 8], state: "sullysmod:petrified_log{axis:z}"},
        {pos: [2, 7, 9], state: "sullysmod:petrified_log{axis:z}"},
        {pos: [2, 7, 10], state: "sullysmod:petrified_log{axis:z}"},
        {pos: [2, 7, 11], state: "sullysmod:petrified_log{axis:z}"},
        {pos: [2, 7, 12], state: "sullysmod:petrified_log{axis:z}"},
        {pos: [2, 7, 13], state: "sullysmod:petrified_log{axis:z}"},
        {pos: [2, 7, 14], state: "sullysmod:petrified_log{axis:z}"},
        {pos: [2, 7, 15], state: "sullysmod:stripped_petrified_log{axis:z}"},
        {pos: [3, 7, 2], state: "minecraft:air"},
        {pos: [3, 7, 3], state: "minecraft:air"},
        {pos: [3, 7, 4], state: "minecraft:air"},
        {pos: [3, 7, 5], state: "sullysmod:rough_amber{is_melted:false}"},
        {pos: [3, 7, 6], state: "sullysmod:rough_amber{is_melted:false}"},
        {pos: [3, 7, 7], state: "minecraft:air"},
        {pos: [3, 7, 8], state: "minecraft:air"},
        {pos: [3, 7, 9], state: "minecraft:air"},
        {pos: [3, 7, 10], state: "minecraft:air"},
        {pos: [3, 7, 11], state: "minecraft:air"},
        {pos: [3, 7, 12], state: "minecraft:air"},
        {pos: [3, 7, 13], state: "minecraft:air"},
        {pos: [3, 7, 14], state: "minecraft:air"},
        {pos: [3, 7, 15], state: "minecraft:air"},
        {pos: [4, 7, 1], state: "minecraft:air"},
        {pos: [4, 7, 3], state: "minecraft:air"},
        {pos: [4, 7, 4], state: "minecraft:air"},
        {pos: [4, 7, 5], state: "sullysmod:amber{is_melted:false}", nbt: {RenderEntity: 0b, StuckEntity: [], id: "sullysmod:amber"}},
        {pos: [4, 7, 6], state: "minecraft:air"},
        {pos: [4, 7, 7], state: "sullysmod:amber{is_melted:false}", nbt: {RenderEntity: 0b, StuckEntity: [], id: "sullysmod:amber"}},
        {pos: [4, 7, 8], state: "minecraft:air"},
        {pos: [4, 7, 9], state: "minecraft:air"},
        {pos: [4, 7, 10], state: "minecraft:air"},
        {pos: [4, 7, 11], state: "minecraft:air"},
        {pos: [4, 7, 12], state: "minecraft:air"},
        {pos: [4, 7, 13], state: "minecraft:air"},
        {pos: [5, 7, 0], state: "minecraft:air"},
        {pos: [5, 7, 1], state: "minecraft:air"},
        {pos: [5, 7, 2], state: "minecraft:air"},
        {pos: [5, 7, 3], state: "minecraft:air"},
        {pos: [5, 7, 4], state: "minecraft:air"},
        {pos: [5, 7, 5], state: "minecraft:air"},
        {pos: [5, 7, 6], state: "minecraft:air"},
        {pos: [5, 7, 7], state: "minecraft:air"},
        {pos: [5, 7, 8], state: "minecraft:air"},
        {pos: [5, 7, 9], state: "minecraft:air"},
        {pos: [5, 7, 10], state: "minecraft:air"},
        {pos: [5, 7, 11], state: "minecraft:air"},
        {pos: [5, 7, 12], state: "minecraft:air"},
        {pos: [5, 7, 13], state: "minecraft:air"},
        {pos: [5, 7, 14], state: "minecraft:air"},
        {pos: [6, 7, 2], state: "minecraft:air"},
        {pos: [6, 7, 3], state: "minecraft:air"},
        {pos: [6, 7, 4], state: "minecraft:air"},
        {pos: [6, 7, 5], state: "minecraft:air"},
        {pos: [6, 7, 6], state: "minecraft:air"},
        {pos: [6, 7, 7], state: "minecraft:air"},
        {pos: [6, 7, 8], state: "minecraft:air"},
        {pos: [6, 7, 9], state: "minecraft:air"},
        {pos: [6, 7, 11], state: "minecraft:air"},
        {pos: [6, 7, 12], state: "minecraft:air"},
        {pos: [6, 7, 13], state: "minecraft:air"},
        {pos: [6, 7, 14], state: "minecraft:air"},
        {pos: [7, 7, 1], state: "minecraft:air"},
        {pos: [7, 7, 2], state: "minecraft:air"},
        {pos: [7, 7, 3], state: "sullysmod:petrified_log{axis:z}"},
        {pos: [7, 7, 4], state: "sullysmod:petrified_log{axis:z}"},
        {pos: [7, 7, 5], state: "sullysmod:petrified_log{axis:z}"},
        {pos: [7, 7, 6], state: "sullysmod:petrified_log{axis:z}"},
        {pos: [7, 7, 7], state: "sullysmod:stripped_petrified_log{axis:z}"},
        {pos: [7, 7, 8], state: "sullysmod:stripped_petrified_log{axis:z}"},
        {pos: [7, 7, 12], state: "sullysmod:stripped_petrified_log{axis:z}"},
        {pos: [7, 7, 13], state: "sullysmod:petrified_log{axis:z}"},
        {pos: [8, 7, 3], state: "minecraft:air"},
        {pos: [8, 7, 4], state: "sullysmod:petrified_log{axis:z}"},
        {pos: [2, 8, 11], state: "sullysmod:stripped_petrified_log{axis:z}"},
        {pos: [2, 8, 12], state: "sullysmod:petrified_log{axis:z}"},
        {pos: [2, 8, 13], state: "sullysmod:petrified_log{axis:z}"},
        {pos: [3, 8, 1], state: "minecraft:air"},
        {pos: [3, 8, 3], state: "sullysmod:stripped_petrified_log{axis:z}"},
        {pos: [3, 8, 4], state: "sullysmod:petrified_log{axis:z}"},
        {pos: [3, 8, 5], state: "sullysmod:petrified_log{axis:z}"},
        {pos: [3, 8, 6], state: "sullysmod:petrified_log{axis:z}"},
        {pos: [3, 8, 7], state: "sullysmod:petrified_log{axis:z}"},
        {pos: [3, 8, 8], state: "sullysmod:petrified_log{axis:z}"},
        {pos: [3, 8, 9], state: "sullysmod:petrified_log{axis:z}"},
        {pos: [3, 8, 10], state: "sullysmod:petrified_log{axis:z}"},
        {pos: [3, 8, 11], state: "sullysmod:petrified_log{axis:z}"},
        {pos: [3, 8, 12], state: "sullysmod:petrified_log{axis:z}"},
        {pos: [3, 8, 13], state: "sullysmod:petrified_log{axis:z}"},
        {pos: [3, 8, 14], state: "sullysmod:stripped_petrified_log{axis:z}"},
        {pos: [4, 8, 2], state: "sullysmod:petrified_log{axis:z}"},
        {pos: [4, 8, 3], state: "sullysmod:petrified_log{axis:z}"},
        {pos: [4, 8, 4], state: "sullysmod:petrified_log{axis:z}"},
        {pos: [4, 8, 5], state: "sullysmod:petrified_log{axis:z}"},
        {pos: [4, 8, 6], state: "sullysmod:petrified_log{axis:z}"},
        {pos: [4, 8, 7], state: "sullysmod:petrified_log{axis:z}"},
        {pos: [4, 8, 8], state: "sullysmod:petrified_log{axis:z}"},
        {pos: [4, 8, 9], state: "sullysmod:petrified_log{axis:z}"},
        {pos: [4, 8, 10], state: "sullysmod:petrified_log{axis:z}"},
        {pos: [4, 8, 11], state: "sullysmod:petrified_log{axis:z}"},
        {pos: [4, 8, 12], state: "sullysmod:petrified_log{axis:z}"},
        {pos: [4, 8, 13], state: "sullysmod:stripped_petrified_log{axis:z}"},
        {pos: [5, 8, 0], state: "sullysmod:stripped_petrified_log{axis:z}"},
        {pos: [5, 8, 1], state: "sullysmod:stripped_petrified_log{axis:z}"},
        {pos: [5, 8, 2], state: "sullysmod:petrified_log{axis:z}"},
        {pos: [5, 8, 3], state: "sullysmod:petrified_log{axis:z}"},
        {pos: [5, 8, 4], state: "sullysmod:petrified_log{axis:z}"},
        {pos: [5, 8, 5], state: "sullysmod:petrified_log{axis:z}"},
        {pos: [5, 8, 6], state: "sullysmod:petrified_log{axis:z}"},
        {pos: [5, 8, 7], state: "sullysmod:petrified_log{axis:z}"},
        {pos: [5, 8, 8], state: "sullysmod:petrified_log{axis:z}"},
        {pos: [5, 8, 9], state: "sullysmod:petrified_log{axis:z}"},
        {pos: [5, 8, 10], state: "sullysmod:stripped_petrified_log{axis:z}"},
        {pos: [5, 8, 11], state: "sullysmod:petrified_log{axis:z}"},
        {pos: [5, 8, 12], state: "sullysmod:petrified_log{axis:z}"},
        {pos: [5, 8, 13], state: "sullysmod:petrified_log{axis:z}"},
        {pos: [5, 8, 14], state: "minecraft:air"},
        {pos: [5, 8, 15], state: "minecraft:air"},
        {pos: [6, 8, 3], state: "sullysmod:stripped_petrified_log{axis:z}"},
        {pos: [6, 8, 4], state: "sullysmod:petrified_log{axis:z}"},
        {pos: [6, 8, 5], state: "sullysmod:petrified_log{axis:z}"},
        {pos: [6, 8, 6], state: "sullysmod:petrified_log{axis:z}"},
        {pos: [6, 8, 7], state: "sullysmod:petrified_log{axis:z}"},
        {pos: [6, 8, 8], state: "sullysmod:petrified_log{axis:z}"},
        {pos: [6, 8, 9], state: "sullysmod:petrified_log{axis:z}"},
        {pos: [6, 8, 11], state: "sullysmod:stripped_petrified_log{axis:z}"},
        {pos: [6, 8, 12], state: "sullysmod:petrified_log{axis:z}"},
        {pos: [6, 8, 13], state: "sullysmod:petrified_log{axis:z}"},
        {pos: [6, 8, 14], state: "sullysmod:stripped_petrified_log{axis:z}"},
        {pos: [7, 8, 2], state: "sullysmod:stripped_petrified_log{axis:z}"},
        {pos: [7, 8, 3], state: "sullysmod:petrified_log{axis:z}"},
        {pos: [7, 8, 4], state: "sullysmod:petrified_log{axis:z}"},
        {pos: [9, 8, 13], state: "minecraft:air"},
        {pos: [1, 9, 7], state: "minecraft:air"},
        {pos: [1, 9, 11], state: "minecraft:air"},
        {pos: [1, 9, 14], state: "minecraft:air"},
        {pos: [2, 9, 2], state: "minecraft:air"},
        {pos: [2, 9, 3], state: "minecraft:air"},
        {pos: [3, 9, 1], state: "minecraft:air"},
        {pos: [3, 9, 2], state: "minecraft:air"},
        {pos: [3, 9, 13], state: "minecraft:air"},
        {pos: [4, 9, 1], state: "minecraft:air"},
        {pos: [4, 9, 2], state: "minecraft:air"},
        {pos: [4, 9, 3], state: "minecraft:air"},
        {pos: [4, 9, 5], state: "sullysmod:petrified_log{axis:z}"},
        {pos: [4, 9, 6], state: "sullysmod:petrified_log{axis:z}"},
        {pos: [4, 9, 7], state: "sullysmod:petrified_log{axis:z}"},
        {pos: [4, 9, 9], state: "minecraft:air"},
        {pos: [4, 9, 10], state: "minecraft:air"},
        {pos: [4, 9, 11], state: "minecraft:air"},
        {pos: [5, 9, 3], state: "minecraft:air"},
        {pos: [5, 9, 4], state: "minecraft:air"},
        {pos: [5, 9, 5], state: "minecraft:air"},
        {pos: [5, 9, 7], state: "sullysmod:petrified_log{axis:z}"},
        {pos: [5, 9, 8], state: "sullysmod:petrified_log{axis:z}"},
        {pos: [5, 9, 9], state: "sullysmod:stripped_petrified_log{axis:z}"},
        {pos: [5, 9, 10], state: "minecraft:air"},
        {pos: [6, 9, 1], state: "minecraft:air"},
        {pos: [6, 9, 2], state: "minecraft:air"},
        {pos: [6, 9, 7], state: "minecraft:air"},
        {pos: [6, 9, 8], state: "minecraft:air"},
        {pos: [7, 9, 1], state: "minecraft:air"},
        {pos: [7, 9, 2], state: "minecraft:air"},
        {pos: [8, 9, 7], state: "minecraft:air"}
    ],
    entities: [],
    palette: [
        "minecraft:gravel",
        "sullysmod:stripped_petrified_log{axis:z}",
        "sullysmod:petrified_log{axis:z}",
        "sullysmod:rough_amber{is_melted:false}",
        "minecraft:air",
        "sullysmod:petrified_sapling{stage:0}",
        "sullysmod:amber{is_melted:false}",
        "minecraft:suspicious_gravel{dusted:0}"
    ]
}
