{
    DataVersion: 3465,
    size: [8, 11, 8],
    data: [
        {pos: [2, 0, 3], state: "minecraft:gravel"},
        {pos: [2, 0, 4], state: "minecraft:gravel"},
        {pos: [2, 0, 5], state: "minecraft:gravel"},
        {pos: [3, 0, 3], state: "minecraft:gravel"},
        {pos: [3, 0, 4], state: "minecraft:gravel"},
        {pos: [3, 0, 5], state: "minecraft:gravel"},
        {pos: [4, 0, 2], state: "minecraft:gravel"},
        {pos: [4, 0, 3], state: "minecraft:gravel"},
        {pos: [4, 0, 4], state: "minecraft:gravel"},
        {pos: [4, 0, 5], state: "minecraft:gravel"},
        {pos: [5, 0, 3], state: "minecraft:gravel"},
        {pos: [5, 0, 4], state: "minecraft:gravel"},
        {pos: [1, 1, 3], state: "minecraft:gravel"},
        {pos: [1, 1, 4], state: "sullysmod:stripped_petrified_log{axis:x}"},
        {pos: [2, 1, 2], state: "minecraft:gravel"},
        {pos: [2, 1, 3], state: "minecraft:gravel"},
        {pos: [2, 1, 4], state: "sullysmod:stripped_petrified_log{axis:x}"},
        {pos: [2, 1, 5], state: "minecraft:gravel"},
        {pos: [2, 1, 6], state: "minecraft:gravel"},
        {pos: [3, 1, 1], state: "sullysmod:petrified_log{axis:z}"},
        {pos: [3, 1, 2], state: "minecraft:gravel"},
        {pos: [3, 1, 3], state: "minecraft:gravel"},
        {pos: [3, 1, 4], state: "minecraft:gravel"},
        {pos: [3, 1, 5], state: "minecraft:gravel"},
        {pos: [3, 1, 6], state: "minecraft:gravel"},
        {pos: [3, 1, 7], state: "minecraft:gravel"},
        {pos: [4, 1, 1], state: "minecraft:gravel"},
        {pos: [4, 1, 2], state: "minecraft:gravel"},
        {pos: [4, 1, 3], state: "minecraft:gravel"},
        {pos: [4, 1, 4], state: "minecraft:gravel"},
        {pos: [4, 1, 5], state: "sullysmod:petrified_log{axis:z}"},
        {pos: [4, 1, 6], state: "sullysmod:stripped_petrified_log{axis:z}"},
        {pos: [5, 1, 2], state: "minecraft:gravel"},
        {pos: [5, 1, 3], state: "minecraft:gravel"},
        {pos: [5, 1, 4], state: "minecraft:gravel"},
        {pos: [5, 1, 5], state: "sullysmod:stripped_petrified_log{axis:x}"},
        {pos: [5, 1, 6], state: "minecraft:gravel"},
        {pos: [6, 1, 2], state: "minecraft:gravel"},
        {pos: [6, 1, 3], state: "minecraft:gravel"},
        {pos: [6, 1, 4], state: "minecraft:gravel"},
        {pos: [6, 1, 5], state: "minecraft:gravel"},
        {pos: [7, 1, 3], state: "minecraft:gravel"},
        {pos: [7, 1, 4], state: "minecraft:gravel"},
        {pos: [1, 2, 2], state: "minecraft:gravel"},
        {pos: [1, 2, 4], state: "minecraft:gravel"},
        {pos: [2, 2, 1], state: "minecraft:gravel"},
        {pos: [2, 2, 2], state: "minecraft:gravel"},
        {pos: [2, 2, 3], state: "minecraft:gravel"},
        {pos: [2, 2, 4], state: "sullysmod:stripped_petrified_log{axis:y}"},
        {pos: [2, 2, 5], state: "minecraft:gravel"},
        {pos: [3, 2, 1], state: "minecraft:suspicious_gravel{dusted:0}", nbt: {id: "minecraft:brushable_block", item: {Count: 0b, id: "minecraft:air"}}},
        {pos: [3, 2, 2], state: "sullysmod:petrified_log{axis:y}"},
        {pos: [3, 2, 3], state: "minecraft:gravel"},
        {pos: [3, 2, 4], state: "minecraft:gravel"},
        {pos: [3, 2, 5], state: "minecraft:gravel"},
        {pos: [3, 2, 6], state: "minecraft:gravel"},
        {pos: [4, 2, 1], state: "minecraft:gravel"},
        {pos: [4, 2, 2], state: "minecraft:air"},
        {pos: [4, 2, 3], state: "sullysmod:rough_amber{is_melted:false}"},
        {pos: [4, 2, 4], state: "sullysmod:petrified_log{axis:y}"},
        {pos: [4, 2, 5], state: "minecraft:gravel"},
        {pos: [4, 2, 6], state: "minecraft:suspicious_gravel{dusted:0}", nbt: {id: "minecraft:brushable_block", item: {Count: 0b, id: "minecraft:air"}}},
        {pos: [4, 2, 7], state: "minecraft:gravel"},
        {pos: [5, 2, 1], state: "minecraft:gravel"},
        {pos: [5, 2, 2], state: "minecraft:gravel"},
        {pos: [5, 2, 3], state: "sullysmod:petrified_log{axis:y}"},
        {pos: [5, 2, 4], state: "minecraft:gravel"},
        {pos: [5, 2, 6], state: "minecraft:gravel"},
        {pos: [6, 2, 3], state: "minecraft:gravel"},
        {pos: [6, 2, 4], state: "minecraft:gravel"},
        {pos: [6, 2, 5], state: "minecraft:gravel"},
        {pos: [1, 3, 4], state: "minecraft:air"},
        {pos: [2, 3, 3], state: "sullysmod:petrified_log{axis:y}"},
        {pos: [2, 3, 4], state: "minecraft:air"},
        {pos: [3, 3, 2], state: "sullysmod:petrified_log{axis:z}"},
        {pos: [3, 3, 3], state: "sullysmod:petrified_log{axis:y}"},
        {pos: [3, 3, 4], state: "sullysmod:petrified_log{axis:y}"},
        {pos: [3, 3, 5], state: "sullysmod:petrified_log{axis:y}"},
        {pos: [4, 3, 2], state: "minecraft:air"},
        {pos: [4, 3, 3], state: "sullysmod:rough_amber{is_melted:false}"},
        {pos: [4, 3, 4], state: "sullysmod:petrified_log{axis:y}"},
        {pos: [4, 3, 5], state: "sullysmod:petrified_log{axis:y}"},
        {pos: [5, 3, 3], state: "minecraft:air"},
        {pos: [5, 3, 4], state: "sullysmod:petrified_log{axis:y}"},
        {pos: [5, 3, 6], state: "minecraft:air"},
        {pos: [2, 4, 4], state: "minecraft:air"},
        {pos: [3, 4, 2], state: "minecraft:air"},
        {pos: [3, 4, 3], state: "sullysmod:petrified_log{axis:y}"},
        {pos: [3, 4, 4], state: "sullysmod:petrified_log{axis:y}"},
        {pos: [3, 4, 5], state: "sullysmod:petrified_log{axis:y}"},
        {pos: [4, 4, 2], state: "sullysmod:stripped_petrified_log{axis:y}"},
        {pos: [4, 4, 3], state: "sullysmod:amber{is_melted:false}", nbt: {RenderEntity: 0b, StuckEntity: [], id: "sullysmod:amber"}},
        {pos: [4, 4, 4], state: "sullysmod:petrified_log{axis:y}"},
        {pos: [4, 4, 5], state: "sullysmod:petrified_log{axis:y}"},
        {pos: [5, 4, 3], state: "minecraft:air"},
        {pos: [1, 5, 4], state: "minecraft:air"},
        {pos: [2, 5, 4], state: "minecraft:air"},
        {pos: [3, 5, 2], state: "minecraft:air"},
        {pos: [3, 5, 3], state: "sullysmod:petrified_log{axis:y}"},
        {pos: [3, 5, 4], state: "sullysmod:petrified_log{axis:y}"},
        {pos: [3, 5, 5], state: "minecraft:air"},
        {pos: [4, 5, 3], state: "sullysmod:petrified_log{axis:y}"},
        {pos: [4, 5, 4], state: "sullysmod:stripped_petrified_log{axis:y}"},
        {pos: [5, 5, 3], state: "sullysmod:petrified_log{axis:x}"},
        {pos: [2, 6, 4], state: "sullysmod:petrified_log{axis:x}"},
        {pos: [2, 6, 6], state: "minecraft:air"},
        {pos: [3, 6, 2], state: "minecraft:air"},
        {pos: [3, 6, 3], state: "sullysmod:stripped_petrified_log{axis:y}"},
        {pos: [3, 6, 4], state: "sullysmod:petrified_log{axis:y}"},
        {pos: [4, 6, 3], state: "sullysmod:petrified_log{axis:y}"},
        {pos: [4, 6, 4], state: "sullysmod:stripped_petrified_log{axis:y}"},
        {pos: [3, 7, 2], state: "sullysmod:petrified_log{axis:z}"},
        {pos: [3, 7, 3], state: "sullysmod:petrified_log{axis:y}"},
        {pos: [3, 7, 4], state: "sullysmod:petrified_log{axis:y}"},
        {pos: [4, 7, 3], state: "sullysmod:petrified_log{axis:y}"},
        {pos: [4, 7, 4], state: "sullysmod:petrified_log{axis:y}"},
        {pos: [3, 8, 3], state: "sullysmod:petrified_log{axis:y}"},
        {pos: [3, 8, 4], state: "sullysmod:petrified_log{axis:y}"},
        {pos: [4, 8, 3], state: "sullysmod:stripped_petrified_log{axis:y}"},
        {pos: [4, 8, 4], state: "sullysmod:petrified_log{axis:y}"},
        {pos: [3, 9, 3], state: "sullysmod:petrified_log{axis:y}"},
        {pos: [4, 9, 4], state: "sullysmod:petrified_log{axis:y}"},
        {pos: [0, 10, 1], state: "minecraft:air"},
        {pos: [1, 10, 0], state: "minecraft:air"},
        {pos: [4, 10, 4], state: "sullysmod:petrified_log{axis:y}"},
        {pos: [7, 10, 0], state: "minecraft:air"},
        {pos: [7, 10, 1], state: "minecraft:air"},
        {pos: [7, 10, 3], state: "minecraft:air"}
    ],
    entities: [],
    palette: [
        "minecraft:gravel",
        "sullysmod:stripped_petrified_log{axis:x}",
        "sullysmod:petrified_log{axis:z}",
        "sullysmod:stripped_petrified_log{axis:z}",
        "sullysmod:stripped_petrified_log{axis:y}",
        "sullysmod:petrified_log{axis:y}",
        "sullysmod:petrified_log{axis:x}",
        "minecraft:air",
        "sullysmod:rough_amber{is_melted:false}",
        "minecraft:suspicious_gravel{dusted:0}",
        "sullysmod:amber{is_melted:false}"
    ]
}
